Workbook

Sheet Scores
A1: Predictions resolved | C1: =COUNTIF(Summary!D2:D103,"<>") -> 24
A2: Predictions to come | C2: =COUNTA(Summary!A2:A103)-C1 -> 78
A4: We are… | B4: =C1/SUM(C1:C2) -> 0.23529412 | C4: there!

Sheet Summary
A1: ID | B1: Category | C1: Prediction | D1: Date resolved | E1: Outcome (0 = false, 1 = true) | F1: Andrew | G1: Boof | H1: Christine | I1: Eileen | J1: Iain | K1: Gäel | L1: Jac | M1: James | N1: Kate | O1: Lachy | P1: Pete | Q1: Rohan | R1: Andrew | S1: Bruce | T1: Christine | U1: Eileen | V1: Iain | W1: Gäel | X1: Jac | Y1: James | Z1: Kate | AA1: Lachy | AB1: Pete | AC1: Rohan | AE1: High-low scores | AF1: Mean prediction | AG1: Variance | AH1: =CONCATENATE(F1," points") -> Andrew points | AI1: =CONCATENATE(G1," points") -> Boof points | AJ1: =CONCATENATE(H1," points") -> Christine points | AK1: =CONCATENATE(I1," points") -> Eileen points | AL1: =CONCATENATE(J1," points") -> Iain points | AM1: =CONCATENATE(K1," points") -> Gäel points | AN1: =CONCATENATE(L1," points") -> Jac points | AO1: =CONCATENATE(M1," points") -> James points | ... AS1: =CONCATENATE(Q1," points") -> Rohan points | AT1: Andrew min | AU1: Boof min | AV1: Christine min | AW1: Eileen min | AX1: Iain min | AY1: Gäel min | AZ1: Jac min | BA1: James min | BB1: Kate min | BC1: Lachy min | BD1: Pete min | BE1: Rohan min | BF1: Andrew max | BG1: Boof max | BH1: Christine max | BI1: Eileen max | BJ1: Iain max | BK1: Gäel max | BL1: Jac max | BM1: James max | BN1: Kate max | BO1: Lachy max | BP1: Pete max | BQ1: Rohan max | BR1: Boof, Andrew | BS1: Jac, James | BW1: Boof | BX1: Andrew | BY1: Boof, Andrew total | BZ1: Jac | CA1: James | CB1: Jac, James total | CC1: Optimistic statement? Yes = optimistic, No = pessimistic, blank is neutral
A2: 1 | B2: Aus Politics | C2: That there will be a hung parliament at the next election and Labor will take office | D2: 44711 | E2: 0 | F2: =Andrew!D2 -> 0.4 | G2: =Bruce!D2 -> 0.7 | H2: =Christine!D2 -> 0.1 | I2: =Eileen!D2 -> 0.2 | J2: =Iain!D2 -> 0.5 | K2: =Gael!D2 -> 0.65 | L2: =Jac!D2 -> 0.2 | M2: =James!D2 -> 0.1 | N2: =Kate!D2 -> 0.8 | O2: =Lachy!D2 -> 0.35 | P2: =Pete!D2 -> 0.1 | Q2: =Rohan!D2 -> 0.45 | R2: =IF($E2=1,(LOG(F2,2)+1),IF($E2=0,(LOG(1-F2,2)+1),"")) -> 0.26303441 | S2: =IF($E2=1,(LOG(G2,2)+1),IF($E2=0,(LOG(1-G2,2)+1),"")) -> -0.73696559 | T2: =IF($E2=1,(LOG(H2,2)+1),IF($E2=0,(LOG(1-H2,2)+1),"")) -> 0.84799691 | U2: =IF($E2=1,(LOG(I2,2)+1),IF($E2=0,(LOG(1-I2,2)+1),"")) -> 0.67807191 | V2: =IF($E2=1,(LOG(J2,2)+1),IF($E2=0,(LOG(1-J2,2)+1),"")) -> 0 | W2: =IF($E2=1,(LOG(K2,2)+1),IF($E2=0,(LOG(1-K2,2)+1),"")) -> -0.51457317 | X2: =IF($E2=1,(LOG(L2,2)+1),IF($E2=0,(LOG(1-L2,2)+1),"")) -> 0.67807191 | Y2: =IF($E2=1,(LOG(M2,2)+1),IF($E2=0,(LOG(1-M2,2)+1),"")) -> 0.84799691 | ... AC2: =IF($E2=1,(LOG(Q2,2)+1),IF($E2=0,(LOG(1-Q2,2)+1),"")) -> 0.13750352 | AD2: Analysis | AE2: =ABS((LOG(F2,2)-LOG(1-F2,2))+ABS(LOG(G2,2)-LOG(1-G2,2))+ABS(LOG(H2,2)-LOG(1-H2,2))+ABS(LOG(I2,2)-LOG(1-I2,2))+ABS(LOG(J2,2)-LOG(1-J2,2))+ABS(LOG(K2,2)-LOG(1-K2,2))+ABS(LOG(L2,2)-LOG(1-L2,2))+ABS(LOG(M2,2)-LOG(1-M2,2))+ABS(LOG(N2,2)-LOG(1-N2,2))+ABS(LOG(O2,2)-LOG(1-O2,2))+ABS(LOG(P2,2)-LOG(1-P2,2))+ABS(LOG(Q2,2)-LOG(1-Q2,2))) -> 18.222881 | AF2: =AVERAGE(F2:Q2) -> 0.37916667 | AG2: =VAR(F2,G2,H2,I2,J2,K2,L2,M2,N2,O2,P2,Q2) -> 0.061117424 | AT2: =IF(F2=MIN($F2:$Q2),"Yes","") | AU2: =IF(G2=MIN($F2:$Q2),"Yes","") | AV2: =IF(H2=MIN($F2:$Q2),"Yes","") -> Yes | AW2: =IF(I2=MIN($F2:$Q2),"Yes","") | AX2: =IF(J2=MIN($F2:$Q2),"Yes","") | AY2: =IF(K2=MIN($F2:$Q2),"Yes","") | AZ2: =IF(L2=MIN($F2:$Q2),"Yes","") | BA2: =IF(M2=MIN($F2:$Q2),"Yes","") -> Yes | ... BE2: =IF(Q2=MIN($F2:$Q2),"Yes","") | BF2: =IF(F2=MAX($F2:$Q2),"Yes","") | BG2: =IF(G2=MAX($F2:$Q2),"Yes","") | BH2: =IF(H2=MAX($F2:$Q2),"Yes","") | BI2: =IF(I2=MAX($F2:$Q2),"Yes","") | BJ2: =IF(J2=MAX($F2:$Q2),"Yes","") | BK2: =IF(K2=MAX($F2:$Q2),"Yes","") | BL2: =IF(L2=MAX($F2:$Q2),"Yes","") | BM2: =IF(M2=MAX($F2:$Q2),"Yes","") | ... BQ2: =IF(Q2=MAX($F2:$Q2),"Yes","") | BR2: =IF((F2-G2)>=0.5,"Yes",IF((G2-F2)>=0.5,"Yes","")) | BS2: =IF((L2-M2)>=0.5,"Yes",IF((M2-L2)>=0.5,"Yes","")) | BW2: =IF(BR2="Yes",-G2,0) -> 0 | BX2: =IF(BR2="Yes",F2,0) -> 0 | BY2: =IF((BX2-BW2)>0.01,(BX2-BW2),"") | BZ2: =IF(BS2="Yes",-L2,0) -> 0 | CA2: =IF(BS2="Yes",M2,0) -> 0 | CB2: =IF((CA2-BZ2)>0.01,(CA2-BZ2),"")
A3: 2 | B3: Aus Politics | C3: Dan Andrews will become leader of the Australian Labor Party | E3: 0 | F3: =Andrew!D3 -> 0.2 | G3: =Bruce!D3 -> 0.1 | H3: =Christine!D3 -> 0.05 | I3: =Eileen!D3 -> 0.2 | J3: =Iain!D3 -> 0.1 | K3: =Gael!D3 -> 0 | L3: =Jac!D3 -> 0.001 | M3: =James!D3 -> 0.05 | N3: =Kate!D3 -> 0.1 | O3: =Lachy!D3 -> 0.001 | P3: =Pete!D3 -> 0.1 | Q3: =Rohan!D3 -> 0.01 | R3: =IF($E3=1,(LOG(F3,2)+1),IF($E3=0,(LOG(1-F3,2)+1),"")) -> 0.67807191 | S3: =IF($E3=1,(LOG(G3,2)+1),IF($E3=0,(LOG(1-G3,2)+1),"")) -> 0.84799691 | T3: =IF($E3=1,(LOG(H3,2)+1),IF($E3=0,(LOG(1-H3,2)+1),"")) -> 0.92599942 | U3: =IF($E3=1,(LOG(I3,2)+1),IF($E3=0,(LOG(1-I3,2)+1),"")) -> 0.67807191 | V3: =IF($E3=1,(LOG(J3,2)+1),IF($E3=0,(LOG(1-J3,2)+1),"")) -> 0.84799691 | W3: =IF($E3=1,(LOG(K3,2)+1),IF($E3=0,(LOG(1-K3,2)+1),"")) -> 1 | X3: =IF($E3=1,(LOG(L3,2)+1),IF($E3=0,(LOG(1-L3,2)+1),"")) -> 0.99855658 | Y3: =IF($E3=1,(LOG(M3,2)+1),IF($E3=0,(LOG(1-M3,2)+1),"")) -> 0.92599942 | ... AC3: =IF($E3=1,(LOG(Q3,2)+1),IF($E3=0,(LOG(1-Q3,2)+1),"")) -> 0.98550043 | AE3: =ABS((LOG(F3,2)-LOG(1-F3,2))+ABS(LOG(G3,2)-LOG(1-G3,2))+ABS(LOG(H3,2)-LOG(1-H3,2))+ABS(LOG(I3,2)-LOG(1-I3,2))+ABS(LOG(J3,2)-LOG(1-J3,2))+ABS(LOG(K3,2)-LOG(1-K3,2))+ABS(LOG(L3,2)-LOG(1-L3,2))+ABS(LOG(M3,2)-LOG(1-M3,2))+ABS(LOG(N3,2)-LOG(1-N3,2))+ABS(LOG(O3,2)-LOG(1-O3,2))+ABS(LOG(P3,2)-LOG(1-P3,2))+ABS(LOG(Q3,2)-LOG(1-Q3,2))) -> #NUM! | AF3: =AVERAGE(F3:Q3) -> 0.076 | AG3: =VAR(F3,G3,H3,I3,J3,K3,L3,M3,N3,O3,P3,Q3) -> 0.0050718182 | AT3: =IF(F3=MIN($F3:$Q3),"Yes","") | AU3: =IF(G3=MIN($F3:$Q3),"Yes","") | AV3: =IF(H3=MIN($F3:$Q3),"Yes","") | AW3: =IF(I3=MIN($F3:$Q3),"Yes","") | AX3: =IF(J3=MIN($F3:$Q3),"Yes","") | AY3: =IF(K3=MIN($F3:$Q3),"Yes","") -> Yes | AZ3: =IF(L3=MIN($F3:$Q3),"Yes","") | BA3: =IF(M3=MIN($F3:$Q3),"Yes","") | ... BE3: =IF(Q3=MIN($F3:$Q3),"Yes","") | BF3: =IF(F3=MAX($F3:$Q3),"Yes","") -> Yes | BG3: =IF(G3=MAX($F3:$Q3),"Yes","") | BH3: =IF(H3=MAX($F3:$Q3),"Yes","") | BI3: =IF(I3=MAX($F3:$Q3),"Yes","") -> Yes | BJ3: =IF(J3=MAX($F3:$Q3),"Yes","") | BK3: =IF(K3=MAX($F3:$Q3),"Yes","") | BL3: =IF(L3=MAX($F3:$Q3),"Yes","") | BM3: =IF(M3=MAX($F3:$Q3),"Yes","") | ... BQ3: =IF(Q3=MAX($F3:$Q3),"Yes","") | BR3: =IF((F3-G3)>=0.5,"Yes",IF((G3-F3)>=0.5,"Yes","")) | BS3: =IF((L3-M3)>=0.5,"Yes",IF((M3-L3)>=0.5,"Yes","")) | BW3: =IF(BR3="Yes",-G3,0) -> 0 | BX3: =IF(BR3="Yes",F3,0) -> 0 | BY3: =IF((BX3-BW3)>0.01,(BX3-BW3),"") | BZ3: =IF(BS3="Yes",-L3,0) -> 0 | CA3: =IF(BS3="Yes",M3,0) -> 0 | CB3: =IF((CA3-BZ3)>0.01,(CA3-BZ3),"") | CC3: Yes
A4: 3 | B4: Aus Politics | C4: The Greens will get more than 9 senators in the next federal election | D4: 44702 | E4: 1 | F4: =Andrew!D4 -> 0.6 | G4: =Bruce!D4 -> 0.3 | H4: =Christine!D4 -> 0.1 | I4: =Eileen!D4 -> 0.6 | J4: =Iain!D4 -> 0.7 | K4: =Gael!D4 -> 0.6 | L4: =Jac!D4 -> 0.7 | M4: =James!D4 -> 0.1 | N4: =Kate!D4 -> 0.1 | O4: =Lachy!D4 -> 0.5 | P4: =Pete!D4 -> 0.5 | Q4: =Rohan!D4 -> 0.55 | R4: =IF($E4=1,(LOG(F4,2)+1),IF($E4=0,(LOG(1-F4,2)+1),"")) -> 0.26303441 | S4: =IF($E4=1,(LOG(G4,2)+1),IF($E4=0,(LOG(1-G4,2)+1),"")) -> -0.73696559 | T4: =IF($E4=1,(LOG(H4,2)+1),IF($E4=0,(LOG(1-H4,2)+1),"")) -> -2.3219281 | U4: =IF($E4=1,(LOG(I4,2)+1),IF($E4=0,(LOG(1-I4,2)+1),"")) -> 0.26303441 | V4: =IF($E4=1,(LOG(J4,2)+1),IF($E4=0,(LOG(1-J4,2)+1),"")) -> 0.48542683 | W4: =IF($E4=1,(LOG(K4,2)+1),IF($E4=0,(LOG(1-K4,2)+1),"")) -> 0.26303441 | X4: =IF($E4=1,(LOG(L4,2)+1),IF($E4=0,(LOG(1-L4,2)+1),"")) -> 0.48542683 | Y4: =IF($E4=1,(LOG(M4,2)+1),IF($E4=0,(LOG(1-M4,2)+1),"")) -> -2.3219281 | ... AC4: =IF($E4=1,(LOG(Q4,2)+1),IF($E4=0,(LOG(1-Q4,2)+1),"")) -> 0.13750352 | AE4: =ABS((LOG(F4,2)-LOG(1-F4,2))+ABS(LOG(G4,2)-LOG(1-G4,2))+ABS(LOG(H4,2)-LOG(1-H4,2))+ABS(LOG(I4,2)-LOG(1-I4,2))+ABS(LOG(J4,2)-LOG(1-J4,2))+ABS(LOG(K4,2)-LOG(1-K4,2))+ABS(LOG(L4,2)-LOG(1-L4,2))+ABS(LOG(M4,2)-LOG(1-M4,2))+ABS(LOG(N4,2)-LOG(1-N4,2))+ABS(LOG(O4,2)-LOG(1-O4,2))+ABS(LOG(P4,2)-LOG(1-P4,2))+ABS(LOG(Q4,2)-LOG(1-Q4,2))) -> 15.221346 | AF4: =AVERAGE(F4:Q4) -> 0.44583333 | AG4: =VAR(F4,G4,H4,I4,J4,K4,L4,M4,N4,O4,P4,Q4) -> 0.054299242 | AT4: =IF(F4=MIN($F4:$Q4),"Yes","") | AU4: =IF(G4=MIN($F4:$Q4),"Yes","") | AV4: =IF(H4=MIN($F4:$Q4),"Yes","") -> Yes | AW4: =IF(I4=MIN($F4:$Q4),"Yes","") | AX4: =IF(J4=MIN($F4:$Q4),"Yes","") | AY4: =IF(K4=MIN($F4:$Q4),"Yes","") | AZ4: =IF(L4=MIN($F4:$Q4),"Yes","") | BA4: =IF(M4=MIN($F4:$Q4),"Yes","") -> Yes | ... BE4: =IF(Q4=MIN($F4:$Q4),"Yes","") | BF4: =IF(F4=MAX($F4:$Q4),"Yes","") | BG4: =IF(G4=MAX($F4:$Q4),"Yes","") | BH4: =IF(H4=MAX($F4:$Q4),"Yes","") | BI4: =IF(I4=MAX($F4:$Q4),"Yes","") | BJ4: =IF(J4=MAX($F4:$Q4),"Yes","") -> Yes | BK4: =IF(K4=MAX($F4:$Q4),"Yes","") | BL4: =IF(L4=MAX($F4:$Q4),"Yes","") -> Yes | BM4: =IF(M4=MAX($F4:$Q4),"Yes","") | ... BQ4: =IF(Q4=MAX($F4:$Q4),"Yes","") | BR4: =IF((F4-G4)>=0.5,"Yes",IF((G4-F4)>=0.5,"Yes","")) | BS4: =IF((L4-M4)>=0.5,"Yes",IF((M4-L4)>=0.5,"Yes","")) -> Yes | BW4: =IF(BR4="Yes",-G4,0) -> 0 | BX4: =IF(BR4="Yes",F4,0) -> 0 | BY4: =IF((BX4-BW4)>0.01,(BX4-BW4),"") | BZ4: =IF(BS4="Yes",-L4,0) -> -0.7 | CA4: =IF(BS4="Yes",M4,0) -> 0.1 | CB4: =IF((CA4-BZ4)>0.01,(CA4-BZ4),"") -> 0.8 | CC4: Yes
A5: 4 | B5: Aus Politics | C5: The House of Reps will include 5 independents by the end of the federal election | D5: 44702 | E5: 1 | F5: =Andrew!D5 -> 0.7 | G5: =Bruce!D5 -> 0.3 | H5: =Christine!D5 -> 0.1 | I5: =Eileen!D5 -> 0.7 | J5: =Iain!D5 -> 0.9 | K5: =Gael!D5 -> 0.75 | L5: =Jac!D5 -> 0.001 | M5: =James!D5 -> 0.1 | N5: =Kate!D5 -> 0.9 | O5: =Lachy!D5 -> 0.5 | P5: =Pete!D5 -> 0.8 | Q5: =Rohan!D5 -> 0.7 | R5: =IF($E5=1,(LOG(F5,2)+1),IF($E5=0,(LOG(1-F5,2)+1),"")) -> 0.48542683 | S5: =LOG(1-G5,2)+1 -> 0.48542683 | T5: =IF($E5=1,(LOG(H5,2)+1),IF($E5=0,(LOG(1-H5,2)+1),"")) -> -2.3219281 | U5: =IF($E5=1,(LOG(I5,2)+1),IF($E5=0,(LOG(1-I5,2)+1),"")) -> 0.48542683 | V5: =IF($E5=1,(LOG(J5,2)+1),IF($E5=0,(LOG(1-J5,2)+1),"")) -> 0.84799691 | W5: =IF($E5=1,(LOG(K5,2)+1),IF($E5=0,(LOG(1-K5,2)+1),"")) -> 0.5849625 | X5: =LOG(1-L5,2)+1 -> 0.99855658 | Y5: =IF($E5=1,(LOG(M5,2)+1),IF($E5=0,(LOG(1-M5,2)+1),"")) -> -2.3219281 | Z5: =IF($E5=1,(LOG(N5,2)+1),IF($E5=0,(LOG(1-N5,2)+1),"")) -> 0.84799691 | AA5: =IF($E5=1,(LOG(O5,2)+1),IF($E5=0,(LOG(1-O5,2)+1),"")) -> 0 | AB5: =IF($E5=1,(LOG(P5,2)+1),IF($E5=0,(LOG(1-P5,2)+1),"")) -> 0.67807191 | AC5: =IF($E5=1,(LOG(Q5,2)+1),IF($E5=0,(LOG(1-Q5,2)+1),"")) -> 0.48542683 | AE5: =ABS((LOG(F5,2)-LOG(1-F5,2))+ABS(LOG(G5,2)-LOG(1-G5,2))+ABS(LOG(H5,2)-LOG(1-H5,2))+ABS(LOG(I5,2)-LOG(1-I5,2))+ABS(LOG(J5,2)-LOG(1-J5,2))+ABS(LOG(K5,2)-LOG(1-K5,2))+ABS(LOG(L5,2)-LOG(1-L5,2))+ABS(LOG(M5,2)-LOG(1-M5,2))+ABS(LOG(N5,2)-LOG(1-N5,2))+ABS(LOG(O5,2)-LOG(1-O5,2))+ABS(LOG(P5,2)-LOG(1-P5,2))+ABS(LOG(Q5,2)-LOG(1-Q5,2))) -> 31.118573 | AF5: =AVERAGE(F5:Q5) -> 0.53758333 | AG5: =VAR(F5,G5,H5,I5,J5,K5,L5,M5,N5,O5,P5,Q5) -> 0.10768645 | AH5: =IF(F5=MIN($F5:$Q5),LOG(1-F5,2)+1,IF(F5=MAX($F5:$Q5),LOG(F5,2)+1,"")) | AI5: =IF(G5=MIN($F5:$Q5),LOG(1-G5,2)+1,IF(G5=MAX($F5:$Q5),LOG(G5,2)+1,"")) | AJ5: =IF(H5=MIN($F5:$Q5),LOG(1-H5,2)+1,IF(H5=MAX($F5:$Q5),LOG(H5,2)+1,"")) | AK5: =IF(I5=MIN($F5:$Q5),LOG(1-I5,2)+1,IF(I5=MAX($F5:$Q5),LOG(I5,2)+1,"")) | AL5: =IF(J5=MIN($F5:$Q5),LOG(1-J5,2)+1,IF(J5=MAX($F5:$Q5),LOG(J5,2)+1,"")) -> 0.84799691 | AM5: =IF(K5=MIN($F5:$Q5),LOG(1-K5,2)+1,IF(K5=MAX($F5:$Q5),LOG(K5,2)+1,"")) | AN5: =IF(L5=MIN($F5:$Q5),LOG(1-L5,2)+1,IF(L5=MAX($F5:$Q5),LOG(L5,2)+1,"")) -> 0.99855658 | AO5: =IF(M5=MIN($F5:$Q5),LOG(1-M5,2)+1,IF(M5=MAX($F5:$Q5),LOG(M5,2)+1,"")) | ... AS5: =IF(Q5=MIN($F5:$Q5),LOG(1-Q5,2)+1,IF(Q5=MAX($F5:$Q5),LOG(Q5,2)+1,"")) | AT5: =IF(F5=MIN($F5:$Q5),"Yes","") | AU5: =IF(G5=MIN($F5:$Q5),"Yes","") | AV5: =IF(H5=MIN($F5:$Q5),"Yes","") | AW5: =IF(I5=MIN($F5:$Q5),"Yes","") | AX5: =IF(J5=MIN($F5:$Q5),"Yes","") | AY5: =IF(K5=MIN($F5:$Q5),"Yes","") | AZ5: =IF(L5=MIN($F5:$Q5),"Yes","") -> Yes | BA5: =IF(M5=MIN($F5:$Q5),"Yes","") | ... BE5: =IF(Q5=MIN($F5:$Q5),"Yes","") | BF5: =IF(F5=MAX($F5:$Q5),"Yes","") | BG5: =IF(G5=MAX($F5:$Q5),"Yes","") | BH5: =IF(H5=MAX($F5:$Q5),"Yes","") | BI5: =IF(I5=MAX($F5:$Q5),"Yes","") | BJ5: =IF(J5=MAX($F5:$Q5),"Yes","") -> Yes | BK5: =IF(K5=MAX($F5:$Q5),"Yes","") | BL5: =IF(L5=MAX($F5:$Q5),"Yes","") | BM5: =IF(M5=MAX($F5:$Q5),"Yes","") | ... BQ5: =IF(Q5=MAX($F5:$Q5),"Yes","") | BR5: =IF((F5-G5)>=0.5,"Yes",IF((G5-F5)>=0.5,"Yes","")) | BS5: =IF((L5-M5)>=0.5,"Yes",IF((M5-L5)>=0.5,"Yes","")) | BW5: =IF(BR5="Yes",-G5,0) -> 0 | BX5: =IF(BR5="Yes",F5,0) -> 0 | BY5: =IF((BX5-BW5)>0.01,(BX5-BW5),"") | BZ5: =IF(BS5="Yes",-L5,0) -> 0 | CA5: =IF(BS5="Yes",M5,0) -> 0 | CB5: =IF((CA5-BZ5)>0.01,(CA5-BZ5),"") | CC5: Yes
A6: 5 | B6: Aus Politics | C6: The Australian Labor Party will not pledge to reverse the uni fee structure introduced in 2020 | E6: 1 | F6: =Andrew!D6 -> 0.6 | G6: =Bruce!D6 -> 0.8 | H6: =Christine!D6 -> 0.9 | I6: =Eileen!D6 -> 0.7 | J6: =Iain!D6 -> 0.5 | K6: =Gael!D6 -> 0.85 | L6: =Jac!D6 -> 0.9 | M6: =James!D6 -> 0.9 | N6: =Kate!D6 -> 0.9 | O6: =Lachy!D6 -> 0.85 | P6: =Pete!D6 -> 0.8 | Q6: =Rohan!D6 -> 0.75 | R6: =IF($E6=1,(LOG(F6,2)+1),IF($E6=0,(LOG(1-F6,2)+1),"")) -> 0.26303441 | S6: =IF($E6=1,(LOG(G6,2)+1),IF($E6=0,(LOG(1-G6,2)+1),"")) -> 0.67807191 | T6: =IF($E6=1,(LOG(H6,2)+1),IF($E6=0,(LOG(1-H6,2)+1),"")) -> 0.84799691 | U6: =IF($E6=1,(LOG(I6,2)+1),IF($E6=0,(LOG(1-I6,2)+1),"")) -> 0.48542683 | V6: =IF($E6=1,(LOG(J6,2)+1),IF($E6=0,(LOG(1-J6,2)+1),"")) -> 0 | W6: =IF($E6=1,(LOG(K6,2)+1),IF($E6=0,(LOG(1-K6,2)+1),"")) -> 0.76553475 | X6: =IF($E6=1,(LOG(L6,2)+1),IF($E6=0,(LOG(1-L6,2)+1),"")) -> 0.84799691 | Y6: =IF($E6=1,(LOG(M6,2)+1),IF($E6=0,(LOG(1-M6,2)+1),"")) -> 0.84799691 | ... AC6: =IF($E6=1,(LOG(Q6,2)+1),IF($E6=0,(LOG(1-Q6,2)+1),"")) -> 0.5849625 | AE6: =ABS((LOG(F6,2)-LOG(1-F6,2))+ABS(LOG(G6,2)-LOG(1-G6,2))+ABS(LOG(H6,2)-LOG(1-H6,2))+ABS(LOG(I6,2)-LOG(1-I6,2))+ABS(LOG(J6,2)-LOG(1-J6,2))+ABS(LOG(K6,2)-LOG(1-K6,2))+ABS(LOG(L6,2)-LOG(1-L6,2))+ABS(LOG(M6,2)-LOG(1-M6,2))+ABS(LOG(N6,2)-LOG(1-N6,2))+ABS(LOG(O6,2)-LOG(1-O6,2))+ABS(LOG(P6,2)-LOG(1-P6,2))+ABS(LOG(Q6,2)-LOG(1-Q6,2))) -> 25.077018 | AF6: =AVERAGE(F6:Q6) -> 0.7875 | AG6: =VAR(F6,G6,H6,I6,J6,K6,L6,M6,N6,O6,P6,Q6) -> 0.016875 | AT6: =IF(F6=MIN($F6:$Q6),"Yes","") | AU6: =IF(G6=MIN($F6:$Q6),"Yes","") | AV6: =IF(H6=MIN($F6:$Q6),"Yes","") | AW6: =IF(I6=MIN($F6:$Q6),"Yes","") | AX6: =IF(J6=MIN($F6:$Q6),"Yes","") -> Yes | AY6: =IF(K6=MIN($F6:$Q6),"Yes","") | AZ6: =IF(L6=MIN($F6:$Q6),"Yes","") | BA6: =IF(M6=MIN($F6:$Q6),"Yes","") | ... BE6: =IF(Q6=MIN($F6:$Q6),"Yes","") | BF6: =IF(F6=MAX($F6:$Q6),"Yes","") | BG6: =IF(G6=MAX($F6:$Q6),"Yes","") | BH6: =IF(H6=MAX($F6:$Q6),"Yes","") -> Yes | BI6: =IF(I6=MAX($F6:$Q6),"Yes","") | BJ6: =IF(J6=MAX($F6:$Q6),"Yes","") | BK6: =IF(K6=MAX($F6:$Q6),"Yes","") | BL6: =IF(L6=MAX($F6:$Q6),"Yes","") -> Yes | BM6: =IF(M6=MAX($F6:$Q6),"Yes","") -> Yes | ... BQ6: =IF(Q6=MAX($F6:$Q6),"Yes","") | BR6: =IF((F6-G6)>=0.5,"Yes",IF((G6-F6)>=0.5,"Yes","")) | BS6: =IF((L6-M6)>=0.5,"Yes",IF((M6-L6)>=0.5,"Yes","")) | BW6: =IF(BR6="Yes",-G6,0) -> 0 | BX6: =IF(BR6="Yes",F6,0) -> 0 | BY6: =IF((BX6-BW6)>0.01,(BX6-BW6),"") | BZ6: =IF(BS6="Yes",-L6,0) -> 0 | CA6: =IF(BS6="Yes",M6,0) -> 0 | CB6: =IF((CA6-BZ6)>0.01,(CA6-BZ6),"") | CC6: No
A7: 6 | B7: Aus Politics | C7: Zali Steggal and Helen Haines will both retain their seats in Federal Parliament | D7: 44702 | E7: 1 | F7: =Andrew!D7 -> 0.5 | G7: =Bruce!D7 -> 0.9 | H7: =Christine!D7 -> 0.5 | I7: =Eileen!D7 -> 0.7 | J7: =Iain!D7 -> 0.9 | K7: =Gael!D7 -> 0.95 | L7: =Jac!D7 -> 0.4 | M7: =James!D7 -> 0.5 | N7: =Kate!D7 -> 0.9 | O7: =Lachy!D7 -> 0.85 | P7: =Pete!D7 -> 0.9 | Q7: =Rohan!D7 -> 0.5 | R7: =IF($E7=1,(LOG(F7,2)+1),IF($E7=0,(LOG(1-F7,2)+1),"")) -> 0 | S7: =IF($E7=1,(LOG(G7,2)+1),IF($E7=0,(LOG(1-G7,2)+1),"")) -> 0.84799691 | T7: =IF($E7=1,(LOG(H7,2)+1),IF($E7=0,(LOG(1-H7,2)+1),"")) -> 0 | U7: =IF($E7=1,(LOG(I7,2)+1),IF($E7=0,(LOG(1-I7,2)+1),"")) -> 0.48542683 | V7: =IF($E7=1,(LOG(J7,2)+1),IF($E7=0,(LOG(1-J7,2)+1),"")) -> 0.84799691 | W7: =IF($E7=1,(LOG(K7,2)+1),IF($E7=0,(LOG(1-K7,2)+1),"")) -> 0.92599942 | X7: =IF($E7=1,(LOG(L7,2)+1),IF($E7=0,(LOG(1-L7,2)+1),"")) -> -0.32192809 | Y7: =IF($E7=1,(LOG(M7,2)+1),IF($E7=0,(LOG(1-M7,2)+1),"")) -> 0 | ... AC7: =IF($E7=1,(LOG(Q7,2)+1),IF($E7=0,(LOG(1-Q7,2)+1),"")) -> 0 | AE7: =ABS((LOG(F7,2)-LOG(1-F7,2))+ABS(LOG(G7,2)-LOG(1-G7,2))+ABS(LOG(H7,2)-LOG(1-H7,2))+ABS(LOG(I7,2)-LOG(1-I7,2))+ABS(LOG(J7,2)-LOG(1-J7,2))+ABS(LOG(K7,2)-LOG(1-K7,2))+ABS(LOG(L7,2)-LOG(1-L7,2))+ABS(LOG(M7,2)-LOG(1-M7,2))+ABS(LOG(N7,2)-LOG(1-N7,2))+ABS(LOG(O7,2)-LOG(1-O7,2))+ABS(LOG(P7,2)-LOG(1-P7,2))+ABS(LOG(Q7,2)-LOG(1-Q7,2))) -> 21.237483 | AF7: =AVERAGE(F7:Q7) -> 0.70833333 | AG7: =VAR(F7,G7,H7,I7,J7,K7,L7,M7,N7,O7,P7,Q7) -> 0.044924242 | AT7: =IF(F7=MIN($F7:$Q7),"Yes","") | AU7: =IF(G7=MIN($F7:$Q7),"Yes","") | AV7: =IF(H7=MIN($F7:$Q7),"Yes","") | AW7: =IF(I7=MIN($F7:$Q7),"Yes","") | AX7: =IF(J7=MIN($F7:$Q7),"Yes","") | AY7: =IF(K7=MIN($F7:$Q7),"Yes","") | AZ7: =IF(L7=MIN($F7:$Q7),"Yes","") -> Yes | BA7: =IF(M7=MIN($F7:$Q7),"Yes","") | ... BE7: =IF(Q7=MIN($F7:$Q7),"Yes","") | BF7: =IF(F7=MAX($F7:$Q7),"Yes","") | BG7: =IF(G7=MAX($F7:$Q7),"Yes","") | BH7: =IF(H7=MAX($F7:$Q7),"Yes","") | BI7: =IF(I7=MAX($F7:$Q7),"Yes","") | BJ7: =IF(J7=MAX($F7:$Q7),"Yes","") | BK7: =IF(K7=MAX($F7:$Q7),"Yes","") -> Yes | BL7: =IF(L7=MAX($F7:$Q7),"Yes","") | BM7: =IF(M7=MAX($F7:$Q7),"Yes","") | ... BQ7: =IF(Q7=MAX($F7:$Q7),"Yes","") | BR7: =IF((F7-G7)>=0.5,"Yes",IF((G7-F7)>=0.5,"Yes","")) | BS7: =IF((L7-M7)>=0.5,"Yes",IF((M7-L7)>=0.5,"Yes","")) | BW7: =IF(BR7="Yes",-G7,0) -> 0 | BX7: =IF(BR7="Yes",F7,0) -> 0 | BY7: =IF((BX7-BW7)>0.01,(BX7-BW7),"") | BZ7: =IF(BS7="Yes",-L7,0) -> 0 | CA7: =IF(BS7="Yes",M7,0) -> 0 | CB7: =IF((CA7-BZ7)>0.01,(CA7-BZ7),"")
A8: 7 | B8: Aus Politics | C8: Scott Morrison will lose leadership of the Liberal Party at least once | D8: 44702 | E8: 1 | F8: =Andrew!D8 -> 0.8 | G8: =Bruce!D8 -> 0.7 | H8: =Christine!D8 -> 0.15 | I8: =Eileen!D8 -> 0.3 | J8: =Iain!D8 -> 0.6 | K8: =Gael!D8 -> 0.75 | L8: =Jac!D8 -> 0.5 | M8: =James!D8 -> 0.05 | N8: =Kate!D8 -> 0.9 | O8: =Lachy!D8 -> 0.35 | P8: =Pete!D8 -> 0.7 | Q8: =Rohan!D8 -> 0.9 | R8: =IF($E8=1,(LOG(F8,2)+1),IF($E8=0,(LOG(1-F8,2)+1),"")) -> 0.67807191 | S8: =IF($E8=1,(LOG(G8,2)+1),IF($E8=0,(LOG(1-G8,2)+1),"")) -> 0.48542683 | T8: =IF($E8=1,(LOG(H8,2)+1),IF($E8=0,(LOG(1-H8,2)+1),"")) -> -1.7369656 | U8: =IF($E8=1,(LOG(I8,2)+1),IF($E8=0,(LOG(1-I8,2)+1),"")) -> -0.73696559 | V8: =IF($E8=1,(LOG(J8,2)+1),IF($E8=0,(LOG(1-J8,2)+1),"")) -> 0.26303441 | W8: =IF($E8=1,(LOG(K8,2)+1),IF($E8=0,(LOG(1-K8,2)+1),"")) -> 0.5849625 | X8: =IF($E8=1,(LOG(L8,2)+1),IF($E8=0,(LOG(1-L8,2)+1),"")) -> 0 | Y8: =IF($E8=1,(LOG(M8,2)+1),IF($E8=0,(LOG(1-M8,2)+1),"")) -> -3.3219281 | ... AC8: =IF($E8=1,(LOG(Q8,2)+1),IF($E8=0,(LOG(1-Q8,2)+1),"")) -> 0.84799691 | AE8: =ABS((LOG(F8,2)-LOG(1-F8,2))+ABS(LOG(G8,2)-LOG(1-G8,2))+ABS(LOG(H8,2)-LOG(1-H8,2))+ABS(LOG(I8,2)-LOG(1-I8,2))+ABS(LOG(J8,2)-LOG(1-J8,2))+ABS(LOG(K8,2)-LOG(1-K8,2))+ABS(LOG(L8,2)-LOG(1-L8,2))+ABS(LOG(M8,2)-LOG(1-M8,2))+ABS(LOG(N8,2)-LOG(1-N8,2))+ABS(LOG(O8,2)-LOG(1-O8,2))+ABS(LOG(P8,2)-LOG(1-P8,2))+ABS(LOG(Q8,2)-LOG(1-Q8,2))) -> 21.820465 | AF8: =AVERAGE(F8:Q8) -> 0.55833333 | AG8: =VAR(F8,G8,H8,I8,J8,K8,L8,M8,N8,O8,P8,Q8) -> 0.082651515 | AH8: =IF(F8=MIN($F8:$Q8),LOG(1-F8,2)+1,IF(F8=MAX($F8:$Q8),LOG(F8,2)+1,"")) | AI8: =IF(G8=MIN($F8:$Q8),LOG(1-G8,2)+1,IF(G8=MAX($F8:$Q8),LOG(G8,2)+1,"")) | AJ8: =IF(H8=MIN($F8:$Q8),LOG(1-H8,2)+1,IF(H8=MAX($F8:$Q8),LOG(H8,2)+1,"")) | AK8: =IF(I8=MIN($F8:$Q8),LOG(1-I8,2)+1,IF(I8=MAX($F8:$Q8),LOG(I8,2)+1,"")) | AL8: =IF(J8=MIN($F8:$Q8),LOG(1-J8,2)+1,IF(J8=MAX($F8:$Q8),LOG(J8,2)+1,"")) | AM8: =IF(K8=MIN($F8:$Q8),LOG(1-K8,2)+1,IF(K8=MAX($F8:$Q8),LOG(K8,2)+1,"")) | AN8: =IF(L8=MIN($F8:$Q8),LOG(1-L8,2)+1,IF(L8=MAX($F8:$Q8),LOG(L8,2)+1,"")) | AO8: =IF(M8=MIN($F8:$Q8),LOG(1-M8,2)+1,IF(M8=MAX($F8:$Q8),LOG(M8,2)+1,"")) -> 0.92599942 | ... AS8: =IF(Q8=MIN($F8:$Q8),LOG(1-Q8,2)+1,IF(Q8=MAX($F8:$Q8),LOG(Q8,2)+1,"")) -> 0.84799691 | AT8: =IF(F8=MIN($F8:$Q8),"Yes","") | AU8: =IF(G8=MIN($F8:$Q8),"Yes","") | AV8: =IF(H8=MIN($F8:$Q8),"Yes","") | AW8: =IF(I8=MIN($F8:$Q8),"Yes","") | AX8: =IF(J8=MIN($F8:$Q8),"Yes","") | AY8: =IF(K8=MIN($F8:$Q8),"Yes","") | AZ8: =IF(L8=MIN($F8:$Q8),"Yes","") | BA8: =IF(M8=MIN($F8:$Q8),"Yes","") -> Yes | ... BE8: =IF(Q8=MIN($F8:$Q8),"Yes","") | BF8: =IF(F8=MAX($F8:$Q8),"Yes","") | BG8: =IF(G8=MAX($F8:$Q8),"Yes","") | BH8: =IF(H8=MAX($F8:$Q8),"Yes","") | BI8: =IF(I8=MAX($F8:$Q8),"Yes","") | BJ8: =IF(J8=MAX($F8:$Q8),"Yes","") | BK8: =IF(K8=MAX($F8:$Q8),"Yes","") | BL8: =IF(L8=MAX($F8:$Q8),"Yes","") | BM8: =IF(M8=MAX($F8:$Q8),"Yes","") | ... BQ8: =IF(Q8=MAX($F8:$Q8),"Yes","") -> Yes | BR8: =IF((F8-G8)>=0.5,"Yes",IF((G8-F8)>=0.5,"Yes","")) | BS8: =IF((L8-M8)>=0.5,"Yes",IF((M8-L8)>=0.5,"Yes","")) | BW8: =IF(BR8="Yes",-G8,0) -> 0 | BX8: =IF(BR8="Yes",F8,0) -> 0 | BY8: =IF((BX8-BW8)>0.01,(BX8-BW8),"") | BZ8: =IF(BS8="Yes",-L8,0) -> 0 | CA8: =IF(BS8="Yes",M8,0) -> 0 | CB8: =IF((CA8-BZ8)>0.01,(CA8-BZ8),"") | CC8: Yes
A9: 8 | B9: Aus Politics | C9: Anthony Albanese will be Prime Minister on at least one day | D9: 44702 | E9: 1 | F9: =Andrew!D9 -> 0.6 | G9: =Bruce!D9 -> 0.9 | H9: =Christine!D9 -> 0.05 | I9: =Eileen!D9 -> 0.3 | J9: =Iain!D9 -> 0.1 | K9: =Gael!D9 -> 0.75 | L9: =Jac!D9 -> 0.3 | M9: =James!D9 -> 0.05 | N9: =Kate!D9 -> 0.9 | O9: =Lachy!D9 -> 0.35 | P9: =Pete!D9 -> 0.8 | Q9: =Rohan!D9 -> 0.4 | R9: =IF($E9=1,(LOG(F9,2)+1),IF($E9=0,(LOG(1-F9,2)+1),"")) -> 0.26303441 | S9: =IF($E9=1,(LOG(G9,2)+1),IF($E9=0,(LOG(1-G9,2)+1),"")) -> 0.84799691 | T9: =IF($E9=1,(LOG(H9,2)+1),IF($E9=0,(LOG(1-H9,2)+1),"")) -> -3.3219281 | U9: =IF($E9=1,(LOG(I9,2)+1),IF($E9=0,(LOG(1-I9,2)+1),"")) -> -0.73696559 | V9: =IF($E9=1,(LOG(J9,2)+1),IF($E9=0,(LOG(1-J9,2)+1),"")) -> -2.3219281 | W9: =IF($E9=1,(LOG(K9,2)+1),IF($E9=0,(LOG(1-K9,2)+1),"")) -> 0.5849625 | X9: =IF($E9=1,(LOG(L9,2)+1),IF($E9=0,(LOG(1-L9,2)+1),"")) -> -0.73696559 | Y9: =IF($E9=1,(LOG(M9,2)+1),IF($E9=0,(LOG(1-M9,2)+1),"")) -> -3.3219281 | ... AC9: =IF($E9=1,(LOG(Q9,2)+1),IF($E9=0,(LOG(1-Q9,2)+1),"")) -> -0.32192809 | AE9: =ABS((LOG(F9,2)-LOG(1-F9,2))+ABS(LOG(G9,2)-LOG(1-G9,2))+ABS(LOG(H9,2)-LOG(1-H9,2))+ABS(LOG(I9,2)-LOG(1-I9,2))+ABS(LOG(J9,2)-LOG(1-J9,2))+ABS(LOG(K9,2)-LOG(1-K9,2))+ABS(LOG(L9,2)-LOG(1-L9,2))+ABS(LOG(M9,2)-LOG(1-M9,2))+ABS(LOG(N9,2)-LOG(1-N9,2))+ABS(LOG(O9,2)-LOG(1-O9,2))+ABS(LOG(P9,2)-LOG(1-P9,2))+ABS(LOG(Q9,2)-LOG(1-Q9,2))) -> 26.098387 | AF9: =AVERAGE(F9:Q9) -> 0.45833333 | AG9: =VAR(F9,G9,H9,I9,J9,K9,L9,M9,N9,O9,P9,Q9) -> 0.10356061 | AH9: =IF(F9=MIN($F9:$Q9),LOG(1-F9,2)+1,IF(F9=MAX($F9:$Q9),LOG(F9,2)+1,"")) | AI9: =IF(G9=MIN($F9:$Q9),LOG(1-G9,2)+1,IF(G9=MAX($F9:$Q9),LOG(G9,2)+1,"")) -> 0.84799691 | AJ9: =IF(H9=MIN($F9:$Q9),LOG(1-H9,2)+1,IF(H9=MAX($F9:$Q9),LOG(H9,2)+1,"")) -> 0.92599942 | AK9: =IF(I9=MIN($F9:$Q9),LOG(1-I9,2)+1,IF(I9=MAX($F9:$Q9),LOG(I9,2)+1,"")) | AL9: =IF(J9=MIN($F9:$Q9),LOG(1-J9,2)+1,IF(J9=MAX($F9:$Q9),LOG(J9,2)+1,"")) | AM9: =IF(K9=MIN($F9:$Q9),LOG(1-K9,2)+1,IF(K9=MAX($F9:$Q9),LOG(K9,2)+1,"")) | AN9: =IF(L9=MIN($F9:$Q9),LOG(1-L9,2)+1,IF(L9=MAX($F9:$Q9),LOG(L9,2)+1,"")) | AO9: =IF(M9=MIN($F9:$Q9),LOG(1-M9,2)+1,IF(M9=MAX($F9:$Q9),LOG(M9,2)+1,"")) -> 0.92599942 | ... AS9: =IF(Q9=MIN($F9:$Q9),LOG(1-Q9,2)+1,IF(Q9=MAX($F9:$Q9),LOG(Q9,2)+1,"")) | AT9: =IF(F9=MIN($F9:$Q9),"Yes","") | AU9: =IF(G9=MIN($F9:$Q9),"Yes","") | AV9: =IF(H9=MIN($F9:$Q9),"Yes","") -> Yes | AW9: =IF(I9=MIN($F9:$Q9),"Yes","") | AX9: =IF(J9=MIN($F9:$Q9),"Yes","") | AY9: =IF(K9=MIN($F9:$Q9),"Yes","") | AZ9: =IF(L9=MIN($F9:$Q9),"Yes","") | BA9: =IF(M9=MIN($F9:$Q9),"Yes","") -> Yes | ... BE9: =IF(Q9=MIN($F9:$Q9),"Yes","") | BF9: =IF(F9=MAX($F9:$Q9),"Yes","") | BG9: =IF(G9=MAX($F9:$Q9),"Yes","") -> Yes | BH9: =IF(H9=MAX($F9:$Q9),"Yes","") | BI9: =IF(I9=MAX($F9:$Q9),"Yes","") | BJ9: =IF(J9=MAX($F9:$Q9),"Yes","") | BK9: =IF(K9=MAX($F9:$Q9),"Yes","") | BL9: =IF(L9=MAX($F9:$Q9),"Yes","") | BM9: =IF(M9=MAX($F9:$Q9),"Yes","") | ... BQ9: =IF(Q9=MAX($F9:$Q9),"Yes","") | BR9: =IF((F9-G9)>=0.5,"Yes",IF((G9-F9)>=0.5,"Yes","")) | BS9: =IF((L9-M9)>=0.5,"Yes",IF((M9-L9)>=0.5,"Yes","")) | BW9: =IF(BR9="Yes",-G9,0) -> 0 | BX9: =IF(BR9="Yes",F9,0) -> 0 | BY9: =IF((BX9-BW9)>0.01,(BX9-BW9),"") | BZ9: =IF(BS9="Yes",-L9,0) -> 0 | CA9: =IF(BS9="Yes",M9,0) -> 0 | CB9: =IF((CA9-BZ9)>0.01,(CA9-BZ9),"") | CC9: Yes
A10: 9 | B10: Aus Politics | C10: A sitting MP will make allegations of possible voter fraud or election 'rigging' in the 2022 Australian federal election | E10: 0 | F10: =Andrew!D10 -> 0.55 | G10: =Bruce!D10 -> 0.3 | H10: =Christine!D10 -> 0.3 | I10: =Eileen!D10 -> 0.4 | J10: =Iain!D10 -> 0.9 | K10: =Gael!D10 -> 0.35 | L10: =Jac!D10 -> 0.9 | M10: =James!D10 -> 0.3 | N10: =Kate!D10 -> 0.7 | O10: =Lachy!D10 -> 0.85 | P10: =Pete!D10 -> 0.4 | Q10: =Rohan!D10 -> 0.8 | R10: =IF($E10=1,(LOG(F10,2)+1),IF($E10=0,(LOG(1-F10,2)+1),"")) -> -0.15200309 | S10: =IF($E10=1,(LOG(G10,2)+1),IF($E10=0,(LOG(1-G10,2)+1),"")) -> 0.48542683 | T10: =IF($E10=1,(LOG(H10,2)+1),IF($E10=0,(LOG(1-H10,2)+1),"")) -> 0.48542683 | U10: =IF($E10=1,(LOG(I10,2)+1),IF($E10=0,(LOG(1-I10,2)+1),"")) -> 0.26303441 | V10: =IF($E10=1,(LOG(J10,2)+1),IF($E10=0,(LOG(1-J10,2)+1),"")) -> -2.3219281 | W10: =IF($E10=1,(LOG(K10,2)+1),IF($E10=0,(LOG(1-K10,2)+1),"")) -> 0.37851162 | X10: =IF($E10=1,(LOG(L10,2)+1),IF($E10=0,(LOG(1-L10,2)+1),"")) -> -2.3219281 | Y10: =IF($E10=1,(LOG(M10,2)+1),IF($E10=0,(LOG(1-M10,2)+1),"")) -> 0.48542683 | ... AC10: =IF($E10=1,(LOG(Q10,2)+1),IF($E10=0,(LOG(1-Q10,2)+1),"")) -> -1.3219281 | AE10: =ABS((LOG(F10,2)-LOG(1-F10,2))+ABS(LOG(G10,2)-LOG(1-G10,2))+ABS(LOG(H10,2)-LOG(1-H10,2))+ABS(LOG(I10,2)-LOG(1-I10,2))+ABS(LOG(J10,2)-LOG(1-J10,2))+ABS(LOG(K10,2)-LOG(1-K10,2))+ABS(LOG(L10,2)-LOG(1-L10,2))+ABS(LOG(M10,2)-LOG(1-M10,2))+ABS(LOG(N10,2)-LOG(1-N10,2))+ABS(LOG(O10,2)-LOG(1-O10,2))+ABS(LOG(P10,2)-LOG(1-P10,2))+ABS(LOG(Q10,2)-LOG(1-Q10,2))) -> 18.084436 | AF10: =AVERAGE(F10:Q10) -> 0.5625 | AG10: =VAR(F10,G10,H10,I10,J10,K10,L10,M10,N10,O10,P10,Q10) -> 0.062784091 | AT10: =IF(F10=MIN($F10:$Q10),"Yes","") | AU10: =IF(G10=MIN($F10:$Q10),"Yes","") -> Yes | AV10: =IF(H10=MIN($F10:$Q10),"Yes","") -> Yes | AW10: =IF(I10=MIN($F10:$Q10),"Yes","") | AX10: =IF(J10=MIN($F10:$Q10),"Yes","") | AY10: =IF(K10=MIN($F10:$Q10),"Yes","") | AZ10: =IF(L10=MIN($F10:$Q10),"Yes","") | BA10: =IF(M10=MIN($F10:$Q10),"Yes","") -> Yes | ... BE10: =IF(Q10=MIN($F10:$Q10),"Yes","") | BF10: =IF(F10=MAX($F10:$Q10),"Yes","") | BG10: =IF(G10=MAX($F10:$Q10),"Yes","") | BH10: =IF(H10=MAX($F10:$Q10),"Yes","") | BI10: =IF(I10=MAX($F10:$Q10),"Yes","") | BJ10: =IF(J10=MAX($F10:$Q10),"Yes","") -> Yes | BK10: =IF(K10=MAX($F10:$Q10),"Yes","") | BL10: =IF(L10=MAX($F10:$Q10),"Yes","") -> Yes | BM10: =IF(M10=MAX($F10:$Q10),"Yes","") | ... BQ10: =IF(Q10=MAX($F10:$Q10),"Yes","") | BR10: =IF((F10-G10)>=0.5,"Yes",IF((G10-F10)>=0.5,"Yes","")) | BS10: =IF((L10-M10)>=0.5,"Yes",IF((M10-L10)>=0.5,"Yes","")) -> Yes | BW10: =IF(BR10="Yes",-G10,0) -> 0 | BX10: =IF(BR10="Yes",F10,0) -> 0 | BY10: =IF((BX10-BW10)>0.01,(BX10-BW10),"") | BZ10: =IF(BS10="Yes",-L10,0) -> -0.9 | CA10: =IF(BS10="Yes",M10,0) -> 0.3 | CB10: =IF((CA10-BZ10)>0.01,(CA10-BZ10),"") -> 1.2
A11: 10 | B11: Aus Politics | C11: The Australian Intelligence Community will release a statement contradicting a Government minister or MP during the 2022 election campaign | D11: 44702 | E11: 0 | F11: =Andrew!D11 -> 0.4 | G11: =Bruce!D11 -> 0.2 | H11: =Christine!D11 -> 0.1 | I11: =Eileen!D11 -> 0.2 | J11: =Iain!D11 -> 0.1 | K11: =Gael!D11 -> 0.55 | L11: =Jac!D11 -> 0.15 | M11: =James!D11 -> 0.1 | N11: =Kate!D11 -> 0.9 | O11: =Lachy!D11 -> 0.001 | P11: =Pete!D11 -> 0.1 | Q11: =Rohan!D11 -> 0.75 | R11: =IF($E11=1,(LOG(F11,2)+1),IF($E11=0,(LOG(1-F11,2)+1),"")) -> 0.26303441 | S11: =IF($E11=1,(LOG(G11,2)+1),IF($E11=0,(LOG(1-G11,2)+1),"")) -> 0.67807191 | T11: =IF($E11=1,(LOG(H11,2)+1),IF($E11=0,(LOG(1-H11,2)+1),"")) -> 0.84799691 | U11: =IF($E11=1,(LOG(I11,2)+1),IF($E11=0,(LOG(1-I11,2)+1),"")) -> 0.67807191 | V11: =IF($E11=1,(LOG(J11,2)+1),IF($E11=0,(LOG(1-J11,2)+1),"")) -> 0.84799691 | W11: =IF($E11=1,(LOG(K11,2)+1),IF($E11=0,(LOG(1-K11,2)+1),"")) -> -0.15200309 | X11: =IF($E11=1,(LOG(L11,2)+1),IF($E11=0,(LOG(1-L11,2)+1),"")) -> 0.76553475 | Y11: =IF($E11=1,(LOG(M11,2)+1),IF($E11=0,(LOG(1-M11,2)+1),"")) -> 0.84799691 | ... AC11: =IF($E11=1,(LOG(Q11,2)+1),IF($E11=0,(LOG(1-Q11,2)+1),"")) -> -1 | AE11: =ABS((LOG(F11,2)-LOG(1-F11,2))+ABS(LOG(G11,2)-LOG(1-G11,2))+ABS(LOG(H11,2)-LOG(1-H11,2))+ABS(LOG(I11,2)-LOG(1-I11,2))+ABS(LOG(J11,2)-LOG(1-J11,2))+ABS(LOG(K11,2)-LOG(1-K11,2))+ABS(LOG(L11,2)-LOG(1-L11,2))+ABS(LOG(M11,2)-LOG(1-M11,2))+ABS(LOG(N11,2)-LOG(1-N11,2))+ABS(LOG(O11,2)-LOG(1-O11,2))+ABS(LOG(P11,2)-LOG(1-P11,2))+ABS(LOG(Q11,2)-LOG(1-Q11,2))) -> 33.605973 | AF11: =AVERAGE(F11:Q11) -> 0.29591667 | AG11: =VAR(F11,G11,H11,I11,J11,K11,L11,M11,N11,O11,P11,Q11) -> 0.084245538 | AH11: =IF(F11=MIN($F11:$Q11),LOG(1-F11,2)+1,IF(F11=MAX($F11:$Q11),LOG(F11,2)+1,"")) | AI11: =IF(G11=MIN($F11:$Q11),LOG(1-G11,2)+1,IF(G11=MAX($F11:$Q11),LOG(G11,2)+1,"")) | AJ11: =IF(H11=MIN($F11:$Q11),LOG(1-H11,2)+1,IF(H11=MAX($F11:$Q11),LOG(H11,2)+1,"")) | AK11: =IF(I11=MIN($F11:$Q11),LOG(1-I11,2)+1,IF(I11=MAX($F11:$Q11),LOG(I11,2)+1,"")) | AL11: =IF(J11=MIN($F11:$Q11),LOG(1-J11,2)+1,IF(J11=MAX($F11:$Q11),LOG(J11,2)+1,"")) | AM11: =IF(K11=MIN($F11:$Q11),LOG(1-K11,2)+1,IF(K11=MAX($F11:$Q11),LOG(K11,2)+1,"")) | AN11: =IF(L11=MIN($F11:$Q11),LOG(1-L11,2)+1,IF(L11=MAX($F11:$Q11),LOG(L11,2)+1,"")) | AO11: =IF(M11=MIN($F11:$Q11),LOG(1-M11,2)+1,IF(M11=MAX($F11:$Q11),LOG(M11,2)+1,"")) | ... AS11: =IF(Q11=MIN($F11:$Q11),LOG(1-Q11,2)+1,IF(Q11=MAX($F11:$Q11),LOG(Q11,2)+1,"")) | AT11: =IF(F11=MIN($F11:$Q11),"Yes","") | AU11: =IF(G11=MIN($F11:$Q11),"Yes","") | AV11: =IF(H11=MIN($F11:$Q11),"Yes","") | AW11: =IF(I11=MIN($F11:$Q11),"Yes","") | AX11: =IF(J11=MIN($F11:$Q11),"Yes","") | AY11: =IF(K11=MIN($F11:$Q11),"Yes","") | AZ11: =IF(L11=MIN($F11:$Q11),"Yes","") | BA11: =IF(M11=MIN($F11:$Q11),"Yes","") | ... BE11: =IF(Q11=MIN($F11:$Q11),"Yes","") | BF11: =IF(F11=MAX($F11:$Q11),"Yes","") | BG11: =IF(G11=MAX($F11:$Q11),"Yes","") | BH11: =IF(H11=MAX($F11:$Q11),"Yes","") | BI11: =IF(I11=MAX($F11:$Q11),"Yes","") | BJ11: =IF(J11=MAX($F11:$Q11),"Yes","") | BK11: =IF(K11=MAX($F11:$Q11),"Yes","") | BL11: =IF(L11=MAX($F11:$Q11),"Yes","") | BM11: =IF(M11=MAX($F11:$Q11),"Yes","") | ... BQ11: =IF(Q11=MAX($F11:$Q11),"Yes","") | BR11: =IF((F11-G11)>=0.5,"Yes",IF((G11-F11)>=0.5,"Yes","")) | BS11: =IF((L11-M11)>=0.5,"Yes",IF((M11-L11)>=0.5,"Yes","")) | BW11: =IF(BR11="Yes",-G11,0) -> 0 | BX11: =IF(BR11="Yes",F11,0) -> 0 | BY11: =IF((BX11-BW11)>0.01,(BX11-BW11),"") | BZ11: =IF(BS11="Yes",-L11,0) -> 0 | CA11: =IF(BS11="Yes",M11,0) -> 0 | CB11: =IF((CA11-BZ11)>0.01,(CA11-BZ11),"") | CC11: No
A12: 11 | B12: Aus Politics | C12: Scott Morrison will still be the Prime Minister of Australia | E12: 0 | F12: =Andrew!D12 -> 0.4 | G12: =Bruce!D12 -> 0.2 | H12: =Christine!D12 -> 0.2 | I12: =Eileen!D12 -> 0.8 | J12: =Iain!D12 -> 0.5 | K12: =Gael!D12 -> 0.75 | L12: =Jac!D12 -> 0.7 | M12: =James!D12 -> 0.05 | N12: =Kate!D12 -> 0.1 | O12: =Lachy!D12 -> 0.65 | P12: =Pete!D12 -> 0.3 | Q12: =Rohan!D12 -> 0.1 | R12: =IF($E12=1,(LOG(F12,2)+1),IF($E12=0,(LOG(1-F12,2)+1),"")) -> 0.26303441 | S12: =IF($E12=1,(LOG(G12,2)+1),IF($E12=0,(LOG(1-G12,2)+1),"")) -> 0.67807191 | T12: =IF($E12=1,(LOG(H12,2)+1),IF($E12=0,(LOG(1-H12,2)+1),"")) -> 0.67807191 | U12: =IF($E12=1,(LOG(I12,2)+1),IF($E12=0,(LOG(1-I12,2)+1),"")) -> -1.3219281 | V12: =IF($E12=1,(LOG(J12,2)+1),IF($E12=0,(LOG(1-J12,2)+1),"")) -> 0 | W12: =IF($E12=1,(LOG(K12,2)+1),IF($E12=0,(LOG(1-K12,2)+1),"")) -> -1 | X12: =IF($E12=1,(LOG(L12,2)+1),IF($E12=0,(LOG(1-L12,2)+1),"")) -> -0.73696559 | Y12: =IF($E12=1,(LOG(M12,2)+1),IF($E12=0,(LOG(1-M12,2)+1),"")) -> 0.92599942 | ... AC12: =IF($E12=1,(LOG(Q12,2)+1),IF($E12=0,(LOG(1-Q12,2)+1),"")) -> 0.84799691 | AE12: =ABS((LOG(F12,2)-LOG(1-F12,2))+ABS(LOG(G12,2)-LOG(1-G12,2))+ABS(LOG(H12,2)-LOG(1-H12,2))+ABS(LOG(I12,2)-LOG(1-I12,2))+ABS(LOG(J12,2)-LOG(1-J12,2))+ABS(LOG(K12,2)-LOG(1-K12,2))+ABS(LOG(L12,2)-LOG(1-L12,2))+ABS(LOG(M12,2)-LOG(1-M12,2))+ABS(LOG(N12,2)-LOG(1-N12,2))+ABS(LOG(O12,2)-LOG(1-O12,2))+ABS(LOG(P12,2)-LOG(1-P12,2))+ABS(LOG(Q12,2)-LOG(1-Q12,2))) -> 20.925647 | AF12: =AVERAGE(F12:Q12) -> 0.39583333 | AG12: =VAR(F12,G12,H12,I12,J12,K12,L12,M12,N12,O12,P12,Q12) -> 0.076117424 | AT12: =IF(F12=MIN($F12:$Q12),"Yes","") | AU12: =IF(G12=MIN($F12:$Q12),"Yes","") | AV12: =IF(H12=MIN($F12:$Q12),"Yes","") | AW12: =IF(I12=MIN($F12:$Q12),"Yes","") | AX12: =IF(J12=MIN($F12:$Q12),"Yes","") | AY12: =IF(K12=MIN($F12:$Q12),"Yes","") | AZ12: =IF(L12=MIN($F12:$Q12),"Yes","") | BA12: =IF(M12=MIN($F12:$Q12),"Yes","") -> Yes | ... BE12: =IF(Q12=MIN($F12:$Q12),"Yes","") | BF12: =IF(F12=MAX($F12:$Q12),"Yes","") | BG12: =IF(G12=MAX($F12:$Q12),"Yes","") | BH12: =IF(H12=MAX($F12:$Q12),"Yes","") | BI12: =IF(I12=MAX($F12:$Q12),"Yes","") -> Yes | BJ12: =IF(J12=MAX($F12:$Q12),"Yes","") | BK12: =IF(K12=MAX($F12:$Q12),"Yes","") | BL12: =IF(L12=MAX($F12:$Q12),"Yes","") | BM12: =IF(M12=MAX($F12:$Q12),"Yes","") | ... BQ12: =IF(Q12=MAX($F12:$Q12),"Yes","") | BR12: =IF((F12-G12)>=0.5,"Yes",IF((G12-F12)>=0.5,"Yes","")) | BS12: =IF((L12-M12)>=0.5,"Yes",IF((M12-L12)>=0.5,"Yes","")) -> Yes | BW12: =IF(BR12="Yes",-G12,0) -> 0 | BX12: =IF(BR12="Yes",F12,0) -> 0 | BY12: =IF((BX12-BW12)>0.01,(BX12-BW12),"") | BZ12: =IF(BS12="Yes",-L12,0) -> -0.7 | CA12: =IF(BS12="Yes",M12,0) -> 0.05 | CB12: =IF((CA12-BZ12)>0.01,(CA12-BZ12),"") -> 0.75 | CC12: No
A13: 12 | B13: Aus Politics | C13: An Australian federal Minister will step down from their position due to direct involvement (proven or otherwise) in sexual misconduct at some point in the year. | E13: 0 | F13: =Andrew!D13 -> 0.65 | G13: =Bruce!D13 -> 0.4 | H13: =Christine!D13 -> 0.1 | I13: =Eileen!D13 -> 0.9 | J13: =Iain!D13 -> 0.9 | K13: =Gael!D13 -> 0.35 | L13: =Jac!D13 -> 0.2 | M13: =James!D13 -> 0.1 | N13: =Kate!D13 -> 0.6 | O13: =Lachy!D13 -> 0.15 | P13: =Pete!D13 -> 0.3 | Q13: =Rohan!D13 -> 0.6 | R13: =IF($E13=1,(LOG(F13,2)+1),IF($E13=0,(LOG(1-F13,2)+1),"")) -> -0.51457317 | S13: =IF($E13=1,(LOG(G13,2)+1),IF($E13=0,(LOG(1-G13,2)+1),"")) -> 0.26303441 | T13: =IF($E13=1,(LOG(H13,2)+1),IF($E13=0,(LOG(1-H13,2)+1),"")) -> 0.84799691 | U13: =IF($E13=1,(LOG(I13,2)+1),IF($E13=0,(LOG(1-I13,2)+1),"")) -> -2.3219281 | V13: =IF($E13=1,(LOG(J13,2)+1),IF($E13=0,(LOG(1-J13,2)+1),"")) -> -2.3219281 | W13: =IF($E13=1,(LOG(K13,2)+1),IF($E13=0,(LOG(1-K13,2)+1),"")) -> 0.37851162 | X13: =IF($E13=1,(LOG(L13,2)+1),IF($E13=0,(LOG(1-L13,2)+1),"")) -> 0.67807191 | Y13: =IF($E13=1,(LOG(M13,2)+1),IF($E13=0,(LOG(1-M13,2)+1),"")) -> 0.84799691 | ... AC13: =IF($E13=1,(LOG(Q13,2)+1),IF($E13=0,(LOG(1-Q13,2)+1),"")) -> -0.32192809 | AE13: =ABS((LOG(F13,2)-LOG(1-F13,2))+ABS(LOG(G13,2)-LOG(1-G13,2))+ABS(LOG(H13,2)-LOG(1-H13,2))+ABS(LOG(I13,2)-LOG(1-I13,2))+ABS(LOG(J13,2)-LOG(1-J13,2))+ABS(LOG(K13,2)-LOG(1-K13,2))+ABS(LOG(L13,2)-LOG(1-L13,2))+ABS(LOG(M13,2)-LOG(1-M13,2))+ABS(LOG(N13,2)-LOG(1-N13,2))+ABS(LOG(O13,2)-LOG(1-O13,2))+ABS(LOG(P13,2)-LOG(1-P13,2))+ABS(LOG(Q13,2)-LOG(1-Q13,2))) -> 21.94565 | AF13: =AVERAGE(F13:Q13) -> 0.4375 | AG13: =VAR(F13,G13,H13,I13,J13,K13,L13,M13,N13,O13,P13,Q13) -> 0.083693182 | AH13: =IF(F13=MIN($F13:$Q13),LOG(1-F13,2)+1,IF(F13=MAX($F13:$Q13),LOG(F13,2)+1,"")) | AI13: =IF(G13=MIN($F13:$Q13),LOG(1-G13,2)+1,IF(G13=MAX($F13:$Q13),LOG(G13,2)+1,"")) | AJ13: =IF(H13=MIN($F13:$Q13),LOG(1-H13,2)+1,IF(H13=MAX($F13:$Q13),LOG(H13,2)+1,"")) -> 0.84799691 | AK13: =IF(I13=MIN($F13:$Q13),LOG(1-I13,2)+1,IF(I13=MAX($F13:$Q13),LOG(I13,2)+1,"")) -> 0.84799691 | AL13: =IF(J13=MIN($F13:$Q13),LOG(1-J13,2)+1,IF(J13=MAX($F13:$Q13),LOG(J13,2)+1,"")) -> 0.84799691 | AM13: =IF(K13=MIN($F13:$Q13),LOG(1-K13,2)+1,IF(K13=MAX($F13:$Q13),LOG(K13,2)+1,"")) | AN13: =IF(L13=MIN($F13:$Q13),LOG(1-L13,2)+1,IF(L13=MAX($F13:$Q13),LOG(L13,2)+1,"")) | AO13: =IF(M13=MIN($F13:$Q13),LOG(1-M13,2)+1,IF(M13=MAX($F13:$Q13),LOG(M13,2)+1,"")) -> 0.84799691 | ... AS13: =IF(Q13=MIN($F13:$Q13),LOG(1-Q13,2)+1,IF(Q13=MAX($F13:$Q13),LOG(Q13,2)+1,"")) | AT13: =IF(F13=MIN($F13:$Q13),"Yes","") | AU13: =IF(G13=MIN($F13:$Q13),"Yes","") | AV13: =IF(H13=MIN($F13:$Q13),"Yes","") -> Yes | AW13: =IF(I13=MIN($F13:$Q13),"Yes","") | AX13: =IF(J13=MIN($F13:$Q13),"Yes","") | AY13: =IF(K13=MIN($F13:$Q13),"Yes","") | AZ13: =IF(L13=MIN($F13:$Q13),"Yes","") | BA13: =IF(M13=MIN($F13:$Q13),"Yes","") -> Yes | ... BE13: =IF(Q13=MIN($F13:$Q13),"Yes","") | BF13: =IF(F13=MAX($F13:$Q13),"Yes","") | BG13: =IF(G13=MAX($F13:$Q13),"Yes","") | BH13: =IF(H13=MAX($F13:$Q13),"Yes","") | BI13: =IF(I13=MAX($F13:$Q13),"Yes","") -> Yes | BJ13: =IF(J13=MAX($F13:$Q13),"Yes","") -> Yes | BK13: =IF(K13=MAX($F13:$Q13),"Yes","") | BL13: =IF(L13=MAX($F13:$Q13),"Yes","") | BM13: =IF(M13=MAX($F13:$Q13),"Yes","") | ... BQ13: =IF(Q13=MAX($F13:$Q13),"Yes","") | BR13: =IF((F13-G13)>=0.5,"Yes",IF((G13-F13)>=0.5,"Yes","")) | BS13: =IF((L13-M13)>=0.5,"Yes",IF((M13-L13)>=0.5,"Yes","")) | BW13: =IF(BR13="Yes",-G13,0) -> 0 | BX13: =IF(BR13="Yes",F13,0) -> 0 | BY13: =IF((BX13-BW13)>0.01,(BX13-BW13),"") | BZ13: =IF(BS13="Yes",-L13,0) -> 0 | CA13: =IF(BS13="Yes",M13,0) -> 0 | CB13: =IF((CA13-BZ13)>0.01,(CA13-BZ13),"") | CC13: No
A14: 13 | B14: Aus Politics | C14: Friendlyjordies, or evidence he has brought to light, will feature in a court case or ICAC inquiry. | E14: 1 | F14: =Andrew!D14 -> 0.55 | G14: =Bruce!D14 -> 0.7 | H14: =Christine!D14 -> 0.3 | I14: =Eileen!D14 -> 0.6 | J14: =Iain!D14 -> 0.7 | K14: =Gael!D14 -> 0.65 | L14: =Jac!D14 -> 0.5 | M14: =James!D14 -> 0.3 | N14: =Kate!D14 -> 0.1 | O14: =Lachy!D14 -> 0.15 | P14: =Pete!D14 -> 0.5 | Q14: =Rohan!D14 -> 0.5 | R14: =IF($E14=1,(LOG(F14,2)+1),IF($E14=0,(LOG(1-F14,2)+1),"")) -> 0.13750352 | S14: =IF($E14=1,(LOG(G14,2)+1),IF($E14=0,(LOG(1-G14,2)+1),"")) -> 0.48542683 | T14: =IF($E14=1,(LOG(H14,2)+1),IF($E14=0,(LOG(1-H14,2)+1),"")) -> -0.73696559 | U14: =IF($E14=1,(LOG(I14,2)+1),IF($E14=0,(LOG(1-I14,2)+1),"")) -> 0.26303441 | V14: =IF($E14=1,(LOG(J14,2)+1),IF($E14=0,(LOG(1-J14,2)+1),"")) -> 0.48542683 | W14: =IF($E14=1,(LOG(K14,2)+1),IF($E14=0,(LOG(1-K14,2)+1),"")) -> 0.37851162 | X14: =IF($E14=1,(LOG(L14,2)+1),IF($E14=0,(LOG(1-L14,2)+1),"")) -> 0 | Y14: =IF($E14=1,(LOG(M14,2)+1),IF($E14=0,(LOG(1-M14,2)+1),"")) -> -0.73696559 | ... AC14: =IF($E14=1,(LOG(Q14,2)+1),IF($E14=0,(LOG(1-Q14,2)+1),"")) -> 0 | AE14: =ABS((LOG(F14,2)-LOG(1-F14,2))+ABS(LOG(G14,2)-LOG(1-G14,2))+ABS(LOG(H14,2)-LOG(1-H14,2))+ABS(LOG(I14,2)-LOG(1-I14,2))+ABS(LOG(J14,2)-LOG(1-J14,2))+ABS(LOG(K14,2)-LOG(1-K14,2))+ABS(LOG(L14,2)-LOG(1-L14,2))+ABS(LOG(M14,2)-LOG(1-M14,2))+ABS(LOG(N14,2)-LOG(1-N14,2))+ABS(LOG(O14,2)-LOG(1-O14,2))+ABS(LOG(P14,2)-LOG(1-P14,2))+ABS(LOG(Q14,2)-LOG(1-Q14,2))) -> 12.329549 | AF14: =AVERAGE(F14:Q14) -> 0.4625 | AG14: =VAR(F14,G14,H14,I14,J14,K14,L14,M14,N14,O14,P14,Q14) -> 0.041875 | AT14: =IF(F14=MIN($F14:$Q14),"Yes","") | AU14: =IF(G14=MIN($F14:$Q14),"Yes","") | AV14: =IF(H14=MIN($F14:$Q14),"Yes","") | AW14: =IF(I14=MIN($F14:$Q14),"Yes","") | AX14: =IF(J14=MIN($F14:$Q14),"Yes","") | AY14: =IF(K14=MIN($F14:$Q14),"Yes","") | AZ14: =IF(L14=MIN($F14:$Q14),"Yes","") | BA14: =IF(M14=MIN($F14:$Q14),"Yes","") | ... BE14: =IF(Q14=MIN($F14:$Q14),"Yes","") | BF14: =IF(F14=MAX($F14:$Q14),"Yes","") | BG14: =IF(G14=MAX($F14:$Q14),"Yes","") -> Yes | BH14: =IF(H14=MAX($F14:$Q14),"Yes","") | BI14: =IF(I14=MAX($F14:$Q14),"Yes","") | BJ14: =IF(J14=MAX($F14:$Q14),"Yes","") -> Yes | BK14: =IF(K14=MAX($F14:$Q14),"Yes","") | BL14: =IF(L14=MAX($F14:$Q14),"Yes","") | BM14: =IF(M14=MAX($F14:$Q14),"Yes","") | ... BQ14: =IF(Q14=MAX($F14:$Q14),"Yes","") | BR14: =IF((F14-G14)>=0.5,"Yes",IF((G14-F14)>=0.5,"Yes","")) | BS14: =IF((L14-M14)>=0.5,"Yes",IF((M14-L14)>=0.5,"Yes","")) | BW14: =IF(BR14="Yes",-G14,0) -> 0 | BX14: =IF(BR14="Yes",F14,0) -> 0 | BY14: =IF((BX14-BW14)>0.01,(BX14-BW14),"") | BZ14: =IF(BS14="Yes",-L14,0) -> 0 | CA14: =IF(BS14="Yes",M14,0) -> 0 | CB14: =IF((CA14-BZ14)>0.01,(CA14-BZ14),"")
A15: 14 | B15: Aus Politics | C15: At least one person commits suicide as an effect of the Royal Commission into Defence and Veteran Suicide, as reported in The Guardian | E15: 0 | F15: =Andrew!D15 -> 0.4 | G15: =Bruce!D15 -> 0.8 | H15: =Christine!D15 -> 0.7 | I15: =Eileen!D15 -> 0.4 | J15: =Iain!D15 -> 0.3 | K15: =Gael!D15 -> 0.85 | L15: =Jac!D15 -> 0.6 | M15: =James!D15 -> 0.7 | N15: =Kate!D15 -> 0.9 | O15: =Lachy!D15 -> 0.15 | P15: =Pete!D15 -> 0.5 | Q15: =Rohan!D15 -> 0.4 | R15: =IF($E15=1,(LOG(F15,2)+1),IF($E15=0,(LOG(1-F15,2)+1),"")) -> 0.26303441 | S15: =IF($E15=1,(LOG(G15,2)+1),IF($E15=0,(LOG(1-G15,2)+1),"")) -> -1.3219281 | T15: =IF($E15=1,(LOG(H15,2)+1),IF($E15=0,(LOG(1-H15,2)+1),"")) -> -0.73696559 | U15: =IF($E15=1,(LOG(I15,2)+1),IF($E15=0,(LOG(1-I15,2)+1),"")) -> 0.26303441 | V15: =IF($E15=1,(LOG(J15,2)+1),IF($E15=0,(LOG(1-J15,2)+1),"")) -> 0.48542683 | W15: =IF($E15=1,(LOG(K15,2)+1),IF($E15=0,(LOG(1-K15,2)+1),"")) -> -1.7369656 | X15: =IF($E15=1,(LOG(L15,2)+1),IF($E15=0,(LOG(1-L15,2)+1),"")) -> -0.32192809 | Y15: =IF($E15=1,(LOG(M15,2)+1),IF($E15=0,(LOG(1-M15,2)+1),"")) -> -0.73696559 | ... AC15: =IF($E15=1,(LOG(Q15,2)+1),IF($E15=0,(LOG(1-Q15,2)+1),"")) -> 0.26303441 | AE15: =ABS((LOG(F15,2)-LOG(1-F15,2))+ABS(LOG(G15,2)-LOG(1-G15,2))+ABS(LOG(H15,2)-LOG(1-H15,2))+ABS(LOG(I15,2)-LOG(1-I15,2))+ABS(LOG(J15,2)-LOG(1-J15,2))+ABS(LOG(K15,2)-LOG(1-K15,2))+ABS(LOG(L15,2)-LOG(1-L15,2))+ABS(LOG(M15,2)-LOG(1-M15,2))+ABS(LOG(N15,2)-LOG(1-N15,2))+ABS(LOG(O15,2)-LOG(1-O15,2))+ABS(LOG(P15,2)-LOG(1-P15,2))+ABS(LOG(Q15,2)-LOG(1-Q15,2))) -> 15.012028 | AF15: =AVERAGE(F15:Q15) -> 0.55833333 | AG15: =VAR(F15,G15,H15,I15,J15,K15,L15,M15,N15,O15,P15,Q15) -> 0.055833333 | AT15: =IF(F15=MIN($F15:$Q15),"Yes","") | AU15: =IF(G15=MIN($F15:$Q15),"Yes","") | AV15: =IF(H15=MIN($F15:$Q15),"Yes","") | AW15: =IF(I15=MIN($F15:$Q15),"Yes","") | AX15: =IF(J15=MIN($F15:$Q15),"Yes","") | AY15: =IF(K15=MIN($F15:$Q15),"Yes","") | AZ15: =IF(L15=MIN($F15:$Q15),"Yes","") | BA15: =IF(M15=MIN($F15:$Q15),"Yes","") | ... BE15: =IF(Q15=MIN($F15:$Q15),"Yes","") | BF15: =IF(F15=MAX($F15:$Q15),"Yes","") | BG15: =IF(G15=MAX($F15:$Q15),"Yes","") | BH15: =IF(H15=MAX($F15:$Q15),"Yes","") | BI15: =IF(I15=MAX($F15:$Q15),"Yes","") | BJ15: =IF(J15=MAX($F15:$Q15),"Yes","") | BK15: =IF(K15=MAX($F15:$Q15),"Yes","") | BL15: =IF(L15=MAX($F15:$Q15),"Yes","") | BM15: =IF(M15=MAX($F15:$Q15),"Yes","") | ... BQ15: =IF(Q15=MAX($F15:$Q15),"Yes","") | BR15: =IF((F15-G15)>=0.5,"Yes",IF((G15-F15)>=0.5,"Yes","")) | BS15: =IF((L15-M15)>=0.5,"Yes",IF((M15-L15)>=0.5,"Yes","")) | BW15: =IF(BR15="Yes",-G15,0) -> 0 | BX15: =IF(BR15="Yes",F15,0) -> 0 | BY15: =IF((BX15-BW15)>0.01,(BX15-BW15),"") | BZ15: =IF(BS15="Yes",-L15,0) -> 0 | CA15: =IF(BS15="Yes",M15,0) -> 0 | CB15: =IF((CA15-BZ15)>0.01,(CA15-BZ15),"") | CC15: No
A16: 15 | B16: Celebrities | C16: Taylor Swift will get married | E16: 0 | F16: =Andrew!D16 -> 0.55 | G16: =Bruce!D16 -> 0.4 | H16: =Christine!D16 -> 0.7 | I16: =Eileen!D16 -> 0.15 | J16: =Iain!D16 -> 0.6 | K16: =Gael!D16 -> 0.8 | L16: =Jac!D16 -> 0.2 | M16: =James!D16 -> 0.7 | N16: =Kate!D16 -> 0.8 | O16: =Lachy!D16 -> 0.15 | P16: =Pete!D16 -> 0.5 | Q16: =Rohan!D16 -> 0.01 | R16: =IF($E16=1,(LOG(F16,2)+1),IF($E16=0,(LOG(1-F16,2)+1),"")) -> -0.15200309 | S16: =IF($E16=1,(LOG(G16,2)+1),IF($E16=0,(LOG(1-G16,2)+1),"")) -> 0.26303441 | T16: =IF($E16=1,(LOG(H16,2)+1),IF($E16=0,(LOG(1-H16,2)+1),"")) -> -0.73696559 | U16: =IF($E16=1,(LOG(I16,2)+1),IF($E16=0,(LOG(1-I16,2)+1),"")) -> 0.76553475 | V16: =IF($E16=1,(LOG(J16,2)+1),IF($E16=0,(LOG(1-J16,2)+1),"")) -> -0.32192809 | W16: =IF($E16=1,(LOG(K16,2)+1),IF($E16=0,(LOG(1-K16,2)+1),"")) -> -1.3219281 | X16: =IF($E16=1,(LOG(L16,2)+1),IF($E16=0,(LOG(1-L16,2)+1),"")) -> 0.67807191 | Y16: =IF($E16=1,(LOG(M16,2)+1),IF($E16=0,(LOG(1-M16,2)+1),"")) -> -0.73696559 | ... AC16: =IF($E16=1,(LOG(Q16,2)+1),IF($E16=0,(LOG(1-Q16,2)+1),"")) -> 0.98550043 | AE16: =ABS((LOG(F16,2)-LOG(1-F16,2))+ABS(LOG(G16,2)-LOG(1-G16,2))+ABS(LOG(H16,2)-LOG(1-H16,2))+ABS(LOG(I16,2)-LOG(1-I16,2))+ABS(LOG(J16,2)-LOG(1-J16,2))+ABS(LOG(K16,2)-LOG(1-K16,2))+ABS(LOG(L16,2)-LOG(1-L16,2))+ABS(LOG(M16,2)-LOG(1-M16,2))+ABS(LOG(N16,2)-LOG(1-N16,2))+ABS(LOG(O16,2)-LOG(1-O16,2))+ABS(LOG(P16,2)-LOG(1-P16,2))+ABS(LOG(Q16,2)-LOG(1-Q16,2))) -> 21.538574 | AF16: =AVERAGE(F16:Q16) -> 0.46333333 | AG16: =VAR(F16,G16,H16,I16,J16,K16,L16,M16,N16,O16,P16,Q16) -> 0.07649697 | AT16: =IF(F16=MIN($F16:$Q16),"Yes","") | AU16: =IF(G16=MIN($F16:$Q16),"Yes","") | AV16: =IF(H16=MIN($F16:$Q16),"Yes","") | AW16: =IF(I16=MIN($F16:$Q16),"Yes","") | AX16: =IF(J16=MIN($F16:$Q16),"Yes","") | AY16: =IF(K16=MIN($F16:$Q16),"Yes","") | AZ16: =IF(L16=MIN($F16:$Q16),"Yes","") | BA16: =IF(M16=MIN($F16:$Q16),"Yes","") | ... BE16: =IF(Q16=MIN($F16:$Q16),"Yes","") -> Yes | BF16: =IF(F16=MAX($F16:$Q16),"Yes","") | BG16: =IF(G16=MAX($F16:$Q16),"Yes","") | BH16: =IF(H16=MAX($F16:$Q16),"Yes","") | BI16: =IF(I16=MAX($F16:$Q16),"Yes","") | BJ16: =IF(J16=MAX($F16:$Q16),"Yes","") | BK16: =IF(K16=MAX($F16:$Q16),"Yes","") -> Yes | BL16: =IF(L16=MAX($F16:$Q16),"Yes","") | BM16: =IF(M16=MAX($F16:$Q16),"Yes","") | ... BQ16: =IF(Q16=MAX($F16:$Q16),"Yes","") | BR16: =IF((F16-G16)>=0.5,"Yes",IF((G16-F16)>=0.5,"Yes","")) | BS16: =IF((L16-M16)>=0.5,"Yes",IF((M16-L16)>=0.5,"Yes","")) -> Yes | BW16: =IF(BR16="Yes",-G16,0) -> 0 | BX16: =IF(BR16="Yes",F16,0) -> 0 | BY16: =IF((BX16-BW16)>0.01,(BX16-BW16),"") | BZ16: =IF(BS16="Yes",-L16,0) -> -0.2 | CA16: =IF(BS16="Yes",M16,0) -> 0.7 | CB16: =IF((CA16-BZ16)>0.01,(CA16-BZ16),"") -> 0.9
A17: 16 | B17: Celebrities | C17: Jane Campion will win the Oscar for Best Director | D17: 44648 | E17: 1 | F17: =Andrew!D17 -> 0.8 | G17: =Bruce!D17 -> 0.6 | H17: =Christine!D17 -> 0.2 | I17: =Eileen!D17 -> 0.9 | J17: =Iain!D17 -> 0.9 | K17: =Gael!D17 -> 0.95 | L17: =Jac!D17 -> 0.7 | M17: =James!D17 -> 0.2 | N17: =Kate!D17 -> 0.1 | O17: =Lachy!D17 -> 0.5 | P17: =Pete!D17 -> 0.5 | Q17: =Rohan!D17 -> 0.3 | R17: =IF($E17=1,(LOG(F17,2)+1),IF($E17=0,(LOG(1-F17,2)+1),"")) -> 0.67807191 | S17: =IF($E17=1,(LOG(G17,2)+1),IF($E17=0,(LOG(1-G17,2)+1),"")) -> 0.26303441 | T17: =IF($E17=1,(LOG(H17,2)+1),IF($E17=0,(LOG(1-H17,2)+1),"")) -> -1.3219281 | U17: =IF($E17=1,(LOG(I17,2)+1),IF($E17=0,(LOG(1-I17,2)+1),"")) -> 0.84799691 | V17: =IF($E17=1,(LOG(J17,2)+1),IF($E17=0,(LOG(1-J17,2)+1),"")) -> 0.84799691 | W17: =IF($E17=1,(LOG(K17,2)+1),IF($E17=0,(LOG(1-K17,2)+1),"")) -> 0.92599942 | X17: =IF($E17=1,(LOG(L17,2)+1),IF($E17=0,(LOG(1-L17,2)+1),"")) -> 0.48542683 | Y17: =IF($E17=1,(LOG(M17,2)+1),IF($E17=0,(LOG(1-M17,2)+1),"")) -> -1.3219281 | ... AC17: =IF($E17=1,(LOG(Q17,2)+1),IF($E17=0,(LOG(1-Q17,2)+1),"")) -> -0.73696559 | AE17: =ABS((LOG(F17,2)-LOG(1-F17,2))+ABS(LOG(G17,2)-LOG(1-G17,2))+ABS(LOG(H17,2)-LOG(1-H17,2))+ABS(LOG(I17,2)-LOG(1-I17,2))+ABS(LOG(J17,2)-LOG(1-J17,2))+ABS(LOG(K17,2)-LOG(1-K17,2))+ABS(LOG(L17,2)-LOG(1-L17,2))+ABS(LOG(M17,2)-LOG(1-M17,2))+ABS(LOG(N17,2)-LOG(1-N17,2))+ABS(LOG(O17,2)-LOG(1-O17,2))+ABS(LOG(P17,2)-LOG(1-P17,2))+ABS(LOG(Q17,2)-LOG(1-Q17,2))) -> 22.78745 | AF17: =AVERAGE(F17:Q17) -> 0.55416667 | AG17: =VAR(F17,G17,H17,I17,J17,K17,L17,M17,N17,O17,P17,Q17) -> 0.09157197 | AH17: =IF(F17=MIN($F17:$Q17),LOG(1-F17,2)+1,IF(F17=MAX($F17:$Q17),LOG(F17,2)+1,"")) | AI17: =IF(G17=MIN($F17:$Q17),LOG(1-G17,2)+1,IF(G17=MAX($F17:$Q17),LOG(G17,2)+1,"")) | AJ17: =IF(H17=MIN($F17:$Q17),LOG(1-H17,2)+1,IF(H17=MAX($F17:$Q17),LOG(H17,2)+1,"")) | AK17: =IF(I17=MIN($F17:$Q17),LOG(1-I17,2)+1,IF(I17=MAX($F17:$Q17),LOG(I17,2)+1,"")) | AL17: =IF(J17=MIN($F17:$Q17),LOG(1-J17,2)+1,IF(J17=MAX($F17:$Q17),LOG(J17,2)+1,"")) | AM17: =IF(K17=MIN($F17:$Q17),LOG(1-K17,2)+1,IF(K17=MAX($F17:$Q17),LOG(K17,2)+1,"")) -> 0.92599942 | AN17: =IF(L17=MIN($F17:$Q17),LOG(1-L17,2)+1,IF(L17=MAX($F17:$Q17),LOG(L17,2)+1,"")) | AO17: =IF(M17=MIN($F17:$Q17),LOG(1-M17,2)+1,IF(M17=MAX($F17:$Q17),LOG(M17,2)+1,"")) | ... AS17: =IF(Q17=MIN($F17:$Q17),LOG(1-Q17,2)+1,IF(Q17=MAX($F17:$Q17),LOG(Q17,2)+1,"")) | AT17: =IF(F17=MIN($F17:$Q17),"Yes","") | AU17: =IF(G17=MIN($F17:$Q17),"Yes","") | AV17: =IF(H17=MIN($F17:$Q17),"Yes","") | AW17: =IF(I17=MIN($F17:$Q17),"Yes","") | AX17: =IF(J17=MIN($F17:$Q17),"Yes","") | AY17: =IF(K17=MIN($F17:$Q17),"Yes","") | AZ17: =IF(L17=MIN($F17:$Q17),"Yes","") | BA17: =IF(M17=MIN($F17:$Q17),"Yes","") | ... BE17: =IF(Q17=MIN($F17:$Q17),"Yes","") | BF17: =IF(F17=MAX($F17:$Q17),"Yes","") | BG17: =IF(G17=MAX($F17:$Q17),"Yes","") | BH17: =IF(H17=MAX($F17:$Q17),"Yes","") | BI17: =IF(I17=MAX($F17:$Q17),"Yes","") | BJ17: =IF(J17=MAX($F17:$Q17),"Yes","") | BK17: =IF(K17=MAX($F17:$Q17),"Yes","") -> Yes | BL17: =IF(L17=MAX($F17:$Q17),"Yes","") | BM17: =IF(M17=MAX($F17:$Q17),"Yes","") | ... BQ17: =IF(Q17=MAX($F17:$Q17),"Yes","") | BR17: =IF((F17-G17)>=0.5,"Yes",IF((G17-F17)>=0.5,"Yes","")) | BS17: =IF((L17-M17)>=0.5,"Yes",IF((M17-L17)>=0.5,"Yes","")) -> Yes | BW17: =IF(BR17="Yes",-G17,0) -> 0 | BX17: =IF(BR17="Yes",F17,0) -> 0 | BY17: =IF((BX17-BW17)>0.01,(BX17-BW17),"") | BZ17: =IF(BS17="Yes",-L17,0) -> -0.7 | CA17: =IF(BS17="Yes",M17,0) -> 0.2 | CB17: =IF((CA17-BZ17)>0.01,(CA17-BZ17),"") -> 0.9
A18: 17 | B18: Celebrities | C18: Harry and Megan's animated series "Pearl" will be released and have over 50% on Rotten Tomatoes | E18: 0 | F18: =Andrew!D18 -> 0.4 | G18: =Bruce!D18 -> 0.3 | H18: =Christine!D18 -> 0.8 | I18: =Eileen!D18 -> 0.4 | J18: =Iain!D18 -> 0.1 | K18: =Gael!D18 -> 0.8 | L18: =Jac!D18 -> 0.2 | M18: =James!D18 -> 0.8 | N18: =Kate!D18 -> 0.8 | O18: =Lachy!D18 -> 0.15 | P18: =Pete!D18 -> 0.5 | Q18: =Rohan!D18 -> 0.4 | R18: =IF($E18=1,(LOG(F18,2)+1),IF($E18=0,(LOG(1-F18,2)+1),"")) -> 0.26303441 | S18: =IF($E18=1,(LOG(G18,2)+1),IF($E18=0,(LOG(1-G18,2)+1),"")) -> 0.48542683 | T18: =IF($E18=1,(LOG(H18,2)+1),IF($E18=0,(LOG(1-H18,2)+1),"")) -> -1.3219281 | U18: =IF($E18=1,(LOG(I18,2)+1),IF($E18=0,(LOG(1-I18,2)+1),"")) -> 0.26303441 | V18: =IF($E18=1,(LOG(J18,2)+1),IF($E18=0,(LOG(1-J18,2)+1),"")) -> 0.84799691 | W18: =IF($E18=1,(LOG(K18,2)+1),IF($E18=0,(LOG(1-K18,2)+1),"")) -> -1.3219281 | X18: =IF($E18=1,(LOG(L18,2)+1),IF($E18=0,(LOG(1-L18,2)+1),"")) -> 0.67807191 | Y18: =IF($E18=1,(LOG(M18,2)+1),IF($E18=0,(LOG(1-M18,2)+1),"")) -> -1.3219281 | ... AC18: =IF($E18=1,(LOG(Q18,2)+1),IF($E18=0,(LOG(1-Q18,2)+1),"")) -> 0.26303441 | AE18: =ABS((LOG(F18,2)-LOG(1-F18,2))+ABS(LOG(G18,2)-LOG(1-G18,2))+ABS(LOG(H18,2)-LOG(1-H18,2))+ABS(LOG(I18,2)-LOG(1-I18,2))+ABS(LOG(J18,2)-LOG(1-J18,2))+ABS(LOG(K18,2)-LOG(1-K18,2))+ABS(LOG(L18,2)-LOG(1-L18,2))+ABS(LOG(M18,2)-LOG(1-M18,2))+ABS(LOG(N18,2)-LOG(1-N18,2))+ABS(LOG(O18,2)-LOG(1-O18,2))+ABS(LOG(P18,2)-LOG(1-P18,2))+ABS(LOG(Q18,2)-LOG(1-Q18,2))) -> 17.47978 | AF18: =AVERAGE(F18:Q18) -> 0.47083333 | AG18: =VAR(F18,G18,H18,I18,J18,K18,L18,M18,N18,O18,P18,Q18) -> 0.072026515 | AT18: =IF(F18=MIN($F18:$Q18),"Yes","") | AU18: =IF(G18=MIN($F18:$Q18),"Yes","") | AV18: =IF(H18=MIN($F18:$Q18),"Yes","") | AW18: =IF(I18=MIN($F18:$Q18),"Yes","") | AX18: =IF(J18=MIN($F18:$Q18),"Yes","") -> Yes | AY18: =IF(K18=MIN($F18:$Q18),"Yes","") | AZ18: =IF(L18=MIN($F18:$Q18),"Yes","") | BA18: =IF(M18=MIN($F18:$Q18),"Yes","") | ... BE18: =IF(Q18=MIN($F18:$Q18),"Yes","") | BF18: =IF(F18=MAX($F18:$Q18),"Yes","") | BG18: =IF(G18=MAX($F18:$Q18),"Yes","") | BH18: =IF(H18=MAX($F18:$Q18),"Yes","") -> Yes | BI18: =IF(I18=MAX($F18:$Q18),"Yes","") | BJ18: =IF(J18=MAX($F18:$Q18),"Yes","") | BK18: =IF(K18=MAX($F18:$Q18),"Yes","") -> Yes | BL18: =IF(L18=MAX($F18:$Q18),"Yes","") | BM18: =IF(M18=MAX($F18:$Q18),"Yes","") -> Yes | ... BQ18: =IF(Q18=MAX($F18:$Q18),"Yes","") | BR18: =IF((F18-G18)>=0.5,"Yes",IF((G18-F18)>=0.5,"Yes","")) | BS18: =IF((L18-M18)>=0.5,"Yes",IF((M18-L18)>=0.5,"Yes","")) -> Yes | BW18: =IF(BR18="Yes",-G18,0) -> 0 | BX18: =IF(BR18="Yes",F18,0) -> 0 | BY18: =IF((BX18-BW18)>0.01,(BX18-BW18),"") | BZ18: =IF(BS18="Yes",-L18,0) -> -0.2 | CA18: =IF(BS18="Yes",M18,0) -> 0.8 | CB18: =IF((CA18-BZ18)>0.01,(CA18-BZ18),"") -> 1
A19: 18 | B19: Celebrities | C19: Prince Andrew will enter or exit a courtroom wearing an oxygen mask and/or sitting in a wheelchair | E19: 0 | F19: =Andrew!D19 -> 0.3 | G19: =Bruce!D19 -> 0.2 | H19: =Christine!D19 -> 0.7 | I19: =Eileen!D19 -> 0.1 | J19: =Iain!D19 -> 0.4 | K19: =Gael!D19 -> 0.2 | L19: =Jac!D19 -> 0.1 | M19: =James!D19 -> 0.05 | N19: =Kate!D19 -> 0.1 | O19: =Lachy!D19 -> 0.15 | P19: =Pete!D19 -> 0.1 | Q19: =Rohan!D19 -> 0.2 | R19: =IF($E19=1,(LOG(F19,2)+1),IF($E19=0,(LOG(1-F19,2)+1),"")) -> 0.48542683 | S19: =IF($E19=1,(LOG(G19,2)+1),IF($E19=0,(LOG(1-G19,2)+1),"")) -> 0.67807191 | T19: =IF($E19=1,(LOG(H19,2)+1),IF($E19=0,(LOG(1-H19,2)+1),"")) -> -0.73696559 | U19: =IF($E19=1,(LOG(I19,2)+1),IF($E19=0,(LOG(1-I19,2)+1),"")) -> 0.84799691 | V19: =IF($E19=1,(LOG(J19,2)+1),IF($E19=0,(LOG(1-J19,2)+1),"")) -> 0.26303441 | W19: =IF($E19=1,(LOG(K19,2)+1),IF($E19=0,(LOG(1-K19,2)+1),"")) -> 0.67807191 | X19: =IF($E19=1,(LOG(L19,2)+1),IF($E19=0,(LOG(1-L19,2)+1),"")) -> 0.84799691 | Y19: =IF($E19=1,(LOG(M19,2)+1),IF($E19=0,(LOG(1-M19,2)+1),"")) -> 0.92599942 | ... AC19: =IF($E19=1,(LOG(Q19,2)+1),IF($E19=0,(LOG(1-Q19,2)+1),"")) -> 0.67807191 | AE19: =ABS((LOG(F19,2)-LOG(1-F19,2))+ABS(LOG(G19,2)-LOG(1-G19,2))+ABS(LOG(H19,2)-LOG(1-H19,2))+ABS(LOG(I19,2)-LOG(1-I19,2))+ABS(LOG(J19,2)-LOG(1-J19,2))+ABS(LOG(K19,2)-LOG(1-K19,2))+ABS(LOG(L19,2)-LOG(1-L19,2))+ABS(LOG(M19,2)-LOG(1-M19,2))+ABS(LOG(N19,2)-LOG(1-N19,2))+ABS(LOG(O19,2)-LOG(1-O19,2))+ABS(LOG(P19,2)-LOG(1-P19,2))+ABS(LOG(Q19,2)-LOG(1-Q19,2))) -> 26.01509 | AF19: =AVERAGE(F19:Q19) -> 0.21666667 | AG19: =VAR(F19,G19,H19,I19,J19,K19,L19,M19,N19,O19,P19,Q19) -> 0.032878788 | AT19: =IF(F19=MIN($F19:$Q19),"Yes","") | AU19: =IF(G19=MIN($F19:$Q19),"Yes","") | AV19: =IF(H19=MIN($F19:$Q19),"Yes","") | AW19: =IF(I19=MIN($F19:$Q19),"Yes","") | AX19: =IF(J19=MIN($F19:$Q19),"Yes","") | AY19: =IF(K19=MIN($F19:$Q19),"Yes","") | AZ19: =IF(L19=MIN($F19:$Q19),"Yes","") | BA19: =IF(M19=MIN($F19:$Q19),"Yes","") -> Yes | ... BE19: =IF(Q19=MIN($F19:$Q19),"Yes","") | BF19: =IF(F19=MAX($F19:$Q19),"Yes","") | BG19: =IF(G19=MAX($F19:$Q19),"Yes","") | BH19: =IF(H19=MAX($F19:$Q19),"Yes","") -> Yes | BI19: =IF(I19=MAX($F19:$Q19),"Yes","") | BJ19: =IF(J19=MAX($F19:$Q19),"Yes","") | BK19: =IF(K19=MAX($F19:$Q19),"Yes","") | BL19: =IF(L19=MAX($F19:$Q19),"Yes","") | BM19: =IF(M19=MAX($F19:$Q19),"Yes","") | ... BQ19: =IF(Q19=MAX($F19:$Q19),"Yes","") | BR19: =IF((F19-G19)>=0.5,"Yes",IF((G19-F19)>=0.5,"Yes","")) | BS19: =IF((L19-M19)>=0.5,"Yes",IF((M19-L19)>=0.5,"Yes","")) | BW19: =IF(BR19="Yes",-G19,0) -> 0 | BX19: =IF(BR19="Yes",F19,0) -> 0 | BY19: =IF((BX19-BW19)>0.01,(BX19-BW19),"") | BZ19: =IF(BS19="Yes",-L19,0) -> 0 | CA19: =IF(BS19="Yes",M19,0) -> 0 | CB19: =IF((CA19-BZ19)>0.01,(CA19-BZ19),"")
A20: 19 | B20: Celebrities | C20: News Ltd will report on the emergence of a conspiracy theory relating to the Queen's death: that the palace is either secretly concealing her death or her continuing life | E20: 0 | F20: =Andrew!D20 -> 0.25 | G20: =Bruce!D20 -> 0.4 | H20: =Christine!D20 -> 0.8 | I20: =Eileen!D20 -> 0.05 | J20: =Iain!D20 -> 0.5 | K20: =Gael!D20 -> 0.85 | L20: =Jac!D20 -> 0.05 | M20: =James!D20 -> 0.8 | N20: =Kate!D20 -> 0.1 | O20: =Lachy!D20 -> 0.001 | P20: =Pete!D20 -> 0.1 | Q20: =Rohan!D20 -> 0.5 | R20: =IF($E20=1,(LOG(F20,2)+1),IF($E20=0,(LOG(1-F20,2)+1),"")) -> 0.5849625 | S20: =IF($E20=1,(LOG(G20,2)+1),IF($E20=0,(LOG(1-G20,2)+1),"")) -> 0.26303441 | T20: =IF($E20=1,(LOG(H20,2)+1),IF($E20=0,(LOG(1-H20,2)+1),"")) -> -1.3219281 | U20: =IF($E20=1,(LOG(I20,2)+1),IF($E20=0,(LOG(1-I20,2)+1),"")) -> 0.92599942 | V20: =IF($E20=1,(LOG(J20,2)+1),IF($E20=0,(LOG(1-J20,2)+1),"")) -> 0 | W20: =IF($E20=1,(LOG(K20,2)+1),IF($E20=0,(LOG(1-K20,2)+1),"")) -> -1.7369656 | X20: =IF($E20=1,(LOG(L20,2)+1),IF($E20=0,(LOG(1-L20,2)+1),"")) -> 0.92599942 | Y20: =IF($E20=1,(LOG(M20,2)+1),IF($E20=0,(LOG(1-M20,2)+1),"")) -> -1.3219281 | ... AC20: =IF($E20=1,(LOG(Q20,2)+1),IF($E20=0,(LOG(1-Q20,2)+1),"")) -> 0 | AE20: =ABS((LOG(F20,2)-LOG(1-F20,2))+ABS(LOG(G20,2)-LOG(1-G20,2))+ABS(LOG(H20,2)-LOG(1-H20,2))+ABS(LOG(I20,2)-LOG(1-I20,2))+ABS(LOG(J20,2)-LOG(1-J20,2))+ABS(LOG(K20,2)-LOG(1-K20,2))+ABS(LOG(L20,2)-LOG(1-L20,2))+ABS(LOG(M20,2)-LOG(1-M20,2))+ABS(LOG(N20,2)-LOG(1-N20,2))+ABS(LOG(O20,2)-LOG(1-O20,2))+ABS(LOG(P20,2)-LOG(1-P20,2))+ABS(LOG(Q20,2)-LOG(1-Q20,2))) -> 30.302546 | AF20: =AVERAGE(F20:Q20) -> 0.36675 | AG20: =VAR(F20,G20,H20,I20,J20,K20,L20,M20,N20,O20,P20,Q20) -> 0.10326675 | AH20: =IF(F20=MIN($F20:$Q20),LOG(1-F20,2)+1,IF(F20=MAX($F20:$Q20),LOG(F20,2)+1,"")) | AI20: =IF(G20=MIN($F20:$Q20),LOG(1-G20,2)+1,IF(G20=MAX($F20:$Q20),LOG(G20,2)+1,"")) | AJ20: =IF(H20=MIN($F20:$Q20),LOG(1-H20,2)+1,IF(H20=MAX($F20:$Q20),LOG(H20,2)+1,"")) | AK20: =IF(I20=MIN($F20:$Q20),LOG(1-I20,2)+1,IF(I20=MAX($F20:$Q20),LOG(I20,2)+1,"")) | AL20: =IF(J20=MIN($F20:$Q20),LOG(1-J20,2)+1,IF(J20=MAX($F20:$Q20),LOG(J20,2)+1,"")) | AM20: =IF(K20=MIN($F20:$Q20),LOG(1-K20,2)+1,IF(K20=MAX($F20:$Q20),LOG(K20,2)+1,"")) -> 0.76553475 | AN20: =IF(L20=MIN($F20:$Q20),LOG(1-L20,2)+1,IF(L20=MAX($F20:$Q20),LOG(L20,2)+1,"")) | AO20: =IF(M20=MIN($F20:$Q20),LOG(1-M20,2)+1,IF(M20=MAX($F20:$Q20),LOG(M20,2)+1,"")) | ... AS20: =IF(Q20=MIN($F20:$Q20),LOG(1-Q20,2)+1,IF(Q20=MAX($F20:$Q20),LOG(Q20,2)+1,"")) | AT20: =IF(F20=MIN($F20:$Q20),"Yes","") | AU20: =IF(G20=MIN($F20:$Q20),"Yes","") | AV20: =IF(H20=MIN($F20:$Q20),"Yes","") | AW20: =IF(I20=MIN($F20:$Q20),"Yes","") | AX20: =IF(J20=MIN($F20:$Q20),"Yes","") | AY20: =IF(K20=MIN($F20:$Q20),"Yes","") | AZ20: =IF(L20=MIN($F20:$Q20),"Yes","") | BA20: =IF(M20=MIN($F20:$Q20),"Yes","") | ... BE20: =IF(Q20=MIN($F20:$Q20),"Yes","") | BF20: =IF(F20=MAX($F20:$Q20),"Yes","") | BG20: =IF(G20=MAX($F20:$Q20),"Yes","") | BH20: =IF(H20=MAX($F20:$Q20),"Yes","") | BI20: =IF(I20=MAX($F20:$Q20),"Yes","") | BJ20: =IF(J20=MAX($F20:$Q20),"Yes","") | BK20: =IF(K20=MAX($F20:$Q20),"Yes","") -> Yes | BL20: =IF(L20=MAX($F20:$Q20),"Yes","") | BM20: =IF(M20=MAX($F20:$Q20),"Yes","") | ... BQ20: =IF(Q20=MAX($F20:$Q20),"Yes","") | BR20: =IF((F20-G20)>=0.5,"Yes",IF((G20-F20)>=0.5,"Yes","")) | BS20: =IF((L20-M20)>=0.5,"Yes",IF((M20-L20)>=0.5,"Yes","")) -> Yes | BW20: =IF(BR20="Yes",-G20,0) -> 0 | BX20: =IF(BR20="Yes",F20,0) -> 0 | BY20: =IF((BX20-BW20)>0.01,(BX20-BW20),"") | BZ20: =IF(BS20="Yes",-L20,0) -> -0.05 | CA20: =IF(BS20="Yes",M20,0) -> 0.8 | CB20: =IF((CA20-BZ20)>0.01,(CA20-BZ20),"") -> 0.85
