Workbook

Sheet Summary
A1: Predictions resolved | C1: =COUNTIF(Input!F2:F61,0)+COUNTIF(Input!F2:F61,1) -> 60
A2: Predictions to come | C2: =COUNTA(Input!A2:A103)-C1 -> 0

Sheet Input
A1: ID | B1: Prediction | C1: Category | D1: Proposer | E1: Clarifications | F1: Outcome (1 = true, 0 = false) | G1: Outcome comments | H1: Outcome supporting link | I1: Scores: | J1: Andrew | K1: ChatGPT | L1: Eileen | M1: Iain | N1: Kate | O1: Rohan | P1: Pete | Q1: Christine | R1: Jac | S1: James | T1: Lachy | U1: Gael | V1: Bruce | X1: Andrew | Y1: ChatGPT | Z1: Eileen | AA1: Iain | AB1: Kate | AC1: Rohan | AD1: Pete | AE1: Christine | AF1: Jac | AG1: James | AH1: Lachy | AI1: Gael | AJ1: Bruce
A2: 1 | B2: Cate Blanchett will win best actress in the Academy Awards. | C2: Entertainment | D2: Gael | F2: 0 | J2: =IF($F2=1,(LOG(X2,2)+1),IF($F2=0,(LOG(1-X2,2)+1),"")) -> 0.48542683 | K2: =IF($F2=1,(LOG(Y2,2)+1),IF($F2=0,(LOG(1-Y2,2)+1),"")) -> 0 | L2: =IF($F2=1,(LOG(Z2,2)+1),IF($F2=0,(LOG(1-Z2,2)+1),"")) -> 0.26303441 | M2: =IF($F2=1,(LOG(AA2,2)+1),IF($F2=0,(LOG(1-AA2,2)+1),"")) -> 0 | N2: =IF($F2=1,(LOG(AB2,2)+1),IF($F2=0,(LOG(1-AB2,2)+1),"")) -> -1.3219281 | O2: =IF($F2=1,(LOG(AC2,2)+1),IF($F2=0,(LOG(1-AC2,2)+1),"")) -> 0.31034012 | P2: =IF($F2=1,(LOG(AD2,2)+1),IF($F2=0,(LOG(1-AD2,2)+1),"")) -> -0.73696559 | Q2: =IF($F2=1,(LOG(AE2,2)+1),IF($F2=0,(LOG(1-AE2,2)+1),"")) -> 0.84799691 | ... V2: =IF($F2=1,(LOG(AJ2,2)+1),IF($F2=0,(LOG(1-AJ2,2)+1),"")) -> -2.3219281 | X2: =Andrew!D2 -> 0.3 | Y2: =ChatGPT!D2 -> 0.5 | Z2: =Eileen!D2 -> 0.4 | AA2: =Iain!D2 -> 0.5 | AB2: =Kate!D2 -> 0.8 | AC2: =Rohan!D2 -> 0.38 | AD2: =Pete!D2 -> 0.7 | AE2: =Christine!D2 -> 0.1 | AF2: =Jac!D2 -> 0.5 | AG2: =James!D2 -> 0.5 | AH2: =Lachy!D2 -> 0.5 | AI2: =Gael!D2 -> 0.9 | AJ2: =Bruce!D2 -> 0.9
A3: 2 | B3: The farthest paper airplane flight will be broken (as reported by Guinness World Records) | C3: Entertainment | D3: Kate | F3: 1 | J3: =IF($F3=1,(LOG(X3,2)+1),IF($F3=0,(LOG(1-X3,2)+1),"")) -> 0.67807191 | K3: =IF($F3=1,(LOG(Y3,2)+1),IF($F3=0,(LOG(1-Y3,2)+1),"")) -> 0 | L3: =IF($F3=1,(LOG(Z3,2)+1),IF($F3=0,(LOG(1-Z3,2)+1),"")) -> 0.48542683 | M3: =IF($F3=1,(LOG(AA3,2)+1),IF($F3=0,(LOG(1-AA3,2)+1),"")) -> 0 | N3: =IF($F3=1,(LOG(AB3,2)+1),IF($F3=0,(LOG(1-AB3,2)+1),"")) -> 0.67807191 | O3: =IF($F3=1,(LOG(AC3,2)+1),IF($F3=0,(LOG(1-AC3,2)+1),"")) -> 0.99855658 | P3: =IF($F3=1,(LOG(AD3,2)+1),IF($F3=0,(LOG(1-AD3,2)+1),"")) -> 0 | Q3: =IF($F3=1,(LOG(AE3,2)+1),IF($F3=0,(LOG(1-AE3,2)+1),"")) -> 0 | ... V3: =IF($F3=1,(LOG(AJ3,2)+1),IF($F3=0,(LOG(1-AJ3,2)+1),"")) -> -2.3219281 | X3: =Andrew!D3 -> 0.8 | Y3: =ChatGPT!D3 -> 0.5 | Z3: =Eileen!D3 -> 0.7 | AA3: =Iain!D3 -> 0.5 | AB3: =Kate!D3 -> 0.8 | AC3: =Rohan!D3 -> 0.999 | AD3: =Pete!D3 -> 0.5 | AE3: =Christine!D3 -> 0.5 | AF3: =Jac!D3 -> 0.65 | AG3: =James!D3 -> 0.5 | AH3: =Lachy!D3 -> 0.5 | AI3: =Gael!D3 -> 0.7 | AJ3: =Bruce!D3 -> 0.1
A4: 3 | B4: Meghan and/or harry will post on social media content relating to the Coronation of King Charles III that, states or implies that Queen Elizabeth 2 'would have wanted them / is looking down from heaven wanting them' at the coronation, and/or describes a counter-ceremony with dubious historical precident performed by harry, meghan or their children to mark the occasion, and/or indicates that their presence at the coronation was prevented by 'deep palace' operatives or similar. | C4: Entertainment | D4: Lachy | F4: 0 | J4: =IF($F4=1,(LOG(X4,2)+1),IF($F4=0,(LOG(1-X4,2)+1),"")) -> 0.13750352 | K4: =IF($F4=1,(LOG(Y4,2)+1),IF($F4=0,(LOG(1-Y4,2)+1),"")) -> 0 | L4: =IF($F4=1,(LOG(Z4,2)+1),IF($F4=0,(LOG(1-Z4,2)+1),"")) -> 0.26303441 | M4: =IF($F4=1,(LOG(AA4,2)+1),IF($F4=0,(LOG(1-AA4,2)+1),"")) -> 0.26303441 | N4: =IF($F4=1,(LOG(AB4,2)+1),IF($F4=0,(LOG(1-AB4,2)+1),"")) -> -2.3219281 | O4: =IF($F4=1,(LOG(AC4,2)+1),IF($F4=0,(LOG(1-AC4,2)+1),"")) -> 0 | P4: =IF($F4=1,(LOG(AD4,2)+1),IF($F4=0,(LOG(1-AD4,2)+1),"")) -> 0.48542683 | Q4: =IF($F4=1,(LOG(AE4,2)+1),IF($F4=0,(LOG(1-AE4,2)+1),"")) -> 0.67807191 | ... V4: =IF($F4=1,(LOG(AJ4,2)+1),IF($F4=0,(LOG(1-AJ4,2)+1),"")) -> 0.84799691 | X4: =Andrew!D4 -> 0.45 | Y4: =ChatGPT!D4 -> 0.5 | Z4: =Eileen!D4 -> 0.4 | AA4: =Iain!D4 -> 0.4 | AB4: =Kate!D4 -> 0.9 | AC4: =Rohan!D4 -> 0.5 | AD4: =Pete!D4 -> 0.3 | AE4: =Christine!D4 -> 0.2 | AF4: =Jac!D4 -> 0.52 | AG4: =James!D4 -> 0.35 | AH4: =Lachy!D4 -> 0.7 | AI4: =Gael!D4 -> 0.5 | AJ4: =Bruce!D4 -> 0.1
A5: 4 | B5: There will be a scandal involving the BTS 10 year anniversary as reported by Korean MSM | C5: Entertainment | D5: Eileen | F5: 0 | J5: =IF($F5=1,(LOG(X5,2)+1),IF($F5=0,(LOG(1-X5,2)+1),"")) -> 0.48542683 | K5: =IF($F5=1,(LOG(Y5,2)+1),IF($F5=0,(LOG(1-Y5,2)+1),"")) -> 1 | L5: =IF($F5=1,(LOG(Z5,2)+1),IF($F5=0,(LOG(1-Z5,2)+1),"")) -> 0.26303441 | M5: =IF($F5=1,(LOG(AA5,2)+1),IF($F5=0,(LOG(1-AA5,2)+1),"")) -> -0.32192809 | N5: =IF($F5=1,(LOG(AB5,2)+1),IF($F5=0,(LOG(1-AB5,2)+1),"")) -> 0 | O5: =IF($F5=1,(LOG(AC5,2)+1),IF($F5=0,(LOG(1-AC5,2)+1),"")) -> 0.50589093 | P5: =IF($F5=1,(LOG(AD5,2)+1),IF($F5=0,(LOG(1-AD5,2)+1),"")) -> 0 | Q5: =IF($F5=1,(LOG(AE5,2)+1),IF($F5=0,(LOG(1-AE5,2)+1),"")) -> 0 | ... V5: =IF($F5=1,(LOG(AJ5,2)+1),IF($F5=0,(LOG(1-AJ5,2)+1),"")) -> 0 | X5: =Andrew!D5 -> 0.3 | Y5: =ChatGPT!D5 | Z5: =Eileen!D5 -> 0.4 | AA5: =Iain!D5 -> 0.6 | AB5: =Kate!D5 -> 0.5 | AC5: =Rohan!D5 -> 0.29 | AD5: =Pete!D5 -> 0.5 | AE5: =Christine!D5 -> 0.5 | AF5: =Jac!D5 -> 0.55 | AG5: =James!D5 -> 0.1 | AH5: =Lachy!D5 -> 0.6 | AI5: =Gael!D5 -> 0.5 | AJ5: =Bruce!D5 -> 0.5
A6: 5 | B6: Twosetviolin (the Youtube channel) will make a video reporting fresh abuse from kpop fans (excluding Blackpink) | C6: Entertainment | D6: Eileen | F6: 0 | J6: =IF($F6=1,(LOG(X6,2)+1),IF($F6=0,(LOG(1-X6,2)+1),"")) -> -0.32192809 | K6: =IF($F6=1,(LOG(Y6,2)+1),IF($F6=0,(LOG(1-Y6,2)+1),"")) -> 1 | L6: =IF($F6=1,(LOG(Z6,2)+1),IF($F6=0,(LOG(1-Z6,2)+1),"")) -> -1.3219281 | M6: =IF($F6=1,(LOG(AA6,2)+1),IF($F6=0,(LOG(1-AA6,2)+1),"")) -> 0 | N6: =IF($F6=1,(LOG(AB6,2)+1),IF($F6=0,(LOG(1-AB6,2)+1),"")) -> 0 | O6: =IF($F6=1,(LOG(AC6,2)+1),IF($F6=0,(LOG(1-AC6,2)+1),"")) -> 0.50589093 | P6: =IF($F6=1,(LOG(AD6,2)+1),IF($F6=0,(LOG(1-AD6,2)+1),"")) -> 0 | Q6: =IF($F6=1,(LOG(AE6,2)+1),IF($F6=0,(LOG(1-AE6,2)+1),"")) -> -2.3219281 | ... V6: =IF($F6=1,(LOG(AJ6,2)+1),IF($F6=0,(LOG(1-AJ6,2)+1),"")) -> 0 | X6: =Andrew!D6 -> 0.6 | Y6: =ChatGPT!D6 | Z6: =Eileen!D6 -> 0.8 | AA6: =Iain!D6 -> 0.5 | AB6: =Kate!D6 -> 0.5 | AC6: =Rohan!D6 -> 0.29 | AD6: =Pete!D6 -> 0.5 | AE6: =Christine!D6 -> 0.9 | AF6: =Jac!D6 -> 0.5 | AG6: =James!D6 -> 0.4 | AH6: =Lachy!D6 -> 0.5 | AI6: =Gael!D6 -> 0.5 | AJ6: =Bruce!D6 -> 0.5
A7: 6 | B7: Lee Min-ho will be the most followed Korean actor on Instagram by the end of 2023 | C7: Entertainment | D7: Eileen | F7: 0 | J7: =IF($F7=1,(LOG(X7,2)+1),IF($F7=0,(LOG(1-X7,2)+1),"")) -> -0.73696559 | K7: =IF($F7=1,(LOG(Y7,2)+1),IF($F7=0,(LOG(1-Y7,2)+1),"")) -> 1 | L7: =IF($F7=1,(LOG(Z7,2)+1),IF($F7=0,(LOG(1-Z7,2)+1),"")) -> -0.73696559 | M7: =IF($F7=1,(LOG(AA7,2)+1),IF($F7=0,(LOG(1-AA7,2)+1),"")) -> 0 | N7: =IF($F7=1,(LOG(AB7,2)+1),IF($F7=0,(LOG(1-AB7,2)+1),"")) -> 0 | O7: =IF($F7=1,(LOG(AC7,2)+1),IF($F7=0,(LOG(1-AC7,2)+1),"")) -> 0.67807191 | P7: =IF($F7=1,(LOG(AD7,2)+1),IF($F7=0,(LOG(1-AD7,2)+1),"")) -> 0 | Q7: =IF($F7=1,(LOG(AE7,2)+1),IF($F7=0,(LOG(1-AE7,2)+1),"")) -> -0.73696559 | ... V7: =IF($F7=1,(LOG(AJ7,2)+1),IF($F7=0,(LOG(1-AJ7,2)+1),"")) -> 0 | X7: =Andrew!D7 -> 0.7 | Y7: =ChatGPT!D7 | Z7: =Eileen!D7 -> 0.7 | AA7: =Iain!D7 -> 0.5 | AB7: =Kate!D7 -> 0.5 | AC7: =Rohan!D7 -> 0.2 | AD7: =Pete!D7 -> 0.5 | AE7: =Christine!D7 -> 0.7 | AF7: =Jac!D7 -> 0.52 | AG7: =James!D7 -> 0.6 | AH7: =Lachy!D7 -> 0.5 | AI7: =Gael!D7 -> 0.6 | AJ7: =Bruce!D7 -> 0.5
A8: 7 | B8: LOONA will disband | C8: Entertainment | D8: Eileen | F8: 1 | J8: =IF($F8=1,(LOG(X8,2)+1),IF($F8=0,(LOG(1-X8,2)+1),"")) -> 0.13750352 | K8: =IF($F8=1,(LOG(Y8,2)+1),IF($F8=0,(LOG(1-Y8,2)+1),"")) -> #NUM! | L8: =IF($F8=1,(LOG(Z8,2)+1),IF($F8=0,(LOG(1-Z8,2)+1),"")) -> -0.32192809 | M8: =IF($F8=1,(LOG(AA8,2)+1),IF($F8=0,(LOG(1-AA8,2)+1),"")) -> 0.26303441 | N8: =IF($F8=1,(LOG(AB8,2)+1),IF($F8=0,(LOG(1-AB8,2)+1),"")) -> 0 | O8: =IF($F8=1,(LOG(AC8,2)+1),IF($F8=0,(LOG(1-AC8,2)+1),"")) -> 0.13750352 | P8: =IF($F8=1,(LOG(AD8,2)+1),IF($F8=0,(LOG(1-AD8,2)+1),"")) -> 0 | Q8: =IF($F8=1,(LOG(AE8,2)+1),IF($F8=0,(LOG(1-AE8,2)+1),"")) -> 0.84799691 | ... V8: =IF($F8=1,(LOG(AJ8,2)+1),IF($F8=0,(LOG(1-AJ8,2)+1),"")) -> 0.67807191 | X8: =Andrew!D8 -> 0.55 | Y8: =ChatGPT!D8 | Z8: =Eileen!D8 -> 0.4 | AA8: =Iain!D8 -> 0.6 | AB8: =Kate!D8 -> 0.5 | AC8: =Rohan!D8 -> 0.55 | AD8: =Pete!D8 -> 0.5 | AE8: =Christine!D8 -> 0.9 | AF8: =Jac!D8 -> 0.85 | AG8: =James!D8 -> 0.6 | AH8: =Lachy!D8 -> 0.5 | AI8: =Gael!D8 -> 0.6 | AJ8: =Bruce!D8 -> 0.8
A9: 8 | B9: A new Korean show will get more than 140 million household views on Netflix | C9: Entertainment | D9: Eileen | E9: (Squid game had 142m in the same year) | F9: 0 | J9: =IF($F9=1,(LOG(X9,2)+1),IF($F9=0,(LOG(1-X9,2)+1),"")) -> 0.26303441 | K9: =IF($F9=1,(LOG(Y9,2)+1),IF($F9=0,(LOG(1-Y9,2)+1),"")) -> 1 | L9: =IF($F9=1,(LOG(Z9,2)+1),IF($F9=0,(LOG(1-Z9,2)+1),"")) -> -0.73696559 | M9: =IF($F9=1,(LOG(AA9,2)+1),IF($F9=0,(LOG(1-AA9,2)+1),"")) -> -0.73696559 | N9: =IF($F9=1,(LOG(AB9,2)+1),IF($F9=0,(LOG(1-AB9,2)+1),"")) -> 0.67807191 | O9: =IF($F9=1,(LOG(AC9,2)+1),IF($F9=0,(LOG(1-AC9,2)+1),"")) -> 0.26303441 | P9: =IF($F9=1,(LOG(AD9,2)+1),IF($F9=0,(LOG(1-AD9,2)+1),"")) -> 0.26303441 | Q9: =IF($F9=1,(LOG(AE9,2)+1),IF($F9=0,(LOG(1-AE9,2)+1),"")) -> -2.3219281 | ... V9: =IF($F9=1,(LOG(AJ9,2)+1),IF($F9=0,(LOG(1-AJ9,2)+1),"")) -> 0 | X9: =Andrew!D9 -> 0.4 | Y9: =ChatGPT!D9 | Z9: =Eileen!D9 -> 0.7 | AA9: =Iain!D9 -> 0.7 | AB9: =Kate!D9 -> 0.2 | AC9: =Rohan!D9 -> 0.4 | AD9: =Pete!D9 -> 0.4 | AE9: =Christine!D9 -> 0.9 | AF9: =Jac!D9 -> 0.1 | AG9: =James!D9 -> 0.3 | AH9: =Lachy!D9 -> 0.7 | AI9: =Gael!D9 -> 0.7 | AJ9: =Bruce!D9 -> 0.5
A10: 9 | B10: Avatar The Way of Water will remain at 8.0 on IMDb by Christmas next year. | C10: Entertainment | D10: Rohan | F10: 0 | J10: =IF($F10=1,(LOG(X10,2)+1),IF($F10=0,(LOG(1-X10,2)+1),"")) -> 0.76553475 | K10: =IF($F10=1,(LOG(Y10,2)+1),IF($F10=0,(LOG(1-Y10,2)+1),"")) -> 1 | L10: =IF($F10=1,(LOG(Z10,2)+1),IF($F10=0,(LOG(1-Z10,2)+1),"")) -> 0.48542683 | M10: =IF($F10=1,(LOG(AA10,2)+1),IF($F10=0,(LOG(1-AA10,2)+1),"")) -> 0.26303441 | N10: =IF($F10=1,(LOG(AB10,2)+1),IF($F10=0,(LOG(1-AB10,2)+1),"")) -> 0.48542683 | O10: =IF($F10=1,(LOG(AC10,2)+1),IF($F10=0,(LOG(1-AC10,2)+1),"")) -> 0.92599942 | P10: =IF($F10=1,(LOG(AD10,2)+1),IF($F10=0,(LOG(1-AD10,2)+1),"")) -> 0 | Q10: =IF($F10=1,(LOG(AE10,2)+1),IF($F10=0,(LOG(1-AE10,2)+1),"")) -> -0.73696559 | ... V10: =IF($F10=1,(LOG(AJ10,2)+1),IF($F10=0,(LOG(1-AJ10,2)+1),"")) -> 0.48542683 | X10: =Andrew!D10 -> 0.15 | Y10: =ChatGPT!D10 | Z10: =Eileen!D10 -> 0.3 | AA10: =Iain!D10 -> 0.4 | AB10: =Kate!D10 -> 0.3 | AC10: =Rohan!D10 -> 0.05 | AD10: =Pete!D10 -> 0.5 | AE10: =Christine!D10 -> 0.7 | AF10: =Jac!D10 -> 0.1 | AG10: =James!D10 -> 0.01 | AH10: =Lachy!D10 -> 0.4 | AI10: =Gael!D10 -> 0.5 | AJ10: =Bruce!D10 -> 0.3
A11: 10 | B11: Kanye West will have 0 twitter suspensions or bans. | C11: Entertainment | D11: Rohan | F11: 0 | J11: =IF($F11=1,(LOG(X11,2)+1),IF($F11=0,(LOG(1-X11,2)+1),"")) -> 0.92599942 | K11: =IF($F11=1,(LOG(Y11,2)+1),IF($F11=0,(LOG(1-Y11,2)+1),"")) -> 1 | L11: =IF($F11=1,(LOG(Z11,2)+1),IF($F11=0,(LOG(1-Z11,2)+1),"")) -> 0.67807191 | M11: =IF($F11=1,(LOG(AA11,2)+1),IF($F11=0,(LOG(1-AA11,2)+1),"")) -> 0.84799691 | N11: =IF($F11=1,(LOG(AB11,2)+1),IF($F11=0,(LOG(1-AB11,2)+1),"")) -> -2.3219281 | O11: =IF($F11=1,(LOG(AC11,2)+1),IF($F11=0,(LOG(1-AC11,2)+1),"")) -> -5.6438562 | P11: =IF($F11=1,(LOG(AD11,2)+1),IF($F11=0,(LOG(1-AD11,2)+1),"")) -> 0 | Q11: =IF($F11=1,(LOG(AE11,2)+1),IF($F11=0,(LOG(1-AE11,2)+1),"")) -> -1.3219281 | ... V11: =IF($F11=1,(LOG(AJ11,2)+1),IF($F11=0,(LOG(1-AJ11,2)+1),"")) -> -0.73696559 | X11: =Andrew!D11 -> 0.05 | Y11: =ChatGPT!D11 | Z11: =Eileen!D11 -> 0.2 | AA11: =Iain!D11 -> 0.1 | AB11: =Kate!D11 -> 0.9 | AC11: =Rohan!D11 -> 0.99 | AD11: =Pete!D11 -> 0.5 | AE11: =Christine!D11 -> 0.8 | AF11: =Jac!D11 -> 0.55 | AG11: =James!D11 -> 0.5 | AH11: =Lachy!D11 -> 0.5 | AI11: =Gael!D11 -> 0.4 | AJ11: =Bruce!D11 -> 0.7
A12: 11 | B12: At either the Grammys, the Oscars, the Emmys or the game awards there will be a significant interruption comparable to the Will Smith Chris Rock slap or the game awards Bill Clinton kid. | C12: Entertainment | D12: Rohan | F12: 0 | J12: =IF($F12=1,(LOG(X12,2)+1),IF($F12=0,(LOG(1-X12,2)+1),"")) -> -0.73696559 | K12: =IF($F12=1,(LOG(Y12,2)+1),IF($F12=0,(LOG(1-Y12,2)+1),"")) -> 1 | L12: =IF($F12=1,(LOG(Z12,2)+1),IF($F12=0,(LOG(1-Z12,2)+1),"")) -> 0.26303441 | M12: =IF($F12=1,(LOG(AA12,2)+1),IF($F12=0,(LOG(1-AA12,2)+1),"")) -> 0.84799691 | N12: =IF($F12=1,(LOG(AB12,2)+1),IF($F12=0,(LOG(1-AB12,2)+1),"")) -> -1.3219281 | O12: =IF($F12=1,(LOG(AC12,2)+1),IF($F12=0,(LOG(1-AC12,2)+1),"")) -> 0.76553475 | P12: =IF($F12=1,(LOG(AD12,2)+1),IF($F12=0,(LOG(1-AD12,2)+1),"")) -> 0.48542683 | Q12: =IF($F12=1,(LOG(AE12,2)+1),IF($F12=0,(LOG(1-AE12,2)+1),"")) -> 0.84799691 | ... V12: =IF($F12=1,(LOG(AJ12,2)+1),IF($F12=0,(LOG(1-AJ12,2)+1),"")) -> 0.67807191 | X12: =Andrew!D12 -> 0.7 | Y12: =ChatGPT!D12 | Z12: =Eileen!D12 -> 0.4 | AA12: =Iain!D12 -> 0.1 | AB12: =Kate!D12 -> 0.8 | AC12: =Rohan!D12 -> 0.15 | AD12: =Pete!D12 -> 0.3 | AE12: =Christine!D12 -> 0.1 | AF12: =Jac!D12 -> 0.35 | AG12: =James!D12 -> 0.3 | AH12: =Lachy!D12 -> 0.1 | AI12: =Gael!D12 -> 0.3 | AJ12: =Bruce!D12 -> 0.2
A13: 12 | B13: Francis will be the Pope on Christmas eve | C13: Entertainment | D13: Pete | F13: 1 | J13: =IF($F13=1,(LOG(X13,2)+1),IF($F13=0,(LOG(1-X13,2)+1),"")) -> 0.26303441 | K13: =IF($F13=1,(LOG(Y13,2)+1),IF($F13=0,(LOG(1-Y13,2)+1),"")) -> #NUM! | L13: =IF($F13=1,(LOG(Z13,2)+1),IF($F13=0,(LOG(1-Z13,2)+1),"")) -> -1.3219281 | M13: =IF($F13=1,(LOG(AA13,2)+1),IF($F13=0,(LOG(1-AA13,2)+1),"")) -> 0.48542683 | N13: =IF($F13=1,(LOG(AB13,2)+1),IF($F13=0,(LOG(1-AB13,2)+1),"")) -> 0.84799691 | O13: =IF($F13=1,(LOG(AC13,2)+1),IF($F13=0,(LOG(1-AC13,2)+1),"")) -> 0.5849625 | P13: =IF($F13=1,(LOG(AD13,2)+1),IF($F13=0,(LOG(1-AD13,2)+1),"")) -> -0.32192809 | Q13: =IF($F13=1,(LOG(AE13,2)+1),IF($F13=0,(LOG(1-AE13,2)+1),"")) -> 0 | ... V13: =IF($F13=1,(LOG(AJ13,2)+1),IF($F13=0,(LOG(1-AJ13,2)+1),"")) -> 0.84799691 | X13: =Andrew!D13 -> 0.6 | Y13: =ChatGPT!D13 | Z13: =Eileen!D13 -> 0.2 | AA13: =Iain!D13 -> 0.7 | AB13: =Kate!D13 -> 0.9 | AC13: =Rohan!D13 -> 0.75 | AD13: =Pete!D13 -> 0.4 | AE13: =Christine!D13 -> 0.5 | AF13: =Jac!D13 -> 0.4 | AG13: =James!D13 -> 0.7 | AH13: =Lachy!D13 -> 0.8 | AI13: =Gael!D13 -> 0.7 | AJ13: =Bruce!D13 -> 0.9
A14: 13 | B14: Rohan will not test positive for COVID in 2023 | C14: Family | D14: Kate | F14: 1 | J14: =IF($F14=1,(LOG(X14,2)+1),IF($F14=0,(LOG(1-X14,2)+1),"")) -> -0.32192809 | K14: =IF($F14=1,(LOG(Y14,2)+1),IF($F14=0,(LOG(1-Y14,2)+1),"")) -> #NUM! | L14: =IF($F14=1,(LOG(Z14,2)+1),IF($F14=0,(LOG(1-Z14,2)+1),"")) -> -0.32192809 | M14: =IF($F14=1,(LOG(AA14,2)+1),IF($F14=0,(LOG(1-AA14,2)+1),"")) -> 0.26303441 | N14: =IF($F14=1,(LOG(AB14,2)+1),IF($F14=0,(LOG(1-AB14,2)+1),"")) -> 0.48542683 | O14: =IF($F14=1,(LOG(AC14,2)+1),IF($F14=0,(LOG(1-AC14,2)+1),"")) -> 0.84799691 | P14: =IF($F14=1,(LOG(AD14,2)+1),IF($F14=0,(LOG(1-AD14,2)+1),"")) -> 0.67807191 | Q14: =IF($F14=1,(LOG(AE14,2)+1),IF($F14=0,(LOG(1-AE14,2)+1),"")) -> 0 | ... V14: =IF($F14=1,(LOG(AJ14,2)+1),IF($F14=0,(LOG(1-AJ14,2)+1),"")) -> 0.26303441 | X14: =Andrew!D14 -> 0.4 | Y14: =ChatGPT!D14 | Z14: =Eileen!D14 -> 0.4 | AA14: =Iain!D14 -> 0.6 | AB14: =Kate!D14 -> 0.7 | AC14: =Rohan!D14 -> 0.9 | AD14: =Pete!D14 -> 0.8 | AE14: =Christine!D14 -> 0.5 | AF14: =Jac!D14 -> 0.6 | AG14: =James!D14 -> 0.7 | AH14: =Lachy!D14 -> 0.6 | AI14: =Gael!D14 -> 0.8 | AJ14: =Bruce!D14 -> 0.6
A15: 14 | B15: Baby McCalman is less than 49cm at birth | C15: Family | D15: James | F15: 1 | G15: Length of 47.5cm | J15: =IF($F15=1,(LOG(X15,2)+1),IF($F15=0,(LOG(1-X15,2)+1),"")) -> 0.13750352 | K15: =IF($F15=1,(LOG(Y15,2)+1),IF($F15=0,(LOG(1-Y15,2)+1),"")) -> #NUM! | L15: =IF($F15=1,(LOG(Z15,2)+1),IF($F15=0,(LOG(1-Z15,2)+1),"")) -> 0.26303441 | M15: =IF($F15=1,(LOG(AA15,2)+1),IF($F15=0,(LOG(1-AA15,2)+1),"")) -> 0 | N15: =IF($F15=1,(LOG(AB15,2)+1),IF($F15=0,(LOG(1-AB15,2)+1),"")) -> 0.67807191 | O15: =IF($F15=1,(LOG(AC15,2)+1),IF($F15=0,(LOG(1-AC15,2)+1),"")) -> -0.32192809 | P15: =IF($F15=1,(LOG(AD15,2)+1),IF($F15=0,(LOG(1-AD15,2)+1),"")) -> 0.48542683 | Q15: =IF($F15=1,(LOG(AE15,2)+1),IF($F15=0,(LOG(1-AE15,2)+1),"")) -> -0.73696559 | ... V15: =IF($F15=1,(LOG(AJ15,2)+1),IF($F15=0,(LOG(1-AJ15,2)+1),"")) -> 0.76553475 | X15: =Andrew!D15 -> 0.55 | Y15: =ChatGPT!D15 | Z15: =Eileen!D15 -> 0.6 | AA15: =Iain!D15 -> 0.5 | AB15: =Kate!D15 -> 0.8 | AC15: =Rohan!D15 -> 0.4 | AD15: =Pete!D15 -> 0.7 | AE15: =Christine!D15 -> 0.3 | AF15: =Jac!D15 -> 0.5 | AG15: =James!D15 -> 0.7 | AH15: =Lachy!D15 -> 0.5 | AI15: =Gael!D15 -> 0.6 | AJ15: =Bruce!D15 -> 0.85
A16: 15 | B16: Jac and Lachy’s baby will say ‘ma’ or make a similar ‘m’ sound by 24 December 2023. | C16: Family | D16: Christine | E16: This will need some governance... | F16: 1 | J16: =IF($F16=1,(LOG(X16,2)+1),IF($F16=0,(LOG(1-X16,2)+1),"")) -> -1 | K16: =IF($F16=1,(LOG(Y16,2)+1),IF($F16=0,(LOG(1-Y16,2)+1),"")) -> #NUM! | L16: =IF($F16=1,(LOG(Z16,2)+1),IF($F16=0,(LOG(1-Z16,2)+1),"")) -> 0.48542683 | M16: =IF($F16=1,(LOG(AA16,2)+1),IF($F16=0,(LOG(1-AA16,2)+1),"")) -> 0.67807191 | N16: =IF($F16=1,(LOG(AB16,2)+1),IF($F16=0,(LOG(1-AB16,2)+1),"")) -> -0.32192809 | O16: =IF($F16=1,(LOG(AC16,2)+1),IF($F16=0,(LOG(1-AC16,2)+1),"")) -> 0.76553475 | P16: =IF($F16=1,(LOG(AD16,2)+1),IF($F16=0,(LOG(1-AD16,2)+1),"")) -> 0.67807191 | Q16: =IF($F16=1,(LOG(AE16,2)+1),IF($F16=0,(LOG(1-AE16,2)+1),"")) -> 0.67807191 | ... V16: =IF($F16=1,(LOG(AJ16,2)+1),IF($F16=0,(LOG(1-AJ16,2)+1),"")) -> 0.67807191 | X16: =Andrew!D16 -> 0.25 | Y16: =ChatGPT!D16 | Z16: =Eileen!D16 -> 0.7 | AA16: =Iain!D16 -> 0.8 | AB16: =Kate!D16 -> 0.4 | AC16: =Rohan!D16 -> 0.85 | AD16: =Pete!D16 -> 0.8 | AE16: =Christine!D16 -> 0.8 | AF16: =Jac!D16 -> 0.7 | AG16: =James!D16 -> 0.3 | AH16: =Lachy!D16 -> 0.7 | AI16: =Gael!D16 -> 0.8 | AJ16: =Bruce!D16 -> 0.8
A17: 16 | B17: Rohan will be at least 6'1" | C17: Family | D17: Andrew | F17: 0 | J17: =IF($F17=1,(LOG(X17,2)+1),IF($F17=0,(LOG(1-X17,2)+1),"")) -> 0.67807191 | K17: =IF($F17=1,(LOG(Y17,2)+1),IF($F17=0,(LOG(1-Y17,2)+1),"")) -> 0.84799691 | L17: =IF($F17=1,(LOG(Z17,2)+1),IF($F17=0,(LOG(1-Z17,2)+1),"")) -> 0.48542683 | M17: =IF($F17=1,(LOG(AA17,2)+1),IF($F17=0,(LOG(1-AA17,2)+1),"")) -> -0.32192809 | N17: =IF($F17=1,(LOG(AB17,2)+1),IF($F17=0,(LOG(1-AB17,2)+1),"")) -> 0.48542683 | O17: =IF($F17=1,(LOG(AC17,2)+1),IF($F17=0,(LOG(1-AC17,2)+1),"")) -> 0.13750352 | P17: =IF($F17=1,(LOG(AD17,2)+1),IF($F17=0,(LOG(1-AD17,2)+1),"")) -> -0.73696559 | Q17: =IF($F17=1,(LOG(AE17,2)+1),IF($F17=0,(LOG(1-AE17,2)+1),"")) -> -0.73696559 | ... V17: =IF($F17=1,(LOG(AJ17,2)+1),IF($F17=0,(LOG(1-AJ17,2)+1),"")) -> 0.84799691 | X17: =Andrew!D17 -> 0.2 | Y17: =ChatGPT!D17 -> 0.1 | Z17: =Eileen!D17 -> 0.3 | AA17: =Iain!D17 -> 0.6 | AB17: =Kate!D17 -> 0.3 | AC17: =Rohan!D17 -> 0.45 | AD17: =Pete!D17 -> 0.7 | AE17: =Christine!D17 -> 0.7 | AF17: =Jac!D17 -> 0.35 | AG17: =James!D17 -> 0.5 | AH17: =Lachy!D17 -> 0.3 | AI17: =Gael!D17 -> 0.4 | AJ17: =Bruce!D17 -> 0.1
A18: 17 | B18: Andrew and Eileen will buy a house | C18: Family | D18: Iain | F18: 1 | J18: =IF($F18=1,(LOG(X18,2)+1),IF($F18=0,(LOG(1-X18,2)+1),"")) -> 0.98550043 | K18: =IF($F18=1,(LOG(Y18,2)+1),IF($F18=0,(LOG(1-Y18,2)+1),"")) -> #NUM! | L18: =IF($F18=1,(LOG(Z18,2)+1),IF($F18=0,(LOG(1-Z18,2)+1),"")) -> 0.98550043 | M18: =IF($F18=1,(LOG(AA18,2)+1),IF($F18=0,(LOG(1-AA18,2)+1),"")) -> 0.48542683 | N18: =IF($F18=1,(LOG(AB18,2)+1),IF($F18=0,(LOG(1-AB18,2)+1),"")) -> 0.84799691 | O18: =IF($F18=1,(LOG(AC18,2)+1),IF($F18=0,(LOG(1-AC18,2)+1),"")) -> 0.37851162 | P18: =IF($F18=1,(LOG(AD18,2)+1),IF($F18=0,(LOG(1-AD18,2)+1),"")) -> 0 | Q18: =IF($F18=1,(LOG(AE18,2)+1),IF($F18=0,(LOG(1-AE18,2)+1),"")) -> 0 | ... V18: =IF($F18=1,(LOG(AJ18,2)+1),IF($F18=0,(LOG(1-AJ18,2)+1),"")) -> 0.48542683 | X18: =Andrew!D18 -> 0.99 | Y18: =ChatGPT!D18 | Z18: =Eileen!D18 -> 0.99 | AA18: =Iain!D18 -> 0.7 | AB18: =Kate!D18 -> 0.9 | AC18: =Rohan!D18 -> 0.65 | AD18: =Pete!D18 -> 0.5 | AE18: =Christine!D18 -> 0.5 | AF18: =Jac!D18 -> 0.7 | AG18: =James!D18 -> 0.5 | AH18: =Lachy!D18 -> 0.9 | AI18: =Gael!D18 -> 0.7 | AJ18: =Bruce!D18 -> 0.7
A19: 18 | B19: Lachy and Jac’s baby will be at least 68 cm by next Christmas. | C19: Family | D19: Rohan | F19: 0 | J19: =IF($F19=1,(LOG(X19,2)+1),IF($F19=0,(LOG(1-X19,2)+1),"")) -> -0.15200309 | K19: =IF($F19=1,(LOG(Y19,2)+1),IF($F19=0,(LOG(1-Y19,2)+1),"")) -> 1 | L19: =IF($F19=1,(LOG(Z19,2)+1),IF($F19=0,(LOG(1-Z19,2)+1),"")) -> 0.13750352 | M19: =IF($F19=1,(LOG(AA19,2)+1),IF($F19=0,(LOG(1-AA19,2)+1),"")) -> 0.26303441 | N19: =IF($F19=1,(LOG(AB19,2)+1),IF($F19=0,(LOG(1-AB19,2)+1),"")) -> -0.32192809 | O19: =IF($F19=1,(LOG(AC19,2)+1),IF($F19=0,(LOG(1-AC19,2)+1),"")) -> -0.15200309 | P19: =IF($F19=1,(LOG(AD19,2)+1),IF($F19=0,(LOG(1-AD19,2)+1),"")) -> -1.3219281 | Q19: =IF($F19=1,(LOG(AE19,2)+1),IF($F19=0,(LOG(1-AE19,2)+1),"")) -> -1.3219281 | ... V19: =IF($F19=1,(LOG(AJ19,2)+1),IF($F19=0,(LOG(1-AJ19,2)+1),"")) -> -0.32192809 | X19: =Andrew!D19 -> 0.55 | Y19: =ChatGPT!D19 | Z19: =Eileen!D19 -> 0.45 | AA19: =Iain!D19 -> 0.4 | AB19: =Kate!D19 -> 0.6 | AC19: =Rohan!D19 -> 0.55 | AD19: =Pete!D19 -> 0.8 | AE19: =Christine!D19 -> 0.8 | AF19: =Jac!D19 -> 0.85 | AG19: =James!D19 -> 0.5 | AH19: =Lachy!D19 -> 0.5 | AI19: =Gael!D19 -> 0.7 | AJ19: =Bruce!D19 -> 0.6
A20: 19 | B20: The annual inflation rate in Australia will be below 6% when the RBA releases its announcement of the October 2023 result | C20: Finance | D20: Bruce | F20: 1 | J20: =IF($F20=1,(LOG(X20,2)+1),IF($F20=0,(LOG(1-X20,2)+1),"")) -> -0.73696559 | K20: =IF($F20=1,(LOG(Y20,2)+1),IF($F20=0,(LOG(1-Y20,2)+1),"")) -> #NUM! | L20: =IF($F20=1,(LOG(Z20,2)+1),IF($F20=0,(LOG(1-Z20,2)+1),"")) -> 0.48542683 | M20: =IF($F20=1,(LOG(AA20,2)+1),IF($F20=0,(LOG(1-AA20,2)+1),"")) -> -1.3219281 | N20: =IF($F20=1,(LOG(AB20,2)+1),IF($F20=0,(LOG(1-AB20,2)+1),"")) -> -0.32192809 | O20: =IF($F20=1,(LOG(AC20,2)+1),IF($F20=0,(LOG(1-AC20,2)+1),"")) -> 0 | P20: =IF($F20=1,(LOG(AD20,2)+1),IF($F20=0,(LOG(1-AD20,2)+1),"")) -> 0 | Q20: =IF($F20=1,(LOG(AE20,2)+1),IF($F20=0,(LOG(1-AE20,2)+1),"")) -> 0 | ... V20: =IF($F20=1,(LOG(AJ20,2)+1),IF($F20=0,(LOG(1-AJ20,2)+1),"")) -> 0.5849625 | X20: =Andrew!D20 -> 0.3 | Y20: =ChatGPT!D20 | Z20: =Eileen!D20 -> 0.7 | AA20: =Iain!D20 -> 0.2 | AB20: =Kate!D20 -> 0.4 | AC20: =Rohan!D20 -> 0.5 | AD20: =Pete!D20 -> 0.5 | AE20: =Christine!D20 -> 0.5 | AF20: =Jac!D20 -> 0.9 | AG20: =James!D20 -> 0.5 | AH20: =Lachy!D20 -> 0.7 | AI20: =Gael!D20 -> 0.7 | AJ20: =Bruce!D20 -> 0.75
A21: 20 | B21: AUD falls below USD0.64 | C21: Finance | D21: James | F21: 1 | J21: =IF($F21=1,(LOG(X21,2)+1),IF($F21=0,(LOG(1-X21,2)+1),"")) -> 0.35614381 | K21: =IF($F21=1,(LOG(Y21,2)+1),IF($F21=0,(LOG(1-Y21,2)+1),"")) -> #NUM! | L21: =IF($F21=1,(LOG(Z21,2)+1),IF($F21=0,(LOG(1-Z21,2)+1),"")) -> 0.37851162 | M21: =IF($F21=1,(LOG(AA21,2)+1),IF($F21=0,(LOG(1-AA21,2)+1),"")) -> 0 | N21: =IF($F21=1,(LOG(AB21,2)+1),IF($F21=0,(LOG(1-AB21,2)+1),"")) -> 0 | O21: =IF($F21=1,(LOG(AC21,2)+1),IF($F21=0,(LOG(1-AC21,2)+1),"")) -> 0 | P21: =IF($F21=1,(LOG(AD21,2)+1),IF($F21=0,(LOG(1-AD21,2)+1),"")) -> 0 | Q21: =IF($F21=1,(LOG(AE21,2)+1),IF($F21=0,(LOG(1-AE21,2)+1),"")) -> 0 | ... V21: =IF($F21=1,(LOG(AJ21,2)+1),IF($F21=0,(LOG(1-AJ21,2)+1),"")) -> -1 | X21: =Andrew!D21 -> 0.64 | Y21: =ChatGPT!D21 | Z21: =Eileen!D21 -> 0.65 | AA21: =Iain!D21 -> 0.5 | AB21: =Kate!D21 -> 0.5 | AC21: =Rohan!D21 -> 0.5 | AD21: =Pete!D21 -> 0.5 | AE21: =Christine!D21 -> 0.5 | AF21: =Jac!D21 -> 0.35 | AG21: =James!D21 -> 0.5 | AH21: =Lachy!D21 -> 0.5 | AI21: =Gael!D21 -> 0.7 | AJ21: =Bruce!D21 -> 0.25
A22: 21 | B22: Pro-GOP investor makes a meaningful (>US$100m) investment in Twitter | C22: Finance | D22: James | F22: 0 | J22: =IF($F22=1,(LOG(X22,2)+1),IF($F22=0,(LOG(1-X22,2)+1),"")) -> -0.15200309 | K22: =IF($F22=1,(LOG(Y22,2)+1),IF($F22=0,(LOG(1-Y22,2)+1),"")) -> 1 | L22: =IF($F22=1,(LOG(Z22,2)+1),IF($F22=0,(LOG(1-Z22,2)+1),"")) -> 0.48542683 | M22: =IF($F22=1,(LOG(AA22,2)+1),IF($F22=0,(LOG(1-AA22,2)+1),"")) -> 0.48542683 | N22: =IF($F22=1,(LOG(AB22,2)+1),IF($F22=0,(LOG(1-AB22,2)+1),"")) -> -0.32192809 | O22: =IF($F22=1,(LOG(AC22,2)+1),IF($F22=0,(LOG(1-AC22,2)+1),"")) -> 0.084064265 | P22: =IF($F22=1,(LOG(AD22,2)+1),IF($F22=0,(LOG(1-AD22,2)+1),"")) -> 0 | Q22: =IF($F22=1,(LOG(AE22,2)+1),IF($F22=0,(LOG(1-AE22,2)+1),"")) -> 0 | ... V22: =IF($F22=1,(LOG(AJ22,2)+1),IF($F22=0,(LOG(1-AJ22,2)+1),"")) -> 0.48542683 | X22: =Andrew!D22 -> 0.55 | Y22: =ChatGPT!D22 | Z22: =Eileen!D22 -> 0.3 | AA22: =Iain!D22 -> 0.3 | AB22: =Kate!D22 -> 0.6 | AC22: =Rohan!D22 -> 0.47 | AD22: =Pete!D22 -> 0.5 | AE22: =Christine!D22 -> 0.5 | AF22: =Jac!D22 -> 0.15 | AG22: =James!D22 -> 0.6 | AH22: =Lachy!D22 -> 0.3 | AI22: =Gael!D22 -> 0.7 | AJ22: =Bruce!D22 -> 0.3
A23: 22 | B23: The Australian unemployment rate will be more than 4% at time of judging | C23: Finance | D23: Andrew | F23: 0 | J23: =IF($F23=1,(LOG(X23,2)+1),IF($F23=0,(LOG(1-X23,2)+1),"")) -> 0.48542683 | K23: =IF($F23=1,(LOG(Y23,2)+1),IF($F23=0,(LOG(1-Y23,2)+1),"")) -> 1 | L23: =IF($F23=1,(LOG(Z23,2)+1),IF($F23=0,(LOG(1-Z23,2)+1),"")) -> 0.37851162 | M23: =IF($F23=1,(LOG(AA23,2)+1),IF($F23=0,(LOG(1-AA23,2)+1),"")) -> -0.32192809 | N23: =IF($F23=1,(LOG(AB23,2)+1),IF($F23=0,(LOG(1-AB23,2)+1),"")) -> 0.48542683 | O23: =IF($F23=1,(LOG(AC23,2)+1),IF($F23=0,(LOG(1-AC23,2)+1),"")) -> 0.48542683 | P23: =IF($F23=1,(LOG(AD23,2)+1),IF($F23=0,(LOG(1-AD23,2)+1),"")) -> 0.48542683 | Q23: =IF($F23=1,(LOG(AE23,2)+1),IF($F23=0,(LOG(1-AE23,2)+1),"")) -> 0 | ... V23: =IF($F23=1,(LOG(AJ23,2)+1),IF($F23=0,(LOG(1-AJ23,2)+1),"")) -> -0.73696559 | X23: =Andrew!D23 -> 0.3 | Y23: =ChatGPT!D23 | Z23: =Eileen!D23 -> 0.35 | AA23: =Iain!D23 -> 0.6 | AB23: =Kate!D23 -> 0.3 | AC23: =Rohan!D23 -> 0.3 | AD23: =Pete!D23 -> 0.3 | AE23: =Christine!D23 -> 0.5 | AF23: =Jac!D23 -> 0.3 | AG23: =James!D23 -> 0.6 | AH23: =Lachy!D23 -> 0.2 | AI23: =Gael!D23 -> 0.6 | AJ23: =Bruce!D23 -> 0.7
A24: 23 | B24: Binance will collapse slash go into bankruptcy | C24: Finance | D24: Lachy | F24: 0 | J24: =IF($F24=1,(LOG(X24,2)+1),IF($F24=0,(LOG(1-X24,2)+1),"")) -> -0.32192809 | K24: =IF($F24=1,(LOG(Y24,2)+1),IF($F24=0,(LOG(1-Y24,2)+1),"")) -> 1 | L24: =IF($F24=1,(LOG(Z24,2)+1),IF($F24=0,(LOG(1-Z24,2)+1),"")) -> -0.32192809 | M24: =IF($F24=1,(LOG(AA24,2)+1),IF($F24=0,(LOG(1-AA24,2)+1),"")) -> -0.73696559 | N24: =IF($F24=1,(LOG(AB24,2)+1),IF($F24=0,(LOG(1-AB24,2)+1),"")) -> 0 | O24: =IF($F24=1,(LOG(AC24,2)+1),IF($F24=0,(LOG(1-AC24,2)+1),"")) -> -0.029146346 | P24: =IF($F24=1,(LOG(AD24,2)+1),IF($F24=0,(LOG(1-AD24,2)+1),"")) -> 0 | Q24: =IF($F24=1,(LOG(AE24,2)+1),IF($F24=0,(LOG(1-AE24,2)+1),"")) -> -0.73696559 | ... V24: =IF($F24=1,(LOG(AJ24,2)+1),IF($F24=0,(LOG(1-AJ24,2)+1),"")) -> 0.67807191 | X24: =Andrew!D24 -> 0.6 | Y24: =ChatGPT!D24 | Z24: =Eileen!D24 -> 0.6 | AA24: =Iain!D24 -> 0.7 | AB24: =Kate!D24 -> 0.5 | AC24: =Rohan!D24 -> 0.51 | AD24: =Pete!D24 -> 0.5 | AE24: =Christine!D24 -> 0.7 | AF24: =Jac!D24 -> 0.9 | AG24: =James!D24 -> 0.7 | AH24: =Lachy!D24 -> 0.4 | AI24: =Gael!D24 -> 0.5 | AJ24: =Bruce!D24 -> 0.2
A25: 24 | B25: Telsa will remain solvent and operating | C25: Finance | D25: Pete | F25: 1 | J25: =IF($F25=1,(LOG(X25,2)+1),IF($F25=0,(LOG(1-X25,2)+1),"")) -> 0.76553475 | K25: =IF($F25=1,(LOG(Y25,2)+1),IF($F25=0,(LOG(1-Y25,2)+1),"")) -> #NUM! | L25: =IF($F25=1,(LOG(Z25,2)+1),IF($F25=0,(LOG(1-Z25,2)+1),"")) -> 0.67807191 | M25: =IF($F25=1,(LOG(AA25,2)+1),IF($F25=0,(LOG(1-AA25,2)+1),"")) -> 0.26303441 | N25: =IF($F25=1,(LOG(AB25,2)+1),IF($F25=0,(LOG(1-AB25,2)+1),"")) -> 0.67807191 | O25: =IF($F25=1,(LOG(AC25,2)+1),IF($F25=0,(LOG(1-AC25,2)+1),"")) -> 0.92599942 | P25: =IF($F25=1,(LOG(AD25,2)+1),IF($F25=0,(LOG(1-AD25,2)+1),"")) -> 0.84799691 | Q25: =IF($F25=1,(LOG(AE25,2)+1),IF($F25=0,(LOG(1-AE25,2)+1),"")) -> 0.48542683 | ... V25: =IF($F25=1,(LOG(AJ25,2)+1),IF($F25=0,(LOG(1-AJ25,2)+1),"")) -> 0.98550043 | X25: =Andrew!D25 -> 0.85 | Y25: =ChatGPT!D25 | Z25: =Eileen!D25 -> 0.8 | AA25: =Iain!D25 -> 0.6 | AB25: =Kate!D25 -> 0.8 | AC25: =Rohan!D25 -> 0.95 | AD25: =Pete!D25 -> 0.9 | AE25: =Christine!D25 -> 0.7 | AF25: =Jac!D25 -> 0.85 | AG25: =James!D25 -> 0.9 | AH25: =Lachy!D25 -> 0.7 | AI25: =Gael!D25 -> 0.8 | AJ25: =Bruce!D25 -> 0.99
A26: 25 | B26: At least three class action proceedings (or equivalent eg. aggregate litigation) will be filed around the world against Elon Musk or Tesla about the self-driving technology in Tesla cars | C26: Law | D26: Jac | F26: 0 | J26: =IF($F26=1,(LOG(X26,2)+1),IF($F26=0,(LOG(1-X26,2)+1),"")) -> 0.13750352 | K26: =IF($F26=1,(LOG(Y26,2)+1),IF($F26=0,(LOG(1-Y26,2)+1),"")) -> 1 | L26: =IF($F26=1,(LOG(Z26,2)+1),IF($F26=0,(LOG(1-Z26,2)+1),"")) -> 0.26303441 | M26: =IF($F26=1,(LOG(AA26,2)+1),IF($F26=0,(LOG(1-AA26,2)+1),"")) -> -0.32192809 | N26: =IF($F26=1,(LOG(AB26,2)+1),IF($F26=0,(LOG(1-AB26,2)+1),"")) -> -0.32192809 | O26: =IF($F26=1,(LOG(AC26,2)+1),IF($F26=0,(LOG(1-AC26,2)+1),"")) -> -0.029146346 | P26: =IF($F26=1,(LOG(AD26,2)+1),IF($F26=0,(LOG(1-AD26,2)+1),"")) -> -0.32192809 | Q26: =IF($F26=1,(LOG(AE26,2)+1),IF($F26=0,(LOG(1-AE26,2)+1),"")) -> -0.73696559 | ... V26: =IF($F26=1,(LOG(AJ26,2)+1),IF($F26=0,(LOG(1-AJ26,2)+1),"")) -> -2.3219281 | X26: =Andrew!D26 -> 0.45 | Y26: =ChatGPT!D26 | Z26: =Eileen!D26 -> 0.4 | AA26: =Iain!D26 -> 0.6 | AB26: =Kate!D26 -> 0.6 | AC26: =Rohan!D26 -> 0.51 | AD26: =Pete!D26 -> 0.6 | AE26: =Christine!D26 -> 0.7 | AF26: =Jac!D26 -> 0.9 | AG26: =James!D26 -> 0.6 | AH26: =Lachy!D26 -> 0.5 | AI26: =Gael!D26 -> 0.7 | AJ26: =Bruce!D26 -> 0.9
A27: 26 | B27: The case against David McBride will be dropped | C27: Law | D27: Jac | F27: 0 | J27: =IF($F27=1,(LOG(X27,2)+1),IF($F27=0,(LOG(1-X27,2)+1),"")) -> 0.76553475 | K27: =IF($F27=1,(LOG(Y27,2)+1),IF($F27=0,(LOG(1-Y27,2)+1),"")) -> 1 | L27: =IF($F27=1,(LOG(Z27,2)+1),IF($F27=0,(LOG(1-Z27,2)+1),"")) -> 0.48542683 | M27: =IF($F27=1,(LOG(AA27,2)+1),IF($F27=0,(LOG(1-AA27,2)+1),"")) -> 0.26303441 | N27: =IF($F27=1,(LOG(AB27,2)+1),IF($F27=0,(LOG(1-AB27,2)+1),"")) -> -0.32192809 | O27: =IF($F27=1,(LOG(AC27,2)+1),IF($F27=0,(LOG(1-AC27,2)+1),"")) -> 0.084064265 | P27: =IF($F27=1,(LOG(AD27,2)+1),IF($F27=0,(LOG(1-AD27,2)+1),"")) -> -1.3219281 | Q27: =IF($F27=1,(LOG(AE27,2)+1),IF($F27=0,(LOG(1-AE27,2)+1),"")) -> 0 | ... V27: =IF($F27=1,(LOG(AJ27,2)+1),IF($F27=0,(LOG(1-AJ27,2)+1),"")) -> 0.48542683 | X27: =Andrew!D27 -> 0.15 | Y27: =ChatGPT!D27 | Z27: =Eileen!D27 -> 0.3 | AA27: =Iain!D27 -> 0.4 | AB27: =Kate!D27 -> 0.6 | AC27: =Rohan!D27 -> 0.47 | AD27: =Pete!D27 -> 0.8 | AE27: =Christine!D27 -> 0.5 | AF27: =Jac!D27 -> 0.1 | AG27: =James!D27 -> 0.4 | AH27: =Lachy!D27 -> 0.2 | AI27: =Gael!D27 -> 0.8 | AJ27: =Bruce!D27 -> 0.3
A28: 27 | B28: In FY19, there were 58 class actions filed. In FY20, there were 55 class actions filed. In FY21, there were 64 class actions filed. In FY22, there were 54 class actions filed. In FY23, there will be more than 64 class actions filed. (In the first 9 months of CY22, there were 25 class action filings.) | C28: Law | D28: Christine | F28: 0 | J28: =IF($F28=1,(LOG(X28,2)+1),IF($F28=0,(LOG(1-X28,2)+1),"")) -> 0.13750352 | K28: =IF($F28=1,(LOG(Y28,2)+1),IF($F28=0,(LOG(1-Y28,2)+1),"")) -> 1 | L28: =IF($F28=1,(LOG(Z28,2)+1),IF($F28=0,(LOG(1-Z28,2)+1),"")) -> 0.13750352 | M28: =IF($F28=1,(LOG(AA28,2)+1),IF($F28=0,(LOG(1-AA28,2)+1),"")) -> -0.32192809 | N28: =IF($F28=1,(LOG(AB28,2)+1),IF($F28=0,(LOG(1-AB28,2)+1),"")) -> 0.48542683 | O28: =IF($F28=1,(LOG(AC28,2)+1),IF($F28=0,(LOG(1-AC28,2)+1),"")) -> 0.26303441 | P28: =IF($F28=1,(LOG(AD28,2)+1),IF($F28=0,(LOG(1-AD28,2)+1),"")) -> 0 | Q28: =IF($F28=1,(LOG(AE28,2)+1),IF($F28=0,(LOG(1-AE28,2)+1),"")) -> -0.73696559 | ... V28: =IF($F28=1,(LOG(AJ28,2)+1),IF($F28=0,(LOG(1-AJ28,2)+1),"")) -> 0.26303441 | X28: =Andrew!D28 -> 0.45 | Y28: =ChatGPT!D28 | Z28: =Eileen!D28 -> 0.45 | AA28: =Iain!D28 -> 0.6 | AB28: =Kate!D28 -> 0.3 | AC28: =Rohan!D28 -> 0.4 | AD28: =Pete!D28 -> 0.5 | AE28: =Christine!D28 -> 0.7 | AF28: =Jac!D28 -> 0.55 | AG28: =James!D28 -> 0.6 | AH28: =Lachy!D28 -> 0.6 | AI28: =Gael!D28 -> 0.8 | AJ28: =Bruce!D28 -> 0.4
A29: 28 | B29: The New Zealand National party will form government after the next election. | C29: Politics | D29: Gael | F29: 1 | J29: =IF($F29=1,(LOG(X29,2)+1),IF($F29=0,(LOG(1-X29,2)+1),"")) -> -0.51457317 | K29: =IF($F29=1,(LOG(Y29,2)+1),IF($F29=0,(LOG(1-Y29,2)+1),"")) -> #NUM! | L29: =IF($F29=1,(LOG(Z29,2)+1),IF($F29=0,(LOG(1-Z29,2)+1),"")) -> -0.15200309 | M29: =IF($F29=1,(LOG(AA29,2)+1),IF($F29=0,(LOG(1-AA29,2)+1),"")) -> 0.26303441 | N29: =IF($F29=1,(LOG(AB29,2)+1),IF($F29=0,(LOG(1-AB29,2)+1),"")) -> -0.73696559 | O29: =IF($F29=1,(LOG(AC29,2)+1),IF($F29=0,(LOG(1-AC29,2)+1),"")) -> -5.6438562 | P29: =IF($F29=1,(LOG(AD29,2)+1),IF($F29=0,(LOG(1-AD29,2)+1),"")) -> -3.3219281 | Q29: =IF($F29=1,(LOG(AE29,2)+1),IF($F29=0,(LOG(1-AE29,2)+1),"")) -> 0 | ... V29: =IF($F29=1,(LOG(AJ29,2)+1),IF($F29=0,(LOG(1-AJ29,2)+1),"")) -> 0.48542683 | X29: =Andrew!D29 -> 0.35 | Y29: =ChatGPT!D29 | Z29: =Eileen!D29 -> 0.45 | AA29: =Iain!D29 -> 0.6 | AB29: =Kate!D29 -> 0.3 | AC29: =Rohan!D29 -> 0.01 | AD29: =Pete!D29 -> 0.05 | AE29: =Christine!D29 -> 0.5 | AF29: =Jac!D29 -> 0.2 | AG29: =James!D29 -> 0.5 | AH29: =Lachy!D29 -> 0.7 | AI29: =Gael!D29 -> 0.8 | AJ29: =Bruce!D29 -> 0.7
A30: 29 | B30: The British Labour Party will be ahead in the polls in November 2023. | C30: Politics | D30: Gael | E30: Which polls in particular? | F30: 1 | J30: =IF($F30=1,(LOG(X30,2)+1),IF($F30=0,(LOG(1-X30,2)+1),"")) -> 0.48542683 | K30: =IF($F30=1,(LOG(Y30,2)+1),IF($F30=0,(LOG(1-Y30,2)+1),"")) -> #NUM! | L30: =IF($F30=1,(LOG(Z30,2)+1),IF($F30=0,(LOG(1-Z30,2)+1),"")) -> 0.48542683 | M30: =IF($F30=1,(LOG(AA30,2)+1),IF($F30=0,(LOG(1-AA30,2)+1),"")) -> 0.26303441 | N30: =IF($F30=1,(LOG(AB30,2)+1),IF($F30=0,(LOG(1-AB30,2)+1),"")) -> 0.48542683 | O30: =IF($F30=1,(LOG(AC30,2)+1),IF($F30=0,(LOG(1-AC30,2)+1),"")) -> 0.13750352 | P30: =IF($F30=1,(LOG(AD30,2)+1),IF($F30=0,(LOG(1-AD30,2)+1),"")) -> 0.48542683 | Q30: =IF($F30=1,(LOG(AE30,2)+1),IF($F30=0,(LOG(1-AE30,2)+1),"")) -> 0 | ... V30: =IF($F30=1,(LOG(AJ30,2)+1),IF($F30=0,(LOG(1-AJ30,2)+1),"")) -> 0.67807191 | X30: =Andrew!D30 -> 0.7 | Y30: =ChatGPT!D30 | Z30: =Eileen!D30 -> 0.7 | AA30: =Iain!D30 -> 0.6 | AB30: =Kate!D30 -> 0.7 | AC30: =Rohan!D30 -> 0.55 | AD30: =Pete!D30 -> 0.7 | AE30: =Christine!D30 -> 0.5 | AF30: =Jac!D30 -> 0.65 | AG30: =James!D30 -> 0.5 | AH30: =Lachy!D30 -> 0.3 | AI30: =Gael!D30 -> 0.9 | AJ30: =Bruce!D30 -> 0.8
A31: 30 | B31: Liz Cheney will not nominate for the presidency in 2023. | C31: Politics | D31: Gael | F31: 1 | J31: =IF($F31=1,(LOG(X31,2)+1),IF($F31=0,(LOG(1-X31,2)+1),"")) -> 0.13750352 | K31: =IF($F31=1,(LOG(Y31,2)+1),IF($F31=0,(LOG(1-Y31,2)+1),"")) -> #NUM! | L31: =IF($F31=1,(LOG(Z31,2)+1),IF($F31=0,(LOG(1-Z31,2)+1),"")) -> -0.15200309 | M31: =IF($F31=1,(LOG(AA31,2)+1),IF($F31=0,(LOG(1-AA31,2)+1),"")) -> 0.26303441 | N31: =IF($F31=1,(LOG(AB31,2)+1),IF($F31=0,(LOG(1-AB31,2)+1),"")) -> 0.67807191 | O31: =IF($F31=1,(LOG(AC31,2)+1),IF($F31=0,(LOG(1-AC31,2)+1),"")) -> -0.32192809 | P31: =IF($F31=1,(LOG(AD31,2)+1),IF($F31=0,(LOG(1-AD31,2)+1),"")) -> -0.73696559 | Q31: =IF($F31=1,(LOG(AE31,2)+1),IF($F31=0,(LOG(1-AE31,2)+1),"")) -> 0 | ... V31: =IF($F31=1,(LOG(AJ31,2)+1),IF($F31=0,(LOG(1-AJ31,2)+1),"")) -> 0.67807191 | X31: =Andrew!D31 -> 0.55 | Y31: =ChatGPT!D31 | Z31: =Eileen!D31 -> 0.45 | AA31: =Iain!D31 -> 0.6 | AB31: =Kate!D31 -> 0.8 | AC31: =Rohan!D31 -> 0.4 | AD31: =Pete!D31 -> 0.3 | AE31: =Christine!D31 -> 0.5 | AF31: =Jac!D31 -> 0.65 | AG31: =James!D31 -> 0.6 | AH31: =Lachy!D31 -> 0.8 | AI31: =Gael!D31 -> 0.9 | AJ31: =Bruce!D31 -> 0.8
A32: 31 | B32: China will eliminate at least one existing trade sanction against Australia | C32: Politics | D32: Bruce | F32: 1 | G32: 45065 | J32: =IF($F32=1,(LOG(X32,2)+1),IF($F32=0,(LOG(1-X32,2)+1),"")) -> -0.32192809 | K32: =IF($F32=1,(LOG(Y32,2)+1),IF($F32=0,(LOG(1-Y32,2)+1),"")) -> #NUM! | L32: =IF($F32=1,(LOG(Z32,2)+1),IF($F32=0,(LOG(1-Z32,2)+1),"")) -> -1.3219281 | M32: =IF($F32=1,(LOG(AA32,2)+1),IF($F32=0,(LOG(1-AA32,2)+1),"")) -> 0.48542683 | N32: =IF($F32=1,(LOG(AB32,2)+1),IF($F32=0,(LOG(1-AB32,2)+1),"")) -> 0.26303441 | O32: =IF($F32=1,(LOG(AC32,2)+1),IF($F32=0,(LOG(1-AC32,2)+1),"")) -> 0 | P32: =IF($F32=1,(LOG(AD32,2)+1),IF($F32=0,(LOG(1-AD32,2)+1),"")) -> 0.26303441 | Q32: =IF($F32=1,(LOG(AE32,2)+1),IF($F32=0,(LOG(1-AE32,2)+1),"")) -> 0 | ... V32: =IF($F32=1,(LOG(AJ32,2)+1),IF($F32=0,(LOG(1-AJ32,2)+1),"")) -> 0.84799691 | X32: =Andrew!D32 -> 0.4 | Y32: =ChatGPT!D32 | Z32: =Eileen!D32 -> 0.2 | AA32: =Iain!D32 -> 0.7 | AB32: =Kate!D32 -> 0.6 | AC32: =Rohan!D32 -> 0.5 | AD32: =Pete!D32 -> 0.6 | AE32: =Christine!D32 -> 0.5 | AF32: =Jac!D32 -> 0.2 | AG32: =James!D32 -> 0.5 | AH32: =Lachy!D32 -> 0.4 | AI32: =Gael!D32 -> 0.9 | AJ32: =Bruce!D32 -> 0.9
A33: 32 | B33: China will not be admitted to full membership of the Comprehensive and Progressive Agreement for Trans-Pacific Partnership | C33: Politics | D33: Bruce | F33: 1 | J33: =IF($F33=1,(LOG(X33,2)+1),IF($F33=0,(LOG(1-X33,2)+1),"")) -> 0.26303441 | K33: =IF($F33=1,(LOG(Y33,2)+1),IF($F33=0,(LOG(1-Y33,2)+1),"")) -> #NUM! | L33: =IF($F33=1,(LOG(Z33,2)+1),IF($F33=0,(LOG(1-Z33,2)+1),"")) -> -0.32192809 | M33: =IF($F33=1,(LOG(AA33,2)+1),IF($F33=0,(LOG(1-AA33,2)+1),"")) -> 0 | N33: =IF($F33=1,(LOG(AB33,2)+1),IF($F33=0,(LOG(1-AB33,2)+1),"")) -> 0.67807191 | O33: =IF($F33=1,(LOG(AC33,2)+1),IF($F33=0,(LOG(1-AC33,2)+1),"")) -> -0.029146346 | P33: =IF($F33=1,(LOG(AD33,2)+1),IF($F33=0,(LOG(1-AD33,2)+1),"")) -> -0.32192809 | Q33: =IF($F33=1,(LOG(AE33,2)+1),IF($F33=0,(LOG(1-AE33,2)+1),"")) -> 0.48542683 | ... V33: =IF($F33=1,(LOG(AJ33,2)+1),IF($F33=0,(LOG(1-AJ33,2)+1),"")) -> 0.92599942 | X33: =Andrew!D33 -> 0.6 | Y33: =ChatGPT!D33 | Z33: =Eileen!D33 -> 0.4 | AA33: =Iain!D33 -> 0.5 | AB33: =Kate!D33 -> 0.8 | AC33: =Rohan!D33 -> 0.49 | AD33: =Pete!D33 -> 0.4 | AE33: =Christine!D33 -> 0.7 | AF33: =Jac!D33 -> 0.7 | AG33: =James!D33 -> 0.7 | AH33: =Lachy!D33 -> 0.8 | AI33: =Gael!D33 -> 0.4 | AJ33: =Bruce!D33 -> 0.95
A34: 33 | B34: Henry Kissinger will die | C34: Politics | D34: Kate | F34: 1 | J34: =IF($F34=1,(LOG(X34,2)+1),IF($F34=0,(LOG(1-X34,2)+1),"")) -> -0.59946207 | K34: =IF($F34=1,(LOG(Y34,2)+1),IF($F34=0,(LOG(1-Y34,2)+1),"")) -> #NUM! | L34: =IF($F34=1,(LOG(Z34,2)+1),IF($F34=0,(LOG(1-Z34,2)+1),"")) -> -0.73696559 | M34: =IF($F34=1,(LOG(AA34,2)+1),IF($F34=0,(LOG(1-AA34,2)+1),"")) -> -0.73696559 | N34: =IF($F34=1,(LOG(AB34,2)+1),IF($F34=0,(LOG(1-AB34,2)+1),"")) -> 0.84799691 | O34: =IF($F34=1,(LOG(AC34,2)+1),IF($F34=0,(LOG(1-AC34,2)+1),"")) -> 0.26303441 | P34: =IF($F34=1,(LOG(AD34,2)+1),IF($F34=0,(LOG(1-AD34,2)+1),"")) -> 0.48542683 | Q34: =IF($F34=1,(LOG(AE34,2)+1),IF($F34=0,(LOG(1-AE34,2)+1),"")) -> 0.48542683 | ... V34: =IF($F34=1,(LOG(AJ34,2)+1),IF($F34=0,(LOG(1-AJ34,2)+1),"")) -> 0.48542683 | X34: =Andrew!D34 -> 0.33 | Y34: =ChatGPT!D34 | Z34: =Eileen!D34 -> 0.3 | AA34: =Iain!D34 -> 0.3 | AB34: =Kate!D34 -> 0.9 | AC34: =Rohan!D34 -> 0.6 | AD34: =Pete!D34 -> 0.7 | AE34: =Christine!D34 -> 0.7 | AF34: =Jac!D34 -> 0.5 | AG34: =James!D34 -> 0.6 | AH34: =Lachy!D34 -> 0.5 | AI34: =Gael!D34 -> 0.9 | AJ34: =Bruce!D34 -> 0.7
A35: 34 | B35: The Australian government will announce that the referendum for the Indigenous Voice to Parliament will occur in 2024 | C35: Politics | D35: Kate | F35: 0 | J35: =IF($F35=1,(LOG(X35,2)+1),IF($F35=0,(LOG(1-X35,2)+1),"")) -> 0.67807191 | K35: =IF($F35=1,(LOG(Y35,2)+1),IF($F35=0,(LOG(1-Y35,2)+1),"")) -> 1 | L35: =IF($F35=1,(LOG(Z35,2)+1),IF($F35=0,(LOG(1-Z35,2)+1),"")) -> 0.13750352 | M35: =IF($F35=1,(LOG(AA35,2)+1),IF($F35=0,(LOG(1-AA35,2)+1),"")) -> 0.67807191 | N35: =IF($F35=1,(LOG(AB35,2)+1),IF($F35=0,(LOG(1-AB35,2)+1),"")) -> -2.3219281 | O35: =IF($F35=1,(LOG(AC35,2)+1),IF($F35=0,(LOG(1-AC35,2)+1),"")) -> 0.028569152 | P35: =IF($F35=1,(LOG(AD35,2)+1),IF($F35=0,(LOG(1-AD35,2)+1),"")) -> -1.3219281 | Q35: =IF($F35=1,(LOG(AE35,2)+1),IF($F35=0,(LOG(1-AE35,2)+1),"")) -> -0.73696559 | ... V35: =IF($F35=1,(LOG(AJ35,2)+1),IF($F35=0,(LOG(1-AJ35,2)+1),"")) -> 0.48542683 | X35: =Andrew!D35 -> 0.2 | Y35: =ChatGPT!D35 | Z35: =Eileen!D35 -> 0.45 | AA35: =Iain!D35 -> 0.2 | AB35: =Kate!D35 -> 0.9 | AC35: =Rohan!D35 -> 0.49 | AD35: =Pete!D35 -> 0.8 | AE35: =Christine!D35 -> 0.7 | AF35: =Jac!D35 -> 0.15 | AG35: =James!D35 -> 0.7 | AH35: =Lachy!D35 -> 0.7 | AI35: =Gael!D35 -> 0.8 | AJ35: =Bruce!D35 -> 0.3
A36: 35 | B36: Labor will win the NSW state election | C36: Politics | D36: Jac | F36: 1 | J36: =IF($F36=1,(LOG(X36,2)+1),IF($F36=0,(LOG(1-X36,2)+1),"")) -> 0.13750352 | K36: =IF($F36=1,(LOG(Y36,2)+1),IF($F36=0,(LOG(1-Y36,2)+1),"")) -> #NUM! | L36: =IF($F36=1,(LOG(Z36,2)+1),IF($F36=0,(LOG(1-Z36,2)+1),"")) -> -0.15200309 | M36: =IF($F36=1,(LOG(AA36,2)+1),IF($F36=0,(LOG(1-AA36,2)+1),"")) -> -0.32192809 | N36: =IF($F36=1,(LOG(AB36,2)+1),IF($F36=0,(LOG(1-AB36,2)+1),"")) -> -0.32192809 | O36: =IF($F36=1,(LOG(AC36,2)+1),IF($F36=0,(LOG(1-AC36,2)+1),"")) -> 0.13750352 | P36: =IF($F36=1,(LOG(AD36,2)+1),IF($F36=0,(LOG(1-AD36,2)+1),"")) -> 0.67807191 | Q36: =IF($F36=1,(LOG(AE36,2)+1),IF($F36=0,(LOG(1-AE36,2)+1),"")) -> 0.48542683 | ... V36: =IF($F36=1,(LOG(AJ36,2)+1),IF($F36=0,(LOG(1-AJ36,2)+1),"")) -> 0.48542683 | X36: =Andrew!D36 -> 0.55 | Y36: =ChatGPT!D36 | Z36: =Eileen!D36 -> 0.45 | AA36: =Iain!D36 -> 0.4 | AB36: =Kate!D36 -> 0.4 | AC36: =Rohan!D36 -> 0.55 | AD36: =Pete!D36 -> 0.8 | AE36: =Christine!D36 -> 0.7 | AF36: =Jac!D36 -> 0.5 | AG36: =James!D36 -> 0.5 | AH36: =Lachy!D36 -> 0.7 | AI36: =Gael!D36 -> 0.6 | AJ36: =Bruce!D36 -> 0.7
A37: 36 | B37: There will be international concerns about the validity of the results of the Myanmar general election e.g. being a 'fair election', counting irregularities (as reported in The Guardian or wikipedia) | C37: Politics | D37: Jac | F37: 0 | J37: =IF($F37=1,(LOG(X37,2)+1),IF($F37=0,(LOG(1-X37,2)+1),"")) -> -0.32192809 | K37: =IF($F37=1,(LOG(Y37,2)+1),IF($F37=0,(LOG(1-Y37,2)+1),"")) -> 1 | L37: =IF($F37=1,(LOG(Z37,2)+1),IF($F37=0,(LOG(1-Z37,2)+1),"")) -> -0.73696559 | M37: =IF($F37=1,(LOG(AA37,2)+1),IF($F37=0,(LOG(1-AA37,2)+1),"")) -> -0.32192809 | N37: =IF($F37=1,(LOG(AB37,2)+1),IF($F37=0,(LOG(1-AB37,2)+1),"")) -> -1.3219281 | O37: =IF($F37=1,(LOG(AC37,2)+1),IF($F37=0,(LOG(1-AC37,2)+1),"")) -> 0.028569152 | P37: =IF($F37=1,(LOG(AD37,2)+1),IF($F37=0,(LOG(1-AD37,2)+1),"")) -> -0.73696559 | Q37: =IF($F37=1,(LOG(AE37,2)+1),IF($F37=0,(LOG(1-AE37,2)+1),"")) -> -0.73696559 | ... V37: =IF($F37=1,(LOG(AJ37,2)+1),IF($F37=0,(LOG(1-AJ37,2)+1),"")) -> -2.3219281 | X37: =Andrew!D37 -> 0.6 | Y37: =ChatGPT!D37 | Z37: =Eileen!D37 -> 0.7 | AA37: =Iain!D37 -> 0.6 | AB37: =Kate!D37 -> 0.8 | AC37: =Rohan!D37 -> 0.49 | AD37: =Pete!D37 -> 0.7 | AE37: =Christine!D37 -> 0.7 | AF37: =Jac!D37 -> 0.5 | AG37: =James!D37 -> 0.8 | AH37: =Lachy!D37 -> 0.9 | AI37: =Gael!D37 -> 0.9 | AJ37: =Bruce!D37 -> 0.9
A38: 37 | B38: At least one senior public servant (Deputy Secretary or above) will face disciplinary action from the Robodebt royal commission | C38: Politics | D38: Jac | F38: 1 | G38: 45127 | H38: https://www.theguardian.com/australia-news/2023/jul/20/senior-public-servant-kathryn-campbell-suspended-without-pay-after-robodebt-findings?CMP=Share_iOSApp_Other | J38: =IF($F38=1,(LOG(X38,2)+1),IF($F38=0,(LOG(1-X38,2)+1),"")) -> -0.15200309 | K38: =IF($F38=1,(LOG(Y38,2)+1),IF($F38=0,(LOG(1-Y38,2)+1),"")) -> #NUM! | L38: =IF($F38=1,(LOG(Z38,2)+1),IF($F38=0,(LOG(1-Z38,2)+1),"")) -> -0.32192809 | M38: =IF($F38=1,(LOG(AA38,2)+1),IF($F38=0,(LOG(1-AA38,2)+1),"")) -> 0.26303441 | N38: =IF($F38=1,(LOG(AB38,2)+1),IF($F38=0,(LOG(1-AB38,2)+1),"")) -> 0.26303441 | O38: =IF($F38=1,(LOG(AC38,2)+1),IF($F38=0,(LOG(1-AC38,2)+1),"")) -> 0.13750352 | P38: =IF($F38=1,(LOG(AD38,2)+1),IF($F38=0,(LOG(1-AD38,2)+1),"")) -> 0.67807191 | Q38: =IF($F38=1,(LOG(AE38,2)+1),IF($F38=0,(LOG(1-AE38,2)+1),"")) -> 0.48542683 | ... V38: =IF($F38=1,(LOG(AJ38,2)+1),IF($F38=0,(LOG(1-AJ38,2)+1),"")) -> 0.26303441 | X38: =Andrew!D38 -> 0.45 | Y38: =ChatGPT!D38 | Z38: =Eileen!D38 -> 0.4 | AA38: =Iain!D38 -> 0.6 | AB38: =Kate!D38 -> 0.6 | AC38: =Rohan!D38 -> 0.55 | AD38: =Pete!D38 -> 0.8 | AE38: =Christine!D38 -> 0.7 | AF38: =Jac!D38 -> 0.35 | AG38: =James!D38 -> 0.6 | AH38: =Lachy!D38 -> 0.9 | AI38: =Gael!D38 -> 0.9 | AJ38: =Bruce!D38 -> 0.6
A39: 38 | B39: China invades Taiwan | C39: Politics | D39: James | F39: 0 | J39: =IF($F39=1,(LOG(X39,2)+1),IF($F39=0,(LOG(1-X39,2)+1),"")) -> 0.84799691 | K39: =IF($F39=1,(LOG(Y39,2)+1),IF($F39=0,(LOG(1-Y39,2)+1),"")) -> 1 | L39: =IF($F39=1,(LOG(Z39,2)+1),IF($F39=0,(LOG(1-Z39,2)+1),"")) -> 0.48542683 | M39: =IF($F39=1,(LOG(AA39,2)+1),IF($F39=0,(LOG(1-AA39,2)+1),"")) -> 0.67807191 | N39: =IF($F39=1,(LOG(AB39,2)+1),IF($F39=0,(LOG(1-AB39,2)+1),"")) -> 0.67807191 | O39: =IF($F39=1,(LOG(AC39,2)+1),IF($F39=0,(LOG(1-AC39,2)+1),"")) -> 0.37851162 | P39: =IF($F39=1,(LOG(AD39,2)+1),IF($F39=0,(LOG(1-AD39,2)+1),"")) -> 0.26303441 | Q39: =IF($F39=1,(LOG(AE39,2)+1),IF($F39=0,(LOG(1-AE39,2)+1),"")) -> 0.67807191 | ... V39: =IF($F39=1,(LOG(AJ39,2)+1),IF($F39=0,(LOG(1-AJ39,2)+1),"")) -> 0.67807191 | X39: =Andrew!D39 -> 0.1 | Y39: =ChatGPT!D39 | Z39: =Eileen!D39 -> 0.3 | AA39: =Iain!D39 -> 0.2 | AB39: =Kate!D39 -> 0.2 | AC39: =Rohan!D39 -> 0.35 | AD39: =Pete!D39 -> 0.4 | AE39: =Christine!D39 -> 0.2 | AF39: =Jac!D39 -> 0.01 | AG39: =James!D39 -> 0.6 | AH39: =Lachy!D39 -> 0.01 | AI39: =Gael!D39 -> 0.2 | AJ39: =Bruce!D39 -> 0.2
A40: 39 | B40: The war in Ukraine will be declared over over by MSM | C40: Politics | D40: Andrew | F40: 0 | J40: =IF($F40=1,(LOG(X40,2)+1),IF($F40=0,(LOG(1-X40,2)+1),"")) -> 0.67807191 | K40: =IF($F40=1,(LOG(Y40,2)+1),IF($F40=0,(LOG(1-Y40,2)+1),"")) -> 1 | L40: =IF($F40=1,(LOG(Z40,2)+1),IF($F40=0,(LOG(1-Z40,2)+1),"")) -> 0.48542683 | M40: =IF($F40=1,(LOG(AA40,2)+1),IF($F40=0,(LOG(1-AA40,2)+1),"")) -> 0.26303441 | N40: =IF($F40=1,(LOG(AB40,2)+1),IF($F40=0,(LOG(1-AB40,2)+1),"")) -> 0.67807191 | O40: =IF($F40=1,(LOG(AC40,2)+1),IF($F40=0,(LOG(1-AC40,2)+1),"")) -> 0.84799691 | P40: =IF($F40=1,(LOG(AD40,2)+1),IF($F40=0,(LOG(1-AD40,2)+1),"")) -> 0 | Q40: =IF($F40=1,(LOG(AE40,2)+1),IF($F40=0,(LOG(1-AE40,2)+1),"")) -> -0.73696559 | ... V40: =IF($F40=1,(LOG(AJ40,2)+1),IF($F40=0,(LOG(1-AJ40,2)+1),"")) -> 0.84799691 | X40: =Andrew!D40 -> 0.2 | Y40: =ChatGPT!D40 | Z40: =Eileen!D40 -> 0.3 | AA40: =Iain!D40 -> 0.4 | AB40: =Kate!D40 -> 0.2 | AC40: =Rohan!D40 -> 0.1 | AD40: =Pete!D40 -> 0.5 | AE40: =Christine!D40 -> 0.7 | AF40: =Jac!D40 -> 0.35 | AG40: =James!D40 -> 0.3 | AH40: =Lachy!D40 -> 0.3 | AI40: =Gael!D40 -> 0.7 | AJ40: =Bruce!D40 -> 0.1
...

Sheet Andrew
A1: ID | B1: Prediction | C1: Category | D1: Probability
A2: =Input!A2 -> 1 | B2: =Input!B2 -> Cate Blanchett will win best actress in the Academy Awards. | C2: =Input!C2 -> Entertainment | D2: 0.3
A3: =Input!A3 -> 2 | B3: =Input!B3 -> The farthest paper airplane flight will be broken (as reported by Guinness World Records) | C3: =Input!C3 -> Entertainment | D3: 0.8
A4: =Input!A4 -> 3 | B4: =Input!B4 -> Meghan and/or harry will post on social media content relating to the Coronation of King Charles III that, states or implies that Queen Elizabeth 2 'would have wanted them / is looking down from heaven wanting them' at the coronation, and/or describes a counter-ceremony with dubious historical precident performed by harry, meghan or their children to mark the occasion, and/or indicates that their presence at the coronation was prevented by 'deep palace' operatives or similar. | C4: =Input!C4 -> Entertainment | D4: 0.45
A5: =Input!A5 -> 4 | B5: =Input!B5 -> There will be a scandal involving the BTS 10 year anniversary as reported by Korean MSM | C5: =Input!C5 -> Entertainment | D5: 0.3
A6: =Input!A6 -> 5 | B6: =Input!B6 -> Twosetviolin (the Youtube channel) will make a video reporting fresh abuse from kpop fans (excluding Blackpink) | C6: =Input!C6 -> Entertainment | D6: 0.6
A7: =Input!A7 -> 6 | B7: =Input!B7 -> Lee Min-ho will be the most followed Korean actor on Instagram by the end of 2023 | C7: =Input!C7 -> Entertainment | D7: 0.7
A8: =Input!A8 -> 7 | B8: =Input!B8 -> LOONA will disband | C8: =Input!C8 -> Entertainment | D8: 0.55
A9: =Input!A9 -> 8 | B9: =Input!B9 -> A new Korean show will get more than 140 million household views on Netflix | C9: =Input!C9 -> Entertainment | D9: 0.4
A10: =Input!A10 -> 9 | B10: =Input!B10 -> Avatar The Way of Water will remain at 8.0 on IMDb by Christmas next year. | C10: =Input!C10 -> Entertainment | D10: 0.15
A11: =Input!A11 -> 10 | B11: =Input!B11 -> Kanye West will have 0 twitter suspensions or bans. | C11: =Input!C11 -> Entertainment | D11: 0.05
A12: =Input!A12 -> 11 | B12: =Input!B12 -> At either the Grammys, the Oscars, the Emmys or the game awards there will be a significant interruption comparable to the Will Smith Chris Rock slap or the game awards Bill Clinton kid. | C12: =Input!C12 -> Entertainment | D12: 0.7
A13: =Input!A13 -> 12 | B13: =Input!B13 -> Francis will be the Pope on Christmas eve | C13: =Input!C13 -> Entertainment | D13: 0.6
... A61: =Input!A61 -> 60 | B61: =Input!B61 -> A country enshrines some form of rights/personhood/protection of AI systems motivated by the welfare of the system itself | C61: =Input!C61 -> Technology | D61: 0.25
A62: =Input!A62 | B62: =Input!B62 | C62: =Input!C62
A63: =Input!A63 | B63: =Input!B63 | C63: =Input!C63
A64: =Input!A64 | B64: =Input!B64 | C64: =Input!C64
A65: =Input!A65 | B65: =Input!B65 | C65: =Input!C65
A66: =Input!A66 | B66: =Input!B66 | C66: =Input!C66
A67: =Input!A67 | B67: =Input!B67 | C67: =Input!C67
A68: =Input!A68 | B68: =Input!B68 -> Top score | C68: =Input!C68
A69: =Input!A69 | B69: =Input!B69 -> Bottom score | C69: =Input!C69
A70: =Input!A70 | B70: =Input!B70 -> Avg +ve | C70: =Input!C70
A71: =Input!A67 | B71: =Input!B67 | C71: =Input!C67
A72: =Input!A68 | B72: =Input!B68 -> Top score | C72: =Input!C68
A73: =Input!A69 | B73: =Input!B69 -> Bottom score | C73: =Input!C69
A74: =Input!A70 | B74: =Input!B70 -> Avg +ve | C74: =Input!C70
A75: =Input!A71 | B75: =Input!B71 -> Avg -ve | C75: =Input!C71
A76: =Input!A72 | B76: =Input!B72 -> avg mag. | C76: =Input!C72
A77: =Input!A73 | B77: =Input!B73 | C77: =Input!C73
A78: =Input!A74 | B78: =Input!B74 | C78: =Input!C74
A79: =Input!A75 | B79: =Input!B75 | C79: =Input!C75
A80: =Input!A76 | B80: =Input!B76 | C80: =Input!C76
A81: =Input!A77 | B81: =Input!B77 | C81: =Input!C77
A82: =Input!A78 | B82: =Input!B78 | C82: =Input!C78
... A100: =Input!A96 | B100: =Input!B96 | C100: =Input!C96

Sheet ChatGPT
A1: ID | B1: Prediction | C1: Category | D1: Probability
A2: =Input!A2 -> 1 | B2: =Input!B2 -> Cate Blanchett will win best actress in the Academy Awards. | C2: =Input!C2 -> Entertainment | D2: 0.5
A3: =Input!A3 -> 2 | B3: =Input!B3 -> The farthest paper airplane flight will be broken (as reported by Guinness World Records) | C3: =Input!C3 -> Entertainment | D3: 0.5
A4: =Input!A4 -> 3 | B4: =Input!B4 -> Meghan and/or harry will post on social media content relating to the Coronation of King Charles III that, states or implies that Queen Elizabeth 2 'would have wanted them / is looking down from heaven wanting them' at the coronation, and/or describes a counter-ceremony with dubious historical precident performed by harry, meghan or their children to mark the occasion, and/or indicates that their presence at the coronation was prevented by 'deep palace' operatives or similar. | C4: =Input!C4 -> Entertainment | D4: 0.5
A5: =Input!A5 -> 4 | B5: =Input!B5 -> There will be a scandal involving the BTS 10 year anniversary as reported by Korean MSM | C5: =Input!C5 -> Entertainment
A6: =Input!A6 -> 5 | B6: =Input!B6 -> Twosetviolin (the Youtube channel) will make a video reporting fresh abuse from kpop fans (excluding Blackpink) | C6: =Input!C6 -> Entertainment
A7: =Input!A7 -> 6 | B7: =Input!B7 -> Lee Min-ho will be the most followed Korean actor on Instagram by the end of 2023 | C7: =Input!C7 -> Entertainment
A8: =Input!A8 -> 7 | B8: =Input!B8 -> LOONA will disband | C8: =Input!C8 -> Entertainment
A9: =Input!A9 -> 8 | B9: =Input!B9 -> A new Korean show will get more than 140 million household views on Netflix | C9: =Input!C9 -> Entertainment
A10: =Input!A10 -> 9 | B10: =Input!B10 -> Avatar The Way of Water will remain at 8.0 on IMDb by Christmas next year. | C10: =Input!C10 -> Entertainment
A11: =Input!A11 -> 10 | B11: =Input!B11 -> Kanye West will have 0 twitter suspensions or bans. | C11: =Input!C11 -> Entertainment
A12: =Input!A12 -> 11 | B12: =Input!B12 -> At either the Grammys, the Oscars, the Emmys or the game awards there will be a significant interruption comparable to the Will Smith Chris Rock slap or the game awards Bill Clinton kid. | C12: =Input!C12 -> Entertainment
A13: =Input!A13 -> 12 | B13: =Input!B13 -> Francis will be the Pope on Christmas eve | C13: =Input!C13 -> Entertainment
A14: =Input!A14 -> 13 | B14: =Input!W1 | C14: =Input!C14 -> Family
A15: =Input!A15 -> 14 | B15: =Input!B15 -> Baby McCalman is less than 49cm at birth | C15: =Input!C15 -> Family
A16: =Input!A16 -> 15 | B16: =Input!B16 -> Jac and Lachy’s baby will say ‘ma’ or make a similar ‘m’ sound by 24 December 2023. | C16: =Input!C16 -> Family
A17: =Input!A17 -> 16 | B17: =Input!B17 -> Rohan will be at least 6'1" | C17: =Input!C17 -> Family | D17: 0.1
A18: =Input!A18 -> 17 | B18: =Input!B18 -> Andrew and Eileen will buy a house | C18: =Input!C18 -> Family
A19: =Input!A19 -> 18 | B19: =Input!B19 -> Lachy and Jac’s baby will be at least 68 cm by next Christmas. | C19: =Input!C19 -> Family
A20: =Input!A20 -> 19 | B20: =Input!B20 -> The annual inflation rate in Australia will be below 6% when the RBA releases its announcement of the October 2023 result | C20: =Input!C20 -> Finance
A21: =Input!A21 -> 20 | B21: =Input!B21 -> AUD falls below USD0.64 | C21: =Input!C21 -> Finance
A22: =Input!A22 -> 21 | B22: =Input!B22 -> Pro-GOP investor makes a meaningful (>US$100m) investment in Twitter | C22: =Input!C22 -> Finance
A23: =Input!A23 -> 22 | B23: =#REF! -> #REF! | C23: =#REF! -> #REF!
A24: =Input!A24 -> 23 | B24: =Input!B24 -> Binance will collapse slash go into bankruptcy | C24: =Input!C23 -> Finance
A25: =Input!A25 -> 24 | B25: =Input!B25 -> Telsa will remain solvent and operating | C25: =Input!C25 -> Finance
A26: =Input!A26 -> 25 | B26: =Input!B23 -> The Australian unemployment rate will be more than 4% at time of judging | C26: =Input!C26 -> Law
A27: =Input!A27 -> 26 | B27: =Input!B27 -> The case against David McBride will be dropped | C27: =Input!C27 -> Law
A28: =Input!A28 -> 27 | B28: =Input!B28 -> In FY19, there were 58 class actions filed. In FY20, there were 55 class actions filed. In FY21, there were 64 class actions filed. In FY22, there were 54 class actions filed. In FY23, there will be more than 64 class actions filed. (In the first 9 months of CY22, there were 25 class action filings.) | C28: =Input!C28 -> Law
A29: =Input!A29 -> 28 | B29: =Input!B29 -> The New Zealand National party will form government after the next election. | C29: =Input!C29 -> Politics
A30: =Input!A30 -> 29 | B30: =Input!B30 -> The British Labour Party will be ahead in the polls in November 2023. | C30: =Input!C30 -> Politics
A31: =Input!A31 -> 30 | B31: =Input!B31 -> Liz Cheney will not nominate for the presidency in 2023. | C31: =Input!C31 -> Politics
A32: =Input!A32 -> 31 | B32: =Input!B32 -> China will eliminate at least one existing trade sanction against Australia | C32: =Input!C32 -> Politics
A33: =Input!A33 -> 32 | B33: =Input!S1 -> James | C33: =Input!C33 -> Politics
A34: =Input!A34 -> 33 | B34: =Input!B34 -> Henry Kissinger will die | C34: =Input!C34 -> Politics
A35: =Input!A35 -> 34 | B35: =#REF! -> #REF! | C35: =Input!C35 -> Politics
A36: =Input!A36 -> 35 | B36: =#REF! -> #REF! | C36: =Input!C36 -> Politics
A37: =#REF! -> #REF! | B37: =Input!B37 -> There will be international concerns about the validity of the results of the Myanmar general election e.g. being a 'fair election', counting irregularities (as reported in The Guardian or wikipedia) | C37: =Input!C37 -> Politics
A38: =#REF! -> #REF! | B38: =Input!B38 -> At least one senior public servant (Deputy Secretary or above) will face disciplinary action from the Robodebt royal commission | C38: =Input!C38 -> Politics
A39: =Input!A39 -> 38 | B39: =Input!B39 -> China invades Taiwan | C39: =Input!C39 -> Politics
A40: =Input!A40 -> 39 | B40: =Input!B40 -> The war in Ukraine will be declared over over by MSM | C40: =Input!C40 -> Politics
...

Sheet Eileen
A1: ID | B1: Prediction | C1: Category | D1: Probability
A2: =Input!A2 -> 1 | B2: =Input!B2 -> Cate Blanchett will win best actress in the Academy Awards. | C2: =Input!C2 -> Entertainment | D2: 0.4
A3: =Input!A3 -> 2 | B3: =Input!B3 -> The farthest paper airplane flight will be broken (as reported by Guinness World Records) | C3: =Input!C3 -> Entertainment | D3: 0.7
A4: =Input!A4 -> 3 | B4: =Input!B4 -> Meghan and/or harry will post on social media content relating to the Coronation of King Charles III that, states or implies that Queen Elizabeth 2 'would have wanted them / is looking down from heaven wanting them' at the coronation, and/or describes a counter-ceremony with dubious historical precident performed by harry, meghan or their children to mark the occasion, and/or indicates that their presence at the coronation was prevented by 'deep palace' operatives or similar. | C4: =Input!C4 -> Entertainment | D4: 0.4
A5: =Input!A5 -> 4 | B5: =Input!B5 -> There will be a scandal involving the BTS 10 year anniversary as reported by Korean MSM | C5: =Input!C5 -> Entertainment | D5: 0.4
A6: =Input!A6 -> 5 | B6: =Input!B6 -> Twosetviolin (the Youtube channel) will make a video reporting fresh abuse from kpop fans (excluding Blackpink) | C6: =Input!C6 -> Entertainment | D6: 0.8
A7: =Input!A7 -> 6 | B7: =Input!B7 -> Lee Min-ho will be the most followed Korean actor on Instagram by the end of 2023 | C7: =Input!C7 -> Entertainment | D7: 0.7
A8: =Input!A8 -> 7 | B8: =Input!B8 -> LOONA will disband | C8: =Input!C8 -> Entertainment | D8: 0.4
A9: =Input!A9 -> 8 | B9: =Input!B9 -> A new Korean show will get more than 140 million household views on Netflix | C9: =Input!C9 -> Entertainment | D9: 0.7
A10: =Input!A10 -> 9 | B10: =Input!B10 -> Avatar The Way of Water will remain at 8.0 on IMDb by Christmas next year. | C10: =Input!C10 -> Entertainment | D10: 0.3
A11: =Input!A11 -> 10 | B11: =Input!B11 -> Kanye West will have 0 twitter suspensions or bans. | C11: =Input!C11 -> Entertainment | D11: 0.2
A12: =Input!A12 -> 11 | B12: =Input!B12 -> At either the Grammys, the Oscars, the Emmys or the game awards there will be a significant interruption comparable to the Will Smith Chris Rock slap or the game awards Bill Clinton kid. | C12: =Input!C12 -> Entertainment | D12: 0.4
A13: =Input!A13 -> 12 | B13: =Input!B13 -> Francis will be the Pope on Christmas eve | C13: =Input!C13 -> Entertainment | D13: 0.2
... A23: =Input!A23 -> 22 | B23: =Input!B23 -> The Australian unemployment rate will be more than 4% at time of judging | C23: =Input!C23 -> Finance | D23: 0.35
A24: =Input!A24 -> 23 | B24: =Input!B24 -> Binance will collapse slash go into bankruptcy | C24: =Input!C23 -> Finance | D24: 0.6
A25: =Input!A25 -> 24 | B25: =Input!B25 -> Telsa will remain solvent and operating | C25: =Input!C25 -> Finance | D25: 0.8
A26: =Input!A26 -> 25 | B26: =Input!B26 -> At least three class action proceedings (or equivalent eg. aggregate litigation) will be filed around the world against Elon Musk or Tesla about the self-driving technology in Tesla cars | C26: =Input!C26 -> Law | D26: 0.4
A27: =Input!A27 -> 26 | B27: =Input!B27 -> The case against David McBride will be dropped | C27: =Input!C27 -> Law | D27: 0.3
