Workbook

Sheet Summary
A1: Predictions resolved | C1: =COUNTIF(Statements!E2:E61,0)+COUNTIF(Statements!E2:E61,1) -> 56
A2: Predictions to come | C2: =COUNTA(Statements!A2:A103)-C1 -> 4

Sheet Statements
A1: Number | B1: Prediction | C1: Author | D1: Category | E1: Outcome (1 = true, 0 = false) | F1: Andrew | G1: Eileen | H1: Iain | I1: Kate | J1: Rohan | K1: Pete | L1: Jac | M1: James | N1: Lachy | O1: Gael | P1: Bruce | Q1: Total | R1: Andrew | S1: Eileen | T1: Iain | U1: Kate | V1: Rohan | W1: Pete | X1: Jac | Y1: James | Z1: Lachy | AA1: Gael | AB1: Bruce
A2: 1 | B2: ”What was I made for?” (Billie Eilish) wins Best Music - Original Song at the Oscars | C2: Christine | D2: Entertainment | E2: - | F2: =IF($E2=1,(LOG(R2,2)+1),IF($E2=0,(LOG(1-R2,2)+1),"")) | G2: =IF($E2=1,(LOG(S2,2)+1),IF($E2=0,(LOG(1-S2,2)+1),"")) | H2: =IF($E2=1,(LOG(T2,2)+1),IF($E2=0,(LOG(1-T2,2)+1),"")) | I2: =IF($E2=1,(LOG(U2,2)+1),IF($E2=0,(LOG(1-U2,2)+1),"")) | J2: =IF($E2=1,(LOG(V2,2)+1),IF($E2=0,(LOG(1-V2,2)+1),"")) | K2: =IF($E2=1,(LOG(W2,2)+1),IF($E2=0,(LOG(1-W2,2)+1),"")) | L2: =IF($E2=1,(LOG(X2,2)+1),IF($E2=0,(LOG(1-X2,2)+1),"")) | M2: =IF($E2=1,(LOG(Y2,2)+1),IF($E2=0,(LOG(1-Y2,2)+1),"")) | ... P2: =IF($E2=1,(LOG(AB2,2)+1),IF($E2=0,(LOG(1-AB2,2)+1),"")) | Q2: =SUM(F2:P2) -> 0
A3: 2 | B3: NewJeans surpass 13M subscribers on instagram (currently 11.3M) | C3: Christine | D3: Entertainment | E3: 1 | F3: =IF($E3=1,(LOG(R3,2)+1),IF($E3=0,(LOG(1-R3,2)+1),"")) -> 0.84799691 | G3: =IF($E3=1,(LOG(S3,2)+1),IF($E3=0,(LOG(1-S3,2)+1),"")) -> 0.84799691 | H3: =IF($E3=1,(LOG(T3,2)+1),IF($E3=0,(LOG(1-T3,2)+1),"")) -> -1.3219281 | I3: =IF($E3=1,(LOG(U3,2)+1),IF($E3=0,(LOG(1-U3,2)+1),"")) -> 0 | J3: =IF($E3=1,(LOG(V3,2)+1),IF($E3=0,(LOG(1-V3,2)+1),"")) -> 0.11103131 | K3: =IF($E3=1,(LOG(W3,2)+1),IF($E3=0,(LOG(1-W3,2)+1),"")) -> 0.26303441 | L3: =IF($E3=1,(LOG(X3,2)+1),IF($E3=0,(LOG(1-X3,2)+1),"")) -> -0.15200309 | M3: =IF($E3=1,(LOG(Y3,2)+1),IF($E3=0,(LOG(1-Y3,2)+1),"")) -> 0.67807191 | ... P3: =IF($E3=1,(LOG(AB3,2)+1),IF($E3=0,(LOG(1-AB3,2)+1),"")) -> 0.98550043 | Q3: =SUM(F3:P3) -> 2.1076976 | R3: =Andrew!C3 -> 0.9 | S3: =Eileen!C3 -> 0.9 | T3: =Iain!C3 -> 0.2 | U3: =Kate!C3 -> 0.5 | V3: =Rohan!C3 -> 0.54 | W3: =Pete!C3 -> 0.6 | X3: =Jac!C3 -> 0.45 | Y3: =James!C3 -> 0.8 | Z3: =Lachy!C3 -> 0.45 | AA3: =Gael!C3 -> 0.5 | AB3: =Bruce!C3 -> 0.99
A4: 3 | B4: Timothee and Kylie break up | C4: Christine | D4: Entertainment | E4: 0 | F4: =IF($E4=1,(LOG(R4,2)+1),IF($E4=0,(LOG(1-R4,2)+1),"")) -> -0.51457317 | G4: =IF($E4=1,(LOG(S4,2)+1),IF($E4=0,(LOG(1-S4,2)+1),"")) -> -0.73696559 | H4: =IF($E4=1,(LOG(T4,2)+1),IF($E4=0,(LOG(1-T4,2)+1),"")) -> -1.3219281 | I4: =IF($E4=1,(LOG(U4,2)+1),IF($E4=0,(LOG(1-U4,2)+1),"")) -> -1.3219281 | J4: =IF($E4=1,(LOG(V4,2)+1),IF($E4=0,(LOG(1-V4,2)+1),"")) -> -0.15200309 | K4: =IF($E4=1,(LOG(W4,2)+1),IF($E4=0,(LOG(1-W4,2)+1),"")) -> 0.26303441 | L4: =IF($E4=1,(LOG(X4,2)+1),IF($E4=0,(LOG(1-X4,2)+1),"")) -> 0 | M4: =IF($E4=1,(LOG(Y4,2)+1),IF($E4=0,(LOG(1-Y4,2)+1),"")) -> 0 | ... P4: =IF($E4=1,(LOG(AB4,2)+1),IF($E4=0,(LOG(1-AB4,2)+1),"")) -> 0 | Q4: =SUM(F4:P4) -> -3.6208649 | R4: =Andrew!C4 -> 0.65 | S4: =Eileen!C4 -> 0.7 | T4: =Iain!C4 -> 0.8 | U4: =Kate!C4 -> 0.8 | V4: =Rohan!C4 -> 0.55 | W4: =Pete!C4 -> 0.4 | X4: =Jac!C4 -> 0.5 | Y4: =James!C4 -> 0.5 | Z4: =Lachy!C4 -> 0.3 | AA4: =Gael!C4 -> 0.6 | AB4: =Bruce!C4 -> 0.5
A5: 4 | B5: A guest on Hot Ones will not complete the full set of hot sauces/wings | C5: Eileen | D5: Entertainment | E5: 0 | F5: =IF($E5=1,(LOG(R5,2)+1),IF($E5=0,(LOG(1-R5,2)+1),"")) -> 0.67807191 | G5: =IF($E5=1,(LOG(S5,2)+1),IF($E5=0,(LOG(1-S5,2)+1),"")) -> 0.84799691 | H5: =IF($E5=1,(LOG(T5,2)+1),IF($E5=0,(LOG(1-T5,2)+1),"")) -> 0.84799691 | I5: =IF($E5=1,(LOG(U5,2)+1),IF($E5=0,(LOG(1-U5,2)+1),"")) -> -1.3219281 | J5: =IF($E5=1,(LOG(V5,2)+1),IF($E5=0,(LOG(1-V5,2)+1),"")) -> -1.1844246 | K5: =IF($E5=1,(LOG(W5,2)+1),IF($E5=0,(LOG(1-W5,2)+1),"")) -> 0.26303441 | L5: =IF($E5=1,(LOG(X5,2)+1),IF($E5=0,(LOG(1-X5,2)+1),"")) -> -0.51457317 | M5: =IF($E5=1,(LOG(Y5,2)+1),IF($E5=0,(LOG(1-Y5,2)+1),"")) -> -0.73696559 | ... P5: =IF($E5=1,(LOG(AB5,2)+1),IF($E5=0,(LOG(1-AB5,2)+1),"")) -> 0.26303441 | Q5: =SUM(F5:P5) -> -1.9166506 | R5: =Andrew!C5 -> 0.2 | S5: =Eileen!C5 -> 0.1 | T5: =Iain!C5 -> 0.1 | U5: =Kate!C5 -> 0.8 | V5: =Rohan!C5 -> 0.78 | W5: =Pete!C5 -> 0.4 | X5: =Jac!C5 -> 0.65 | Y5: =James!C5 -> 0.7 | Z5: =Lachy!C5 -> 0.8 | AA5: =Gael!C5 -> 0.4 | AB5: =Bruce!C5 -> 0.4
A6: 5 | B6: An alone participant in a 2024 season (Australia/Denmark/UK) will fall ill from eating poisonous fruit they misidentify | C6: Eileen | D6: Entertainment | E6: 1 | F6: =IF($E6=1,(LOG(R6,2)+1),IF($E6=0,(LOG(1-R6,2)+1),"")) -> 0.5849625 | G6: =IF($E6=1,(LOG(S6,2)+1),IF($E6=0,(LOG(1-S6,2)+1),"")) -> 0.48542683 | H6: =IF($E6=1,(LOG(T6,2)+1),IF($E6=0,(LOG(1-T6,2)+1),"")) -> -0.73696559 | I6: =IF($E6=1,(LOG(U6,2)+1),IF($E6=0,(LOG(1-U6,2)+1),"")) -> -1.3219281 | J6: =IF($E6=1,(LOG(V6,2)+1),IF($E6=0,(LOG(1-V6,2)+1),"")) -> -0.15200309 | K6: =IF($E6=1,(LOG(W6,2)+1),IF($E6=0,(LOG(1-W6,2)+1),"")) -> -0.73696559 | L6: =IF($E6=1,(LOG(X6,2)+1),IF($E6=0,(LOG(1-X6,2)+1),"")) -> -0.73696559 | M6: =IF($E6=1,(LOG(Y6,2)+1),IF($E6=0,(LOG(1-Y6,2)+1),"")) -> -0.32192809 | ... P6: =IF($E6=1,(LOG(AB6,2)+1),IF($E6=0,(LOG(1-AB6,2)+1),"")) -> -0.73696559 | Q6: =SUM(F6:P6) -> -5.3171885 | R6: =Andrew!C6 -> 0.75 | S6: =Eileen!C6 -> 0.7 | T6: =Iain!C6 -> 0.3 | U6: =Kate!C6 -> 0.2 | V6: =Rohan!C6 -> 0.45 | W6: =Pete!C6 -> 0.3 | X6: =Jac!C6 -> 0.3 | Y6: =James!C6 -> 0.4 | Z6: =Lachy!C6 -> 0.2 | AA6: =Gael!C6 -> 0.4 | AB6: =Bruce!C6 -> 0.3
A7: 6 | B7: An Australian or New Zealand restaurant will feature on the 2024 "World's 50 Best Restaurants" list | C7: Eileen | D7: Entertainment | E7: 0 | F7: =IF($E7=1,(LOG(R7,2)+1),IF($E7=0,(LOG(1-R7,2)+1),"")) -> 0.48542683 | G7: =IF($E7=1,(LOG(S7,2)+1),IF($E7=0,(LOG(1-S7,2)+1),"")) -> 0.67807191 | H7: =IF($E7=1,(LOG(T7,2)+1),IF($E7=0,(LOG(1-T7,2)+1),"")) -> -0.73696559 | I7: =IF($E7=1,(LOG(U7,2)+1),IF($E7=0,(LOG(1-U7,2)+1),"")) -> -0.73696559 | J7: =IF($E7=1,(LOG(V7,2)+1),IF($E7=0,(LOG(1-V7,2)+1),"")) -> 0.13750352 | K7: =IF($E7=1,(LOG(W7,2)+1),IF($E7=0,(LOG(1-W7,2)+1),"")) -> 0.26303441 | L7: =IF($E7=1,(LOG(X7,2)+1),IF($E7=0,(LOG(1-X7,2)+1),"")) -> 0.26303441 | M7: =IF($E7=1,(LOG(Y7,2)+1),IF($E7=0,(LOG(1-Y7,2)+1),"")) -> 0.48542683 | ... P7: =IF($E7=1,(LOG(AB7,2)+1),IF($E7=0,(LOG(1-AB7,2)+1),"")) -> 0.26303441 | Q7: =SUM(F7:P7) -> -0.95729258 | R7: =Andrew!C7 -> 0.3 | S7: =Eileen!C7 -> 0.2 | T7: =Iain!C7 -> 0.7 | U7: =Kate!C7 -> 0.7 | V7: =Rohan!C7 -> 0.45 | W7: =Pete!C7 -> 0.4 | X7: =Jac!C7 -> 0.4 | Y7: =James!C7 -> 0.3 | Z7: =Lachy!C7 -> 0.9 | AA7: =Gael!C7 -> 0.4 | AB7: =Bruce!C7 -> 0.4
A8: 7 | B8: Dex (Kim Jin Young) will feature as a guest or star in a food-based show available on Netflix AU/NZ | C8: Eileen | D8: Entertainment | E8: 0 | F8: =IF($E8=1,(LOG(R8,2)+1),IF($E8=0,(LOG(1-R8,2)+1),"")) -> 0.37851162 | G8: =IF($E8=1,(LOG(S8,2)+1),IF($E8=0,(LOG(1-S8,2)+1),"")) -> 0.48542683 | H8: =IF($E8=1,(LOG(T8,2)+1),IF($E8=0,(LOG(1-T8,2)+1),"")) -> 0 | I8: =IF($E8=1,(LOG(U8,2)+1),IF($E8=0,(LOG(1-U8,2)+1),"")) -> 0 | J8: =IF($E8=1,(LOG(V8,2)+1),IF($E8=0,(LOG(1-V8,2)+1),"")) -> 0.48542683 | K8: =IF($E8=1,(LOG(W8,2)+1),IF($E8=0,(LOG(1-W8,2)+1),"")) -> 0.48542683 | L8: =IF($E8=1,(LOG(X8,2)+1),IF($E8=0,(LOG(1-X8,2)+1),"")) -> 0.37851162 | M8: =IF($E8=1,(LOG(Y8,2)+1),IF($E8=0,(LOG(1-Y8,2)+1),"")) -> 0 | ... P8: =IF($E8=1,(LOG(AB8,2)+1),IF($E8=0,(LOG(1-AB8,2)+1),"")) -> 0.26303441 | Q8: =SUM(F8:P8) -> 2.15441 | R8: =Andrew!C8 -> 0.35 | S8: =Eileen!C8 -> 0.3 | T8: =Iain!C8 -> 0.5 | U8: =Kate!C8 -> 0.5 | V8: =Rohan!C8 -> 0.3 | W8: =Pete!C8 -> 0.3 | X8: =Jac!C8 -> 0.35 | Y8: =James!C8 -> 0.5 | Z8: =Lachy!C8 -> 0.5 | AA8: =Gael!C8 -> 0.6 | AB8: =Bruce!C8 -> 0.4
A9: 8 | B9: Taylor will break up with Travis | C9: Kate | D9: Entertainment | E9: 0 | F9: =IF($E9=1,(LOG(R9,2)+1),IF($E9=0,(LOG(1-R9,2)+1),"")) -> -0.15200309 | G9: =IF($E9=1,(LOG(S9,2)+1),IF($E9=0,(LOG(1-S9,2)+1),"")) -> 0.13750352 | H9: =IF($E9=1,(LOG(T9,2)+1),IF($E9=0,(LOG(1-T9,2)+1),"")) -> 0.67807191 | I9: =IF($E9=1,(LOG(U9,2)+1),IF($E9=0,(LOG(1-U9,2)+1),"")) -> 0.26303441 | J9: =IF($E9=1,(LOG(V9,2)+1),IF($E9=0,(LOG(1-V9,2)+1),"")) -> 0.26303441 | K9: =IF($E9=1,(LOG(W9,2)+1),IF($E9=0,(LOG(1-W9,2)+1),"")) -> 0.26303441 | L9: =IF($E9=1,(LOG(X9,2)+1),IF($E9=0,(LOG(1-X9,2)+1),"")) -> -0.15200309 | M9: =IF($E9=1,(LOG(Y9,2)+1),IF($E9=0,(LOG(1-Y9,2)+1),"")) -> -0.32192809 | ... P9: =IF($E9=1,(LOG(AB9,2)+1),IF($E9=0,(LOG(1-AB9,2)+1),"")) -> 0.26303441 | Q9: =SUM(F9:P9) -> 1.99024 | R9: =Andrew!C9 -> 0.55 | S9: =Eileen!C9 -> 0.45 | T9: =Iain!C9 -> 0.2 | U9: =Kate!C9 -> 0.4 | V9: =Rohan!C9 -> 0.4 | W9: =Pete!C9 -> 0.4 | X9: =Jac!C9 -> 0.55 | Y9: =James!C9 -> 0.6 | Z9: =Lachy!C9 -> 0.3 | AA9: =Gael!C9 -> 0.4 | AB9: =Bruce!C9 -> 0.4
A10: 9 | B10: Taylor will release the re-record of her debut album in 2024. | C10: Kate | D10: Entertainment | E10: 0 | F10: =IF($E10=1,(LOG(R10,2)+1),IF($E10=0,(LOG(1-R10,2)+1),"")) -> 0.26303441 | G10: =IF($E10=1,(LOG(S10,2)+1),IF($E10=0,(LOG(1-S10,2)+1),"")) -> -0.32192809 | H10: =IF($E10=1,(LOG(T10,2)+1),IF($E10=0,(LOG(1-T10,2)+1),"")) -> -0.73696559 | I10: =IF($E10=1,(LOG(U10,2)+1),IF($E10=0,(LOG(1-U10,2)+1),"")) -> -0.73696559 | J10: =IF($E10=1,(LOG(V10,2)+1),IF($E10=0,(LOG(1-V10,2)+1),"")) -> 0 | K10: =IF($E10=1,(LOG(W10,2)+1),IF($E10=0,(LOG(1-W10,2)+1),"")) -> 0.26303441 | L10: =IF($E10=1,(LOG(X10,2)+1),IF($E10=0,(LOG(1-X10,2)+1),"")) -> 0.48542683 | M10: =IF($E10=1,(LOG(Y10,2)+1),IF($E10=0,(LOG(1-Y10,2)+1),"")) -> 0.48542683 | ... P10: =IF($E10=1,(LOG(AB10,2)+1),IF($E10=0,(LOG(1-AB10,2)+1),"")) -> 0.37851162 | Q10: =SUM(F10:P10) -> -0.39435638 | R10: =Andrew!C10 -> 0.4 | S10: =Eileen!C10 -> 0.6 | T10: =Iain!C10 -> 0.7 | U10: =Kate!C10 -> 0.7 | V10: =Rohan!C10 -> 0.5 | W10: =Pete!C10 -> 0.4 | X10: =Jac!C10 -> 0.3 | Y10: =James!C10 -> 0.3 | Z10: =Lachy!C10 -> 0.4 | AA10: =Gael!C10 -> 0.7 | AB10: =Bruce!C10 -> 0.35
A11: 10 | B11: Barbie will win best picture at the academy awards. | C11: Rohan | D11: Entertainment | E11: - | F11: =IF($E11=1,(LOG(R11,2)+1),IF($E11=0,(LOG(1-R11,2)+1),"")) | G11: =IF($E11=1,(LOG(S11,2)+1),IF($E11=0,(LOG(1-S11,2)+1),"")) | H11: =IF($E11=1,(LOG(T11,2)+1),IF($E11=0,(LOG(1-T11,2)+1),"")) | I11: =IF($E11=1,(LOG(U11,2)+1),IF($E11=0,(LOG(1-U11,2)+1),"")) | J11: =IF($E11=1,(LOG(V11,2)+1),IF($E11=0,(LOG(1-V11,2)+1),"")) | K11: =IF($E11=1,(LOG(W11,2)+1),IF($E11=0,(LOG(1-W11,2)+1),"")) | L11: =IF($E11=1,(LOG(X11,2)+1),IF($E11=0,(LOG(1-X11,2)+1),"")) | M11: =IF($E11=1,(LOG(Y11,2)+1),IF($E11=0,(LOG(1-Y11,2)+1),"")) | ... P11: =IF($E11=1,(LOG(AB11,2)+1),IF($E11=0,(LOG(1-AB11,2)+1),"")) | Q11: =SUM(F11:P11) -> 0
A12: 11 | B12: Kate will win at least two prizes for her Phillip and Bennelong book. | C12: Iain | D12: Family | E12: 1 | F12: =IF($E12=1,(LOG(R12,2)+1),IF($E12=0,(LOG(1-R12,2)+1),"")) -> 0.5849625 | G12: =IF($E12=1,(LOG(S12,2)+1),IF($E12=0,(LOG(1-S12,2)+1),"")) -> 0.5849625 | H12: =IF($E12=1,(LOG(T12,2)+1),IF($E12=0,(LOG(1-T12,2)+1),"")) -> 0.67807191 | I12: =IF($E12=1,(LOG(U12,2)+1),IF($E12=0,(LOG(1-U12,2)+1),"")) -> -1.3219281 | J12: =IF($E12=1,(LOG(V12,2)+1),IF($E12=0,(LOG(1-V12,2)+1),"")) -> 0.62293035 | K12: =IF($E12=1,(LOG(W12,2)+1),IF($E12=0,(LOG(1-W12,2)+1),"")) -> 0.48542683 | L12: =IF($E12=1,(LOG(X12,2)+1),IF($E12=0,(LOG(1-X12,2)+1),"")) -> 0 | M12: =IF($E12=1,(LOG(Y12,2)+1),IF($E12=0,(LOG(1-Y12,2)+1),"")) -> 0.48542683 | ... P12: =IF($E12=1,(LOG(AB12,2)+1),IF($E12=0,(LOG(1-AB12,2)+1),"")) -> 0.26303441 | Q12: =SUM(F12:P12) -> 3.1313485 | R12: =Andrew!C12 -> 0.75 | S12: =Eileen!C12 -> 0.75 | T12: =Iain!C12 -> 0.8 | U12: =Kate!C12 -> 0.2 | V12: =Rohan!C12 -> 0.77 | W12: =Pete!C12 -> 0.7 | X12: =Jac!C12 -> 0.5 | Y12: =James!C12 -> 0.7 | Z12: =Lachy!C12 -> 0.6 | AA12: =Gael!C12 -> 0.7 | AB12: =Bruce!C12 -> 0.6
A13: 12 | B13: Baby Starmeadow will be under 50cm long at birth (Oz average is 50.8cm). | C13: Kate | D13: Family | E13: - | F13: =IF($E13=1,(LOG(R13,2)+1),IF($E13=0,(LOG(1-R13,2)+1),"")) | G13: =IF($E13=1,(LOG(S13,2)+1),IF($E13=0,(LOG(1-S13,2)+1),"")) | H13: =IF($E13=1,(LOG(T13,2)+1),IF($E13=0,(LOG(1-T13,2)+1),"")) | I13: =IF($E13=1,(LOG(U13,2)+1),IF($E13=0,(LOG(1-U13,2)+1),"")) | J13: =IF($E13=1,(LOG(V13,2)+1),IF($E13=0,(LOG(1-V13,2)+1),"")) | K13: =IF($E13=1,(LOG(W13,2)+1),IF($E13=0,(LOG(1-W13,2)+1),"")) | L13: =IF($E13=1,(LOG(X13,2)+1),IF($E13=0,(LOG(1-X13,2)+1),"")) | M13: =IF($E13=1,(LOG(Y13,2)+1),IF($E13=0,(LOG(1-Y13,2)+1),"")) | ... P13: =IF($E13=1,(LOG(AB13,2)+1),IF($E13=0,(LOG(1-AB13,2)+1),"")) | Q13: =SUM(F13:P13) -> 0
A14: 13 | B14: The Reserve Bank will announce at least three interest rate reductions in 2024 | C14: Bruce | D14: Finance | E14: 0 | F14: =IF($E14=1,(LOG(R14,2)+1),IF($E14=0,(LOG(1-R14,2)+1),"")) -> 0.48542683 | G14: =IF($E14=1,(LOG(S14,2)+1),IF($E14=0,(LOG(1-S14,2)+1),"")) -> 0.26303441 | H14: =IF($E14=1,(LOG(T14,2)+1),IF($E14=0,(LOG(1-T14,2)+1),"")) -> 0.26303441 | I14: =IF($E14=1,(LOG(U14,2)+1),IF($E14=0,(LOG(1-U14,2)+1),"")) -> 0.26303441 | J14: =IF($E14=1,(LOG(V14,2)+1),IF($E14=0,(LOG(1-V14,2)+1),"")) -> 0.48542683 | K14: =IF($E14=1,(LOG(W14,2)+1),IF($E14=0,(LOG(1-W14,2)+1),"")) -> 0.48542683 | L14: =IF($E14=1,(LOG(X14,2)+1),IF($E14=0,(LOG(1-X14,2)+1),"")) -> 0.48542683 | M14: =IF($E14=1,(LOG(Y14,2)+1),IF($E14=0,(LOG(1-Y14,2)+1),"")) -> -0.73696559 | ... P14: =IF($E14=1,(LOG(AB14,2)+1),IF($E14=0,(LOG(1-AB14,2)+1),"")) -> 0.48542683 | Q14: =SUM(F14:P14) -> 2.8354156 | R14: =Andrew!C14 -> 0.3 | S14: =Eileen!C14 -> 0.4 | T14: =Iain!C14 -> 0.4 | U14: =Kate!C14 -> 0.4 | V14: =Rohan!C14 -> 0.3 | W14: =Pete!C14 -> 0.3 | X14: =Jac!C14 -> 0.3 | Y14: =James!C14 -> 0.7 | Z14: =Lachy!C14 -> 0.2 | AA14: =Gael!C14 -> 0.6 | AB14: =Bruce!C14 -> 0.3
A15: 14 | B15: Bruce Lehrmann will be awarded damages | C15: Jac | D15: Law | E15: 0 | F15: =IF($E15=1,(LOG(R15,2)+1),IF($E15=0,(LOG(1-R15,2)+1),"")) -> 0.67807191 | G15: =IF($E15=1,(LOG(S15,2)+1),IF($E15=0,(LOG(1-S15,2)+1),"")) -> 0.48542683 | H15: =IF($E15=1,(LOG(T15,2)+1),IF($E15=0,(LOG(1-T15,2)+1),"")) -> 0.84799691 | I15: =IF($E15=1,(LOG(U15,2)+1),IF($E15=0,(LOG(1-U15,2)+1),"")) -> 0.84799691 | J15: =IF($E15=1,(LOG(V15,2)+1),IF($E15=0,(LOG(1-V15,2)+1),"")) -> -0.83650127 | K15: =IF($E15=1,(LOG(W15,2)+1),IF($E15=0,(LOG(1-W15,2)+1),"")) -> 0.26303441 | L15: =IF($E15=1,(LOG(X15,2)+1),IF($E15=0,(LOG(1-X15,2)+1),"")) -> 0.26303441 | M15: =IF($E15=1,(LOG(Y15,2)+1),IF($E15=0,(LOG(1-Y15,2)+1),"")) -> 0 | ... P15: =IF($E15=1,(LOG(AB15,2)+1),IF($E15=0,(LOG(1-AB15,2)+1),"")) -> 0.84799691 | Q15: =SUM(F15:P15) -> 3.3381633 | R15: =Andrew!C15 -> 0.2 | S15: =Eileen!C15 -> 0.3 | T15: =Iain!C15 -> 0.1 | U15: =Kate!C15 -> 0.1 | V15: =Rohan!C15 -> 0.72 | W15: =Pete!C15 -> 0.4 | X15: =Jac!C15 -> 0.4 | Y15: =James!C15 -> 0.5 | Z15: =Lachy!C15 -> 0.6 | AA15: =Gael!C15 -> 0.4 | AB15: =Bruce!C15 -> 0.1
A16: 15 | B16: Chinese courts will refuse Evergrande liquidators’ requests to seize the developer’s assets in mainland China | C16: Jac | D16: Law | E16: 0 | F16: =IF($E16=1,(LOG(R16,2)+1),IF($E16=0,(LOG(1-R16,2)+1),"")) -> 0.48542683 | G16: =IF($E16=1,(LOG(S16,2)+1),IF($E16=0,(LOG(1-S16,2)+1),"")) -> 0 | H16: =IF($E16=1,(LOG(T16,2)+1),IF($E16=0,(LOG(1-T16,2)+1),"")) -> 0 | I16: =IF($E16=1,(LOG(U16,2)+1),IF($E16=0,(LOG(1-U16,2)+1),"")) -> 0 | J16: =IF($E16=1,(LOG(V16,2)+1),IF($E16=0,(LOG(1-V16,2)+1),"")) -> -0.32192809 | K16: =IF($E16=1,(LOG(W16,2)+1),IF($E16=0,(LOG(1-W16,2)+1),"")) -> -0.32192809 | L16: =IF($E16=1,(LOG(X16,2)+1),IF($E16=0,(LOG(1-X16,2)+1),"")) -> 0.67807191 | M16: =IF($E16=1,(LOG(Y16,2)+1),IF($E16=0,(LOG(1-Y16,2)+1),"")) -> -2.3219281 | ... P16: =IF($E16=1,(LOG(AB16,2)+1),IF($E16=0,(LOG(1-AB16,2)+1),"")) -> -1.3219281 | Q16: =SUM(F16:P16) -> -4.5981448 | R16: =Andrew!C16 -> 0.3 | S16: =Eileen!C16 -> 0.5 | T16: =Iain!C16 -> 0.5 | U16: =Kate!C16 -> 0.5 | V16: =Rohan!C16 -> 0.6 | W16: =Pete!C16 -> 0.6 | X16: =Jac!C16 -> 0.2 | Y16: =James!C16 -> 0.9 | Z16: =Lachy!C16 -> 0.7 | AA16: =Gael!C16 -> 0.7 | AB16: =Bruce!C16 -> 0.8
A17: 16 | B17: David McBride will be sentenced to a lifetime jail sentence | C17: Jac | D17: Law | E17: 0 | F17: =IF($E17=1,(LOG(R17,2)+1),IF($E17=0,(LOG(1-R17,2)+1),"")) -> 0.26303441 | G17: =IF($E17=1,(LOG(S17,2)+1),IF($E17=0,(LOG(1-S17,2)+1),"")) -> -0.73696559 | H17: =IF($E17=1,(LOG(T17,2)+1),IF($E17=0,(LOG(1-T17,2)+1),"")) -> 0.48542683 | I17: =IF($E17=1,(LOG(U17,2)+1),IF($E17=0,(LOG(1-U17,2)+1),"")) -> -0.32192809 | J17: =IF($E17=1,(LOG(V17,2)+1),IF($E17=0,(LOG(1-V17,2)+1),"")) -> 0.26303441 | K17: =IF($E17=1,(LOG(W17,2)+1),IF($E17=0,(LOG(1-W17,2)+1),"")) -> -0.32192809 | L17: =IF($E17=1,(LOG(X17,2)+1),IF($E17=0,(LOG(1-X17,2)+1),"")) -> 0.13750352 | M17: =IF($E17=1,(LOG(Y17,2)+1),IF($E17=0,(LOG(1-Y17,2)+1),"")) -> 0.67807191 | ... P17: =IF($E17=1,(LOG(AB17,2)+1),IF($E17=0,(LOG(1-AB17,2)+1),"")) -> 0.84799691 | Q17: =SUM(F17:P17) -> 0.4052775 | R17: =Andrew!C17 -> 0.4 | S17: =Eileen!C17 -> 0.7 | T17: =Iain!C17 -> 0.3 | U17: =Kate!C17 -> 0.6 | V17: =Rohan!C17 -> 0.4 | W17: =Pete!C17 -> 0.6 | X17: =Jac!C17 -> 0.45 | Y17: =James!C17 -> 0.2 | Z17: =Lachy!C17 -> 0.55 | AA17: =Gael!C17 -> 0.7 | AB17: =Bruce!C17 -> 0.1
A18: 17 | B18: The federal court will find that Bruce Lehrmann was not defamed | C18: Jac | D18: Law | E18: 1 | F18: =IF($E18=1,(LOG(R18,2)+1),IF($E18=0,(LOG(1-R18,2)+1),"")) -> 0.37851162 | G18: =IF($E18=1,(LOG(S18,2)+1),IF($E18=0,(LOG(1-S18,2)+1),"")) -> 0.48542683 | H18: =IF($E18=1,(LOG(T18,2)+1),IF($E18=0,(LOG(1-T18,2)+1),"")) -> 0.26303441 | I18: =IF($E18=1,(LOG(U18,2)+1),IF($E18=0,(LOG(1-U18,2)+1),"")) -> 0.26303441 | J18: =IF($E18=1,(LOG(V18,2)+1),IF($E18=0,(LOG(1-V18,2)+1),"")) -> 0 | K18: =IF($E18=1,(LOG(W18,2)+1),IF($E18=0,(LOG(1-W18,2)+1),"")) -> -0.32192809 | L18: =IF($E18=1,(LOG(X18,2)+1),IF($E18=0,(LOG(1-X18,2)+1),"")) -> 0.67807191 | M18: =IF($E18=1,(LOG(Y18,2)+1),IF($E18=0,(LOG(1-Y18,2)+1),"")) -> 0 | ... P18: =IF($E18=1,(LOG(AB18,2)+1),IF($E18=0,(LOG(1-AB18,2)+1),"")) -> 0.67807191 | Q18: =SUM(F18:P18) -> 2.5877217 | R18: =Andrew!C18 -> 0.65 | S18: =Eileen!C18 -> 0.7 | T18: =Iain!C18 -> 0.6 | U18: =Kate!C18 -> 0.6 | V18: =Rohan!C18 -> 0.5 | W18: =Pete!C18 -> 0.4 | X18: =Jac!C18 -> 0.8 | Y18: =James!C18 -> 0.5 | Z18: =Lachy!C18 -> 0.4 | AA18: =Gael!C18 -> 0.7 | AB18: =Bruce!C18 -> 0.8
A19: 18 | B19: OpenAI successfully defends the New York Times' claim on the basis of fair use | C19: James | D19: Law | E19: 0 | F19: =IF($E19=1,(LOG(R19,2)+1),IF($E19=0,(LOG(1-R19,2)+1),"")) -> -0.15200309 | G19: =IF($E19=1,(LOG(S19,2)+1),IF($E19=0,(LOG(1-S19,2)+1),"")) -> 0 | H19: =IF($E19=1,(LOG(T19,2)+1),IF($E19=0,(LOG(1-T19,2)+1),"")) -> 0.26303441 | I19: =IF($E19=1,(LOG(U19,2)+1),IF($E19=0,(LOG(1-U19,2)+1),"")) -> 0.26303441 | J19: =IF($E19=1,(LOG(V19,2)+1),IF($E19=0,(LOG(1-V19,2)+1),"")) -> -0.12029423 | K19: =IF($E19=1,(LOG(W19,2)+1),IF($E19=0,(LOG(1-W19,2)+1),"")) -> -0.32192809 | L19: =IF($E19=1,(LOG(X19,2)+1),IF($E19=0,(LOG(1-X19,2)+1),"")) -> 0.67807191 | M19: =IF($E19=1,(LOG(Y19,2)+1),IF($E19=0,(LOG(1-Y19,2)+1),"")) -> 0.26303441 | ... P19: =IF($E19=1,(LOG(AB19,2)+1),IF($E19=0,(LOG(1-AB19,2)+1),"")) -> -0.32192809 | Q19: =SUM(F19:P19) -> 1.2290935 | R19: =Andrew!C19 -> 0.55 | S19: =Eileen!C19 -> 0.5 | T19: =Iain!C19 -> 0.4 | U19: =Kate!C19 -> 0.4 | V19: =Rohan!C19 -> 0.54 | W19: =Pete!C19 -> 0.6 | X19: =Jac!C19 -> 0.2 | Y19: =James!C19 -> 0.4 | Z19: =Lachy!C19 -> 0.2 | AA19: =Gael!C19 -> 0.5 | AB19: =Bruce!C19 -> 0.6
A20: 19 | B20: 2024 will be the hottest European summer on record. | C20: Gael | D20: Nature | E20: 1 | F20: =IF($E20=1,(LOG(R20,2)+1),IF($E20=0,(LOG(1-R20,2)+1),"")) -> 0.26303441 | G20: =IF($E20=1,(LOG(S20,2)+1),IF($E20=0,(LOG(1-S20,2)+1),"")) -> 0.67807191 | H20: =IF($E20=1,(LOG(T20,2)+1),IF($E20=0,(LOG(1-T20,2)+1),"")) -> 0.26303441 | I20: =IF($E20=1,(LOG(U20,2)+1),IF($E20=0,(LOG(1-U20,2)+1),"")) -> 0.26303441 | J20: =IF($E20=1,(LOG(V20,2)+1),IF($E20=0,(LOG(1-V20,2)+1),"")) -> -0.55639335 | K20: =IF($E20=1,(LOG(W20,2)+1),IF($E20=0,(LOG(1-W20,2)+1),"")) -> 0.26303441 | L20: =IF($E20=1,(LOG(X20,2)+1),IF($E20=0,(LOG(1-X20,2)+1),"")) -> -0.15200309 | M20: =IF($E20=1,(LOG(Y20,2)+1),IF($E20=0,(LOG(1-Y20,2)+1),"")) -> -3.3219281 | ... P20: =IF($E20=1,(LOG(AB20,2)+1),IF($E20=0,(LOG(1-AB20,2)+1),"")) -> -5.6438562 | Q20: =SUM(F20:P20) -> -6.7804725 | R20: =Andrew!C20 -> 0.6 | S20: =Eileen!C20 -> 0.8 | T20: =Iain!C20 -> 0.6 | U20: =Kate!C20 -> 0.6 | V20: =Rohan!C20 -> 0.34 | W20: =Pete!C20 -> 0.6 | X20: =Jac!C20 -> 0.45 | Y20: =James!C20 -> 0.05 | Z20: =Lachy!C20 -> 0.7 | AA20: =Gael!C20 -> 0.8 | AB20: =Bruce!C20 -> 0.01
A21: 20 | B21: The NOAA will announce an alert level 5 bleaching event on the Great Barrier Reef | C21: Iain | D21: Nature | E21: 0 | F21: =IF($E21=1,(LOG(R21,2)+1),IF($E21=0,(LOG(1-R21,2)+1),"")) -> -0.51457317 | G21: =IF($E21=1,(LOG(S21,2)+1),IF($E21=0,(LOG(1-S21,2)+1),"")) -> -0.32192809 | H21: =IF($E21=1,(LOG(T21,2)+1),IF($E21=0,(LOG(1-T21,2)+1),"")) -> -0.73696559 | I21: =IF($E21=1,(LOG(U21,2)+1),IF($E21=0,(LOG(1-U21,2)+1),"")) -> -0.32192809 | J21: =IF($E21=1,(LOG(V21,2)+1),IF($E21=0,(LOG(1-V21,2)+1),"")) -> 0.67807191 | K21: =IF($E21=1,(LOG(W21,2)+1),IF($E21=0,(LOG(1-W21,2)+1),"")) -> 0.26303441 | L21: =IF($E21=1,(LOG(X21,2)+1),IF($E21=0,(LOG(1-X21,2)+1),"")) -> 0.48542683 | M21: =IF($E21=1,(LOG(Y21,2)+1),IF($E21=0,(LOG(1-Y21,2)+1),"")) -> 0.26303441 | ... P21: =IF($E21=1,(LOG(AB21,2)+1),IF($E21=0,(LOG(1-AB21,2)+1),"")) -> 0.26303441 | Q21: =SUM(F21:P21) -> 0.16823831 | R21: =Andrew!C21 -> 0.65 | S21: =Eileen!C21 -> 0.6 | T21: =Iain!C21 -> 0.7 | U21: =Kate!C21 -> 0.6 | V21: =Rohan!C21 -> 0.2 | W21: =Pete!C21 -> 0.4 | X21: =Jac!C21 -> 0.3 | Y21: =James!C21 -> 0.4 | Z21: =Lachy!C21 -> 0.1 | AA21: =Gael!C21 -> 0.7 | AB21: =Bruce!C21 -> 0.4
A22: 21 | B22: At least three cyclones will drench North Queensland before the end of the year. | C22: Pete | D22: Nature | E22: 0 | F22: =IF($E22=1,(LOG(R22,2)+1),IF($E22=0,(LOG(1-R22,2)+1),"")) -> 0.37851162 | G22: =IF($E22=1,(LOG(S22,2)+1),IF($E22=0,(LOG(1-S22,2)+1),"")) -> -0.32192809 | H22: =IF($E22=1,(LOG(T22,2)+1),IF($E22=0,(LOG(1-T22,2)+1),"")) -> -1.3219281 | I22: =IF($E22=1,(LOG(U22,2)+1),IF($E22=0,(LOG(1-U22,2)+1),"")) -> 0.26303441 | J22: =IF($E22=1,(LOG(V22,2)+1),IF($E22=0,(LOG(1-V22,2)+1),"")) -> 0.26303441 | K22: =IF($E22=1,(LOG(W22,2)+1),IF($E22=0,(LOG(1-W22,2)+1),"")) -> -0.73696559 | L22: =IF($E22=1,(LOG(X22,2)+1),IF($E22=0,(LOG(1-X22,2)+1),"")) -> 0 | M22: =IF($E22=1,(LOG(Y22,2)+1),IF($E22=0,(LOG(1-Y22,2)+1),"")) -> -0.32192809 | ... P22: =IF($E22=1,(LOG(AB22,2)+1),IF($E22=0,(LOG(1-AB22,2)+1),"")) -> 0.48542683 | Q22: =SUM(F22:P22) -> -0.95659881 | R22: =Andrew!C22 -> 0.35 | S22: =Eileen!C22 -> 0.6 | T22: =Iain!C22 -> 0.8 | U22: =Kate!C22 -> 0.4 | V22: =Rohan!C22 -> 0.4 | W22: =Pete!C22 -> 0.7 | X22: =Jac!C22 -> 0.5 | Y22: =James!C22 -> 0.6 | Z22: =Lachy!C22 -> 0.2 | AA22: =Gael!C22 -> 0.6 | AB22: =Bruce!C22 -> 0.3
A23: 22 | B23: A head of state or relevant minister from an island nation will declare their geographic country no longer inhabitable in the long term, due to climate-related issues. This will include a commitment to relevant action of some kind | C23: Andrew | D23: Politics | E23: 0 | F23: =IF($E23=1,(LOG(R23,2)+1),IF($E23=0,(LOG(1-R23,2)+1),"")) -> 0.84799691 | G23: =IF($E23=1,(LOG(S23,2)+1),IF($E23=0,(LOG(1-S23,2)+1),"")) -> 0.67807191 | H23: =IF($E23=1,(LOG(T23,2)+1),IF($E23=0,(LOG(1-T23,2)+1),"")) -> -1.3219281 | I23: =IF($E23=1,(LOG(U23,2)+1),IF($E23=0,(LOG(1-U23,2)+1),"")) -> 0.67807191 | J23: =IF($E23=1,(LOG(V23,2)+1),IF($E23=0,(LOG(1-V23,2)+1),"")) -> -0.73696559 | K23: =IF($E23=1,(LOG(W23,2)+1),IF($E23=0,(LOG(1-W23,2)+1),"")) -> -0.32192809 | L23: =IF($E23=1,(LOG(X23,2)+1),IF($E23=0,(LOG(1-X23,2)+1),"")) -> 0.13750352 | M23: =IF($E23=1,(LOG(Y23,2)+1),IF($E23=0,(LOG(1-Y23,2)+1),"")) -> -0.32192809 | ... P23: =IF($E23=1,(LOG(AB23,2)+1),IF($E23=0,(LOG(1-AB23,2)+1),"")) -> 0.26303441 | Q23: =SUM(F23:P23) -> 0.5655011 | R23: =Andrew!C23 -> 0.1 | S23: =Eileen!C23 -> 0.2 | T23: =Iain!C23 -> 0.8 | U23: =Kate!C23 -> 0.2 | V23: =Rohan!C23 -> 0.7 | W23: =Pete!C23 -> 0.6 | X23: =Jac!C23 -> 0.45 | Y23: =James!C23 -> 0.6 | Z23: =Lachy!C23 -> 0.01 | AA23: =Gael!C23 -> 0.6 | AB23: =Bruce!C23 -> 0.4
A24: 23 | B24: Trump will promise to enact an order or legislation with the express intention of negatively impacting Taylor Swift | C24: Andrew | D24: Politics | E24: 0 | F24: =IF($E24=1,(LOG(R24,2)+1),IF($E24=0,(LOG(1-R24,2)+1),"")) -> -0.15200309 | G24: =IF($E24=1,(LOG(S24,2)+1),IF($E24=0,(LOG(1-S24,2)+1),"")) -> -0.32192809 | H24: =IF($E24=1,(LOG(T24,2)+1),IF($E24=0,(LOG(1-T24,2)+1),"")) -> -0.73696559 | I24: =IF($E24=1,(LOG(U24,2)+1),IF($E24=0,(LOG(1-U24,2)+1),"")) -> 0.84799691 | J24: =IF($E24=1,(LOG(V24,2)+1),IF($E24=0,(LOG(1-V24,2)+1),"")) -> 0.028569152 | K24: =IF($E24=1,(LOG(W24,2)+1),IF($E24=0,(LOG(1-W24,2)+1),"")) -> 0.26303441 | L24: =IF($E24=1,(LOG(X24,2)+1),IF($E24=0,(LOG(1-X24,2)+1),"")) -> 0.26303441 | M24: =IF($E24=1,(LOG(Y24,2)+1),IF($E24=0,(LOG(1-Y24,2)+1),"")) -> 0.84799691 | ... P24: =IF($E24=1,(LOG(AB24,2)+1),IF($E24=0,(LOG(1-AB24,2)+1),"")) -> 0.92599942 | Q24: =SUM(F24:P24) -> 2.1292331 | R24: =Andrew!C24 -> 0.55 | S24: =Eileen!C24 -> 0.6 | T24: =Iain!C24 -> 0.7 | U24: =Kate!C24 -> 0.1 | V24: =Rohan!C24 -> 0.49 | W24: =Pete!C24 -> 0.4 | X24: =Jac!C24 -> 0.4 | Y24: =James!C24 -> 0.1 | Z24: =Lachy!C24 -> 0.6 | AA24: =Gael!C24 -> 0.3 | AB24: =Bruce!C24 -> 0.05
A25: 24 | B25: Netanyahu will lose the prime ministership of Israel during 2024 | C25: Bruce | D25: Politics | E25: 0 | F25: =IF($E25=1,(LOG(R25,2)+1),IF($E25=0,(LOG(1-R25,2)+1),"")) -> 0.48542683 | G25: =IF($E25=1,(LOG(S25,2)+1),IF($E25=0,(LOG(1-S25,2)+1),"")) -> 0 | H25: =IF($E25=1,(LOG(T25,2)+1),IF($E25=0,(LOG(1-T25,2)+1),"")) -> -0.73696559 | I25: =IF($E25=1,(LOG(U25,2)+1),IF($E25=0,(LOG(1-U25,2)+1),"")) -> 0.26303441 | J25: =IF($E25=1,(LOG(V25,2)+1),IF($E25=0,(LOG(1-V25,2)+1),"")) -> -0.15200309 | K25: =IF($E25=1,(LOG(W25,2)+1),IF($E25=0,(LOG(1-W25,2)+1),"")) -> 0.26303441 | L25: =IF($E25=1,(LOG(X25,2)+1),IF($E25=0,(LOG(1-X25,2)+1),"")) -> 0.67807191 | M25: =IF($E25=1,(LOG(Y25,2)+1),IF($E25=0,(LOG(1-Y25,2)+1),"")) -> 0.67807191 | ... P25: =IF($E25=1,(LOG(AB25,2)+1),IF($E25=0,(LOG(1-AB25,2)+1),"")) -> 0.48542683 | Q25: =SUM(F25:P25) -> 2.1275963 | R25: =Andrew!C25 -> 0.3 | S25: =Eileen!C25 -> 0.5 | T25: =Iain!C25 -> 0.7 | U25: =Kate!C25 -> 0.4 | V25: =Rohan!C25 -> 0.55 | W25: =Pete!C25 -> 0.4 | X25: =Jac!C25 -> 0.2 | Y25: =James!C25 -> 0.2 | Z25: =Lachy!C25 -> 0.3 | AA25: =Gael!C25 -> 0.6 | AB25: =Bruce!C25 -> 0.3
... A60: 59 | B60: SpaceX's Starship vehicle will complete at least 1 full orbit of the Earth | C60: Lachy | D60: Technology | E60: 0 | F60: =IF($E60=1,(LOG(R60,2)+1),IF($E60=0,(LOG(1-R60,2)+1),"")) -> 0.67807191 | G60: =IF($E60=1,(LOG(S60,2)+1),IF($E60=0,(LOG(1-S60,2)+1),"")) -> -0.73696559 | H60: =IF($E60=1,(LOG(T60,2)+1),IF($E60=0,(LOG(1-T60,2)+1),"")) -> 0.67807191 | I60: =IF($E60=1,(LOG(U60,2)+1),IF($E60=0,(LOG(1-U60,2)+1),"")) -> 0.26303441 | J60: =IF($E60=1,(LOG(V60,2)+1),IF($E60=0,(LOG(1-V60,2)+1),"")) -> -1.5563933 | K60: =IF($E60=1,(LOG(W60,2)+1),IF($E60=0,(LOG(1-W60,2)+1),"")) -> -0.32192809 | L60: =IF($E60=1,(LOG(X60,2)+1),IF($E60=0,(LOG(1-X60,2)+1),"")) -> -1.3219281 | M60: =IF($E60=1,(LOG(Y60,2)+1),IF($E60=0,(LOG(1-Y60,2)+1),"")) -> -2.3219281 | ... P60: =IF($E60=1,(LOG(AB60,2)+1),IF($E60=0,(LOG(1-AB60,2)+1),"")) -> -5.6438562 | Q60: =SUM(F60:P60) -> -12.927677 | R60: =Andrew!C60 -> 0.2 | S60: =Eileen!C60 -> 0.7 | T60: =Iain!C60 -> 0.2 | U60: =Kate!C60 -> 0.4 | V60: =Rohan!C60 -> 0.83 | W60: =Pete!C60 -> 0.6 | X60: =Jac!C60 -> 0.8 | Y60: =James!C60 -> 0.9 | Z60: =Lachy!C60 -> 0.9 | AA60: =Gael!C60 -> 0.6 | AB60: =Bruce!C60 -> 0.99
A61: 60 | B61: A reputable newspaper publishes a story that Kate Middleton's disappearance is linked to William getting funky with Lady Rose Hanbury (otherwise known as: the Marchioness of Molmondeley) | C61: James | D61: Royals | E61: - | F61: =IF($E61=1,(LOG(R61,2)+1),IF($E61=0,(LOG(1-R61,2)+1),"")) | G61: =IF($E61=1,(LOG(S61,2)+1),IF($E61=0,(LOG(1-S61,2)+1),"")) | H61: =IF($E61=1,(LOG(T61,2)+1),IF($E61=0,(LOG(1-T61,2)+1),"")) | I61: =IF($E61=1,(LOG(U61,2)+1),IF($E61=0,(LOG(1-U61,2)+1),"")) | J61: =IF($E61=1,(LOG(V61,2)+1),IF($E61=0,(LOG(1-V61,2)+1),"")) | K61: =IF($E61=1,(LOG(W61,2)+1),IF($E61=0,(LOG(1-W61,2)+1),"")) | L61: =IF($E61=1,(LOG(X61,2)+1),IF($E61=0,(LOG(1-X61,2)+1),"")) | M61: =IF($E61=1,(LOG(Y61,2)+1),IF($E61=0,(LOG(1-Y61,2)+1),"")) | ... P61: =IF($E61=1,(LOG(AB61,2)+1),IF($E61=0,(LOG(1-AB61,2)+1),"")) | Q61: =SUM(F61:P61) -> 0 | R61: 0.5 | S61: 0.5 | T61: 0.5 | U61: =Kate!C61 -> 0.2 | V61: =Rohan!C61 -> 0.4 | W61: 0.5 | X61: =Jac!C61 -> 0.45 | Y61: =James!C61 -> 0.8 | Z61: =Lachy!C61 -> 0.7 | AA61: =Gael!C61 -> 0.65 | AB61: =Bruce!C61 -> 0.01
E63: TOTAL | F63: =IF(SUM(F2:F62)>=0,SUM(F2:F62),"") -> 5.5167033 | G63: =IF(SUM(G2:G62)>=0,SUM(G2:G62),"") | H63: =IF(SUM(H2:H62)>=0,SUM(H2:H62),"") | I63: =IF(SUM(I2:I62)>=0,SUM(I2:I62),"") -> 0.52120625 | J63: =IF(SUM(J2:J62)>=0,SUM(J2:J62),"") -> 3.0154337 | K63: =IF(SUM(K2:K62)>=0,SUM(K2:K62),"") -> 2.957021 | L63: =IF(SUM(L2:L62)>=0,SUM(L2:L62),"") -> 11.175461 | M63: =IF(SUM(M2:M62)>=0,SUM(M2:M62),"") -> 4.1331662 | ... P63: =IF(SUM(P2:P62)>=0,SUM(P2:P62),"") -> 0.19233678
F64: =IF(SUM(F2:F62)<0,SUM(F2:F62),"") | G64: =IF(SUM(G2:G62)<0,SUM(G2:G62),"") -> -4.3563785 | H64: =IF(SUM(H2:H62)<0,SUM(H2:H62),"") -> -1.7257905 | I64: =IF(SUM(I2:I62)<0,SUM(I2:I62),"") | J64: =IF(SUM(J2:J62)<0,SUM(J2:J62),"") | K64: =IF(SUM(K2:K62)<0,SUM(K2:K62),"") | L64: =IF(SUM(L2:L62)<0,SUM(L2:L62),"") | M64: =IF(SUM(M2:M62)<0,SUM(M2:M62),"") | ... P64: =IF(SUM(P2:P62)<0,SUM(P2:P62),"")
E66: Top score | F66: =MAX(F2:F62) -> 0.84799691 | G66: =MAX(G2:G62) -> 0.98550043 | H66: =MAX(H2:H62) -> 0.84799691 | I66: =MAX(I2:I62) -> 0.92599942 | J66: =MAX(J2:J62) -> 0.98550043 | K66: =MAX(K2:K62) -> 0.48542683 | L66: =MAX(L2:L62) -> 0.92599942 | M66: =MAX(M2:M62) -> 0.98550043 | ... P66: =MAX(P2:P62) -> 0.98550043
E67: Bottom score | F67: =MIN(F2:F62) -> -2.3219281 | G67: =MIN(G2:G62) -> -2.3219281 | H67: =MIN(H2:H62) -> -1.3219281 | I67: =MIN(I2:I62) -> -2.3219281 | J67: =MIN(J2:J62) -> -2.3219281 | K67: =MIN(K2:K62) -> -0.73696559 | L67: =MIN(L2:L62) -> -1.3219281 | M67: =MIN(M2:M62) -> -3.3219281 | ... P67: =MIN(P2:P62) -> -5.6438562
E68: Avg +ve | F68: =IFERROR(__xludf.DUMMYFUNCTION("AVERAGE(FILTER(F2:F62, F2:F62 > 0))"),0.4714341962079) -> 0.4714342 | G68: =IFERROR(__xludf.DUMMYFUNCTION("AVERAGE(FILTER(G2:G62, G2:G62 > 0))"),0.48393908796021057) -> 0.48393909 | H68: =IFERROR(__xludf.DUMMYFUNCTION("AVERAGE(FILTER(H2:H62, H2:H62 > 0))"),0.5078317939440012) -> 0.50783179 | I68: =IFERROR(__xludf.DUMMYFUNCTION("AVERAGE(FILTER(I2:I62, I2:I62 > 0))"),0.5906229326673832) -> 0.59062293 | J68: =IFERROR(__xludf.DUMMYFUNCTION("AVERAGE(FILTER(J2:J62, J2:J62 > 0))"),0.4291233484856047) -> 0.42912335 | K68: =IFERROR(__xludf.DUMMYFUNCTION("AVERAGE(FILTER(K2:K62, K2:K62 > 0))"),0.31863251116790586) -> 0.31863251 | L68: =IFERROR(__xludf.DUMMYFUNCTION("AVERAGE(FILTER(L2:L62, L2:L62 > 0))"),0.4496503496489216) -> 0.44965035 | M68: =IFERROR(__xludf.DUMMYFUNCTION("AVERAGE(FILTER(M2:M62, M2:M62 > 0))"),0.6122024321360294) -> 0.61220243 | N68: =IFERROR(__xludf.DUMMYFUNCTION("AVERAGE(FILTER(N2:N62, N2:N62 > 0))"),0.59001379878475) -> 0.5900138 | O68: =IFERROR(__xludf.DUMMYFUNCTION("AVERAGE(FILTER(O2:O62, O2:O62 > 0))"),0.41576267845017306) -> 0.41576268 | P68: =IFERROR(__xludf.DUMMYFUNCTION("AVERAGE(FILTER(P2:P62, P2:P62 > 0))"),0.6028591902204153) -> 0.60285919
E69: Avg -ve | F69: =IFERROR(__xludf.DUMMYFUNCTION("AVERAGE(FILTER(F2:F62, F2:F62 < 0))"),-0.6101940881592866) -> -0.61019409 | G69: =IFERROR(__xludf.DUMMYFUNCTION("AVERAGE(FILTER(G2:G62, G2:G62 < 0))"),-0.8660450371098891) -> -0.86604504 | H69: =IFERROR(__xludf.DUMMYFUNCTION("AVERAGE(FILTER(H2:H62, H2:H62 < 0))"),-0.8858378167089419) -> -0.88583782 | I69: =IFERROR(__xludf.DUMMYFUNCTION("AVERAGE(FILTER(I2:I62, I2:I62 < 0))"),-0.8740451999227865) -> -0.8740452 | J69: =IFERROR(__xludf.DUMMYFUNCTION("AVERAGE(FILTER(J2:J62, J2:J62 < 0))"),-0.6668824165271937) -> -0.66688242 | K69: =IFERROR(__xludf.DUMMYFUNCTION("AVERAGE(FILTER(K2:K62, K2:K62 < 0))"),-0.42568746970707305) -> -0.42568747 | L69: =IFERROR(__xludf.DUMMYFUNCTION("AVERAGE(FILTER(L2:L62, L2:L62 < 0))"),-0.45623010196044583) -> -0.4562301 | M69: =IFERROR(__xludf.DUMMYFUNCTION("AVERAGE(FILTER(M2:M62, M2:M62 < 0))"),-1.112114433224547) -> -1.1121144 | N69: =IFERROR(__xludf.DUMMYFUNCTION("AVERAGE(FILTER(N2:N62, N2:N62 < 0))"),-0.9562280946126359) -> -0.95622809 | O69: =IFERROR(__xludf.DUMMYFUNCTION("AVERAGE(FILTER(O2:O62, O2:O62 < 0))"),-0.5192338237835951) -> -0.51923382 | P69: =IFERROR(__xludf.DUMMYFUNCTION("AVERAGE(FILTER(P2:P62, P2:P62 < 0))"),-1.993502568975159) -> -1.9935026

Sheet Analysis
B1: Top scorers | C1: Worst scorers | D1: Net score
A2: Entertainment | B2: Andrew, Eileen | C2: Kate, Lachy/Dad | D2: =sumif(Statements!$D$2:$D$61,A2,Statements!$Q$2:$Q$61) -> -5.9540054 | E2: =countif(Statements!$D$2:$D$61,A2) -> 10 | F2: =D2/E2 -> -0.59540054
A3: Family | B3: Dad, Rohan | C3: Kate | D3: =sumif(Statements!$D$2:$D$61,A3,Statements!$Q$2:$Q$61) -> 3.1313485 | E3: =countif(Statements!$D$2:$D$61,A3) -> 2 | F3: =D3/E3 -> 1.5656742
A4: Finance | B4: Lachy | C4: James | D4: =sumif(Statements!$D$2:$D$61,A4,Statements!$Q$2:$Q$61) -> 2.8354156 | E4: =countif(Statements!$D$2:$D$61,A4) -> 1 | F4: =D4/E4 -> 2.8354156
A5: Law | B5: Jac | C5: James, Dad | D5: =sumif(Statements!$D$2:$D$61,A5,Statements!$Q$2:$Q$61) -> 2.9621112 | E5: =countif(Statements!$D$2:$D$61,A5) -> 5 | F5: =D5/E5 -> 0.59242224
A6: Nature | B6: Lachy | C6: Boof, James | D6: =sumif(Statements!$D$2:$D$61,A6,Statements!$Q$2:$Q$61) -> -7.568833 | E6: =countif(Statements!$D$2:$D$61,A6) -> 3 | F6: =D6/E6 -> -2.5229443
A7: Politics | B7: James, Boof | C7: Eileen, Dad | D7: =sumif(Statements!$D$2:$D$61,A7,Statements!$Q$2:$Q$61) -> 17.660356 | E7: =countif(Statements!$D$2:$D$61,A7) -> 12 | F7: =D7/E7 -> 1.4716963
A8: Religion | B8: Jac, Lachy, Rohan | C8: Gael | D8: =sumif(Statements!$D$2:$D$61,A8,Statements!$Q$2:$Q$61) -> 3.5605557 | E8: =countif(Statements!$D$2:$D$61,A8) -> 1 | F8: =D8/E8 -> 3.5605557
A9: Royals | B9: Kate, Boof, James | C9: Eileen | D9: =sumif(Statements!$D$2:$D$61,A9,Statements!$Q$2:$Q$61) -> 14.525842 | E9: =countif(Statements!$D$2:$D$61,A9) -> 4 | F9: =D9/E9 -> 3.6314604
A10: Society | B10: Lachy/Dad, Jac | C10: Kate | D10: =sumif(Statements!$D$2:$D$61,A10,Statements!$Q$2:$Q$61) -> 3.1383893 | E10: =countif(Statements!$D$2:$D$61,A10) -> 5 | F10: =D10/E10 -> 0.62767786
A11: Sport | B11: James, Jac | C11: Andrew, Eileen | D11: =sumif(Statements!$D$2:$D$61,A11,Statements!$Q$2:$Q$61) -> -2.1396119 | E11: =countif(Statements!$D$2:$D$61,A11) -> 11 | F11: =D11/E11 -> -0.19451017
A12: Technology | B12: Gael/Dad | C12: Boof, Eileen | D12: =sumif(Statements!$D$2:$D$61,A12,Statements!$Q$2:$Q$61) -> -13.333027 | E12: =countif(Statements!$D$2:$D$61,A12) -> 6 | F12: =D12/E12 -> -2.2221712

Sheet Andrew
A1: =Statements!A1 -> Number | B1: =Statements!B1 -> Prediction | C1: Probability | D1: Score | E1: Category
A2: =Statements!A2 -> 1 | B2: =Statements!B2 -> ”What was I made for?” (Billie Eilish) wins Best Music - Original Song at the Oscars | C2: 0.8 | D2: =vlookup($A2,Statements!$A$2:$P$61,6,TRUE) | E2: =vlookup($A2,Statements!$A$2:$P$61,4,TRUE) -> Entertainment
A3: =Statements!A3 -> 2 | B3: =Statements!B3 -> NewJeans surpass 13M subscribers on instagram (currently 11.3M) | C3: 0.9 | D3: =vlookup($A3,Statements!$A$2:$P$61,6,TRUE) -> 0.84799691 | E3: =vlookup($A3,Statements!$A$2:$P$61,4,TRUE) -> Entertainment
A4: =Statements!A4 -> 3 | B4: =Statements!B4 -> Timothee and Kylie break up | C4: 0.65 | D4: =vlookup($A4,Statements!$A$2:$P$61,6,TRUE) -> -0.51457317 | E4: =vlookup($A4,Statements!$A$2:$P$61,4,TRUE) -> Entertainment
A5: =Statements!A5 -> 4 | B5: =Statements!B5 -> A guest on Hot Ones will not complete the full set of hot sauces/wings | C5: 0.2 | D5: =vlookup($A5,Statements!$A$2:$P$61,6,TRUE) -> 0.67807191 | E5: =vlookup($A5,Statements!$A$2:$P$61,4,TRUE) -> Entertainment
A6: =Statements!A6 -> 5 | B6: =Statements!B6 -> An alone participant in a 2024 season (Australia/Denmark/UK) will fall ill from eating poisonous fruit they misidentify | C6: 0.75 | D6: =vlookup($A6,Statements!$A$2:$P$61,6,TRUE) -> 0.5849625 | E6: =vlookup($A6,Statements!$A$2:$P$61,4,TRUE) -> Entertainment
A7: =Statements!A7 -> 6 | B7: =Statements!B7 -> An Australian or New Zealand restaurant will feature on the 2024 "World's 50 Best Restaurants" list | C7: 0.3 | D7: =vlookup($A7,Statements!$A$2:$P$61,6,TRUE) -> 0.48542683 | E7: =vlookup($A7,Statements!$A$2:$P$61,4,TRUE) -> Entertainment
A8: =Statements!A8 -> 7 | B8: =Statements!B8 -> Dex (Kim Jin Young) will feature as a guest or star in a food-based show available on Netflix AU/NZ | C8: 0.35 | D8: =vlookup($A8,Statements!$A$2:$P$61,6,TRUE) -> 0.37851162 | E8: =vlookup($A8,Statements!$A$2:$P$61,4,TRUE) -> Entertainment
A9: =Statements!A9 -> 8 | B9: =Statements!B9 -> Taylor will break up with Travis | C9: 0.55 | D9: =vlookup($A9,Statements!$A$2:$P$61,6,TRUE) -> -0.15200309 | E9: =vlookup($A9,Statements!$A$2:$P$61,4,TRUE) -> Entertainment
A10: =Statements!A10 -> 9 | B10: =Statements!B10 -> Taylor will release the re-record of her debut album in 2024. | C10: 0.4 | D10: =vlookup($A10,Statements!$A$2:$P$61,6,TRUE) -> 0.26303441 | E10: =vlookup($A10,Statements!$A$2:$P$61,4,TRUE) -> Entertainment
A11: =Statements!A11 -> 10 | B11: =Statements!B11 -> Barbie will win best picture at the academy awards. | C11: 0.3 | D11: =vlookup($A11,Statements!$A$2:$P$61,6,TRUE) | E11: =vlookup($A11,Statements!$A$2:$P$61,4,TRUE) -> Entertainment
A12: =Statements!A12 -> 11 | B12: =Statements!B12 -> Kate will win at least two prizes for her Phillip and Bennelong book. | C12: 0.75 | D12: =vlookup($A12,Statements!$A$2:$P$61,6,TRUE) -> 0.5849625 | E12: =vlookup($A12,Statements!$A$2:$P$61,4,TRUE) -> Family
A13: =Statements!A13 -> 12 | B13: =Statements!B13 -> Baby Starmeadow will be under 50cm long at birth (Oz average is 50.8cm). | C13: NA | D13: =vlookup($A13,Statements!$A$2:$P$61,6,TRUE) | E13: =vlookup($A13,Statements!$A$2:$P$61,4,TRUE) -> Family
A14: =Statements!A14 -> 13 | B14: =Statements!B14 -> The Reserve Bank will announce at least three interest rate reductions in 2024 | C14: 0.3 | D14: =vlookup($A14,Statements!$A$2:$P$61,6,TRUE) -> 0.48542683 | E14: =vlookup($A14,Statements!$A$2:$P$61,4,TRUE) -> Finance
A15: =Statements!A15 -> 14 | B15: =Statements!B15 -> Bruce Lehrmann will be awarded damages | C15: 0.2 | D15: =vlookup($A15,Statements!$A$2:$P$61,6,TRUE) -> 0.67807191 | E15: =vlookup($A15,Statements!$A$2:$P$61,4,TRUE) -> Law
A16: =Statements!A16 -> 15 | B16: =Statements!B16 -> Chinese courts will refuse Evergrande liquidators’ requests to seize the developer’s assets in mainland China | C16: 0.3 | D16: =vlookup($A16,Statements!$A$2:$P$61,6,TRUE) -> 0.48542683 | E16: =vlookup($A16,Statements!$A$2:$P$61,4,TRUE) -> Law
A17: =Statements!A17 -> 16 | B17: =Statements!B17 -> David McBride will be sentenced to a lifetime jail sentence | C17: 0.4 | D17: =vlookup($A17,Statements!$A$2:$P$61,6,TRUE) -> 0.26303441 | E17: =vlookup($A17,Statements!$A$2:$P$61,4,TRUE) -> Law
A18: =Statements!A18 -> 17 | B18: =Statements!B18 -> The federal court will find that Bruce Lehrmann was not defamed | C18: 0.65 | D18: =vlookup($A18,Statements!$A$2:$P$61,6,TRUE) -> 0.37851162 | E18: =vlookup($A18,Statements!$A$2:$P$61,4,TRUE) -> Law
A19: =Statements!A19 -> 18 | B19: =Statements!B19 -> OpenAI successfully defends the New York Times' claim on the basis of fair use | C19: 0.55 | D19: =vlookup($A19,Statements!$A$2:$P$61,6,TRUE) -> -0.15200309 | E19: =vlookup($A19,Statements!$A$2:$P$61,4,TRUE) -> Law
A20: =Statements!A20 -> 19 | B20: =Statements!B20 -> 2024 will be the hottest European summer on record. | C20: 0.6 | D20: =vlookup($A20,Statements!$A$2:$P$61,6,TRUE) -> 0.26303441 | E20: =vlookup($A20,Statements!$A$2:$P$61,4,TRUE) -> Nature
A21: =Statements!A21 -> 20 | B21: =Statements!B21 -> The NOAA will announce an alert level 5 bleaching event on the Great Barrier Reef | C21: 0.65 | D21: =vlookup($A21,Statements!$A$2:$P$61,6,TRUE) -> -0.51457317 | E21: =vlookup($A21,Statements!$A$2:$P$61,4,TRUE) -> Nature
A22: =Statements!A22 -> 21 | B22: =Statements!B22 -> At least three cyclones will drench North Queensland before the end of the year. | C22: 0.35 | D22: =vlookup($A22,Statements!$A$2:$P$61,6,TRUE) -> 0.37851162 | E22: =vlookup($A22,Statements!$A$2:$P$61,4,TRUE) -> Nature
A23: =Statements!A23 -> 22 | B23: =Statements!B23 -> A head of state or relevant minister from an island nation will declare their geographic country no longer inhabitable in the long term, due to climate-related issues. This will include a commitment to relevant action of some kind | C23: 0.1 | D23: =vlookup($A23,Statements!$A$2:$P$61,6,TRUE) -> 0.84799691 | E23: =vlookup($A23,Statements!$A$2:$P$61,4,TRUE) -> Politics
A24: =Statements!A24 -> 23 | B24: =Statements!B24 -> Trump will promise to enact an order or legislation with the express intention of negatively impacting Taylor Swift | C24: 0.55 | D24: =vlookup($A24,Statements!$A$2:$P$61,6,TRUE) -> -0.15200309 | E24: =vlookup($A24,Statements!$A$2:$P$61,4,TRUE) -> Politics
A25: =Statements!A25 -> 24 | B25: =Statements!B25 -> Netanyahu will lose the prime ministership of Israel during 2024 | C25: 0.3 | D25: =vlookup($A25,Statements!$A$2:$P$61,6,TRUE) -> 0.48542683 | E25: =vlookup($A25,Statements!$A$2:$P$61,4,TRUE) -> Politics
... A61: =Statements!A61 -> 60 | B61: =Statements!B61 -> A reputable newspaper publishes a story that Kate Middleton's disappearance is linked to William getting funky with Lady Rose Hanbury (otherwise known as: the Marchioness of Molmondeley) | C61: 0.5 | D61: =vlookup($A61,Statements!$A$2:$P$61,6,TRUE) | E61: =vlookup($A61,Statements!$A$2:$P$61,4,TRUE) -> Royals
A62: =Statements!A62 | B62: =Statements!B62
A63: =Statements!A63 | C63: Highest scoring prediction | D63: =MAX($D$2:$D$61) -> 0.84799691
A64: =Statements!A64 | B64: =Statements!B64 | C64: Lowest scoring prediction | D64: =MIN($D$2:$D$61) -> -2.3219281 | E64: min | F64: max
A65: =Statements!A65 | B65: =Statements!B65 | C65: Entertainment | D65: =sumif($E$2:$E$61,$C65,$D$2:$D$61) -> 2.5714279 | E65: =min(Andrew!D65,Bruce!D65,Eileen!D65,Gael!D65,Iain!D65,Jac!D65,James!D65,Kate!D65,Lachy!D65,Pete!D65,Rohan!D65) -> -5.1766811 | F65: =max(Andrew!D65,Bruce!D65,Eileen!D65,Gael!D65,Iain!D65,Jac!D65,James!D65,Kate!D65,Lachy!D65,Pete!D65,Rohan!D65) -> 2.5714279
A66: =Statements!A66 | B66: =Statements!B66 | C66: Family | D66: =sumif($E$2:$E$61,$C66,$D$2:$D$61) -> 0.5849625 | E66: =min(Andrew!D66,Bruce!D66,Eileen!D66,Gael!D66,Iain!D66,Jac!D66,James!D66,Kate!D66,Lachy!D66,Pete!D66,Rohan!D66) -> -1.3219281 | F66: =max(Andrew!D66,Bruce!D66,Eileen!D66,Gael!D66,Iain!D66,Jac!D66,James!D66,Kate!D66,Lachy!D66,Pete!D66,Rohan!D66) -> 0.67807191
A67: =Statements!A67 | B67: =Statements!B67 | C67: Finance | D67: =sumif($E$2:$E$61,$C67,$D$2:$D$61) -> 0.48542683 | E67: =min(Andrew!D67,Bruce!D67,Eileen!D67,Gael!D67,Iain!D67,Jac!D67,James!D67,Kate!D67,Lachy!D67,Pete!D67,Rohan!D67) -> -0.73696559 | F67: =max(Andrew!D67,Bruce!D67,Eileen!D67,Gael!D67,Iain!D67,Jac!D67,James!D67,Kate!D67,Lachy!D67,Pete!D67,Rohan!D67) -> 0.67807191
A68: =Statements!A68 | B68: =Statements!B68 | C68: Law | D68: =sumif($E$2:$E$61,$C68,$D$2:$D$61) -> 1.6530417 | E68: =min(Andrew!D68,Bruce!D68,Eileen!D68,Gael!D68,Iain!D68,Jac!D68,James!D68,Kate!D68,Lachy!D68,Pete!D68,Rohan!D68) -> -1.3808218 | F68: =max(Andrew!D68,Bruce!D68,Eileen!D68,Gael!D68,Iain!D68,Jac!D68,James!D68,Kate!D68,Lachy!D68,Pete!D68,Rohan!D68) -> 2.4347536
A69: =Statements!A69 | B69: =Statements!B69 | C69: Nature | D69: =sumif($E$2:$E$61,$C69,$D$2:$D$61) -> 0.12697286 | E69: =min(Andrew!D69,Bruce!D69,Eileen!D69,Gael!D69,Iain!D69,Jac!D69,James!D69,Kate!D69,Lachy!D69,Pete!D69,Rohan!D69) -> -4.895395 | F69: =max(Andrew!D69,Bruce!D69,Eileen!D69,Gael!D69,Iain!D69,Jac!D69,James!D69,Kate!D69,Lachy!D69,Pete!D69,Rohan!D69) -> 2.0114956
C70: Politics | D70: =sumif($E$2:$E$61,$C70,$D$2:$D$61) -> 1.4085526 | E70: =min(Andrew!D70,Bruce!D70,Eileen!D70,Gael!D70,Iain!D70,Jac!D70,James!D70,Kate!D70,Lachy!D70,Pete!D70,Rohan!D70) -> -2.2091025 | F70: =max(Andrew!D70,Bruce!D70,Eileen!D70,Gael!D70,Iain!D70,Jac!D70,James!D70,Kate!D70,Lachy!D70,Pete!D70,Rohan!D70) -> 4.9202414
C71: Religion | D71: =sumif($E$2:$E$61,$C71,$D$2:$D$61) -> 0.48542683 | E71: =min(Andrew!D71,Bruce!D71,Eileen!D71,Gael!D71,Iain!D71,Jac!D71,James!D71,Kate!D71,Lachy!D71,Pete!D71,Rohan!D71) -> -0.73696559 | F71: =max(Andrew!D71,Bruce!D71,Eileen!D71,Gael!D71,Iain!D71,Jac!D71,James!D71,Kate!D71,Lachy!D71,Pete!D71,Rohan!D71) -> 0.84799691
C72: Royals | D72: =sumif($E$2:$E$61,$C72,$D$2:$D$61) -> 1.1940871 | E72: =min(Andrew!D72,Bruce!D72,Eileen!D72,Gael!D72,Iain!D72,Jac!D72,James!D72,Kate!D72,Lachy!D72,Pete!D72,Rohan!D72) -> -0.073393259 | F72: =max(Andrew!D72,Bruce!D72,Eileen!D72,Gael!D72,Iain!D72,Jac!D72,James!D72,Kate!D72,Lachy!D72,Pete!D72,Rohan!D72) -> 2.4520682
C73: Society | D73: =sumif($E$2:$E$61,$C73,$D$2:$D$61) -> -0.24004313 | E73: =min(Andrew!D73,Bruce!D73,Eileen!D73,Gael!D73,Iain!D73,Jac!D73,James!D73,Kate!D73,Lachy!D73,Pete!D73,Rohan!D73) -> -0.79585928 | F73: =max(Andrew!D73,Bruce!D73,Eileen!D73,Gael!D73,Iain!D73,Jac!D73,James!D73,Kate!D73,Lachy!D73,Pete!D73,Rohan!D73) -> 1.5196425
C74: Sport | D74: =sumif($E$2:$E$61,$C74,$D$2:$D$61) -> -2.9952604 | E74: =min(Andrew!D74,Bruce!D74,Eileen!D74,Gael!D74,Iain!D74,Jac!D74,James!D74,Kate!D74,Lachy!D74,Pete!D74,Rohan!D74) -> -2.9952604 | F74: =max(Andrew!D74,Bruce!D74,Eileen!D74,Gael!D74,Iain!D74,Jac!D74,James!D74,Kate!D74,Lachy!D74,Pete!D74,Rohan!D74) -> 3.2084138
C75: Technology | D75: =sumif($E$2:$E$61,$C75,$D$2:$D$61) -> 0.24210857 | E75: =min(Andrew!D75,Bruce!D75,Eileen!D75,Gael!D75,Iain!D75,Jac!D75,James!D75,Kate!D75,Lachy!D75,Pete!D75,Rohan!D75) -> -4.2913236 | F75: =max(Andrew!D75,Bruce!D75,Eileen!D75,Gael!D75,Iain!D75,Jac!D75,James!D75,Kate!D75,Lachy!D75,Pete!D75,Rohan!D75) -> 1.8530663

Sheet Bruce
A1: =Statements!A1 -> Number | B1: =Statements!B1 -> Prediction | C1: Probability | D1: Score | E1: Category
A2: =Statements!A2 -> 1 | B2: =Statements!B2 -> ”What was I made for?” (Billie Eilish) wins Best Music - Original Song at the Oscars | C2: 0.6 | D2: =vlookup($A2,Statements!$A$2:$P$61,16,TRUE) | E2: =vlookup($A2,Statements!$A$2:$P$61,4,TRUE) -> Entertainment
A3: =Statements!A3 -> 2 | B3: =Statements!B3 -> NewJeans surpass 13M subscribers on instagram (currently 11.3M) | C3: 0.99 | D3: =vlookup($A3,Statements!$A$2:$P$61,16,TRUE) -> 0.98550043 | E3: =vlookup($A3,Statements!$A$2:$P$61,4,TRUE) -> Entertainment
A4: =Statements!A4 -> 3 | B4: =Statements!B4 -> Timothee and Kylie break up | C4: 0.5 | D4: =vlookup($A4,Statements!$A$2:$P$61,16,TRUE) -> 0 | E4: =vlookup($A4,Statements!$A$2:$P$61,4,TRUE) -> Entertainment
A5: =Statements!A5 -> 4 | B5: =Statements!B5 -> A guest on Hot Ones will not complete the full set of hot sauces/wings | C5: 0.4 | D5: =vlookup($A5,Statements!$A$2:$P$61,16,TRUE) -> 0.26303441 | E5: =vlookup($A5,Statements!$A$2:$P$61,4,TRUE) -> Entertainment
A6: =Statements!A6 -> 5 | B6: =Statements!B6 -> An alone participant in a 2024 season (Australia/Denmark/UK) will fall ill from eating poisonous fruit they misidentify | C6: 0.3 | D6: =vlookup($A6,Statements!$A$2:$P$61,16,TRUE) -> -0.73696559 | E6: =vlookup($A6,Statements!$A$2:$P$61,4,TRUE) -> Entertainment
A7: =Statements!A7 -> 6 | B7: =Statements!B7 -> An Australian or New Zealand restaurant will feature on the 2024 "World's 50 Best Restaurants" list | C7: 0.4 | D7: =vlookup($A7,Statements!$A$2:$P$61,16,TRUE) -> 0.26303441 | E7: =vlookup($A7,Statements!$A$2:$P$61,4,TRUE) -> Entertainment
A8: =Statements!A8 -> 7 | B8: =Statements!B8 -> Dex (Kim Jin Young) will feature as a guest or star in a food-based show available on Netflix AU/NZ | C8: 0.4 | D8: =vlookup($A8,Statements!$A$2:$P$61,16,TRUE) -> 0.26303441 | E8: =vlookup($A8,Statements!$A$2:$P$61,4,TRUE) -> Entertainment
A9: 8 | B9: =Statements!B9 -> Taylor will break up with Travis | C9: 0.4 | D9: =vlookup($A9,Statements!$A$2:$P$61,16,TRUE) -> 0.26303441 | E9: =vlookup($A9,Statements!$A$2:$P$61,4,TRUE) -> Entertainment
A10: 9 | B10: =Statements!B10 -> Taylor will release the re-record of her debut album in 2024. | C10: 0.35 | D10: =vlookup($A10,Statements!$A$2:$P$61,16,TRUE) -> 0.37851162 | E10: =vlookup($A10,Statements!$A$2:$P$61,4,TRUE) -> Entertainment
A11: 10 | B11: =Statements!B11 -> Barbie will win best picture at the academy awards. | C11: 0.05 | D11: =vlookup($A11,Statements!$A$2:$P$61,16,TRUE) | E11: =vlookup($A11,Statements!$A$2:$P$61,4,TRUE) -> Entertainment
A12: 11 | B12: =Statements!B12 -> Kate will win at least two prizes for her Phillip and Bennelong book. | C12: 0.6 | D12: =vlookup($A12,Statements!$A$2:$P$61,16,TRUE) -> 0.26303441 | E12: =vlookup($A12,Statements!$A$2:$P$61,4,TRUE) -> Family
A13: =Statements!A13 -> 12 | B13: =Statements!B13 -> Baby Starmeadow will be under 50cm long at birth (Oz average is 50.8cm). | C13: 0.8 | D13: =vlookup($A13,Statements!$A$2:$P$61,16,TRUE) | E13: =vlookup($A13,Statements!$A$2:$P$61,4,TRUE) -> Family
A14: =Statements!A14 -> 13 | B14: =Statements!B14 -> The Reserve Bank will announce at least three interest rate reductions in 2024 | C14: 0.3 | D14: =vlookup($A14,Statements!$A$2:$P$61,16,TRUE) -> 0.48542683 | E14: =vlookup($A14,Statements!$A$2:$P$61,4,TRUE) -> Finance
A15: =Statements!A15 -> 14 | B15: =Statements!B15 -> Bruce Lehrmann will be awarded damages | C15: 0.1 | D15: =vlookup($A15,Statements!$A$2:$P$61,16,TRUE) -> 0.84799691 | E15: =vlookup($A15,Statements!$A$2:$P$61,4,TRUE) -> Law
A16: =Statements!A16 -> 15 | B16: =Statements!B16 -> Chinese courts will refuse Evergrande liquidators’ requests to seize the developer’s assets in mainland China | C16: 0.8 | D16: =vlookup($A16,Statements!$A$2:$P$61,16,TRUE) -> -1.3219281 | E16: =vlookup($A16,Statements!$A$2:$P$61,4,TRUE) -> Law
A17: =Statements!A17 -> 16 | B17: =Statements!B17 -> David McBride will be sentenced to a lifetime jail sentence | C17: 0.1 | D17: =vlookup($A17,Statements!$A$2:$P$61,16,TRUE) -> 0.84799691 | E17: =vlookup($A17,Statements!$A$2:$P$61,4,TRUE) -> Law
A18: =Statements!A18 -> 17 | B18: =Statements!B18 -> The federal court will find that Bruce Lehrmann was not defamed | C18: 0.8 | D18: =vlookup($A18,Statements!$A$2:$P$61,16,TRUE) -> 0.67807191 | E18: =vlookup($A18,Statements!$A$2:$P$61,4,TRUE) -> Law
A19: =Statements!A19 -> 18 | B19: =Statements!B19 -> OpenAI successfully defends the New York Times' claim on the basis of fair use | C19: 0.6 | D19: =vlookup($A19,Statements!$A$2:$P$61,16,TRUE) -> -0.32192809 | E19: =vlookup($A19,Statements!$A$2:$P$61,4,TRUE) -> Law
A20: =Statements!A20 -> 19 | B20: 2024 will be the hottest European summer on record | C20: 0.01 | D20: =vlookup($A20,Statements!$A$2:$P$61,16,TRUE) -> -5.6438562 | E20: =vlookup($A20,Statements!$A$2:$P$61,4,TRUE) -> Nature
A21: =Statements!A21 -> 20 | B21: The NOAA will announce an alert level 5 bleaching event on the Great Barrier Reef | C21: 0.4 | D21: =vlookup($A21,Statements!$A$2:$P$61,16,TRUE) -> 0.26303441 | E21: =vlookup($A21,Statements!$A$2:$P$61,4,TRUE) -> Nature
A22: =Statements!A22 -> 21 | B22: =Statements!B22 -> At least three cyclones will drench North Queensland before the end of the year. | C22: 0.3 | D22: =vlookup($A22,Statements!$A$2:$P$61,16,TRUE) -> 0.48542683 | E22: =vlookup($A22,Statements!$A$2:$P$61,4,TRUE) -> Nature
A23: =Statements!A23 -> 22 | B23: =Statements!B23 -> A head of state or relevant minister from an island nation will declare their geographic country no longer inhabitable in the long term, due to climate-related issues. This will include a commitment to relevant action of some kind | C23: 0.4 | D23: =vlookup($A23,Statements!$A$2:$P$61,16,TRUE) -> 0.26303441 | E23: =vlookup($A23,Statements!$A$2:$P$61,4,TRUE) -> Politics
A24: =Statements!A24 -> 23 | B24: =Statements!B24 -> Trump will promise to enact an order or legislation with the express intention of negatively impacting Taylor Swift | C24: 0.05 | D24: =vlookup($A24,Statements!$A$2:$P$61,16,TRUE) -> 0.92599942 | E24: =vlookup($A24,Statements!$A$2:$P$61,4,TRUE) -> Politics
A25: =Statements!A25 -> 24 | B25: =Statements!B25 -> Netanyahu will lose the prime ministership of Israel during 2024 | C25: 0.3 | D25: =vlookup($A25,Statements!$A$2:$P$61,16,TRUE) -> 0.48542683 | E25: =vlookup($A25,Statements!$A$2:$P$61,4,TRUE) -> Politics
A26: =Statements!A26 -> 25 | B26: =Statements!B26 -> There will be an Australian Federal election in 2024 | C26: 0.01 | D26: =vlookup($A26,Statements!$A$2:$P$61,16,TRUE) -> 0.98550043 | E26: =vlookup($A26,Statements!$A$2:$P$61,4,TRUE) -> Politics
A27: =Statements!A27 -> 26 | B27: =Statements!B27 -> Donald Trump will get less of the Popular vote than the Democratic candidate. | C27: 0.95 | D27: =vlookup($A27,Statements!$A$2:$P$61,16,TRUE) -> -3.3219281 | E27: =vlookup($A27,Statements!$A$2:$P$61,4,TRUE) -> Politics
A28: =Statements!A28 -> 27 | B28: =Statements!B28 -> An Australian Aboriginal organisation will sign at least one state-based treaty this year. | C28: 0.01 | D28: =vlookup($A28,Statements!$A$2:$P$61,16,TRUE) -> 0.98550043 | E28: =vlookup($A28,Statements!$A$2:$P$61,4,TRUE) -> Politics
A29: =Statements!A29 -> 28 | B29: Donald Trump will not go to prison this year | C29: 0.95 | D29: =vlookup($A29,Statements!$A$2:$P$61,16,TRUE) -> 0.92599942 | E29: =vlookup($A29,Statements!$A$2:$P$61,4,TRUE) -> Politics
A30: =Statements!A30 -> 29 | B30: Modi will be re-elected in the upcoming Indian election | C30: 0.99 | D30: =vlookup($A30,Statements!$A$2:$P$61,16,TRUE) -> 0.98550043 | E30: =vlookup($A30,Statements!$A$2:$P$61,4,TRUE) -> Politics
A31: =Statements!A31 -> 30 | B31: Josh Frydenberg returns to politics, specifically, announces he will contest Kooyong | C31: 0.01 | D31: =vlookup($A31,Statements!$A$2:$P$61,16,TRUE) -> 0.98550043 | E31: =vlookup($A31,Statements!$A$2:$P$61,4,TRUE) -> Politics
A32: =Statements!A32 -> 31 | B32: =Statements!B32 -> The 2024 US Presidential election result will instigate widespread (multiple cities) violent (with injuries or deaths) unrest | C32: 0.3 | D32: =vlookup($A32,Statements!$A$2:$P$61,16,TRUE) -> 0.48542683 | E32: =vlookup($A32,Statements!$A$2:$P$61,4,TRUE) -> Politics
A33: =Statements!A33 -> 32 | B33: =Statements!B33 -> Taylor swift will be credited/mentioned in U.S legislation created this year. | C33: 0.3 | D33: =vlookup($A33,Statements!$A$2:$P$61,16,TRUE) -> 0.48542683 | E33: =vlookup($A33,Statements!$A$2:$P$61,4,TRUE) -> Politics
A34: =Statements!A34 -> 33 | B34: =Statements!B34 -> The guardian Australia will publish more articles covering the UK election than the Russian and Ukrainian elections combined. | C34: 0.7 | D34: =vlookup($A34,Statements!$A$2:$P$61,16,TRUE) -> 0.48542683 | E34: =vlookup($A34,Statements!$A$2:$P$61,4,TRUE) -> Politics
A35: =Statements!A35 -> 34 | B35: =Statements!B35 -> Pope Francis will retire. | C35: 0.6 | D35: =vlookup($A35,Statements!$A$2:$P$61,16,TRUE) -> -0.32192809 | E35: =vlookup($A35,Statements!$A$2:$P$61,4,TRUE) -> Religion
A36: =Statements!A36 -> 35 | B36: =Statements!B36 -> King Charles will announce his abdication of the throne | C36: 0.01 | D36: =vlookup($A36,Statements!$A$2:$P$61,16,TRUE) -> 0.98550043 | E36: =vlookup($A36,Statements!$A$2:$P$61,4,TRUE) -> Royals
A37: =Statements!A37 -> 36 | B37: =Statements!B37 -> Prince Andrew remains resident of the Royal Lodge until 15 Dec 2024 | C37: 0.6 | D37: =vlookup($A37,Statements!$A$2:$P$61,16,TRUE) -> 0.26303441 | E37: =vlookup($A37,Statements!$A$2:$P$61,4,TRUE) -> Royals
A38: =Statements!A38 -> 37 | B38: =Statements!B38 -> Prince Charles' cancer will go into remission in 2024 and he will publically attribute this success to at least one of: - A naturopathic or homeopathic regimen, including 'fresh air' or tramping through the Scottish countryside, or - God determining that his work as King was not yet done | C38: 0.05 | D38: =vlookup($A38,Statements!$A$2:$P$61,16,TRUE) -> 0.92599942 | E38: =vlookup($A38,Statements!$A$2:$P$61,4,TRUE) -> Royals
A39: =Statements!A39 -> 38 | B39: =Statements!B39 -> A direct flight between Canberra and Queenstown will commence and run at regular intervals (at least fortnightly, completing at least 3 cycles of its schedule) | C39: 0.3 | D39: =vlookup($A39,Statements!$A$2:$P$61,16,TRUE) -> 0.48542683 | E39: =vlookup($A39,Statements!$A$2:$P$61,4,TRUE) -> Society
A40: =Statements!A40 -> 39 | B40: =Statements!B40 -> Canberra restaurants will have more than 30 hats by the end of 2024 as per the Australian Good Food Guide | C40: 0.5 | D40: =vlookup($A40,Statements!$A$2:$P$61,16,TRUE) -> 0 | E40: =vlookup($A40,Statements!$A$2:$P$61,4,TRUE) -> Society
...

Sheet Eileen
A1: =Statements!A1 -> Number | B1: =Statements!B1 -> Prediction | C1: Probability | D1: Score | E1: Category
A2: =Statements!A2 -> 1 | B2: =Statements!B2 -> ”What was I made for?” (Billie Eilish) wins Best Music - Original Song at the Oscars | C2: 0.85 | D2: =vlookup($A2,Statements!$A$2:$P$61,7,TRUE) | E2: =vlookup($A2,Statements!$A$2:$P$61,4,TRUE) -> Entertainment
A3: =Statements!A3 -> 2 | B3: =Statements!B3 -> NewJeans surpass 13M subscribers on instagram (currently 11.3M) | C3: 0.9 | D3: =vlookup($A3,Statements!$A$2:$P$61,7,TRUE) -> 0.84799691 | E3: =vlookup($A3,Statements!$A$2:$P$61,4,TRUE) -> Entertainment
A4: =Statements!A4 -> 3 | B4: =Statements!B4 -> Timothee and Kylie break up | C4: 0.7 | D4: =vlookup($A4,Statements!$A$2:$P$61,7,TRUE) -> -0.73696559 | E4: =vlookup($A4,Statements!$A$2:$P$61,4,TRUE) -> Entertainment
A5: =Statements!A5 -> 4 | B5: =Statements!B5 -> A guest on Hot Ones will not complete the full set of hot sauces/wings | C5: 0.1 | D5: =vlookup($A5,Statements!$A$2:$P$61,7,TRUE) -> 0.84799691 | E5: =vlookup($A5,Statements!$A$2:$P$61,4,TRUE) -> Entertainment
A6: =Statements!A6 -> 5 | B6: =Statements!B6 -> An alone participant in a 2024 season (Australia/Denmark/UK) will fall ill from eating poisonous fruit they misidentify | C6: 0.7 | D6: =vlookup($A6,Statements!$A$2:$P$61,7,TRUE) -> 0.48542683 | E6: =vlookup($A6,Statements!$A$2:$P$61,4,TRUE) -> Entertainment
A7: =Statements!A7 -> 6 | B7: =Statements!B7 -> An Australian or New Zealand restaurant will feature on the 2024 "World's 50 Best Restaurants" list | C7: 0.2 | D7: =vlookup($A7,Statements!$A$2:$P$61,7,TRUE) -> 0.67807191 | E7: =vlookup($A7,Statements!$A$2:$P$61,4,TRUE) -> Entertainment
A8: =Statements!A8 -> 7 | B8: =Statements!B8 -> Dex (Kim Jin Young) will feature as a guest or star in a food-based show available on Netflix AU/NZ | C8: 0.3 | D8: =vlookup($A8,Statements!$A$2:$P$61,7,TRUE) -> 0.48542683 | E8: =vlookup($A8,Statements!$A$2:$P$61,4,TRUE) -> Entertainment
A9: =Statements!A9 -> 8 | B9: =Statements!B9 -> Taylor will break up with Travis | C9: 0.45 | D9: =vlookup($A9,Statements!$A$2:$P$61,7,TRUE) -> 0.13750352 | E9: =vlookup($A9,Statements!$A$2:$P$61,4,TRUE) -> Entertainment
A10: =Statements!A10 -> 9 | B10: =Statements!B10 -> Taylor will release the re-record of her debut album in 2024. | C10: 0.6 | D10: =vlookup($A10,Statements!$A$2:$P$61,7,TRUE) -> -0.32192809 | E10: =vlookup($A10,Statements!$A$2:$P$61,4,TRUE) -> Entertainment
A11: =Statements!A11 -> 10 | B11: =Statements!B11 -> Barbie will win best picture at the academy awards. | C11: NA | D11: =vlookup($A11,Statements!$A$2:$P$61,7,TRUE) | E11: =vlookup($A11,Statements!$A$2:$P$61,4,TRUE) -> Entertainment
A12: =Statements!A12 -> 11 | B12: =Statements!B12 -> Kate will win at least two prizes for her Phillip and Bennelong book. | C12: 0.75 | D12: =vlookup($A12,Statements!$A$2:$P$61,7,TRUE) -> 0.5849625 | E12: =vlookup($A12,Statements!$A$2:$P$61,4,TRUE) -> Family
A13: =Statements!A13 -> 12 | B13: =Statements!B13 -> Baby Starmeadow will be under 50cm long at birth (Oz average is 50.8cm). | C13: NA | D13: =vlookup($A13,Statements!$A$2:$P$61,7,TRUE) | E13: =vlookup($A13,Statements!$A$2:$P$61,4,TRUE) -> Family
