Workbook

Sheet Summary
A1: Predictions resolved | C1: =COUNTIF(Statements!E2:E61,0)+COUNTIF(Statements!E2:E61,1) -> 57
A2: Predictions to come | C2: =COUNTA(Statements!A2:A103)-C1 -> 2

Sheet Statements
A1: Number | B1: Name | C1: Prediction | D1: Category | E1: Outcome (1 = true, 0 = false) | F1: Andrew | G1: Eileen | H1: Iain | I1: Kate | J1: Rohan | K1: David | L1: Jac | M1: James | N1: Chris | O1: Lachy | P1: Gael | Q1: Bruce | R1: Total | S1: Andrew | T1: Eileen | U1: Iain | V1: Kate | W1: Rohan | X1: David | Y1: Jac | Z1: James | AA1: Chris | AB1: Lachy | AC1: Gael | AD1: Bruce | AE1: Jac2 | AF1: Jac3 | AG1: Jac4 | AH1: Boof2 | AI1: Boof3
A2: 1 | B2: Rohan | C2: Arsenal will be at the top of the 2025/2026 Premier League table by Christmas. | D2: Sport | E2: 1 | F2: =IF($E2=1,(LOG(S2,2)+1),IF($E2=0,(LOG(1-S2,2)+1),"")) -> -0.15200309 | G2: =IF($E2=1,(LOG(T2,2)+1),IF($E2=0,(LOG(1-T2,2)+1),"")) -> -0.73696559 | H2: =IF($E2=1,(LOG(U2,2)+1),IF($E2=0,(LOG(1-U2,2)+1),"")) -> 0.26303441 | I2: =IF($E2=1,(LOG(V2,2)+1),IF($E2=0,(LOG(1-V2,2)+1),"")) -> 0.48542683 | J2: =IF($E2=1,(LOG(W2,2)+1),IF($E2=0,(LOG(1-W2,2)+1),"")) -> 0.35614381 | K2: =IF($E2=1,(LOG(X2,2)+1),IF($E2=0,(LOG(1-X2,2)+1),"")) -> -2.3219281 | L2: =IF($E2=1,(LOG(Y2,2)+1),IF($E2=0,(LOG(1-Y2,2)+1),"")) -> 0 | M2: =IF($E2=1,(LOG(Z2,2)+1),IF($E2=0,(LOG(1-Z2,2)+1),"")) -> -0.64385619 | ... Q2: =IF($E2=1,(LOG(AD2,2)+1),IF($E2=0,(LOG(1-AD2,2)+1),"")) -> -0.73696559 | R2: =SUM(F2:Q2) -> -5.5460072 | S2: =Andrew!D2 -> 0.45 | T2: =Eileen!D2 -> 0.3 | U2: =Iain!D2 -> 0.6 | V2: =Kate!D2 -> 0.7 | W2: =Rohan!D2 -> 0.64 | X2: =David!D2 -> 0.1 | Y2: =Jac!D2 -> 0.5 | Z2: =James!D2 -> 0.32 | AA2: =Chris!D2 -> 0.2 | AB2: =Lachy!D2 -> 0.5 | AC2: =Gael!D2 -> 0.3 | AD2: =Bruce!D2 -> 0.3 | AE2: =Jac!E2 -> 0.4 | AF2: =Jac!F2 -> 0.4 | AG2: =Jac!G2 -> 0.5 | AH2: =Bruce!E2 -> 0.45 | AI2: =Bruce!F2 -> 0.2
A3: 2 | B3: Rohan | C3: There will be an assassination of a CEO in 2025, sufficiently high-profile to be reported in major news outlets in more than one country. | D3: Society | E3: 0 | F3: =IF($E3=1,(LOG(S3,2)+1),IF($E3=0,(LOG(1-S3,2)+1),"")) -> -0.32192809 | G3: =IF($E3=1,(LOG(T3,2)+1),IF($E3=0,(LOG(1-T3,2)+1),"")) -> 0.84799691 | H3: =IF($E3=1,(LOG(U3,2)+1),IF($E3=0,(LOG(1-U3,2)+1),"")) -> -0.73696559 | I3: =IF($E3=1,(LOG(V3,2)+1),IF($E3=0,(LOG(1-V3,2)+1),"")) -> 0.48542683 | J3: =IF($E3=1,(LOG(W3,2)+1),IF($E3=0,(LOG(1-W3,2)+1),"")) -> 0.16349873 | K3: =IF($E3=1,(LOG(X3,2)+1),IF($E3=0,(LOG(1-X3,2)+1),"")) -> 0 | L3: =IF($E3=1,(LOG(Y3,2)+1),IF($E3=0,(LOG(1-Y3,2)+1),"")) -> 0 | M3: =IF($E3=1,(LOG(Z3,2)+1),IF($E3=0,(LOG(1-Z3,2)+1),"")) -> 0.67807191 | ... Q3: =IF($E3=1,(LOG(AD3,2)+1),IF($E3=0,(LOG(1-AD3,2)+1),"")) -> 0.48542683 | R3: =SUM(F3:Q3) -> 2.8146037 | S3: =Andrew!D3 -> 0.6 | T3: =Eileen!D3 -> 0.1 | U3: =Iain!D3 -> 0.7 | V3: =Kate!D3 -> 0.3 | W3: =Rohan!D3 -> 0.44 | X3: =David!D3 -> 0.5 | Y3: =Jac!D3 -> 0.5 | Z3: =James!D3 -> 0.2 | AA3: =Chris!D3 -> 0.3 | AB3: =Lachy!D3 -> 0.31002552 | AC3: =Gael!D3 -> 0.4 | AD3: =Bruce!D3 -> 0.3 | AE3: =Jac!E3 -> 0.4 | AF3: =Jac!F3 -> 0.4 | AG3: =Jac!G3 -> 0.5 | AH3: =Bruce!E3 -> 0.4 | AI3: =Bruce!F3 -> 0.2
A4: 3 | B4: Rohan | C4: As reported by any news outlet or social media, Trump will label sharks as “bad,” “evil,” “not good,” or in any way imply that shark attacks are malicious and immoral acts on behalf of the shark. | D4: Politics | E4: 0 | F4: =IF($E4=1,(LOG(S4,2)+1),IF($E4=0,(LOG(1-S4,2)+1),"")) -> -0.25153877 | G4: =IF($E4=1,(LOG(T4,2)+1),IF($E4=0,(LOG(1-T4,2)+1),"")) -> 0.84799691 | H4: =IF($E4=1,(LOG(U4,2)+1),IF($E4=0,(LOG(1-U4,2)+1),"")) -> 0.48542683 | I4: =IF($E4=1,(LOG(V4,2)+1),IF($E4=0,(LOG(1-V4,2)+1),"")) -> -0.32192809 | J4: =IF($E4=1,(LOG(W4,2)+1),IF($E4=0,(LOG(1-W4,2)+1),"")) -> 0.84799691 | K4: =IF($E4=1,(LOG(X4,2)+1),IF($E4=0,(LOG(1-X4,2)+1),"")) -> 0.48542683 | L4: =IF($E4=1,(LOG(Y4,2)+1),IF($E4=0,(LOG(1-Y4,2)+1),"")) -> 0.48542683 | M4: =IF($E4=1,(LOG(Z4,2)+1),IF($E4=0,(LOG(1-Z4,2)+1),"")) -> 0.76553475 | ... Q4: =IF($E4=1,(LOG(AD4,2)+1),IF($E4=0,(LOG(1-AD4,2)+1),"")) -> 0.26303441 | R4: =SUM(F4:Q4) -> 4.2512592 | S4: =Andrew!D4 -> 0.58 | T4: =Eileen!D4 -> 0.1 | U4: =Iain!D4 -> 0.3 | V4: =Kate!D4 -> 0.6 | W4: =Rohan!D4 -> 0.1 | X4: =David!D4 -> 0.3 | Y4: =Jac!D4 -> 0.3 | Z4: =James!D4 -> 0.15 | AA4: =Chris!D4 -> 0.1 | AB4: =Lachy!D4 -> 0.68997448 | AC4: =Gael!D4 -> 0.3 | AD4: =Bruce!D4 -> 0.4 | AE4: =Jac!E4 -> 0.3 | AF4: =Jac!F4 -> 0.3 | AG4: =Jac!G4 -> 0.4 | AH4: =Bruce!E4 -> 0.45 | AI4: =Bruce!F4 -> 0.3
A5: 4 | B5: Rohan | C5: Oasis will release an album in 2025 | D5: Entertainment | E5: 1 | F5: =IF($E5=1,(LOG(S5,2)+1),IF($E5=0,(LOG(1-S5,2)+1),"")) -> 0.26303441 | G5: =IF($E5=1,(LOG(T5,2)+1),IF($E5=0,(LOG(1-T5,2)+1),"")) -> -1.3219281 | H5: =IF($E5=1,(LOG(U5,2)+1),IF($E5=0,(LOG(1-U5,2)+1),"")) -> 0.48542683 | I5: =IF($E5=1,(LOG(V5,2)+1),IF($E5=0,(LOG(1-V5,2)+1),"")) -> -0.73696559 | J5: =IF($E5=1,(LOG(W5,2)+1),IF($E5=0,(LOG(1-W5,2)+1),"")) -> -2.3219281 | K5: =IF($E5=1,(LOG(X5,2)+1),IF($E5=0,(LOG(1-X5,2)+1),"")) -> 0.84799691 | L5: =IF($E5=1,(LOG(Y5,2)+1),IF($E5=0,(LOG(1-Y5,2)+1),"")) -> -1.3219281 | M5: =IF($E5=1,(LOG(Z5,2)+1),IF($E5=0,(LOG(1-Z5,2)+1),"")) -> -3.3219281 | ... Q5: =IF($E5=1,(LOG(AD5,2)+1),IF($E5=0,(LOG(1-AD5,2)+1),"")) -> 0.48542683 | R5: =SUM(F5:Q5) -> -8.2761903 | S5: =Andrew!D5 -> 0.6 | T5: =Eileen!D5 -> 0.2 | U5: =Iain!D5 -> 0.7 | V5: =Kate!D5 -> 0.3 | W5: =Rohan!D5 -> 0.1 | X5: =David!D5 -> 0.9 | Y5: =Jac!D5 -> 0.2 | Z5: =James!D5 -> 0.05 | AA5: =Chris!D5 -> 0.2 | AB5: =Lachy!D5 -> 0.31002552 | AC5: =Gael!D5 -> 0.8 | AD5: =Bruce!D5 -> 0.7 | AE5: =Jac!E5 -> 0.2 | AF5: =Jac!F5 -> 0.2 | AG5: =Jac!G5 -> 0.3 | AH5: =Bruce!E5 -> 0.55 | AI5: =Bruce!F5 -> 0.8
A6: 5 | B6: Bruce | C6: No party will gain a majority of House of Representatives seats in the Australian federal election | D6: Politics | E6: 0 | F6: =IF($E6=1,(LOG(S6,2)+1),IF($E6=0,(LOG(1-S6,2)+1),"")) -> 0.37851162 | G6: =IF($E6=1,(LOG(T6,2)+1),IF($E6=0,(LOG(1-T6,2)+1),"")) -> 0.48542683 | H6: =IF($E6=1,(LOG(U6,2)+1),IF($E6=0,(LOG(1-U6,2)+1),"")) -> -0.32192809 | I6: =IF($E6=1,(LOG(V6,2)+1),IF($E6=0,(LOG(1-V6,2)+1),"")) -> -0.32192809 | J6: =IF($E6=1,(LOG(W6,2)+1),IF($E6=0,(LOG(1-W6,2)+1),"")) -> -0.089267338 | K6: =IF($E6=1,(LOG(X6,2)+1),IF($E6=0,(LOG(1-X6,2)+1),"")) -> 0.48542683 | L6: =IF($E6=1,(LOG(Y6,2)+1),IF($E6=0,(LOG(1-Y6,2)+1),"")) -> -0.32192809 | M6: =IF($E6=1,(LOG(Z6,2)+1),IF($E6=0,(LOG(1-Z6,2)+1),"")) -> 0.21412481 | ... Q6: =IF($E6=1,(LOG(AD6,2)+1),IF($E6=0,(LOG(1-AD6,2)+1),"")) -> -5.6438562 | R6: =SUM(F6:Q6) -> -4.7296965 | S6: =Andrew!D6 -> 0.35 | T6: =Eileen!D6 -> 0.3 | U6: =Iain!D6 -> 0.6 | V6: =Kate!D6 -> 0.6 | W6: =Rohan!D6 -> 0.53 | X6: =David!D6 -> 0.3 | Y6: =Jac!D6 -> 0.6 | Z6: =James!D6 -> 0.42 | AA6: =Chris!D6 -> 0.4 | AB6: =Lachy!D6 -> 0.31002552 | AC6: =Gael!D6 -> 0.6 | AD6: =Bruce!D6 -> 0.99 | AE6: =Jac!E6 -> 0.6 | AF6: =Jac!F6 -> 0.6 | AG6: =Jac!G6 -> 0.5 | AH6: =Bruce!E6 -> 0.8 | AI6: =Bruce!F6 -> 0.99
A7: 6 | B7: Bruce | C7: Nick Kyrgios will compete in men’s singles in at least three of the four tennis slam events (Australian, French and US opens and Wimbledon) | D7: Sport | E7: 0 | F7: =IF($E7=1,(LOG(S7,2)+1),IF($E7=0,(LOG(1-S7,2)+1),"")) -> -0.73696559 | G7: =IF($E7=1,(LOG(T7,2)+1),IF($E7=0,(LOG(1-T7,2)+1),"")) -> 0 | H7: =IF($E7=1,(LOG(U7,2)+1),IF($E7=0,(LOG(1-U7,2)+1),"")) -> 0.67807191 | I7: =IF($E7=1,(LOG(V7,2)+1),IF($E7=0,(LOG(1-V7,2)+1),"")) -> 0.26303441 | J7: =IF($E7=1,(LOG(W7,2)+1),IF($E7=0,(LOG(1-W7,2)+1),"")) -> 0 | K7: =IF($E7=1,(LOG(X7,2)+1),IF($E7=0,(LOG(1-X7,2)+1),"")) -> 0.84799691 | L7: =IF($E7=1,(LOG(Y7,2)+1),IF($E7=0,(LOG(1-Y7,2)+1),"")) -> 0.13750352 | M7: =IF($E7=1,(LOG(Z7,2)+1),IF($E7=0,(LOG(1-Z7,2)+1),"")) -> 0.62293035 | ... Q7: =IF($E7=1,(LOG(AD7,2)+1),IF($E7=0,(LOG(1-AD7,2)+1),"")) -> 0.37851162 | R7: =SUM(F7:Q7) -> 3.3567203 | S7: =Andrew!D7 -> 0.7 | T7: =Eileen!D7 -> 0.5 | U7: =Iain!D7 -> 0.2 | V7: =Kate!D7 -> 0.4 | W7: =Rohan!D7 -> 0.5 | X7: =David!D7 -> 0.1 | Y7: =Jac!D7 -> 0.45 | Z7: =James!D7 -> 0.23 | AA7: =Chris!D7 -> 0.15 | AB7: =Lachy!D7 -> 0.450166 | AC7: =Gael!D7 -> 0.4 | AD7: =Bruce!D7 -> 0.35 | AE7: =Jac!E7 -> 0.45 | AF7: =Jac!F7 -> 0.4 | AG7: =Jac!G7 -> 0.5 | AH7: =Bruce!E7 -> 0.45 | AI7: =Bruce!F7 -> 0.2
A8: 7 | B8: Bruce | C8: Collingwood will play at least one AFL men’s final in 2025 | D8: Sport | E8: 1 | F8: =IF($E8=1,(LOG(S8,2)+1),IF($E8=0,(LOG(1-S8,2)+1),"")) -> 0.13750352 | G8: =IF($E8=1,(LOG(T8,2)+1),IF($E8=0,(LOG(1-T8,2)+1),"")) -> 0.67807191 | H8: =IF($E8=1,(LOG(U8,2)+1),IF($E8=0,(LOG(1-U8,2)+1),"")) -> 0 | I8: =IF($E8=1,(LOG(V8,2)+1),IF($E8=0,(LOG(1-V8,2)+1),"")) -> 0.26303441 | J8: =IF($E8=1,(LOG(W8,2)+1),IF($E8=0,(LOG(1-W8,2)+1),"")) -> -0.15200309 | K8: =IF($E8=1,(LOG(X8,2)+1),IF($E8=0,(LOG(1-X8,2)+1),"")) -> -2.3219281 | L8: =IF($E8=1,(LOG(Y8,2)+1),IF($E8=0,(LOG(1-Y8,2)+1),"")) -> 0.13750352 | M8: =IF($E8=1,(LOG(Z8,2)+1),IF($E8=0,(LOG(1-Z8,2)+1),"")) -> 0.13750352 | ... Q8: =IF($E8=1,(LOG(AD8,2)+1),IF($E8=0,(LOG(1-AD8,2)+1),"")) -> 0.37851162 | R8: =SUM(F8:Q8) -> 0.0034995838 | S8: =Andrew!D8 -> 0.55 | T8: =Eileen!D8 -> 0.8 | U8: =Iain!D8 -> 0.5 | V8: =Kate!D8 -> 0.6 | W8: =Rohan!D8 -> 0.45 | X8: =David!D8 -> 0.1 | Y8: =Jac!D8 -> 0.55 | Z8: =James!D8 -> 0.55 | AA8: =Chris!D8 -> 0.5 | AB8: =Lachy!D8 -> 0.59868766 | AC8: =Gael!D8 -> 0.7 | AD8: =Bruce!D8 -> 0.65 | AE8: =Jac!E8 -> 0.5 | AF8: =Jac!F8 -> 0.6 | AG8: =Jac!G8 -> 0.5 | AH8: =Bruce!E8 -> 0.55 | AI8: =Bruce!F8 -> 0.8
A9: 8 | B9: Bruce | C9: Alan Jones will be found guilty by a jury on at least one sexual assault charge and will go to jail | D9: Law | E9: 0 | F9: =IF($E9=1,(LOG(S9,2)+1),IF($E9=0,(LOG(1-S9,2)+1),"")) -> -0.51457317 | G9: =IF($E9=1,(LOG(T9,2)+1),IF($E9=0,(LOG(1-T9,2)+1),"")) -> 0 | H9: =IF($E9=1,(LOG(U9,2)+1),IF($E9=0,(LOG(1-U9,2)+1),"")) -> -0.32192809 | I9: =IF($E9=1,(LOG(V9,2)+1),IF($E9=0,(LOG(1-V9,2)+1),"")) -> 0.67807191 | J9: =IF($E9=1,(LOG(W9,2)+1),IF($E9=0,(LOG(1-W9,2)+1),"")) -> -0.32192809 | K9: =IF($E9=1,(LOG(X9,2)+1),IF($E9=0,(LOG(1-X9,2)+1),"")) -> 0.48542683 | L9: =IF($E9=1,(LOG(Y9,2)+1),IF($E9=0,(LOG(1-Y9,2)+1),"")) -> 0.84799691 | M9: =IF($E9=1,(LOG(Z9,2)+1),IF($E9=0,(LOG(1-Z9,2)+1),"")) -> 0.67807191 | ... Q9: =IF($E9=1,(LOG(AD9,2)+1),IF($E9=0,(LOG(1-AD9,2)+1),"")) -> 0.84799691 | R9: =SUM(F9:Q9) -> 2.7400044 | S9: =Andrew!D9 -> 0.65 | T9: =Eileen!D9 -> 0.5 | U9: =Iain!D9 -> 0.6 | V9: =Kate!D9 -> 0.2 | W9: =Rohan!D9 -> 0.6 | X9: =David!D9 -> 0.3 | Y9: =Jac!D9 -> 0.1 | Z9: =James!D9 -> 0.2 | AA9: =Chris!D9 -> 0.5 | AB9: =Lachy!D9 -> 0.59868766 | AC9: =Gael!D9 -> 0.2 | AD9: =Bruce!D9 -> 0.1 | AE9: =Jac!E9 -> 0.1 | AF9: =Jac!F9 -> 0.01 | AG9: =Jac!G9 -> 0.2 | AH9: =Bruce!E9 -> 0.3 | AI9: =Bruce!F9 -> 0.01
A10: 9 | B10: Bruce | C10: The Reserve Bank will cut interest rates before the Australian Federal election | D10: Finance | E10: 1 | F10: =IF($E10=1,(LOG(S10,2)+1),IF($E10=0,(LOG(1-S10,2)+1),"")) -> 0.76553475 | G10: =IF($E10=1,(LOG(T10,2)+1),IF($E10=0,(LOG(1-T10,2)+1),"")) -> 0.26303441 | H10: =IF($E10=1,(LOG(U10,2)+1),IF($E10=0,(LOG(1-U10,2)+1),"")) -> -0.32192809 | I10: =IF($E10=1,(LOG(V10,2)+1),IF($E10=0,(LOG(1-V10,2)+1),"")) -> 0.26303441 | J10: =IF($E10=1,(LOG(W10,2)+1),IF($E10=0,(LOG(1-W10,2)+1),"")) -> -0.15200309 | K10: =IF($E10=1,(LOG(X10,2)+1),IF($E10=0,(LOG(1-X10,2)+1),"")) -> 0 | L10: =IF($E10=1,(LOG(Y10,2)+1),IF($E10=0,(LOG(1-Y10,2)+1),"")) -> 0.48542683 | M10: =IF($E10=1,(LOG(Z10,2)+1),IF($E10=0,(LOG(1-Z10,2)+1),"")) -> 0.48542683 | ... Q10: =IF($E10=1,(LOG(AD10,2)+1),IF($E10=0,(LOG(1-AD10,2)+1),"")) -> 0.67807191 | R10: =SUM(F10:Q10) -> 3.2502604 | S10: =Andrew!D10 -> 0.85 | T10: =Eileen!D10 -> 0.6 | U10: =Iain!D10 -> 0.4 | V10: =Kate!D10 -> 0.6 | W10: =Rohan!D10 -> 0.45 | X10: =David!D10 -> 0.5 | Y10: =Jac!D10 -> 0.7 | Z10: =James!D10 -> 0.7 | AA10: =Chris!D10 -> 0.4 | AB10: =Lachy!D10 -> 0.76852478 | AC10: =Gael!D10 -> 0.7 | AD10: =Bruce!D10 -> 0.8 | AE10: =Jac!E10 -> 0.4 | AF10: =Jac!F10 -> 0.8 | AG10: =Jac!G10 -> 0.6 | AH10: =Bruce!E10 -> 0.65 | AI10: =Bruce!F10 -> 0.9
A11: 10 | B11: Eileen | C11: A country with GDP of $30 billion or more will default on its sovereign debt. | D11: Finance | E11: 0 | F11: =IF($E11=1,(LOG(S11,2)+1),IF($E11=0,(LOG(1-S11,2)+1),"")) -> 0.84799691 | G11: =IF($E11=1,(LOG(T11,2)+1),IF($E11=0,(LOG(1-T11,2)+1),"")) -> 0.26303441 | H11: =IF($E11=1,(LOG(U11,2)+1),IF($E11=0,(LOG(1-U11,2)+1),"")) -> 0.67807191 | I11: =IF($E11=1,(LOG(V11,2)+1),IF($E11=0,(LOG(1-V11,2)+1),"")) -> 0 | J11: =IF($E11=1,(LOG(W11,2)+1),IF($E11=0,(LOG(1-W11,2)+1),"")) -> -0.51457317 | K11: =IF($E11=1,(LOG(X11,2)+1),IF($E11=0,(LOG(1-X11,2)+1),"")) -> 0.48542683 | L11: =IF($E11=1,(LOG(Y11,2)+1),IF($E11=0,(LOG(1-Y11,2)+1),"")) -> -0.73696559 | M11: =IF($E11=1,(LOG(Z11,2)+1),IF($E11=0,(LOG(1-Z11,2)+1),"")) -> 0.52606881 | ... Q11: =IF($E11=1,(LOG(AD11,2)+1),IF($E11=0,(LOG(1-AD11,2)+1),"")) -> -0.32192809 | R11: =SUM(F11:Q11) -> 2.6575981 | S11: =Andrew!D11 -> 0.1 | T11: =Eileen!D11 -> 0.4 | U11: =Iain!D11 -> 0.2 | V11: =Kate!D11 -> 0.5 | W11: =Rohan!D11 -> 0.65 | X11: =David!D11 -> 0.3 | Y11: =Jac!D11 -> 0.7 | Z11: =James!D11 -> 0.28 | AA11: =Chris!D11 -> 0.3 | AB11: =Lachy!D11 -> 0.19781611 | AC11: =Gael!D11 -> 0.4 | AD11: =Bruce!D11 -> 0.6 | AE11: =Jac!E11 -> 0.6 | AF11: =Jac!F11 -> 0.8 | AG11: =Jac!G11 -> 0.6 | AH11: =Bruce!E11 -> 0.55 | AI11: =Bruce!F11 -> 0.7
A12: 11 | B12: Eileen | C12: An AI/LLM "escapes" (moves onto infrastructure it aquired against the intention of the group or person who set it running initally) or is otherwise deemed too dangerous to continue functioning and the entity responsible for running it makes efforts to shut it down. | D12: Technology | E12: 0 | F12: =IF($E12=1,(LOG(S12,2)+1),IF($E12=0,(LOG(1-S12,2)+1),"")) -> 0.76553475 | G12: =IF($E12=1,(LOG(T12,2)+1),IF($E12=0,(LOG(1-T12,2)+1),"")) -> -0.51457317 | H12: =IF($E12=1,(LOG(U12,2)+1),IF($E12=0,(LOG(1-U12,2)+1),"")) -> 0.67807191 | I12: =IF($E12=1,(LOG(V12,2)+1),IF($E12=0,(LOG(1-V12,2)+1),"")) -> 0.84799691 | J12: =IF($E12=1,(LOG(W12,2)+1),IF($E12=0,(LOG(1-W12,2)+1),"")) -> 0 | K12: =IF($E12=1,(LOG(X12,2)+1),IF($E12=0,(LOG(1-X12,2)+1),"")) -> 0 | L12: =IF($E12=1,(LOG(Y12,2)+1),IF($E12=0,(LOG(1-Y12,2)+1),"")) -> 0.67807191 | M12: =IF($E12=1,(LOG(Z12,2)+1),IF($E12=0,(LOG(1-Z12,2)+1),"")) -> 0.67807191 | ... Q12: =IF($E12=1,(LOG(AD12,2)+1),IF($E12=0,(LOG(1-AD12,2)+1),"")) -> 0 | R12: =SUM(F12:Q12) -> 2.8725551 | S12: =Andrew!D12 -> 0.15 | T12: =Eileen!D12 -> 0.65 | U12: =Iain!D12 -> 0.2 | V12: =Kate!D12 -> 0.1 | W12: =Rohan!D12 -> 0.5 | X12: =David!D12 -> 0.5 | Y12: =Jac!D12 -> 0.2 | Z12: =James!D12 -> 0.2 | AA12: =Chris!D12 -> 0.35 | AB12: =Lachy!D12 -> 0.59868766 | AC12: =Gael!D12 -> 0.6 | AD12: =Bruce!D12 -> 0.5 | AE12: =Jac!E12 -> 0.2 | AF12: =Jac!F12 -> 0.2 | AG12: =Jac!G12 -> 0.3 | AH12: =Bruce!E12 -> 0.5 | AI12: =Bruce!F12 -> 0.5
A13: 12 | B13: Eileen | C13: A major national space agency (e.g. NASA) confirms the discovery or otherwise acknowledges evidence of extraterrestrial life. | D13: Society | E13: 0 | F13: =IF($E13=1,(LOG(S13,2)+1),IF($E13=0,(LOG(1-S13,2)+1),"")) -> 0.92599942 | G13: =IF($E13=1,(LOG(T13,2)+1),IF($E13=0,(LOG(1-T13,2)+1),"")) -> 0.67807191 | H13: =IF($E13=1,(LOG(U13,2)+1),IF($E13=0,(LOG(1-U13,2)+1),"")) -> 0.67807191 | I13: =IF($E13=1,(LOG(V13,2)+1),IF($E13=0,(LOG(1-V13,2)+1),"")) -> 0.84799691 | J13: =IF($E13=1,(LOG(W13,2)+1),IF($E13=0,(LOG(1-W13,2)+1),"")) -> 0.84799691 | K13: =IF($E13=1,(LOG(X13,2)+1),IF($E13=0,(LOG(1-X13,2)+1),"")) -> 0.84799691 | L13: =IF($E13=1,(LOG(Y13,2)+1),IF($E13=0,(LOG(1-Y13,2)+1),"")) -> 0.67807191 | M13: =IF($E13=1,(LOG(Z13,2)+1),IF($E13=0,(LOG(1-Z13,2)+1),"")) -> 0.81557543 | ... Q13: =IF($E13=1,(LOG(AD13,2)+1),IF($E13=0,(LOG(1-AD13,2)+1),"")) -> 0.84799691 | R13: =SUM(F13:Q13) -> 9.5107286 | S13: =Andrew!D13 -> 0.05 | T13: =Eileen!D13 -> 0.2 | U13: =Iain!D13 -> 0.2 | V13: =Kate!D13 -> 0.1 | W13: =Rohan!D13 -> 0.1 | X13: =David!D13 -> 0.1 | Y13: =Jac!D13 -> 0.2 | Z13: =James!D13 -> 0.12 | AA13: =Chris!D13 -> 0.1 | AB13: =Lachy!D13 -> 0.11920292 | AC13: =Gael!D13 -> 0.2 | AD13: =Bruce!D13 -> 0.1 | AE13: =Jac!E13 -> 0.2 | AF13: =Jac!F13 -> 0.2 | AG13: =Jac!G13 -> 0.3 | AH13: =Bruce!E13 -> 0.2 | AI13: =Bruce!F13 -> 0.05
... A22: 21 | B22: James | C22: The UK enters recession | D22: Finance | E22: 0 | F22: =IF($E22=1,(LOG(S22,2)+1),IF($E22=0,(LOG(1-S22,2)+1),"")) -> -0.51457317 | G22: =IF($E22=1,(LOG(T22,2)+1),IF($E22=0,(LOG(1-T22,2)+1),"")) -> 0.37851162 | H22: =IF($E22=1,(LOG(U22,2)+1),IF($E22=0,(LOG(1-U22,2)+1),"")) -> 0 | I22: =IF($E22=1,(LOG(V22,2)+1),IF($E22=0,(LOG(1-V22,2)+1),"")) -> -0.73696559 | J22: =IF($E22=1,(LOG(W22,2)+1),IF($E22=0,(LOG(1-W22,2)+1),"")) -> -0.32192809 | K22: =IF($E22=1,(LOG(X22,2)+1),IF($E22=0,(LOG(1-X22,2)+1),"")) -> 0 | L22: =IF($E22=1,(LOG(Y22,2)+1),IF($E22=0,(LOG(1-Y22,2)+1),"")) -> 0.67807191 | M22: =IF($E22=1,(LOG(Z22,2)+1),IF($E22=0,(LOG(1-Z22,2)+1),"")) -> 0.52606881 | ... Q22: =IF($E22=1,(LOG(AD22,2)+1),IF($E22=0,(LOG(1-AD22,2)+1),"")) -> 0.26303441 | R22: =SUM(F22:Q22) -> 1.6779411 | S22: =Andrew!D22 -> 0.65 | T22: =Eileen!D22 -> 0.35 | U22: =Iain!D22 -> 0.5 | V22: =Kate!D22 -> 0.7 | W22: =Rohan!D22 -> 0.6 | X22: =David!D22 -> 0.5 | Y22: =Jac!D22 -> 0.2 | Z22: =James!D22 -> 0.28 | AA22: =Chris!D22 -> 0.2 | AB22: =Lachy!D22 -> 0.31002552 | AC22: =Gael!D22 -> 0.4 | AD22: =Bruce!D22 -> 0.4 | AE22: =Jac!E22 -> 0.2 | AF22: =Jac!F22 -> 0.2 | AG22: =Jac!G22 -> 0.3 | AH22: =Bruce!E22 -> 0.45 | AI22: =Bruce!F22 -> 0.3
A23: 22 | B23: James | C23: At least four members of KPop group New Jeans form a new group | D23: Entertainment | E23: - | F23: =IF($E23=1,(LOG(S23,2)+1),IF($E23=0,(LOG(1-S23,2)+1),"")) | G23: =IF($E23=1,(LOG(T23,2)+1),IF($E23=0,(LOG(1-T23,2)+1),"")) | H23: =IF($E23=1,(LOG(U23,2)+1),IF($E23=0,(LOG(1-U23,2)+1),"")) | I23: =IF($E23=1,(LOG(V23,2)+1),IF($E23=0,(LOG(1-V23,2)+1),"")) | J23: =IF($E23=1,(LOG(W23,2)+1),IF($E23=0,(LOG(1-W23,2)+1),"")) | K23: =IF($E23=1,(LOG(X23,2)+1),IF($E23=0,(LOG(1-X23,2)+1),"")) | L23: =IF($E23=1,(LOG(Y23,2)+1),IF($E23=0,(LOG(1-Y23,2)+1),"")) | M23: =IF($E23=1,(LOG(Z23,2)+1),IF($E23=0,(LOG(1-Z23,2)+1),"")) | ... Q23: =IF($E23=1,(LOG(AD23,2)+1),IF($E23=0,(LOG(1-AD23,2)+1),"")) | R23: =SUM(F23:Q23) -> 0 | S23: =Andrew!D23 -> 0.3 | T23: =Eileen!D23 -> 0.1 | U23: =Iain!D23 -> 0.2 | V23: =Kate!D23 -> 0.4 | W23: =Rohan!D23 -> 0.05 | X23: =David!D23 -> 0.9 | Y23: =Jac!D23 -> 0.2 | Z23: =James!D23 -> 0.18 | AA23: =Chris!D23 -> 0.2 | AB23: =Lachy!D23 -> 0.450166 | AC23: =Gael!D23 -> 0.6 | AD23: =Bruce!D23 -> 0.6 | AE23: =Jac!E23 -> 0.2 | AF23: =Jac!F23 -> 0.2 | AG23: =Jac!G23 -> 0.3 | AH23: =Bruce!E23 -> 0.55 | AI23: =Bruce!F23 -> 0.7
A24: 23 | B24: James | C24: Gen G are crowned champions at the League of Legends World Championships | D24: Entertainment | E24: 0 | F24: =IF($E24=1,(LOG(S24,2)+1),IF($E24=0,(LOG(1-S24,2)+1),"")) -> 0.26303441 | G24: =IF($E24=1,(LOG(T24,2)+1),IF($E24=0,(LOG(1-T24,2)+1),"")) -> -0.51457317 | H24: =IF($E24=1,(LOG(U24,2)+1),IF($E24=0,(LOG(1-U24,2)+1),"")) -> 0.67807191 | I24: =IF($E24=1,(LOG(V24,2)+1),IF($E24=0,(LOG(1-V24,2)+1),"")) -> 0 | J24: =IF($E24=1,(LOG(W24,2)+1),IF($E24=0,(LOG(1-W24,2)+1),"")) -> 0.60407132 | K24: =IF($E24=1,(LOG(X24,2)+1),IF($E24=0,(LOG(1-X24,2)+1),"")) -> 0 | L24: =IF($E24=1,(LOG(Y24,2)+1),IF($E24=0,(LOG(1-Y24,2)+1),"")) -> 0.48542683 | M24: =IF($E24=1,(LOG(Z24,2)+1),IF($E24=0,(LOG(1-Z24,2)+1),"")) -> 0.48542683 | ... Q24: =IF($E24=1,(LOG(AD24,2)+1),IF($E24=0,(LOG(1-AD24,2)+1),"")) -> 0.26303441 | R24: =SUM(F24:Q24) -> 2.9921418 | S24: =Andrew!D24 -> 0.4 | T24: =Eileen!D24 -> 0.65 | U24: =Iain!D24 -> 0.2 | V24: =Kate!D24 -> 0.5 | W24: =Rohan!D24 -> 0.24 | X24: =David!D24 -> 0.5 | Y24: =Jac!D24 -> 0.3 | Z24: =James!D24 -> 0.3 | AA24: =Chris!D24 -> 0.4 | AB24: =Lachy!D24 -> 0.31002552 | AC24: =Gael!D24 -> 0.5 | AD24: =Bruce!D24 -> 0.4 | AE24: =Jac!E24 -> 0.3 | AF24: =Jac!F24 -> 0.3 | AG24: =Jac!G24 -> 0.4 | AH24: =Bruce!E24 -> 0.45 | AI24: =Bruce!F24 -> 0.6
A25: 24 | B25: James | C25: Honda, Nissan and Mitsubishi will execute a binding merger agreement by June 2025 | D25: Law | E25: 0 | F25: =IF($E25=1,(LOG(S25,2)+1),IF($E25=0,(LOG(1-S25,2)+1),"")) -> 0.67807191 | G25: =IF($E25=1,(LOG(T25,2)+1),IF($E25=0,(LOG(1-T25,2)+1),"")) -> 0.84799691 | H25: =IF($E25=1,(LOG(U25,2)+1),IF($E25=0,(LOG(1-U25,2)+1),"")) -> -0.73696559 | I25: =IF($E25=1,(LOG(V25,2)+1),IF($E25=0,(LOG(1-V25,2)+1),"")) -> -0.32192809 | J25: =IF($E25=1,(LOG(W25,2)+1),IF($E25=0,(LOG(1-W25,2)+1),"")) -> 0.92599942 | K25: =IF($E25=1,(LOG(X25,2)+1),IF($E25=0,(LOG(1-X25,2)+1),"")) -> 0 | L25: =IF($E25=1,(LOG(Y25,2)+1),IF($E25=0,(LOG(1-Y25,2)+1),"")) -> 0.92599942 | M25: =IF($E25=1,(LOG(Z25,2)+1),IF($E25=0,(LOG(1-Z25,2)+1),"")) -> 0.5849625 | ... Q25: =IF($E25=1,(LOG(AD25,2)+1),IF($E25=0,(LOG(1-AD25,2)+1),"")) -> 0.5849625 | R25: =SUM(F25:Q25) -> 4.3346026 | S25: =Andrew!D25 -> 0.2 | T25: =Eileen!D25 -> 0.1 | U25: =Iain!D25 -> 0.7 | V25: =Kate!D25 -> 0.6 | W25: =Rohan!D25 -> 0.05 | X25: =David!D25 -> 0.5 | Y25: =Jac!D25 -> 0.05 | Z25: =James!D25 -> 0.25 | AA25: =Chris!D25 -> 0.3 | AB25: =Lachy!D25 -> 0.19781611 | AC25: =Gael!D25 -> 0.6 | AD25: =Bruce!D25 -> 0.25 | AE25: =Jac!E25 -> 0.05 | AF25: =Jac!F25 -> 0.01 | AG25: =Jac!G25 -> 0.2 | AH25: =Bruce!E25 -> 0.4 | AI25: =Bruce!F25 -> 0.15
A26: 25 | B26: Iain | C26: In 2025 trump will give musk at least one demeaning nickname. | D26: Politics | E26: 0 | F26: =IF($E26=1,(LOG(S26,2)+1),IF($E26=0,(LOG(1-S26,2)+1),"")) -> -0.73696559 | G26: =IF($E26=1,(LOG(T26,2)+1),IF($E26=0,(LOG(1-T26,2)+1),"")) -> 0.84799691 | H26: =IF($E26=1,(LOG(U26,2)+1),IF($E26=0,(LOG(1-U26,2)+1),"")) -> -0.32192809 | I26: =IF($E26=1,(LOG(V26,2)+1),IF($E26=0,(LOG(1-V26,2)+1),"")) -> -1.3219281 | J26: =IF($E26=1,(LOG(W26,2)+1),IF($E26=0,(LOG(1-W26,2)+1),"")) -> -0.32192809 | K26: =IF($E26=1,(LOG(X26,2)+1),IF($E26=0,(LOG(1-X26,2)+1),"")) -> -0.73696559 | L26: =IF($E26=1,(LOG(Y26,2)+1),IF($E26=0,(LOG(1-Y26,2)+1),"")) -> 0.26303441 | M26: =IF($E26=1,(LOG(Z26,2)+1),IF($E26=0,(LOG(1-Z26,2)+1),"")) -> 0.26303441 | ... Q26: =IF($E26=1,(LOG(AD26,2)+1),IF($E26=0,(LOG(1-AD26,2)+1),"")) -> 0 | R26: =SUM(F26:Q26) -> -1.7691296 | S26: =Andrew!D26 -> 0.7 | T26: =Eileen!D26 -> 0.1 | U26: =Iain!D26 -> 0.6 | V26: =Kate!D26 -> 0.8 | W26: =Rohan!D26 -> 0.6 | X26: =David!D26 -> 0.7 | Y26: =Jac!D26 -> 0.4 | Z26: =James!D26 -> 0.4 | AA26: =Chris!D26 -> 0.4 | AB26: =Lachy!D26 -> 0.26894142 | AC26: =Gael!D26 -> 0.65 | AD26: =Bruce!D26 -> 0.5 | AE26: =Jac!E26 -> 0.4 | AF26: =Jac!F26 -> 0.3 | AG26: =Jac!G26 -> 0.5 | AH26: =Bruce!E26 -> 0.5 | AI26: =Bruce!F26 -> 0.5
A27: 26 | B27: Iain | C27: Raygun will publish a book that includes discussion of her experiences at 24 Paris Olympics. | D27: Entertainment | E27: 0 | F27: =IF($E27=1,(LOG(S27,2)+1),IF($E27=0,(LOG(1-S27,2)+1),"")) -> -0.32192809 | G27: =IF($E27=1,(LOG(T27,2)+1),IF($E27=0,(LOG(1-T27,2)+1),"")) -> 0.76553475 | H27: =IF($E27=1,(LOG(U27,2)+1),IF($E27=0,(LOG(1-U27,2)+1),"")) -> -0.73696559 | I27: =IF($E27=1,(LOG(V27,2)+1),IF($E27=0,(LOG(1-V27,2)+1),"")) -> -0.73696559 | J27: =IF($E27=1,(LOG(W27,2)+1),IF($E27=0,(LOG(1-W27,2)+1),"")) -> 0.5849625 | K27: =IF($E27=1,(LOG(X27,2)+1),IF($E27=0,(LOG(1-X27,2)+1),"")) -> -0.73696559 | L27: =IF($E27=1,(LOG(Y27,2)+1),IF($E27=0,(LOG(1-Y27,2)+1),"")) -> 0.26303441 | M27: =IF($E27=1,(LOG(Z27,2)+1),IF($E27=0,(LOG(1-Z27,2)+1),"")) -> 0.21412481 | ... Q27: =IF($E27=1,(LOG(AD27,2)+1),IF($E27=0,(LOG(1-AD27,2)+1),"")) -> 0 | R27: =SUM(F27:Q27) -> -2.7082998 | S27: =Andrew!D27 -> 0.6 | T27: =Eileen!D27 -> 0.15 | U27: =Iain!D27 -> 0.7 | V27: =Kate!D27 -> 0.7 | W27: =Rohan!D27 -> 0.25 | X27: =David!D27 -> 0.7 | Y27: =Jac!D27 -> 0.4 | Z27: =James!D27 -> 0.42 | AA27: =Chris!D27 -> 0.6 | AB27: =Lachy!D27 -> 0.64565631 | AC27: =Gael!D27 -> 0.78 | AD27: =Bruce!D27 -> 0.5 | AE27: =Jac!E27 -> 0.4 | AF27: =Jac!F27 -> 0.3 | AG27: =Jac!G27 -> 0.5 | AH27: =Bruce!E27 -> 0.5 | AI27: =Bruce!F27 -> 0.5
A28: 27 | B28: Iain | C28: Rupert Murdoch (94) will die. | D28: Society | E28: 0 | F28: =IF($E28=1,(LOG(S28,2)+1),IF($E28=0,(LOG(1-S28,2)+1),"")) -> 0.37851162 | G28: =IF($E28=1,(LOG(T28,2)+1),IF($E28=0,(LOG(1-T28,2)+1),"")) -> 0.84799691 | H28: =IF($E28=1,(LOG(U28,2)+1),IF($E28=0,(LOG(1-U28,2)+1),"")) -> 0.48542683 | I28: =IF($E28=1,(LOG(V28,2)+1),IF($E28=0,(LOG(1-V28,2)+1),"")) -> 0.48542683 | J28: =IF($E28=1,(LOG(W28,2)+1),IF($E28=0,(LOG(1-W28,2)+1),"")) -> 0.37851162 | K28: =IF($E28=1,(LOG(X28,2)+1),IF($E28=0,(LOG(1-X28,2)+1),"")) -> -0.73696559 | L28: =IF($E28=1,(LOG(Y28,2)+1),IF($E28=0,(LOG(1-Y28,2)+1),"")) -> -0.32192809 | M28: =IF($E28=1,(LOG(Z28,2)+1),IF($E28=0,(LOG(1-Z28,2)+1),"")) -> 0.31034012 | ... Q28: =IF($E28=1,(LOG(AD28,2)+1),IF($E28=0,(LOG(1-AD28,2)+1),"")) -> 0.5849625 | R28: =SUM(F28:Q28) -> 1.8435414 | S28: =Andrew!D28 -> 0.35 | T28: =Eileen!D28 -> 0.1 | U28: =Iain!D28 -> 0.3 | V28: =Kate!D28 -> 0.3 | W28: =Rohan!D28 -> 0.35 | X28: =David!D28 -> 0.7 | Y28: =Jac!D28 -> 0.6 | Z28: =James!D28 -> 0.38 | AA28: =Chris!D28 -> 0.4 | AB28: =Lachy!D28 -> 0.59868766 | AC28: =Gael!D28 -> 0.65 | AD28: =Bruce!D28 -> 0.25 | AE28: =Jac!E28 -> 0.4 | AF28: =Jac!F28 -> 0.6 | AG28: =Jac!G28 -> 0.5 | AH28: =Bruce!E28 -> 0.2 | AI28: =Bruce!F28 -> 0.3
A29: 28 | B29: Iain | C29: Clint Eastwood (95) will still be alive at Xmas. | D29: Society | E29: 1 | F29: =IF($E29=1,(LOG(S29,2)+1),IF($E29=0,(LOG(1-S29,2)+1),"")) -> -0.32192809 | G29: =IF($E29=1,(LOG(T29,2)+1),IF($E29=0,(LOG(1-T29,2)+1),"")) -> 0.48542683 | H29: =IF($E29=1,(LOG(U29,2)+1),IF($E29=0,(LOG(1-U29,2)+1),"")) -> 0.26303441 | I29: =IF($E29=1,(LOG(V29,2)+1),IF($E29=0,(LOG(1-V29,2)+1),"")) -> -0.73696559 | J29: =IF($E29=1,(LOG(W29,2)+1),IF($E29=0,(LOG(1-W29,2)+1),"")) -> 0.26303441 | K29: =IF($E29=1,(LOG(X29,2)+1),IF($E29=0,(LOG(1-X29,2)+1),"")) -> 0.48542683 | L29: =IF($E29=1,(LOG(Y29,2)+1),IF($E29=0,(LOG(1-Y29,2)+1),"")) -> 0.26303441 | M29: =IF($E29=1,(LOG(Z29,2)+1),IF($E29=0,(LOG(1-Z29,2)+1),"")) -> 0.13750352 | ... Q29: =IF($E29=1,(LOG(AD29,2)+1),IF($E29=0,(LOG(1-AD29,2)+1),"")) -> 0.54596837 | R29: =SUM(F29:Q29) -> 2.3752188 | S29: =Andrew!D29 -> 0.4 | T29: =Eileen!D29 -> 0.7 | U29: =Iain!D29 -> 0.6 | V29: =Kate!D29 -> 0.3 | W29: =Rohan!D29 -> 0.6 | X29: =David!D29 -> 0.7 | Y29: =Jac!D29 -> 0.6 | Z29: =James!D29 -> 0.55 | AA29: =Chris!D29 -> 0.6 | AB29: =Lachy!D29 -> 0.68997448 | AC29: =Gael!D29 -> 0.6 | AD29: =Bruce!D29 -> 0.73 | AE29: =Jac!E29 -> 0.6 | AF29: =Jac!F29 -> 0.6 | AG29: =Jac!G29 -> 0.5 | AH29: =Bruce!E29 -> 0.6 | AI29: =Bruce!F29 -> 0.85
A30: 29 | B30: Iain | C30: The cost of studying ‘society and culture’ (currently in cluster 1 in tertiary education) will not be lowered : https://www.studyassist.gov.au/financial-and-study-support/commonwealth-supported-places/student-contribution-amounts | D30: Society | E30: 1 | F30: =IF($E30=1,(LOG(S30,2)+1),IF($E30=0,(LOG(1-S30,2)+1),"")) -> 0.26303441 | G30: =IF($E30=1,(LOG(T30,2)+1),IF($E30=0,(LOG(1-T30,2)+1),"")) -> 0 | H30: =IF($E30=1,(LOG(U30,2)+1),IF($E30=0,(LOG(1-U30,2)+1),"")) -> 0.26303441 | I30: =IF($E30=1,(LOG(V30,2)+1),IF($E30=0,(LOG(1-V30,2)+1),"")) -> 0.84799691 | J30: =IF($E30=1,(LOG(W30,2)+1),IF($E30=0,(LOG(1-W30,2)+1),"")) -> -0.15200309 | K30: =IF($E30=1,(LOG(X30,2)+1),IF($E30=0,(LOG(1-X30,2)+1),"")) -> 0.48542683 | L30: =IF($E30=1,(LOG(Y30,2)+1),IF($E30=0,(LOG(1-Y30,2)+1),"")) -> 0.84799691 | M30: =IF($E30=1,(LOG(Z30,2)+1),IF($E30=0,(LOG(1-Z30,2)+1),"")) -> 0.44360665 | ... Q30: =IF($E30=1,(LOG(AD30,2)+1),IF($E30=0,(LOG(1-AD30,2)+1),"")) -> 0.67807191 | R30: =SUM(F30:Q30) -> 5.3300235 | S30: =Andrew!D30 -> 0.6 | T30: =Eileen!D30 -> 0.5 | U30: =Iain!D30 -> 0.6 | V30: =Kate!D30 -> 0.9 | W30: =Rohan!D30 -> 0.45 | X30: =David!D30 -> 0.7 | Y30: =Jac!D30 -> 0.9 | Z30: =James!D30 -> 0.68 | AA30: =Chris!D30 -> 0.7 | AB30: =Lachy!D30 -> 0.80218389 | AC30: =Gael!D30 -> 0.7 | AD30: =Bruce!D30 -> 0.8 | AE30: =Jac!E30 -> 0.9 | AF30: =Jac!F30 -> 0.9 | AG30: =Jac!G30 -> 0.8 | AH30: =Bruce!E30 -> 0.7 | AI30: =Bruce!F30 -> 0.9
A31: 30 | B31: Dave | C31: Taylor announces she is pregnant | D31: Entertainment | E31: 0 | F31: =IF($E31=1,(LOG(S31,2)+1),IF($E31=0,(LOG(1-S31,2)+1),"")) -> 0.26303441 | G31: =IF($E31=1,(LOG(T31,2)+1),IF($E31=0,(LOG(1-T31,2)+1),"")) -> 0.84799691 | H31: =IF($E31=1,(LOG(U31,2)+1),IF($E31=0,(LOG(1-U31,2)+1),"")) -> 0.26303441 | I31: =IF($E31=1,(LOG(V31,2)+1),IF($E31=0,(LOG(1-V31,2)+1),"")) -> 0 | J31: =IF($E31=1,(LOG(W31,2)+1),IF($E31=0,(LOG(1-W31,2)+1),"")) -> 0.76553475 | K31: =IF($E31=1,(LOG(X31,2)+1),IF($E31=0,(LOG(1-X31,2)+1),"")) -> -0.73696559 | L31: =IF($E31=1,(LOG(Y31,2)+1),IF($E31=0,(LOG(1-Y31,2)+1),"")) -> 0 | M31: =IF($E31=1,(LOG(Z31,2)+1),IF($E31=0,(LOG(1-Z31,2)+1),"")) -> 0.52606881 | ... Q31: =IF($E31=1,(LOG(AD31,2)+1),IF($E31=0,(LOG(1-AD31,2)+1),"")) -> 0 | R31: =SUM(F31:Q31) -> 1.7742073 | S31: =Andrew!D31 -> 0.4 | T31: =Eileen!D31 -> 0.1 | U31: =Iain!D31 -> 0.4 | V31: =Kate!D31 -> 0.5 | W31: =Rohan!D31 -> 0.15 | X31: =David!D31 -> 0.7 | Y31: =Jac!D31 -> 0.5 | Z31: =James!D31 -> 0.28 | AA31: =Chris!D31 -> 0.3 | AB31: =Lachy!D31 -> 0.19781611 | AC31: =Gael!D31 -> 0.8 | AD31: =Bruce!D31 -> 0.5 | AE31: =Jac!E31 -> 0.4 | AF31: =Jac!F31 -> 0.3 | AG31: =Jac!G31 -> 0.5 | AH31: =Bruce!E31 -> 0.5 | AI31: =Bruce!F31 -> 0.5
A32: 31 | B32: Dave | C32: Kansas City wins the Super Bowl (a threepeat) | D32: Sport | E32: 0 | F32: =IF($E32=1,(LOG(S32,2)+1),IF($E32=0,(LOG(1-S32,2)+1),"")) -> 0.5849625 | G32: =IF($E32=1,(LOG(T32,2)+1),IF($E32=0,(LOG(1-T32,2)+1),"")) -> -0.73696559 | H32: =IF($E32=1,(LOG(U32,2)+1),IF($E32=0,(LOG(1-U32,2)+1),"")) -> 0 | I32: =IF($E32=1,(LOG(V32,2)+1),IF($E32=0,(LOG(1-V32,2)+1),"")) -> 0.67807191 | J32: =IF($E32=1,(LOG(W32,2)+1),IF($E32=0,(LOG(1-W32,2)+1),"")) -> -1 | K32: =IF($E32=1,(LOG(X32,2)+1),IF($E32=0,(LOG(1-X32,2)+1),"")) -> 0 | L32: =IF($E32=1,(LOG(Y32,2)+1),IF($E32=0,(LOG(1-Y32,2)+1),"")) -> -0.32192809 | M32: =IF($E32=1,(LOG(Z32,2)+1),IF($E32=0,(LOG(1-Z32,2)+1),"")) -> -0.73696559 | ... Q32: =IF($E32=1,(LOG(AD32,2)+1),IF($E32=0,(LOG(1-AD32,2)+1),"")) -> 0.26303441 | R32: =SUM(F32:Q32) -> -1.8483003 | S32: =Andrew!D32 -> 0.25 | T32: =Eileen!D32 -> 0.7 | U32: =Iain!D32 -> 0.5 | V32: =Kate!D32 -> 0.2 | W32: =Rohan!D32 -> 0.75 | X32: =David!D32 -> 0.5 | Y32: =Jac!D32 -> 0.6 | Z32: =James!D32 -> 0.7 | AA32: =Chris!D32 -> 0.1 | AB32: =Lachy!D32 -> 0.68997448 | AC32: =Gael!D32 -> 0.7 | AD32: =Bruce!D32 -> 0.4 | AE32: =Jac!E32 -> 0.3 | AF32: =Jac!F32 -> 0.7 | AG32: =Jac!G32 -> 0.4 | AH32: =Bruce!E32 -> 0.45 | AI32: =Bruce!F32 -> 0.3
A33: 32 | B33: Dave | C33: James Gunn’s Superman reboot (to be released mid year) will have a worldwide box office over US$2 billion (the last time a movie was > 2 billion was the second Avatar movie in 2022). (https://www.boxofficemojo.com/year/world/2025/) | D33: Entertainment | E33: 0 | F33: =IF($E33=1,(LOG(S33,2)+1),IF($E33=0,(LOG(1-S33,2)+1),"")) -> 0.26303441 | G33: =IF($E33=1,(LOG(T33,2)+1),IF($E33=0,(LOG(1-T33,2)+1),"")) -> 0.26303441 | H33: =IF($E33=1,(LOG(U33,2)+1),IF($E33=0,(LOG(1-U33,2)+1),"")) -> -0.32192809 | I33: =IF($E33=1,(LOG(V33,2)+1),IF($E33=0,(LOG(1-V33,2)+1),"")) -> 0.26303441 | J33: =IF($E33=1,(LOG(W33,2)+1),IF($E33=0,(LOG(1-W33,2)+1),"")) -> 0.76553475 | K33: =IF($E33=1,(LOG(X33,2)+1),IF($E33=0,(LOG(1-X33,2)+1),"")) -> 0.84799691 | L33: =IF($E33=1,(LOG(Y33,2)+1),IF($E33=0,(LOG(1-Y33,2)+1),"")) -> 0.67807191 | M33: =IF($E33=1,(LOG(Z33,2)+1),IF($E33=0,(LOG(1-Z33,2)+1),"")) -> 0.76553475 | ... Q33: =IF($E33=1,(LOG(AD33,2)+1),IF($E33=0,(LOG(1-AD33,2)+1),"")) -> -0.32192809 | R33: =SUM(F33:Q33) -> 3.410459 | S33: =Andrew!D33 -> 0.4 | T33: =Eileen!D33 -> 0.4 | U33: =Iain!D33 -> 0.6 | V33: =Kate!D33 -> 0.4 | W33: =Rohan!D33 -> 0.15 | X33: =David!D33 -> 0.1 | Y33: =Jac!D33 -> 0.2 | Z33: =James!D33 -> 0.15 | AA33: =Chris!D33 -> 0.1 | AB33: =Lachy!D33 -> 0.19781611 | AC33: =Gael!D33 -> 0.8 | AD33: =Bruce!D33 -> 0.6 | AE33: =Jac!E33 -> 0.2 | AF33: =Jac!F33 -> 0.2 | AG33: =Jac!G33 -> 0.3 | AH33: =Bruce!E33 -> 0.55 | AI33: =Bruce!F33 -> 0.7
A34: 33 | B34: Dave | C34: Bitcoin will be worth >US$200,000 at some point in the year | D34: Finance | E34: 0 | F34: =IF($E34=1,(LOG(S34,2)+1),IF($E34=0,(LOG(1-S34,2)+1),"")) -> 0.67807191 | G34: =IF($E34=1,(LOG(T34,2)+1),IF($E34=0,(LOG(1-T34,2)+1),"")) -> 0.84799691 | H34: =IF($E34=1,(LOG(U34,2)+1),IF($E34=0,(LOG(1-U34,2)+1),"")) -> 0 | I34: =IF($E34=1,(LOG(V34,2)+1),IF($E34=0,(LOG(1-V34,2)+1),"")) -> 0.67807191 | J34: =IF($E34=1,(LOG(W34,2)+1),IF($E34=0,(LOG(1-W34,2)+1),"")) -> -1.7369656 | K34: =IF($E34=1,(LOG(X34,2)+1),IF($E34=0,(LOG(1-X34,2)+1),"")) -> 0.84799691 | L34: =IF($E34=1,(LOG(Y34,2)+1),IF($E34=0,(LOG(1-Y34,2)+1),"")) -> 0.26303441 | M34: =IF($E34=1,(LOG(Z34,2)+1),IF($E34=0,(LOG(1-Z34,2)+1),"")) -> 0.44360665 | ... Q34: =IF($E34=1,(LOG(AD34,2)+1),IF($E34=0,(LOG(1-AD34,2)+1),"")) -> 0.26303441 | R34: =SUM(F34:Q34) -> 2.7153136 | S34: =Andrew!D34 -> 0.2 | T34: =Eileen!D34 -> 0.1 | U34: =Iain!D34 -> 0.5 | V34: =Kate!D34 -> 0.2 | W34: =Rohan!D34 -> 0.85 | X34: =David!D34 -> 0.1 | Y34: =Jac!D34 -> 0.4 | Z34: =James!D34 -> 0.32 | AA34: =Chris!D34 -> 0.3 | AB34: =Lachy!D34 -> 0.19781611 | AC34: =Gael!D34 -> 0.7 | AD34: =Bruce!D34 -> 0.4 | AE34: =Jac!E34 -> 0.4 | AF34: =Jac!F34 -> 0.3 | AG34: =Jac!G34 -> 0.5 | AH34: =Bruce!E34 -> 0.45 | AI34: =Bruce!F34 -> 0.3
A35: 34 | B35: Dave | C35: Elon will still top the Bloomberg list here https://www.bloomberg.com/billionaires/ | D35: Society | E35: 1 | F35: =IF($E35=1,(LOG(S35,2)+1),IF($E35=0,(LOG(1-S35,2)+1),"")) -> 0.67807191 | G35: =IF($E35=1,(LOG(T35,2)+1),IF($E35=0,(LOG(1-T35,2)+1),"")) -> 0.5849625 | H35: =IF($E35=1,(LOG(U35,2)+1),IF($E35=0,(LOG(1-U35,2)+1),"")) -> 0.48542683 | I35: =IF($E35=1,(LOG(V35,2)+1),IF($E35=0,(LOG(1-V35,2)+1),"")) -> 0.48542683 | J35: =IF($E35=1,(LOG(W35,2)+1),IF($E35=0,(LOG(1-W35,2)+1),"")) -> 0.48542683 | K35: =IF($E35=1,(LOG(X35,2)+1),IF($E35=0,(LOG(1-X35,2)+1),"")) -> -0.73696559 | L35: =IF($E35=1,(LOG(Y35,2)+1),IF($E35=0,(LOG(1-Y35,2)+1),"")) -> 0.26303441 | M35: =IF($E35=1,(LOG(Z35,2)+1),IF($E35=0,(LOG(1-Z35,2)+1),"")) -> 0.67807191 | ... Q35: =IF($E35=1,(LOG(AD35,2)+1),IF($E35=0,(LOG(1-AD35,2)+1),"")) -> 0.84799691 | R35: =SUM(F35:Q35) -> 5.9795262 | S35: =Andrew!D35 -> 0.8 | T35: =Eileen!D35 -> 0.75 | U35: =Iain!D35 -> 0.7 | V35: =Kate!D35 -> 0.7 | W35: =Rohan!D35 -> 0.7 | X35: =David!D35 -> 0.3 | Y35: =Jac!D35 -> 0.6 | Z35: =James!D35 -> 0.8 | AA35: =Chris!D35 -> 0.9 | AB35: =Lachy!D35 -> 0.80218389 | AC35: =Gael!D35 -> 0.8 | AD35: =Bruce!D35 -> 0.9 | AE35: =Jac!E35 -> 0.6 | AF35: =Jac!F35 -> 0.8 | AG35: =Jac!G35 -> 0.5 | AH35: =Bruce!E35 -> 0.8 | AI35: =Bruce!F35 -> 0.99
... A44: 43 | B44: Christine | C44: The market value of the 35th anniversary Sylvanian Families Deluxe Celebration Home will surpass A$2000: see for example https://www.ebay.com.au/itm/395720810837?chn=ps&_ul=AU&norover=1&mkevt=1&mkrid=705-139619-5960-0&mkcid=2&mkscid=101&itemid=395720810837&targetid=2365752142950&device=m&mktype=pla&googleloc=9071971&poi=&campaignid=21776459266&mkgroupid=171915223801&rlsatarget=pla-2365752142950&abcId=10047394&merchantid=694128940&gad_source=1&gbraid=0AAAAAD97CxTMjt0s6W9OxT_H7Qei1ZYr8&gclid=EAIaIQobChMI2JvY_-HYigMV96dmAh1KqxiBEAQYASABEgKsA_D_BwE. | D44: Society | E44: 0 | F44: =IF($E44=1,(LOG(S44,2)+1),IF($E44=0,(LOG(1-S44,2)+1),"")) -> 0.26303441 | G44: =IF($E44=1,(LOG(T44,2)+1),IF($E44=0,(LOG(1-T44,2)+1),"")) -> -0.32192809 | H44: =IF($E44=1,(LOG(U44,2)+1),IF($E44=0,(LOG(1-U44,2)+1),"")) -> 0.48542683 | I44: =IF($E44=1,(LOG(V44,2)+1),IF($E44=0,(LOG(1-V44,2)+1),"")) -> 0.67807191 | J44: =IF($E44=1,(LOG(W44,2)+1),IF($E44=0,(LOG(1-W44,2)+1),"")) -> -0.12029423 | K44: =IF($E44=1,(LOG(X44,2)+1),IF($E44=0,(LOG(1-X44,2)+1),"")) -> 0.48542683 | L44: =IF($E44=1,(LOG(Y44,2)+1),IF($E44=0,(LOG(1-Y44,2)+1),"")) -> 0.84799691 | M44: =IF($E44=1,(LOG(Z44,2)+1),IF($E44=0,(LOG(1-Z44,2)+1),"")) -> 0.5849625 | ... Q44: =IF($E44=1,(LOG(AD44,2)+1),IF($E44=0,(LOG(1-AD44,2)+1),"")) -> 0.67807191 | R44: =SUM(F44:Q44) -> 2.8324515 | S44: =Andrew!D44 -> 0.4 | T44: =Eileen!D44 -> 0.6 | U44: =Iain!D44 -> 0.3 | V44: =Kate!D44 -> 0.2 | W44: =Rohan!D44 -> 0.54 | X44: =David!D44 -> 0.3 | Y44: =Jac!D44 -> 0.1 | Z44: =James!D44 -> 0.25 | AA44: =Chris!D44 -> 0.3 | AB44: =Lachy!D44 -> 0.64565631 | AC44: =Gael!D44 -> 0.7 | AD44: =Bruce!D44 -> 0.2 | AE44: =Jac!E44 -> 0.1 | AF44: =Jac!F44 -> 0.1 | AG44: =Jac!G44 -> 0.2 | AH44: =Bruce!E44 -> 0.3 | AI44: =Bruce!F44 -> 0.1
A45: 44 | B45: Christine | C45: More than 500 new species will be added to Australia’s National Species List in 2025: see https://planetark.org/newsroom/news/750-new-species-added-to-australias-national-species-list | D45: Nature | E45: - | F45: =IF($E45=1,(LOG(S45,2)+1),IF($E45=0,(LOG(1-S45,2)+1),"")) | G45: =IF($E45=1,(LOG(T45,2)+1),IF($E45=0,(LOG(1-T45,2)+1),"")) | H45: =IF($E45=1,(LOG(U45,2)+1),IF($E45=0,(LOG(1-U45,2)+1),"")) | I45: =IF($E45=1,(LOG(V45,2)+1),IF($E45=0,(LOG(1-V45,2)+1),"")) | J45: =IF($E45=1,(LOG(W45,2)+1),IF($E45=0,(LOG(1-W45,2)+1),"")) | K45: =IF($E45=1,(LOG(X45,2)+1),IF($E45=0,(LOG(1-X45,2)+1),"")) | L45: =IF($E45=1,(LOG(Y45,2)+1),IF($E45=0,(LOG(1-Y45,2)+1),"")) | M45: =IF($E45=1,(LOG(Z45,2)+1),IF($E45=0,(LOG(1-Z45,2)+1),"")) | ... Q45: =IF($E45=1,(LOG(AD45,2)+1),IF($E45=0,(LOG(1-AD45,2)+1),"")) | R45: =SUM(F45:Q45) -> 0 | S45: =Andrew!D45 -> 0.6 | T45: =Eileen!D45 -> 0.35 | U45: =Iain!D45 -> 0.6 | V45: =Kate!D45 -> 0.7 | W45: =Rohan!D45 -> 0.39 | X45: =David!D45 -> 0.7 | Y45: =Jac!D45 -> 0.4 | Z45: =James!D45 -> 0.48 | AA45: =Chris!D45 -> 0.4 | AB45: =Lachy!D45 -> 0.35434369 | AC45: =Gael!D45 -> 0.68 | AD45: =Bruce!D45 -> 0.6 | AE45: =Jac!E45 -> 0.4 | AF45: =Jac!F45 -> 0.3 | AG45: =Jac!G45 -> 0.5 | AH45: =Bruce!E45 -> 0.55 | AI45: =Bruce!F45 -> 0.7
A46: 45 | B46: Jac | C46: A Knight of the Seven Kingdoms series being released in 2025 - season 1 will have a rotten tomatoes rating of 90% or greater on 15 December | D46: Entertainment | E46: 0 | F46: =IF($E46=1,(LOG(S46,2)+1),IF($E46=0,(LOG(1-S46,2)+1),"")) -> 0.67807191 | G46: =IF($E46=1,(LOG(T46,2)+1),IF($E46=0,(LOG(1-T46,2)+1),"")) -> 0.37851162 | H46: =IF($E46=1,(LOG(U46,2)+1),IF($E46=0,(LOG(1-U46,2)+1),"")) -> 0.48542683 | I46: =IF($E46=1,(LOG(V46,2)+1),IF($E46=0,(LOG(1-V46,2)+1),"")) -> 0 | J46: =IF($E46=1,(LOG(W46,2)+1),IF($E46=0,(LOG(1-W46,2)+1),"")) -> 0.028569152 | K46: =IF($E46=1,(LOG(X46,2)+1),IF($E46=0,(LOG(1-X46,2)+1),"")) -> -0.73696559 | L46: =IF($E46=1,(LOG(Y46,2)+1),IF($E46=0,(LOG(1-Y46,2)+1),"")) -> 0.48542683 | M46: =IF($E46=1,(LOG(Z46,2)+1),IF($E46=0,(LOG(1-Z46,2)+1),"")) -> 0.21412481 | ... Q46: =IF($E46=1,(LOG(AD46,2)+1),IF($E46=0,(LOG(1-AD46,2)+1),"")) -> -0.32192809 | R46: =SUM(F46:Q46) -> -0.51989994 | S46: =Andrew!D46 -> 0.2 | T46: =Eileen!D46 -> 0.35 | U46: =Iain!D46 -> 0.3 | V46: =Kate!D46 -> 0.5 | W46: =Rohan!D46 -> 0.49 | X46: =David!D46 -> 0.7 | Y46: =Jac!D46 -> 0.3 | Z46: =James!D46 -> 0.42 | AA46: =Chris!D46 -> 0.6 | AB46: =Lachy!D46 -> 0.73105858 | AC46: =Gael!D46 -> 0.65 | AD46: =Bruce!D46 -> 0.6 | AE46: =Jac!E46 -> 0.3 | AF46: =Jac!F46 -> 0.2 | AG46: =Jac!G46 -> 0.3 | AH46: =Bruce!E46 -> 0.55 | AI46: =Bruce!F46 -> 0.7
A47: 46 | B47: Jac | C47: The unemployment rate for Australia is no higher than 4.5% throughout the year until 15 December. | D47: Finance | E47: 1 | F47: =IF($E47=1,(LOG(S47,2)+1),IF($E47=0,(LOG(1-S47,2)+1),"")) -> 0.48542683 | G47: =IF($E47=1,(LOG(T47,2)+1),IF($E47=0,(LOG(1-T47,2)+1),"")) -> -1 | H47: =IF($E47=1,(LOG(U47,2)+1),IF($E47=0,(LOG(1-U47,2)+1),"")) -> 0.26303441 | I47: =IF($E47=1,(LOG(V47,2)+1),IF($E47=0,(LOG(1-V47,2)+1),"")) -> 0.48542683 | J47: =IF($E47=1,(LOG(W47,2)+1),IF($E47=0,(LOG(1-W47,2)+1),"")) -> 0.26303441 | K47: =IF($E47=1,(LOG(X47,2)+1),IF($E47=0,(LOG(1-X47,2)+1),"")) -> 0.48542683 | L47: =IF($E47=1,(LOG(Y47,2)+1),IF($E47=0,(LOG(1-Y47,2)+1),"")) -> 0.26303441 | M47: =IF($E47=1,(LOG(Z47,2)+1),IF($E47=0,(LOG(1-Z47,2)+1),"")) -> 0.62293035 | ... Q47: =IF($E47=1,(LOG(AD47,2)+1),IF($E47=0,(LOG(1-AD47,2)+1),"")) -> 0.26303441 | R47: =SUM(F47:Q47) -> 1.9251772 | S47: =Andrew!D47 -> 0.7 | T47: =Eileen!D47 -> 0.25 | U47: =Iain!D47 -> 0.6 | V47: =Kate!D47 -> 0.7 | W47: =Rohan!D47 -> 0.6 | X47: =David!D47 -> 0.7 | Y47: =Jac!D47 -> 0.6 | Z47: =James!D47 -> 0.77 | AA47: =Chris!D47 -> 0.9 | AB47: =Lachy!D47 -> 0.40131234 | AC47: =Gael!D47 -> 0.3 | AD47: =Bruce!D47 -> 0.6 | AE47: =Jac!E47 -> 0.5 | AF47: =Jac!F47 -> 0.6 | AG47: =Jac!G47 -> 0.5 | AH47: =Bruce!E47 -> 0.55 | AI47: =Bruce!F47 -> 0.7
A48: 47 | B48: Jac | C48: The People's Action Party will win fewer than 80 seats in the Singaporean general election. | D48: Politics | E48: 0 | F48: =IF($E48=1,(LOG(S48,2)+1),IF($E48=0,(LOG(1-S48,2)+1),"")) -> 0.48542683 | G48: =IF($E48=1,(LOG(T48,2)+1),IF($E48=0,(LOG(1-T48,2)+1),"")) -> 0.48542683 | H48: =IF($E48=1,(LOG(U48,2)+1),IF($E48=0,(LOG(1-U48,2)+1),"")) -> 0.67807191 | I48: =IF($E48=1,(LOG(V48,2)+1),IF($E48=0,(LOG(1-V48,2)+1),"")) -> -0.73696559 | J48: =IF($E48=1,(LOG(W48,2)+1),IF($E48=0,(LOG(1-W48,2)+1),"")) -> 0.92599942 | K48: =IF($E48=1,(LOG(X48,2)+1),IF($E48=0,(LOG(1-X48,2)+1),"")) -> 0 | L48: =IF($E48=1,(LOG(Y48,2)+1),IF($E48=0,(LOG(1-Y48,2)+1),"")) -> 0.26303441 | M48: =IF($E48=1,(LOG(Z48,2)+1),IF($E48=0,(LOG(1-Z48,2)+1),"")) -> 0.44360665 | ... Q48: =IF($E48=1,(LOG(AD48,2)+1),IF($E48=0,(LOG(1-AD48,2)+1),"")) -> -0.15200309 | R48: =SUM(F48:Q48) -> 3.020711 | S48: =Andrew!D48 -> 0.3 | T48: =Eileen!D48 -> 0.3 | U48: =Iain!D48 -> 0.2 | V48: =Kate!D48 -> 0.7 | W48: =Rohan!D48 -> 0.05 | X48: =David!D48 -> 0.5 | Y48: =Jac!D48 -> 0.4 | Z48: =James!D48 -> 0.32 | AA48: =Chris!D48 -> 0.3 | AB48: =Lachy!D48 -> 0.31002552 | AC48: =Gael!D48 -> 0.6 | AD48: =Bruce!D48 -> 0.55 | AE48: =Jac!E48 -> 0.4 | AF48: =Jac!F48 -> 0.3 | AG48: =Jac!G48 -> 0.5 | AH48: =Bruce!E48 -> 0.5 | AI48: =Bruce!F48 -> 0.6
A49: 48 | B49: Jac | C49: Peace talks will commence in the Russian/Ukrainian war, involving official reprerestatives of at least Russia and Ukraine, with a declared intention of reaching agreement on ceasing hostilities | D49: Politics | E49: 1 | F49: =IF($E49=1,(LOG(S49,2)+1),IF($E49=0,(LOG(1-S49,2)+1),"")) -> 0.37851162 | G49: =IF($E49=1,(LOG(T49,2)+1),IF($E49=0,(LOG(1-T49,2)+1),"")) -> -0.51457317 | H49: =IF($E49=1,(LOG(U49,2)+1),IF($E49=0,(LOG(1-U49,2)+1),"")) -> 0.26303441 | I49: =IF($E49=1,(LOG(V49,2)+1),IF($E49=0,(LOG(1-V49,2)+1),"")) -> 0.26303441 | J49: =IF($E49=1,(LOG(W49,2)+1),IF($E49=0,(LOG(1-W49,2)+1),"")) -> 0.084064265 | K49: =IF($E49=1,(LOG(X49,2)+1),IF($E49=0,(LOG(1-X49,2)+1),"")) -> 0 | L49: =IF($E49=1,(LOG(Y49,2)+1),IF($E49=0,(LOG(1-Y49,2)+1),"")) -> 0.26303441 | M49: =IF($E49=1,(LOG(Z49,2)+1),IF($E49=0,(LOG(1-Z49,2)+1),"")) -> -0.15200309 | ... Q49: =IF($E49=1,(LOG(AD49,2)+1),IF($E49=0,(LOG(1-AD49,2)+1),"")) -> 0.26303441 | R49: =SUM(F49:Q49) -> 1.7296199 | S49: =Andrew!D49 -> 0.65 | T49: =Eileen!D49 -> 0.35 | U49: =Iain!D49 -> 0.6 | V49: =Kate!D49 -> 0.6 | W49: =Rohan!D49 -> 0.53 | X49: =David!D49 -> 0.5 | Y49: =Jac!D49 -> 0.6 | Z49: =James!D49 -> 0.45 | AA49: =Chris!D49 -> 0.45 | AB49: =Lachy!D49 -> 0.73105858 | AC49: =Gael!D49 -> 0.7 | AD49: =Bruce!D49 -> 0.6 | AE49: =Jac!E49 -> 0.4 | AF49: =Jac!F49 -> 0.6 | AG49: =Jac!G49 -> 0.5 | AH49: =Bruce!E49 -> 0.55 | AI49: =Bruce!F49 -> 0.7
A50: 49 | B50: Jac | C50: Costa Georgiadis removes at least 10cm off his beard for a charitable purpose. | D50: Entertainment | E50: 0 | F50: =IF($E50=1,(LOG(S50,2)+1),IF($E50=0,(LOG(1-S50,2)+1),"")) -> 0.48542683 | G50: =IF($E50=1,(LOG(T50,2)+1),IF($E50=0,(LOG(1-T50,2)+1),"")) -> 0.84799691 | H50: =IF($E50=1,(LOG(U50,2)+1),IF($E50=0,(LOG(1-U50,2)+1),"")) -> 0.67807191 | I50: =IF($E50=1,(LOG(V50,2)+1),IF($E50=0,(LOG(1-V50,2)+1),"")) -> 0.67807191 | J50: =IF($E50=1,(LOG(W50,2)+1),IF($E50=0,(LOG(1-W50,2)+1),"")) -> 0.79908731 | K50: =IF($E50=1,(LOG(X50,2)+1),IF($E50=0,(LOG(1-X50,2)+1),"")) -> 0 | L50: =IF($E50=1,(LOG(Y50,2)+1),IF($E50=0,(LOG(1-Y50,2)+1),"")) -> 0.26303441 | M50: =IF($E50=1,(LOG(Z50,2)+1),IF($E50=0,(LOG(1-Z50,2)+1),"")) -> 0.31034012 | ... Q50: =IF($E50=1,(LOG(AD50,2)+1),IF($E50=0,(LOG(1-AD50,2)+1),"")) -> 0.26303441 | R50: =SUM(F50:Q50) -> 5.0527131 | S50: =Andrew!D50 -> 0.3 | T50: =Eileen!D50 -> 0.1 | U50: =Iain!D50 -> 0.2 | V50: =Kate!D50 -> 0.2 | W50: =Rohan!D50 -> 0.13 | X50: =David!D50 -> 0.5 | Y50: =Jac!D50 -> 0.4 | Z50: =James!D50 -> 0.38 | AA50: =Chris!D50 -> 0.5 | AB50: =Lachy!D50 -> 0.31002552 | AC50: =Gael!D50 -> 0.4 | AD50: =Bruce!D50 -> 0.4 | AE50: =Jac!E50 -> 0.4 | AF50: =Jac!F50 -> 0.6 | AG50: =Jac!G50 -> 0.5 | AH50: =Bruce!E50 -> 0.45 | AI50: =Bruce!F50 -> 0.3
A51: 50 | B51: Kate | C51: Norway’s election will see shift to right (biggest party will be more right wing than current biggest party, as defined by politpro.eu). | D51: Politics | E51: 0 | F51: =IF($E51=1,(LOG(S51,2)+1),IF($E51=0,(LOG(1-S51,2)+1),"")) -> 0.84799691 | G51: =IF($E51=1,(LOG(T51,2)+1),IF($E51=0,(LOG(1-T51,2)+1),"")) -> 0.67807191 | H51: =IF($E51=1,(LOG(U51,2)+1),IF($E51=0,(LOG(1-U51,2)+1),"")) -> -0.73696559 | I51: =IF($E51=1,(LOG(V51,2)+1),IF($E51=0,(LOG(1-V51,2)+1),"")) -> -0.73696559 | J51: =IF($E51=1,(LOG(W51,2)+1),IF($E51=0,(LOG(1-W51,2)+1),"")) -> -0.25153877 | K51: =IF($E51=1,(LOG(X51,2)+1),IF($E51=0,(LOG(1-X51,2)+1),"")) -> 0 | L51: =IF($E51=1,(LOG(Y51,2)+1),IF($E51=0,(LOG(1-Y51,2)+1),"")) -> -2.3219281 | M51: =IF($E51=1,(LOG(Z51,2)+1),IF($E51=0,(LOG(1-Z51,2)+1),"")) -> 0.21412481 | ... Q51: =IF($E51=1,(LOG(AD51,2)+1),IF($E51=0,(LOG(1-AD51,2)+1),"")) -> -2.3219281 | R51: =SUM(F51:Q51) -> -5.5998424 | S51: =Andrew!D51 -> 0.1 | T51: =Eileen!D51 -> 0.2 | U51: =Iain!D51 -> 0.7 | V51: =Kate!D51 -> 0.7 | W51: =Rohan!D51 -> 0.58 | X51: =David!D51 -> 0.5 | Y51: =Jac!D51 -> 0.9 | Z51: =James!D51 -> 0.42 | AA51: =Chris!D51 -> 0.4 | AB51: =Lachy!D51 -> 0.64565631 | AC51: =Gael!D51 -> 0.7 | AD51: =Bruce!D51 -> 0.9 | AE51: =Jac!E51 -> 0.9 | AF51: =Jac!F51 -> 0.9 | AG51: =Jac!G51 -> 0.8 | AH51: =Bruce!E51 -> 0.7 | AI51: =Bruce!F51 -> 0.99
A52: 51 | B52: Kate | C52: Justin Trudeau will lose Prime Ministership | D52: Politics | E52: 1 | F52: =IF($E52=1,(LOG(S52,2)+1),IF($E52=0,(LOG(1-S52,2)+1),"")) -> 0.26303441 | G52: =IF($E52=1,(LOG(T52,2)+1),IF($E52=0,(LOG(1-T52,2)+1),"")) -> -0.51457317 | H52: =IF($E52=1,(LOG(U52,2)+1),IF($E52=0,(LOG(1-U52,2)+1),"")) -> 0.67807191 | I52: =IF($E52=1,(LOG(V52,2)+1),IF($E52=0,(LOG(1-V52,2)+1),"")) -> 0.98550043 | J52: =IF($E52=1,(LOG(W52,2)+1),IF($E52=0,(LOG(1-W52,2)+1),"")) -> 0.98550043 | K52: =IF($E52=1,(LOG(X52,2)+1),IF($E52=0,(LOG(1-X52,2)+1),"")) -> 0.84799691 | L52: =IF($E52=1,(LOG(Y52,2)+1),IF($E52=0,(LOG(1-Y52,2)+1),"")) -> 0.98550043 | M52: =IF($E52=1,(LOG(Z52,2)+1),IF($E52=0,(LOG(1-Z52,2)+1),"")) -> 0.98550043 | ... Q52: =IF($E52=1,(LOG(AD52,2)+1),IF($E52=0,(LOG(1-AD52,2)+1),"")) -> 0.98550043 | R52: =SUM(F52:Q52) -> 7.7953314 | S52: =Andrew!D52 -> 0.6 | T52: =Eileen!D52 -> 0.35 | U52: =Iain!D52 -> 0.8 | V52: =Kate!D52 -> 0.99 | W52: =Rohan!D52 -> 0.99 | X52: =David!D52 -> 0.9 | Y52: =Jac!D52 -> 0.99 | Z52: =James!D52 -> 0.99 | AA52: =Chris!D52 -> 0.9 | AB52: =Lachy!D52 -> 0.59868766 | AC52: =Gael!D52 -> 0.7 | AD52: =Bruce!D52 -> 0.99 | AE52: =Jac!E52 -> 0.9 | AF52: =Jac!F52 -> 0.99 | AG52: =Jac!G52 -> 0.9 | AH52: =Bruce!E52 -> 0.9 | AI52: =Bruce!F52 -> 1
A53: 52 | B53: Kate | C53: Lewis Hamilton will rank lower this third in F1 drivers champ | D53: Sport | E53: 1 | F53: =IF($E53=1,(LOG(S53,2)+1),IF($E53=0,(LOG(1-S53,2)+1),"")) -> -0.73696559 | G53: =IF($E53=1,(LOG(T53,2)+1),IF($E53=0,(LOG(1-T53,2)+1),"")) -> -1.3219281 | H53: =IF($E53=1,(LOG(U53,2)+1),IF($E53=0,(LOG(1-U53,2)+1),"")) -> 0.48542683 | I53: =IF($E53=1,(LOG(V53,2)+1),IF($E53=0,(LOG(1-V53,2)+1),"")) -> 0.67807191 | J53: =IF($E53=1,(LOG(W53,2)+1),IF($E53=0,(LOG(1-W53,2)+1),"")) -> -2.3219281 | K53: =IF($E53=1,(LOG(X53,2)+1),IF($E53=0,(LOG(1-X53,2)+1),"")) -> 0.48542683 | L53: =IF($E53=1,(LOG(Y53,2)+1),IF($E53=0,(LOG(1-Y53,2)+1),"")) -> 0.67807191 | M53: =IF($E53=1,(LOG(Z53,2)+1),IF($E53=0,(LOG(1-Z53,2)+1),"")) -> 0.44360665 | ... Q53: =IF($E53=1,(LOG(AD53,2)+1),IF($E53=0,(LOG(1-AD53,2)+1),"")) -> 0.48542683 | R53: =SUM(F53:Q53) -> 0.40521096 | S53: =Andrew!D53 -> 0.3 | T53: =Eileen!D53 -> 0.2 | U53: =Iain!D53 -> 0.7 | V53: =Kate!D53 -> 0.8 | W53: =Rohan!D53 -> 0.1 | X53: =David!D53 -> 0.7 | Y53: =Jac!D53 -> 0.8 | Z53: =James!D53 -> 0.68 | AA53: =Chris!D53 -> 0.5 | AB53: =Lachy!D53 -> 0.80218389 | AC53: =Gael!D53 -> 0.9 | AD53: =Bruce!D53 -> 0.7 | AE53: =Jac!E53 -> 0.8 | AF53: =Jac!F53 -> 0.8 | AG53: =Jac!G53 -> 0.7 | AH53: =Bruce!E53 -> 0.6 | AI53: =Bruce!F53 -> 0.8
A54: 53 | B54: Kate | C54: THIS YEAR taylor will release debut re record. | D54: Entertainment | E54: 0 | F54: =IF($E54=1,(LOG(S54,2)+1),IF($E54=0,(LOG(1-S54,2)+1),"")) -> -0.51457317 | G54: =IF($E54=1,(LOG(T54,2)+1),IF($E54=0,(LOG(1-T54,2)+1),"")) -> 0.76553475 | H54: =IF($E54=1,(LOG(U54,2)+1),IF($E54=0,(LOG(1-U54,2)+1),"")) -> -1.3219281 | I54: =IF($E54=1,(LOG(V54,2)+1),IF($E54=0,(LOG(1-V54,2)+1),"")) -> -0.32192809 | J54: =IF($E54=1,(LOG(W54,2)+1),IF($E54=0,(LOG(1-W54,2)+1),"")) -> 0.26303441 | K54: =IF($E54=1,(LOG(X54,2)+1),IF($E54=0,(LOG(1-X54,2)+1),"")) -> 0.48542683 | L54: =IF($E54=1,(LOG(Y54,2)+1),IF($E54=0,(LOG(1-Y54,2)+1),"")) -> 0 | M54: =IF($E54=1,(LOG(Z54,2)+1),IF($E54=0,(LOG(1-Z54,2)+1),"")) -> -0.64385619 | ... Q54: =IF($E54=1,(LOG(AD54,2)+1),IF($E54=0,(LOG(1-AD54,2)+1),"")) -> -1 | R54: =SUM(F54:Q54) -> -3.0252552 | S54: =Andrew!D54 -> 0.65 | T54: =Eileen!D54 -> 0.15 | U54: =Iain!D54 -> 0.8 | V54: =Kate!D54 -> 0.6 | W54: =Rohan!D54 -> 0.4 | X54: =David!D54 -> 0.3 | Y54: =Jac!D54 -> 0.5 | Z54: =James!D54 -> 0.68 | AA54: =Chris!D54 -> 0.5 | AB54: =Lachy!D54 -> 0.5 | AC54: =Gael!D54 -> 0.7 | AD54: =Bruce!D54 -> 0.75 | AE54: =Jac!E54 -> 0.4 | AF54: =Jac!F54 -> 0.4 | AG54: =Jac!G54 -> 0.5 | AH54: =Bruce!E54 -> 0.6 | AI54: =Bruce!F54 -> 0.85
A55: 54 | B55: Kate | C55: There will be NO press photo of William and Harry smiling at each other in 2025: https://www.cambridge-news.co.uk/news/royals/psychic-who-predicted-covid-forecasts-30685794?int_source=amp_continue_reading&int_medium=amp&int_campaign=continue_reading_button#amp-readmore-target | D55: Royals | E55: 1 | F55: =IF($E55=1,(LOG(S55,2)+1),IF($E55=0,(LOG(1-S55,2)+1),"")) -> 0.26303441 | G55: =IF($E55=1,(LOG(T55,2)+1),IF($E55=0,(LOG(1-T55,2)+1),"")) -> -2.3219281 | H55: =IF($E55=1,(LOG(U55,2)+1),IF($E55=0,(LOG(1-U55,2)+1),"")) -> 0 | I55: =IF($E55=1,(LOG(V55,2)+1),IF($E55=0,(LOG(1-V55,2)+1),"")) -> 0.67807191 | J55: =IF($E55=1,(LOG(W55,2)+1),IF($E55=0,(LOG(1-W55,2)+1),"")) -> 0.26303441 | K55: =IF($E55=1,(LOG(X55,2)+1),IF($E55=0,(LOG(1-X55,2)+1),"")) -> 0.48542683 | L55: =IF($E55=1,(LOG(Y55,2)+1),IF($E55=0,(LOG(1-Y55,2)+1),"")) -> 0.67807191 | M55: =IF($E55=1,(LOG(Z55,2)+1),IF($E55=0,(LOG(1-Z55,2)+1),"")) -> -0.83650127 | ... Q55: =IF($E55=1,(LOG(AD55,2)+1),IF($E55=0,(LOG(1-AD55,2)+1),"")) -> 0.13750352 | R55: =SUM(F55:Q55) -> -0.077640168 | S55: =Andrew!D55 -> 0.6 | T55: =Eileen!D55 -> 0.1 | U55: =Iain!D55 -> 0.5 | V55: =Kate!D55 -> 0.8 | W55: =Rohan!D55 -> 0.6 | X55: =David!D55 -> 0.7 | Y55: =Jac!D55 -> 0.8 | Z55: =James!D55 -> 0.28 | AA55: =Chris!D55 -> 0.3 | AB55: =Lachy!D55 -> 0.68997448 | AC55: =Gael!D55 -> 0.9 | AD55: =Bruce!D55 -> 0.55 | AE55: =Jac!E55 -> 0.8 | AF55: =Jac!F55 -> 0.9 | AG55: =Jac!G55 -> 0.7 | AH55: =Bruce!E55 -> 0.5 | AI55: =Bruce!F55 -> 0.6
A56: 55 | B56: Gael | C56: Chimamanda Ngozi Adichie’s novel, “Dream Count” will be shortlisted for the Women’s Prize for fiction. | D56: Entertainment | E56: 0 | F56: =IF($E56=1,(LOG(S56,2)+1),IF($E56=0,(LOG(1-S56,2)+1),"")) -> -0.51457317 | G56: =IF($E56=1,(LOG(T56,2)+1),IF($E56=0,(LOG(1-T56,2)+1),"")) -> 0.67807191 | H56: =IF($E56=1,(LOG(U56,2)+1),IF($E56=0,(LOG(1-U56,2)+1),"")) -> -1.3219281 | I56: =IF($E56=1,(LOG(V56,2)+1),IF($E56=0,(LOG(1-V56,2)+1),"")) -> -2.3219281 | J56: =IF($E56=1,(LOG(W56,2)+1),IF($E56=0,(LOG(1-W56,2)+1),"")) -> -0.32192809 | K56: =IF($E56=1,(LOG(X56,2)+1),IF($E56=0,(LOG(1-X56,2)+1),"")) -> -0.73696559 | L56: =IF($E56=1,(LOG(Y56,2)+1),IF($E56=0,(LOG(1-Y56,2)+1),"")) -> -2.3219281 | M56: =IF($E56=1,(LOG(Z56,2)+1),IF($E56=0,(LOG(1-Z56,2)+1),"")) -> -0.51457317 | ... Q56: =IF($E56=1,(LOG(AD56,2)+1),IF($E56=0,(LOG(1-AD56,2)+1),"")) -> -0.73696559 | R56: =SUM(F56:Q56) -> -9.4808453 | S56: =Andrew!D56 -> 0.65 | T56: =Eileen!D56 -> 0.2 | U56: =Iain!D56 -> 0.8 | V56: =Kate!D56 -> 0.9 | W56: =Rohan!D56 -> 0.6 | X56: =David!D56 -> 0.7 | Y56: =Jac!D56 -> 0.9 | Z56: =James!D56 -> 0.65 | AA56: =Chris!D56 -> 0.5 | AB56: =Lachy!D56 -> 0.35434369 | AC56: =Gael!D56 -> 0.85 | AD56: =Bruce!D56 -> 0.7 | AE56: =Jac!E56 -> 0.6 | AF56: =Jac!F56 -> 0.9 | AG56: =Jac!G56 -> 0.8 | AH56: =Bruce!E56 -> 0.6 | AI56: =Bruce!F56 -> 0.8
...

Sheet Andrew
A1: Name | B1: Prediction | C1: Category | D1: Probability
A2: Rohan | B2: Arsenal will be at the top of the 2025/2026 Premier League table by Christmas. | C2: Sport | D2: 0.45
A3: Rohan | B3: There will be an assassination of a CEO in 2025, sufficiently high-profile to be reported in major news outlets in more than one country. | C3: Society | D3: 0.6
A4: Rohan | B4: As reported by any news outlet or social media, Trump will label sharks as “bad,” “evil,” “not good,” or in any way imply that shark attacks are malicious and immoral acts on behalf of the shark. | C4: Politics | D4: 0.58
A5: Rohan | B5: Oasis will release an album in 2025 | C5: Entertainment | D5: 0.6
A6: Bruce | B6: No party will gain a majority of House of Representatives seats in the Australian federal election | C6: Politics | D6: 0.35
A7: Bruce | B7: Nick Kyrgios will compete in men’s singles in at least three of the four tennis slam events (Australian, French and US opens and Wimbledon) | C7: Sport | D7: 0.7
A8: Bruce | B8: Collingwood will play at least one AFL men’s final in 2025 | C8: Sport | D8: 0.55
A9: Bruce | B9: Alan Jones will be found guilty by a jury on at least one sexual assault charge and will go to jail | C9: Law | D9: 0.65
A10: Bruce | B10: The Reserve Bank will cut interest rates before the Australian Federal election | C10: Finance | D10: 0.85
A11: Eileen | B11: A country with GDP of $30 billion or more will default on its sovereign debt. | C11: Finance | D11: 0.1
A12: Eileen | B12: An AI/LLM "escapes" (moves onto infrastructure it aquired against the intention of the group or person who set it running initally) or is otherwise deemed too dangerous to continue functioning and the entity responsible for running it makes efforts to shut it down. | C12: Technology | D12: 0.15
A13: Eileen | B13: A major national space agency (e.g. NASA) confirms the discovery or otherwise acknowledges evidence of extraterrestrial life. | C13: Society | D13: 0.05
... A60: Gael | B60: The movie “Conclave’ will win Best Adapted Screenplay in the Oscars. | C60: Entertainment | D60: 0.6

Sheet Eileen
A1: Name | B1: Prediction | C1: Category | D1: Probability
A2: Rohan | B2: Arsenal will be at the top of the 2025/2026 Premier League table by Christmas. | C2: Sport | D2: 0.3
A3: Rohan | B3: There will be an assassination of a CEO in 2025, sufficiently high-profile to be reported in major news outlets in more than one country. | C3: Society | D3: 0.1
A4: Rohan | B4: As reported by any news outlet or social media, Trump will label sharks as “bad,” “evil,” “not good,” or in any way imply that shark attacks are malicious and immoral acts on behalf of the shark. | C4: Politics | D4: 0.1
A5: Rohan | B5: Oasis will release an album in 2025 | C5: Entertainment | D5: 0.2
A6: Bruce | B6: No party will gain a majority of House of Representatives seats in the Australian federal election | C6: Politics | D6: 0.3
A7: Bruce | B7: Nick Kyrgios will compete in men’s singles in at least three of the four tennis slam events (Australian, French and US opens and Wimbledon) | C7: Sport | D7: 0.5
A8: Bruce | B8: Collingwood will play at least one AFL men’s final in 2025 | C8: Sport | D8: 0.8
A9: Bruce | B9: Alan Jones will be found guilty by a jury on at least one sexual assault charge and will go to jail | C9: Law | D9: 0.5
A10: Bruce | B10: The Reserve Bank will cut interest rates before the Australian Federal election | C10: Finance | D10: 0.6
A11: Eileen | B11: A country with GDP of $30 billion or more will default on its sovereign debt. | C11: Finance | D11: 0.4
A12: Eileen | B12: An AI/LLM "escapes" (moves onto infrastructure it aquired against the intention of the group or person who set it running initally) or is otherwise deemed too dangerous to continue functioning and the entity responsible for running it makes efforts to shut it down. | C12: Technology | D12: 0.65
A13: Eileen | B13: A major national space agency (e.g. NASA) confirms the discovery or otherwise acknowledges evidence of extraterrestrial life. | C13: Society | D13: 0.2
... A60: Gael | B60: The movie “Conclave’ will win Best Adapted Screenplay in the Oscars. | C60: Entertainment | D60: 0.5

Sheet Iain
A1: Name | B1: Prediction | C1: Category | D1: Probability
A2: Rohan | B2: Arsenal will be at the top of the 2025/2026 Premier League table by Christmas. | C2: Sport | D2: 0.6
A3: Rohan | B3: There will be an assassination of a CEO in 2025, sufficiently high-profile to be reported in major news outlets in more than one country. | C3: Society | D3: 0.7
A4: Rohan | B4: As reported by any news outlet or social media, Trump will label sharks as “bad,” “evil,” “not good,” or in any way imply that shark attacks are malicious and immoral acts on behalf of the shark. | C4: Politics | D4: 0.3
A5: Rohan | B5: Oasis will release an album in 2025 | C5: Entertainment | D5: 0.7
A6: Bruce | B6: No party will gain a majority of House of Representatives seats in the Australian federal election | C6: Politics | D6: 0.6
A7: Bruce | B7: Nick Kyrgios will compete in men’s singles in at least three of the four tennis slam events (Australian, French and US opens and Wimbledon) | C7: Sport | D7: 0.2
A8: Bruce | B8: Collingwood will play at least one AFL men’s final in 2025 | C8: Sport | D8: 0.5
A9: Bruce | B9: Alan Jones will be found guilty by a jury on at least one sexual assault charge and will go to jail | C9: Law | D9: 0.6
A10: Bruce | B10: The Reserve Bank will cut interest rates before the Australian Federal election | C10: Finance | D10: 0.4
A11: Eileen | B11: A country with GDP of $30 billion or more will default on its sovereign debt. | C11: Finance | D11: 0.2
A12: Eileen | B12: An AI/LLM "escapes" (moves onto infrastructure it aquired against the intention of the group or person who set it running initally) or is otherwise deemed too dangerous to continue functioning and the entity responsible for running it makes efforts to shut it down. | C12: Technology | D12: 0.2
A13: Eileen | B13: A major national space agency (e.g. NASA) confirms the discovery or otherwise acknowledges evidence of extraterrestrial life. | C13: Society | D13: 0.2
... A60: Gael | B60: The movie “Conclave’ will win Best Adapted Screenplay in the Oscars. | C60: Entertainment | D60: 0.6

Sheet Kate
A1: Name | B1: Prediction | C1: Category | D1: Probability
A2: Rohan | B2: Arsenal will be at the top of the 2025/2026 Premier League table by Christmas. | C2: Sport | D2: 0.7
A3: Rohan | B3: There will be an assassination of a CEO in 2025, sufficiently high-profile to be reported in major news outlets in more than one country. | C3: Society | D3: 0.3
A4: Rohan | B4: As reported by any news outlet or social media, Trump will label sharks as “bad,” “evil,” “not good,” or in any way imply that shark attacks are malicious and immoral acts on behalf of the shark. | C4: Politics | D4: 0.6
A5: Rohan | B5: Oasis will release an album in 2025 | C5: Entertainment | D5: 0.3
A6: Bruce | B6: No party will gain a majority of House of Representatives seats in the Australian federal election | C6: Politics | D6: 0.6
A7: Bruce | B7: Nick Kyrgios will compete in men’s singles in at least three of the four tennis slam events (Australian, French and US opens and Wimbledon) | C7: Sport | D7: 0.4
A8: Bruce | B8: Collingwood will play at least one AFL men’s final in 2025 | C8: Sport | D8: 0.6
A9: Bruce | B9: Alan Jones will be found guilty by a jury on at least one sexual assault charge and will go to jail | C9: Law | D9: 0.2
A10: Bruce | B10: The Reserve Bank will cut interest rates before the Australian Federal election | C10: Finance | D10: 0.6
